Workbook

Sheet Cover
A1: Vanraj Furniture Industries Private Limited
A2: CIN: U36101MH2009PTC194327 | Registered office: Plot No. 47, Anjur Phata Industrial Area, Bhiwandi, Thane 421302, Maharashtra
A3: Financial statements for the period Year ended 31 March 2025
A4: Status: Audited
A5: Amounts in Rs. Lakhs
A7: Contents of this workbook: Balance Sheet, Statement of Profit and Loss, Cash Flow Statement and Notes forming part of the financial statements.
A8: Nature of business: manufacture and sale of home, office and institutional furniture (solid wood, engineered wood and upholstered products) from the factory at Bhiwandi, Thane, sold through company-owned showrooms, dealers, e-commerce marketplaces and contract supplies.
A9: Basis of preparation: Indian GAAP (Accounting Standards notified under the Companies (Accounting Standards) Rules, 2021), Schedule III Division I format, historical cost convention, accrual basis.
A10: Significant accounting policies: inventories at lower of cost (weighted average) and net realisable value; depreciation on WDV basis using Schedule II useful lives; revenue recognised on transfer of significant risks and rewards (dispatch), net of GST, returns and discounts; gratuity provided on actuarial valuation; deferred tax on timing differences.
A11: Statutory auditors: Mehta Sanghvi & Co., Chartered Accountants (Firm Registration No. 108541W), Mumbai. Audit report dated 30 August 2025, unmodified opinion.
A12: Approved by the Board of Directors on 30 August 2025.
A13: All data in this workbook is imaginary and has been prepared solely for the purpose of testing a valuation model. Any resemblance to an actual company is coincidental.

Sheet Notes
A1: Vanraj Furniture Industries Private Limited
A2: CIN: U36101MH2009PTC194327
A3: Notes forming part of the financial statements (Audited financial statements)
A4: Amounts in Rs. Lakhs
A6: Particulars | C6: As at 31 March 2025 | D6: As at 31 March 2024
A8: Note 1: Share capital
A9: Authorised
A10: 60,00,000 equity shares of Rs. 10 each | C10: 600 | D10: 600
A11: 5,00,000 preference shares of Rs. 100 each | C11: 500 | D11: 500
A12: Issued, subscribed and fully paid up
A13: Number of equity shares of Rs. 10 each (in numbers) | C13: 5000000 | D13: 5000000
A14: Face value per equity share (Rs.) | C14: 10 | D14: 10
A15: Equity share capital | C15: =C13*C14/100000 -> 500 | D15: =D13*D14/100000 -> 500
A16: Number of 0.01% Compulsorily Convertible Preference Shares (CCPS) of Rs. 100 each (in numbers) | C16: 0 | D16: 0
A17: Face value per CCPS (Rs.) | C17: 100 | D17: 100
A18: Preference share capital (CCPS) | C18: =C16*C17/100000 -> 0 | D18: =D16*D17/100000 -> 0
A19: Total share capital | C19: =C15+C18 -> 500 | D19: =D15+D18 -> 500
A20: CCPS were issued on 12 November 2025 at Rs. 200 per share (face value Rs. 100, premium Rs. 100). Each CCPS is convertible into 2.5 equity shares of Rs. 10 each at the option of the holder or compulsorily on 11 November 2030.
A21: Shares held by shareholders holding more than 5% (see separate shareholding pattern file).
A23: Note 2: Reserves and surplus
A24: Securities premium
A25: Opening balance | C25: 0 | D25: 0
A26: Add: premium received on issue of CCPS during the period | C26: 0 | D26: 0
A27: Closing balance | C27: =C25+C26 -> 0 | D27: =D25+D26 -> 0
A28: Surplus in statement of profit and loss
A29: Opening balance | C29: 2140 | D29: 1618
A30: Add: profit for the period (from Statement of Profit and Loss) | C30: ='Profit and Loss'!C24 -> 478 | D30: 522
A31: Closing balance | C31: =C29+C30 -> 2618 | D31: =D29+D30 -> 2140
A32: Total reserves and surplus | C32: =C27+C31 -> 2618 | D32: =D27+D31 -> 2140
A33: No dividend has been declared or paid in any of the periods presented.
A35: Note 3: Long-term borrowings
A36: Term loans from banks (secured) | C36: 714 | D36: 805
A37: Vehicle loans from banks (secured) | C37: 51 | D37: 57.5
A38: Unsecured loans from directors | C38: 255 | D38: 287.5
A39: Total | C39: =SUM(C36:C38) -> 1020 | D39: =SUM(D36:D38) -> 1150
A40: Term loans are secured by hypothecation of plant and machinery and equitable mortgage of factory land and building at Bhiwandi, Thane, and carry interest at 9.25% p.a. Unsecured loans from directors carry interest at 9% p.a. and are repayable after 31 March 2028. Current maturities are disclosed under other current liabilities.
A42: Note 4: Deferred tax liabilities (net)
A43: Deferred tax liability on difference between book and tax depreciation | C43: 110 | D43: 95
A45: Note 5: Long-term provisions
A46: Provision for gratuity | C46: 49 | D46: 42
...

Sheet Balance Sheet
A1: Vanraj Furniture Industries Private Limited
A2: CIN: U36101MH2009PTC194327
A3: Balance Sheet as at 31 March 2025 (Audited)
A4: Amounts in Rs. Lakhs
A6: Particulars | B6: Note | C6: As at 31 March 2025 (Audited) | D6: As at 31 March 2024 (Audited)
A7: EQUITY AND LIABILITIES
A8: Shareholders' funds
A9: Share capital | B9: 1 | C9: =Notes!C19 -> 500 | D9: =Notes!D19 -> 500
A10: Reserves and surplus | B10: 2 | C10: =Notes!C32 -> 2618 | D10: =Notes!D32 -> 2140
A11: Total shareholders' funds | C11: =C9+C10 -> 3118 | D11: =D9+D10 -> 2640
A12: Non-current liabilities
A13: Long-term borrowings | B13: 3 | C13: =Notes!C39 -> 1020 | D13: =Notes!D39 -> 1150
A14: Deferred tax liabilities (net) | B14: 4 | C14: =Notes!C43 -> 110 | D14: =Notes!D43 -> 95
A15: Long-term provisions | B15: 5 | C15: =Notes!C48 -> 70 | D15: =Notes!D48 -> 60
A16: Total non-current liabilities | C16: =SUM(C13:C15) -> 1200 | D16: =SUM(D13:D15) -> 1305
A17: Current liabilities
A18: Short-term borrowings | B18: 6 | C18: =Notes!C53 -> 860 | D18: =Notes!D53 -> 780
A19: Trade payables | B19: 7 | C19: =Notes!C59 -> 1080 | D19: =Notes!D59 -> 940
A20: Other current liabilities | B20: 8 | C20: =Notes!C68 -> 350 | D20: =Notes!D68 -> 310
A21: Short-term provisions | B21: 9 | C21: =Notes!C74 -> 95 | D21: =Notes!D74 -> 85
A22: Total current liabilities | C22: =SUM(C18:C21) -> 2385 | D22: =SUM(D18:D21) -> 2115
A23: TOTAL EQUITY AND LIABILITIES | C23: =C11+C16+C22 -> 6703 | D23: =D11+D16+D22 -> 6060
A25: ASSETS
A26: Non-current assets
A27: Property, plant and equipment | B27: 10 | C27: =Notes!K85 -> 2620 | D27: =Notes!L85 -> 2450
A28: Capital work-in-progress | B28: 11 | C28: =Notes!C89 -> 180 | D28: =Notes!D89 -> 120
A29: Intangible assets | B29: 12 | C29: =Notes!C95 -> 30 | D29: =Notes!D95 -> 35
A30: Long-term loans and advances | B30: 13 | C30: =Notes!C101 -> 150 | D30: =Notes!D101 -> 140
A31: Other non-current assets | B31: 14 | C31: =Notes!C105 -> 45 | D31: =Notes!D105 -> 40
A32: Total non-current assets | C32: =SUM(C27:C31) -> 3025 | D32: =SUM(D27:D31) -> 2785
A33: Current assets
A34: Inventories | B34: 15 | C34: =Notes!C112 -> 1560 | D34: =Notes!D112 -> 1380
A35: Trade receivables | B35: 16 | C35: =Notes!C117 -> 1410 | D35: =Notes!D117 -> 1210
A36: Cash and bank balances | B36: 17 | C36: =Notes!C123 -> 388 | D36: =Notes!D123 -> 400
A37: Short-term loans and advances | B37: 18 | C37: =Notes!C130 -> 210 | D37: =Notes!D130 -> 190
A38: Other current assets | B38: 19 | C38: =Notes!C135 -> 110 | D38: =Notes!D135 -> 95
A39: Total current assets | C39: =SUM(C34:C38) -> 3678 | D39: =SUM(D34:D38) -> 3275
A40: TOTAL ASSETS | C40: =C32+C39 -> 6703 | D40: =D32+D39 -> 6060
A42: Check: total assets less total equity and liabilities (should be nil) | C42: =ROUND(C40-C23,2) -> 0 | D42: =ROUND(D40-D23,2) -> 0
A44: Legend: blue figures are hardcoded inputs; black figures are formulas within the sheet; green figures are links to other sheets.
...

Sheet Profit and Loss
A1: Vanraj Furniture Industries Private Limited
A2: CIN: U36101MH2009PTC194327
A3: Statement of Profit and Loss for the period Year ended 31 March 2025 (Audited)
A4: Amounts in Rs. Lakhs
A6: Particulars | B6: Note | C6: Year ended 31 March 2025 (Audited) | D6: Year ended 31 March 2024 (Audited)
A7: INCOME
A8: Revenue from operations | B8: 20 | C8: =Notes!C143 -> 9650 | D8: =Notes!D143 -> 8200
A9: Other income | B9: 21 | C9: =Notes!C150 -> 48 | D9: =Notes!D150 -> 42
A10: Total income | C10: =C8+C9 -> 9698 | D10: =D8+D9 -> 8242
A11: EXPENSES
A12: Cost of materials consumed | B12: 22 | C12: =Notes!C156 -> 5260 | D12: =Notes!D156 -> 4520
A13: Changes in inventories of finished goods and work-in-progress | B13: 23 | C13: =Notes!C163 -> -95 | D13: =Notes!D163 -> -60
A14: Employee benefits expense | B14: 24 | C14: =Notes!C170 -> 1210 | D14: =Notes!D170 -> 1040
A15: Finance costs | B15: 25 | C15: =Notes!C178 -> 260 | D15: =Notes!D178 -> 245
A16: Depreciation and amortisation expense | B16: 26 | C16: =Notes!C183 -> 310 | D16: =Notes!D183 -> 285
A17: Other expenses | B17: 27 | C17: =Notes!C199 -> 2050 | D17: =Notes!D199 -> 1480
A18: Total expenses | C18: =SUM(C12:C17) -> 8995 | D18: =SUM(D12:D17) -> 7510
A20: Profit before tax | C20: =C10-C18 -> 703 | D20: =D10-D18 -> 732
A21: Tax expense
A22: Current tax | B22: 28 | C22: =Notes!C202 -> 210 | D22: =Notes!D202 -> 190
A23: Deferred tax | B23: 28 | C23: =Notes!C203 -> 15 | D23: =Notes!D203 -> 20
A24: Profit for the period | C24: =C20-C22-C23 -> 478 | D24: =D20-D22-D23 -> 522
A26: Supplementary information (not part of the statutory format)
A27: EBITDA (profit before tax + finance costs + depreciation and amortisation - other income) | C27: =C20+C15+C16-C9 -> 1225 | D27: =D20+D15+D16-D9 -> 1220
A28: EBITDA margin (% of revenue from operations) | C28: =IF(C8=0,0,C27/C8) -> 0.12694301 | D28: =IF(D8=0,0,D27/D8) -> 0.14878049
A29: Net profit margin (% of revenue from operations) | C29: =IF(C8=0,0,C24/C8) -> 0.049533679 | D29: =IF(D8=0,0,D24/D8) -> 0.063658537
A30: Basic earnings per equity share (Rs.) (not annualised) | C30: =C24*100000/Notes!C13 -> 9.56 | D30: =D24*100000/Notes!D13 -> 10.44
A32: Legend: blue figures are hardcoded inputs; black figures are formulas within the sheet; green figures are links to other sheets.
A33: All figures are illustrative and imaginary, prepared solely for testing a valuation model. Amounts in Rs. Lakhs unless stated otherwise.

Sheet Cash Flow
A1: Vanraj Furniture Industries Private Limited
A2: CIN: U36101MH2009PTC194327
A3: Cash Flow Statement for the period Year ended 31 March 2025 (Audited) - indirect method
A4: Amounts in Rs. Lakhs
A6: Particulars | C6: Year ended 31 March 2025 (Audited) | D6: Year ended 31 March 2024 (Audited)
A7: A. Cash flow from operating activities
A8: Profit before tax | C8: ='Profit and Loss'!C20 -> 703 | D8: 732
A9: Adjustments for:
A10: Depreciation and amortisation | C10: ='Profit and Loss'!C16 -> 310 | D10: 285
A11: Finance costs | C11: ='Profit and Loss'!C15 -> 260 | D11: 245
A12: Other income (interest and other non-operating income) | C12: =-'Profit and Loss'!C9 -> -48 | D12: -42
A13: Operating profit before working capital changes | C13: =SUM(C8:C12) -> 1225 | D13: =SUM(D8:D12) -> 1220
A14: Movements in working capital:
A15: (Increase) / decrease in inventories | C15: ='Balance Sheet'!D34-'Balance Sheet'!C34 -> -180 | D15: -130
A16: (Increase) / decrease in trade receivables | C16: ='Balance Sheet'!D35-'Balance Sheet'!C35 -> -200 | D16: -130
A17: (Increase) / decrease in short-term loans and advances | C17: ='Balance Sheet'!D37-'Balance Sheet'!C37 -> -20 | D17: -20
A18: (Increase) / decrease in other current assets | C18: ='Balance Sheet'!D38-'Balance Sheet'!C38 -> -15 | D18: -10
A19: (Increase) / decrease in long-term loans and advances | C19: ='Balance Sheet'!D30-'Balance Sheet'!C30 -> -10 | D19: -10
A20: (Increase) / decrease in other non-current assets | C20: ='Balance Sheet'!D31-'Balance Sheet'!C31 -> -5 | D20: -5
A21: Increase / (decrease) in trade payables | C21: ='Balance Sheet'!C19-'Balance Sheet'!D19 -> 140 | D21: 120
A22: Increase / (decrease) in other current liabilities | C22: ='Balance Sheet'!C20-'Balance Sheet'!D20 -> 40 | D22: 30
A23: Increase / (decrease) in long-term provisions | C23: ='Balance Sheet'!C15-'Balance Sheet'!D15 -> 10 | D23: 10
A24: Increase / (decrease) in short-term provisions | C24: ='Balance Sheet'!C21-'Balance Sheet'!D21 -> 10 | D24: 10
A25: Cash generated from operations | C25: =C13+SUM(C15:C24) -> 995 | D25: =D13+SUM(D15:D24) -> 1085
A26: Less: income taxes paid (net) | C26: =-'Profit and Loss'!C22 -> -210 | D26: -190
A27: Net cash from operating activities (A) | C27: =C25+C26 -> 785 | D27: =D25+D26 -> 895
A29: B. Cash flow from investing activities
A30: Purchase of property, plant and equipment, intangibles and capital work-in-progress | C30: =-(('Balance Sheet'!C27-'Balance Sheet'!D27)+('Balance Sheet'!C28-'Balance Sheet'!D28)+('Balance Sheet'!C29-'Balance Sheet'!D29)+'Profit and Loss'!C16) -> -535 | D30: -370
A31: Interest and other income received | C31: ='Profit and Loss'!C9 -> 48 | D31: 42
A32: Net cash used in investing activities (B) | C32: =C30+C31 -> -487 | D32: =D30+D31 -> -328
A34: C. Cash flow from financing activities
A35: Proceeds from issue of share capital (including securities premium) | C35: =('Balance Sheet'!C9-'Balance Sheet'!D9)+(Notes!C26) -> 0 | D35: 0
A36: Proceeds from / (repayment of) long-term borrowings (net) | C36: ='Balance Sheet'!C13-'Balance Sheet'!D13 -> -130 | D36: -250
A37: Proceeds from / (repayment of) short-term borrowings (net) | C37: ='Balance Sheet'!C18-'Balance Sheet'!D18 -> 80 | D37: 80
A38: Finance costs paid | C38: =-'Profit and Loss'!C15 -> -260 | D38: -245
A39: Net cash from / (used in) financing activities (C) | C39: =SUM(C35:C38) -> -310 | D39: =SUM(D35:D38) -> -415
A41: Net increase / (decrease) in cash and bank balances (A+B+C) | C41: =C27+C32+C39 -> -12 | D41: =D27+D32+D39 -> 152
A42: Cash and bank balances at the beginning of the period | C42: ='Balance Sheet'!D36 -> 400 | D42: 248
A43: Cash and bank balances at the end of the period | C43: =C41+C42 -> 388 | D43: =D41+D42 -> 400
A44: Check: closing cash per cash flow less cash per balance sheet (should be nil) | C44: =ROUND(C43-'Balance Sheet'!C36,2) -> 0 | D44: =ROUND(D43-'Balance Sheet'!D36,2) -> 0
...
