Workbook

Sheet Master
A4: Report Of | B4: XT INDIA
A5: From Date | B5: 46113
A6: To Date | B6: 46142 | C6: =UPPER(TEXT(B6,"MMM-YY")) -> APR-26
A8: Sr No | B8: Name of the Report | C8: Link
A10: 1 | B10: Petty Cash | C10: Petty Cash
A12: 2 | B12: Cheque Issued | C12: Cheque issued
A14: 3 | B14: Bank Book | C14: Bank book
A16: 4 | B16: Bank Statement | C16: Bank Statement
A18: 5 | B18: Direct Expenses - ICE | C18: DE-ICE
A20: 6 | B20: Direct Expenses - XT | C20: DE-XT
A22: 7 | B22: General Expenses | C22: General
A24: 8 | B24: Employees Loan Repayment | C24: Employees Loan Repayment
A26: 9 | B26: Inter Company Transfer | C26: Inter Company Transfer
A28: 10 | B28: Crew on Board | C28: CB
A30: 11 | B30: Cost Report | C30: CR
A32: 12 | B32: Consolidated Cost Report | C32: Consolidated CR

Sheet Cheque issued
B2: DBS | C2: Cheque issued for the month of APR 2026
B4: DATE | C4: CHEQUE NO | D4: PARTICULARS | E4: AMOUNT | F4: Type of Exp | G4: Nature of Expenses
B5: 46134 | C5: 000016 | D5: Universal Currency Exchange (I) Pvt Ltd - 16 BY IWCLG/000016/UNIVERSAL CURRENCY EXCHAN/HDFC BANK LTD. | E5: 113050 | F5: Travelling Expenses | G5: Bill no. 6200155 dt. 20.04.26 USD 1200 for rate 93.90 to vessel visit - Cape med
D7: TOTAL | E7: =SUM(E5:E6) -> 113050
B10: AXIS | C10: Cheque issued for the month of APR 2026
B12: DATE | C12: CHEQUE NO | D12: PARTICULARS | E12: AMOUNT | F12: Type of Exp | G12: Nature of Expenses
D13: No cheque issued during the month | E13: 0
D15: TOTAL | E15: =SUM(E13:E14) -> 0

Sheet Petty Cash
B2: XT SHIPS MANAGEMENT INDIA PVT LTD
B6: XT Ships Management India Pvt.Ltd.
B7: Petty Cash for the month of APR 2026
B8: DATE | C8: NAME | E8: AMT Recevd in USD | F8: Amt Rece | G8: Amt paid | H8: Balance
D10: Bal Cd fwd of 31.03.26 | H10: 5145
B11: 01.04.26 | C11: Santhana Clyobas Prosper Rajiv | D11: Being paid for transport services for spare carried to Vessel Blue Sky. Remaining excess amount handed over to India office & same has been credited to ICE DA. | F11: 3400 | G11: 0 | H11: =H10+F11 -> 8545
B12: 07.04.26 | C12: Cash Paid | D12: Airtel sim service fee, lunch expenses paid towards chair old & new pick up on Saturday, sanjay towards MIDC for Knife pick up | G12: 1151 | H12: =H11-G12 -> 7394
B13: 12.04.26 | C13: Bajrang Auto Service | D13: Petrol expenses | G13: 1000 | H13: =H12-G13 -> 6394
B14: 14.04.26 | C14: Siddhivinayak Medical | D14: sanitary pad Siddhivinayak medical | G14: 565 | H14: =H13-G14 -> 5829
B15: 14.04.26 | C15: Sanjay | D15: ambedkar jayanti closed tso sanjay brought fruits | G15: 870 | H15: =H14-G15 -> 4959
B16: 14.04.26 | C16: Cash Paid | D16: dishwash salt & Liquid set | G16: 1201 | H16: =H15-G16 -> 3758
B17: 16.04.26 | C17: Cash Paid | D17: Lunch for officer | G17: 340 | H17: =H16-G17 -> 3418
B18: 20.04.26 | C18: Sai Palace Hotel | D18: Lunch for cadet & officer | G18: 624 | H18: =H17-G18 -> 2794
B19: 21.04.26 | C19: Sai Palace Hotel | D19: Lunch for cadet & officer | G19: 624 | H19: =H18-G19 -> 2170
B20: 28.04.26 | C20: We Fast | D20: Conversion letter to Axis bank | G20: 420 | H20: =H19-G20 -> 1750
B21: 28.04.26 | C21: Sai Palace Hotel | D21: Rohit Suthar & officer | G21: 851 | H21: =H20-G21 -> 899
B22: 30.04.26 | C22: Sai Palace Hotel | D22: Rohit Suthar & officer | G22: 926 | H22: =H21-G22 -> -27
B23: 30.04.26 | C23: Axis Bank 6132 | D23: (No narration in Tally - Contra 4: cash withdrawn from Axis Bank 455010200006132) | F23: 20000 | G23: 0 | H23: =H22+F23 -> 19973
E28: =E10 -> 0 | G28: =SUM(G11:G27) -> 8572

Sheet DE-XT
A1: XT Ships Management India Pvt.Ltd. | P1: 26 APR
P2: XT
A5: ="XT MANAGEMENT INC - for the month of "&Master!C6 -> XT MANAGEMENT INC - for the month of APR-26
B7: Company Name | C7: Total Amount (INR) | D7: Total Amount (USD)
B8: XT | C8: =$J$156 -> 3036049.3 | D8: =$L$156 -> 31977.533
B9: ICE | C9: ='DE-ICE'!C9 -> 918550 | D9: ='DE-ICE'!D9 -> 9674.7318
B10: Grand Total | C10: =SUM(C8:C9) -> 3954599.3 | D10: =SUM(D8:D9) -> 41652.265
A12: SR | B12: NAME | C12: RANK | D12: VESSEL To /From | E12: TYPE OF EXPENSE | F12: BOOKED BY | G12: BILL RECEIVED DATE | H12: NAME OF COMPANY | I12: Inv no. | J12: Taxable Amount | K12: Exch rate as on 04.05.2026 | L12: Amount in USD | M12: GST | N12: Invoice Amount | O12: Eligibility | P12: DOC REF NO
A13: 1 | E13: Amount transferred from DBS AC 0001 towards Cash advance as per instructions from principals (USD 1100) | G13: 46113 | H13: Vincent Alexander | I13: 1 | J13: 102531 | K13: =Forex!$C$2 -> 94.9432 | L13: =J13/K13 -> 1079.9194 | M13: 0 | N13: =J13+M13 -> 102531 | O13: Non-GST | P13: 26 APR /XT/1186
A14: 2 | E14: JAN TO MAR 26 - PAID on 15.04.26 | G14: 46127 | H14: Seafarers Welfare Fund Society | I14: 3 | J14: 372967 | K14: =Forex!$C$2 -> 94.9432 | L14: =J14/K14 -> 3928.3171 | M14: 0 | N14: =J14+M14 -> 372967 | O14: Non-GST | P14: 26 APR /XT/2
A15: 3 | E15: Cook training & orientation program with room stay from 10.04.26 to 14.04.26 | G15: 46120 | H15: SIR Mohamed Yusuf Seamen Welfare Foundation | I15: CAT-26-27/6 | J15: 367950 | K15: =Forex!$C$2 -> 94.9432 | L15: =J15/K15 -> 3875.475 | M15: 66231 | N15: =J15+M15 -> 434181 | O15: Eligible | P15: 26 APR /XT/3
A16: 4 | E16: 20908 dt. 08.04.26 IKEA 365 + Knife S3 for Cook training pragramme Reimb | G16: 46120 | H16: IKEA | I16: 20908 | J16: 21049 | K16: =Forex!$C$2 -> 94.9432 | L16: =J16/K16 -> 221.70097 | M16: 0 | N16: =J16+M16 -> 21049 | O16: Non-GST | P16: 26 APR /XT/4
A17: 5 | E17: Cook Cap & Apron for Trainee Cooks - 20 Nos | G17: 46125 | H17: Best Marine Pvt Ltd | I17: 2627-AD364 | J17: 16188 | K17: =Forex!$C$2 -> 94.9432 | L17: =J17/K17 -> 170.50194 | M17: 0 | N17: =J17+M17 -> 16188 | O17: Non-GST | P17: 26 APR /XT/5
A18: 6 | E18: Courier charges for receiving Mannuals from Synergy office Chennai to Mumbai - India office - 25 Boxes for vessel - MH Arpeggio 13 & MH Adagio 12 against AWB no. D3504359612 | G18: 46132 | H18: Emmar Associates | I18: EA0042/26-27 | J18: 21000 | K18: =Forex!$C$2 -> 94.9432 | L18: =J18/K18 -> 221.18488 | M18: 3780 | N18: =J18+M18 -> 24780 | O18: Eligible | P18: 26 APR /XT/6
A19: 7 | E19: Medical signed off on 13.12.25 due to backache & severe pain in RT leg & hip joint - Sea bird consultation dt/ 18.02.26 , physiotherapy sessions & medications from 18.02.26 to 04.04.26 | G19: 46129 | H19: DIVYA KUMARI PASANTKUMAR TANDEL | I19: 4 | J19: 17307.76 | K19: =Forex!$C$2 -> 94.9432 | L19: =J19/K19 -> 182.29594 | M19: 0 | N19: =J19+M19 -> 17307.76 | O19: Non-GST | P19: 26 APR /XT/7
A20: 8 | E20: Amount transferred from DBS AC 0001 towards Cash advance as per instructions from principals (USD 1057.50) | G20: 46142 | H20: Sujesh Aravindan | I20: 5 | J20: 98569.58 | K20: =Forex!$C$2 -> 94.9432 | L20: =J20/K20 -> 1038.1953 | M20: 0 | N20: =J20+M20 -> 98569.58 | O20: Non-GST | P20: 26 APR /XT/8
A21: 9 | E21: Medical sigend for Ottis media, done left tympanoplasty. Dr. consultation charges & lab test dt. 03.01.26 to 31.03.26 | G21: 46142 | H21: Sea Bird Medicare Pvt. Ltd. | I21: SB/PNI/2627/021 | J21: 3750 | K21: =Forex!$C$2 -> 94.9432 | L21: =J21/K21 -> 39.497299 | M21: 0 | N21: =J21+M21 -> 3750 | O21: Non-GST | P21: 26 APR /XT/9
A22: 10 | E22: Professional fees for board training at Green Forest at Lisas from 21.02.26 to 24.02.26 traveling cost from 19.02.26 to 20.02.26 | G22: 46122 | H22: Shanker Das | I22: 8 | J22: 199100 | K22: =Forex!$C$2 -> 94.9432 | L22: =J22/K22 -> 2097.0433 | M22: 0 | N22: =J22+M22 -> 199100 | O22: Non-GST | P22: 26 APR /XT/10
A23: 11 | E23: Bill no P00417 dt. 24.04.26 Go pro purchase for parwinder singh , same has been handed over to CC ajinkya badekar at sea bird medicare Centre while PJM on 25.04.26 | G23: 46140 | H23: Swiggy | I23: P00417 | J23: 16011 | K23: =Forex!$C$2 -> 94.9432 | L23: =J23/K23 -> 168.63767 | M23: 0 | N23: =J23+M23 -> 16011 | O23: Non-GST | P23: 26 APR /XT/11
A24: 12 | E24: Reimbursment expenses for seafarers signed on/off | G24: 46121 | H24: Creditors for Travelling | I24: 6 | J24: 970593 | K24: =Forex!$C$2 -> 94.9432 | L24: =J24/K24 -> 10222.881 | M24: 0 | N24: =J24+M24 -> 970593 | O24: Non-GST | P24: 626 APR /XT/12
... A138: 126 | E138: REMITTANCE CHARGES - GST ON Fx 0853IT0517861 C317368OCP040126 XT SHIPS MANA XT SHIPS MANAGEMENT INDIA USD 689062.76 at INR93.2100000000 UETR Ref:7953f2b8-08c7-4e89-be58-cb51bcc0691c | G138: 46114 | H138: DBS Bank Ltd | I138: NA | J138: 10800 | K138: =Forex!$C$2 -> 94.9432 | L138: =J138/K138 -> 113.75222 | M138: 0 | N138: =J138+M138 -> 10800 | O138: Non-GST | P138: Payment 2 dt. 02.04.26
A156: Total | J156: =SUM(J13:J155) -> 3036049.3 | L156: =SUM(L13:L155) -> 31977.533 | M156: =SUM(M13:M155) -> 72784.48 | N156: =SUM(N13:N155) -> 3108833.8

Sheet DE-ICE
A1: =UPPER(" XT Ships Management India Pvt.Ltd.") -> XT SHIPS MANAGEMENT INDIA PVT.LTD. | P1: 26 APR
P2: ICE
A5: ="International Crewing Experts Inc. - for the month of "&Master!C6 -> International Crewing Experts Inc. - for the month of APR-26
B7: Company Name | C7: Total Amount (INR) | D7: Total Amount (USD)
B8: XT | C8: ='DE-XT'!C8 -> 3036049.3 | D8: ='DE-XT'!D8 -> 31977.533
B9: ICE | C9: =$J$80 -> 918550 | D9: =$L$80 -> 9674.7318
B10: Grand Total | C10: =SUM(C8:C9) -> 3954599.3 | D10: =SUM(D8:D9) -> 41652.265
A12: SR.NO | B12: NAME | C12: RANK | D12: VESSEL To /From | E12: TYPE OF EXPENSE | F12: BOOKED BY | G12: BILL RECEIVED DATE | H12: NAME OF COMPANY | I12: Inv no. | J12: Taxable Amount | K12: Exch rate as on 04.05.2026 | L12: Amount in USD | M12: GST | N12: Invoice Amount | O12: Eligibility | P12: Doc No
A13: 1 | E13: Fruit basket to the crew residence as a Get Well Soon gesture for speedy recovery & well wishes Tarkeshwar Singh | G13: 46142 | H13: Creative Gifting Solutions Pvt Ltd | I13: CGS/2026-27/14 | J13: 2000 | K13: =Forex!$C$2 -> 94.9432 | L13: =J13/K13 -> 21.065226 | M13: 0 | N13: =J13+M13 -> 2000 | O13: Non-GST | P13: =+$P$1&"/"&$P$2&"/"&A13 -> 26 APR/ICE/1
A14: 2 | E14: Fruit basket to the crew residence as a Get Well Soon gesture for speedy recovery & well wishes Kiran Kumar | G14: 46142 | H14: Creative Gifting Solutions Pvt Ltd | I14: CGS/2026-27/14 | J14: 2000 | K14: =Forex!$C$2 -> 94.9432 | L14: =J14/K14 -> 21.065226 | M14: 0 | N14: =J14+M14 -> 2000 | O14: Non-GST | P14: =+$P$1&"/"&$P$2&"/"&A14 -> 26 APR/ICE/2
A15: 3 | E15: JAN TO MAR 26 - PAID on 15.04.26 | G15: 46127 | H15: Seafarers Welfare Fund Society | I15: 3 | J15: 372083 | K15: =Forex!$C$2 -> 94.9432 | L15: =J15/K15 -> 3919.0063 | M15: 0 | N15: =J15+M15 -> 372083 | O15: Non-GST | P15: =+$P$1&"/"&$P$2&"/"&A15 -> 26 APR/ICE/3
A16: 4 | E16: Being paid for transport services for spare carried to Vessel Blue Sky. Remaining excess amount handed over to India office & same has been credited to ICE DA. Santhana Clyobas Prosper Rajiv | G16: 46127 | H16: Santhana Clyobas Prosper Rajiv | I16: 2 | J16: -3400 | K16: =Forex!$C$2 -> 94.9432 | L16: =J16/K16 -> -35.810885 | M16: 0 | N16: =J16+M16 -> -3400 | O16: Non-GST | P16: =+$P$1&"/"&$P$2&"/"&A16 -> 26 APR/ICE/4
A17: 5 | E17: Course fees towards LCHS dt. 29.04.26 | G17: 46142 | H17: Prakriti Marine Service | I17: PMS/IND/2026-020 | J17: 14500 | K17: =Forex!$C$2 -> 94.9432 | L17: =J17/K17 -> 152.72289 | M17: 2610 | N17: =J17+M17 -> 17110 | O17: Eligible | P17: =+$P$1&"/"&$P$2&"/"&A17 -> 26 APR/ICE/5
A18: 6 | E18: Netherland visa charges 9360/- VFS 2662/-appointment 1770/- Print 150/- Ticket 500/- Service fee 750/- GST 135-/ | G18: 46142 | H18: ATPI India Private Ltd | I18: 16616007 | J18: 15192 | K18: =Forex!$C$2 -> 94.9432 | L18: =J18/K18 -> 160.01146 | M18: 135 | N18: =J18+M18 -> 15327 | O18: Eligible | P18: =+$P$1&"/"&$P$2&"/"&A18 -> 26 APR/ICE/6
A19: 7 | E19: Insurance cancellation charges | G19: 46142 | H19: ATPI India Private Ltd | I19: 16616009 | J19: 350 | K19: =Forex!$C$2 -> 94.9432 | L19: =J19/K19 -> 3.6864146 | M19: 0 | N19: =J19+M19 -> 350 | O19: Non-GST | P19: =+$P$1&"/"&$P$2&"/"&A19 -> 26 APR/ICE/7
A20: 8 | E20: Netherland visa charges 9360/- VFS 1325/-appointment 1770/- Service fee 750/- GST 135-/ | G20: 46142 | H20: ATPI India Private Ltd | I20: 16615661 | J20: 13205 | K20: =Forex!$C$2 -> 94.9432 | L20: =J20/K20 -> 139.08316 | M20: 135 | N20: =J20+M20 -> 13340 | O20: Eligible | P20: =+$P$1&"/"&$P$2&"/"&A20 -> 26 APR/ICE/8
A21: 9 | E21: Insurance cancellation charges | G21: 46142 | H21: ATPI India Private Ltd | I21: 16615664 | J21: 350 | K21: =Forex!$C$2 -> 94.9432 | L21: =J21/K21 -> 3.6864146 | M21: 0 | N21: =J21+M21 -> 350 | O21: Non-GST | P21: =+$P$1&"/"&$P$2&"/"&A21 -> 26 APR/ICE/9
A22: 10 | E22: Belgium Visa 9270/- VFS appointment 2575/- VFS service 1445/- Print 20/- service fee 750/- GST 135/- | G22: 46142 | H22: ATPI India Private Ltd | I22: 16615489 | J22: 14060 | K22: =Forex!$C$2 -> 94.9432 | L22: =J22/K22 -> 148.08854 | M22: 135 | N22: =J22+M22 -> 14195 | O22: Eligible | P22: =+$P$1&"/"&$P$2&"/"&A22 -> 26 APR/ICE/10
A23: 11 | E23: Insurance cancellation charges | G23: 46142 | H23: ATPI India Private Ltd | I23: 16593579 | J23: 350 | K23: =Forex!$C$2 -> 94.9432 | L23: =J23/K23 -> 3.6864146 | M23: 0 | N23: =J23+M23 -> 350 | O23: Non-GST | P23: =+$P$1&"/"&$P$2&"/"&A23 -> 26 APR/ICE/11
A24: 12 | E24: Belgium Visa 9270/- VFS appointment 2575/- VFS service 1445/- Print 20/- service fee 750/- GST 135/- | G24: 46142 | H24: ATPI India Private Ltd | I24: 16615547 | J24: 14060 | K24: =Forex!$C$2 -> 94.9432 | L24: =J24/K24 -> 148.08854 | M24: 135 | N24: =J24+M24 -> 14195 | O24: Eligible | P24: =+$P$1&"/"&$P$2&"/"&A24 -> 26 APR/ICE/12
... A61: 49 | E61: Prejoning medical expenses dt. 05.03.26 Liberia Flag | G61: 46142 | H61: Sea Bird Medicare Pvt. Ltd. | I61: SB/PEME2627/0054 | J61: 3000 | K61: =Forex!$C$2 -> 94.9432 | L61: =J61/K61 -> 31.59784 | M61: 0 | N61: =J61+M61 -> 3000 | O61: Non-GST | P61: =+$P$1&"/"&$P$2&"/"&A61 -> 26 APR/ICE/49
A62: 50 | E62: REMITTANCE CHARGES - GST ON Fx 0853IT0517991 IH0304003743479 XT SHIPS MANAG XT SHIPS MANAGEMENT INDIA PRIVATE L USD 661177.49 at INR92.2212000000 UETR Ref:18ff3daa-e309-4f86-8567-516a07923557 | G62: 46120 | H62: DBS Bank Ltd | I62: NA | J62: 10800 | K62: =Forex!$C$2 -> 94.9432 | L62: =J62/K62 -> 113.75222 | M62: 0 | N62: =J62+M62 -> 10800 | O62: Non-GST | P62: Payment 211 dt. 08.04.26
A80: Total | J80: =SUM(J13:J79) -> 918550 | L80: =SUM(L13:L79) -> 9674.7318 | M80: =SUM(M13:M79) -> 4030 | N80: =SUM(N13:N79) -> 922580

Sheet Bank book-AXIS 
B3: AXIS BANK STATEMENT - A/c 455010200006132 (01.04.2026 to 12.05.2026; balance as on 30.04.2026 Rs 4,36,445.38)

Sheet Bank Book- DBS
A1: Account Details for : | B1: XT SHIPS MANAGEMENT INDIA PRIVATE LIMITED 8853210000030001 INR
A2: Statement as at : | B2: 01-Apr-2026 | C2: To : | D2: 30-Apr-2026
A3: Opening Balance : | B3: 5961993.1
A4: Ledger Balance : | B4: 7261701.3
A5: Available Balance : | B5: 7261701.3
A6: Date | B6: Value Date | C6: Transaction Description 1 | D6: Transaction Description 2 | E6: Debit | F6: Credit | G6: Running Balance
A7: 01-Apr-2026 | B7: 01-Apr-2026 | C7: TRANSFER | D7: NEFT 0811OP6171943970 Global Traders AXIS BANK UTIB0001062 REF Bill 780 dt. 30.03.26 Chair 52pcs Global Traders INR 141128 | E7: 141128 | G7: 5820865.1
A8: 02-Apr-2026 | B8: 02-Apr-2026 | C8: TRANSFER | D8: REMITTANCE CHARGES - GST ON Fx 0853IT0517861 C317368OCP040126 XT SHIPS MANA XT SHIPS MANAGEMENT INDIA USD 689062.76 at INR93.2100000000 UETR Ref:7953f2b8-08c7-4e89-be58-cb51bcc0691c | E8: 10800 | G8: 5810065.1
A9: 02-Apr-2026 | B9: 02-Apr-2026 | C9: TRANSFER | D9: NEFT 0811OP6172030374 XT Ships Management India Pv AXIS BANK UTIB0000004 REF TDS PF MAR 26 XT Ships Management India Pvt Ltd INR 2650000 | E9: 2650000 | G9: 3160065.1
A10: 06-Apr-2026 | B10: 06-Apr-2026 | C10: TRANSFER | D10: NEFT 0811OP6172226661 MOHAMMED SHAHID NAUSHAD BORK IDBI BANK IBKL0000574 REF MOHAMMED SHAHID NAUSHAD BORKAR INR 17020 | E10: 17020 | G10: 3143045.1
A11: 06-Apr-2026 | B11: 06-Apr-2026 | C11: TRANSFER | D11: NEFT 0811OP6172226665 EDWIN VINOTH M STATE BANK OF INDIA SBIN000931 REF EDWIN VINOTH M INR 3324 | E11: 3324 | G11: 3139721.1
A12: 06-Apr-2026 | B12: 06-Apr-2026 | C12: TRANSFER | D12: NEFT 0811OP6172226660 Pranshu Gupta ICICI BANK LIMITED ICIC0007237 REF Pranshu Gupta INR 3983 | E12: 3983 | G12: 3135738.1
A13: 06-Apr-2026 | B13: 06-Apr-2026 | C13: TRANSFER | D13: NEFT 0811OP6172226684 Hitesh Kumar Ninganiya STATE BANK OF INDIA SBIN000239 REF Hitesh Kumar Ninganiya INR 3240 | E13: 3240 | G13: 3132498.1
A14: 06-Apr-2026 | B14: 06-Apr-2026 | C14: TRANSFER | D14: NEFT 0811OP6172226693 ARUN DINAKAR ICICI BANK LIMITED ICIC0000807 REF ARUN DINAKAR INR 5404 | E14: 5404 | G14: 3127094.1
A15: 06-Apr-2026 | B15: 06-Apr-2026 | C15: TRANSFER | D15: NEFT 0811OP6172226690 Jorawar singh PUNJAB NATIONAL BANK PUNB00745 REF Jorawar singh INR 4650 | E15: 4650 | G15: 3122444.1
A16: 06-Apr-2026 | B16: 06-Apr-2026 | C16: TRANSFER | D16: NEFT 0811OP6172226678 Gopinath A STATE BANK OF INDIA SBIN000966 REF Gopinath A INR 3500 | E16: 3500 | G16: 3118944.1
A17: 06-Apr-2026 | B17: 06-Apr-2026 | C17: TRANSFER | D17: NEFT 0811OP6172226694 Manju bisht AXIS BANK UTIB0000093 REF Manju bisht INR 6865 | E17: 6865 | G17: 3112079.1
A18: 06-Apr-2026 | B18: 06-Apr-2026 | C18: TRANSFER | D18: NEFT 0811OP6172226675 Dinny Abraham ICICI BANK LIMITED ICIC0001952 REF Dinny Abraham INR 11778 | E18: 11778 | G18: 3100301.1
... A205: 06-Apr-2026 | B205: 06-Apr-2026 | C205: TRANSFER | D205: NEFT 0811OP6172226868 Tanmay Anil More BANK OF BARODA BARB0TISGAO REF Tanmay Anil More INR 1300 | E205: 1300 | G205: 2105924.1
A206: 06-Apr-2026 | B206: 06-Apr-2026 | C206: TRANSFER | D206: NEFT RETURN 0811OP6172226867 XT SHIPS MANAGEMENT I 0811OP6172226867 AXIS BANK NOT COMPLIANT Org Txn dated 2026 04 06 17:08:46.9 Arun Nadumane INR 2500 | F206: 2500 | G206: 2108424.1
A207: 06-Apr-2026 | B207: 06-Apr-2026 | C207: TRANSFER | D207: NEFT RETURN 0811OP6172226711 XT SHIPS MANAGEMENT I 0811OP6172226711 BANK OF BAROD INCORRECT ACCOUNT NUMBER Org Txn dated 2026 04 06 Mehul Kumar BARB0BALODA INR 4411 | F207: 4411 | G207: 2112835.1
A208: 06-Apr-2026 | B208: 06-Apr-2026 | C208: TRANSFER | D208: NEFT RETURN 0811OP6172226746 XT SHIPS MANAGEMENT I 0811OP6172226746 CANARA BANK INCORRECT ACCOUNT NUMBER Org Txn dated 2026 04 06 SUGIRTHA J INR 4410 | F208: 4410 | G208: 2117245.1
A209: 06-Apr-2026 | B209: 06-Apr-2026 | C209: TRANSFER | D209: NEFT RETURN 0811OP6172226725 XT SHIPS MANAGEMENT I 0811OP6172226725 STANDARD CHAR NOT COMPLIANT Org Txn dated 2026 04 06 17:37:26.3 Shubham Sanjay Chavan INR 15540 | F209: 15540 | G209: 2132785.1
A210: 06-Apr-2026 | B210: 06-Apr-2026 | C210: TRANSFER | D210: NEFT RETURN 0811OP6172226724 XT SHIPS MANAGEMENT I 0811OP6172226724 STANDARD CHAR NOT COMPLIANT Org Txn dated 2026 04 06 17:39:09.5 Shubham Sanjay Chavan INR 700 | F210: 700 | G210: 2133485.1
A211: 06-Apr-2026 | B211: 06-Apr-2026 | C211: TRANSFER | D211: NEFT RETURN 0811OP6172226681 XT SHIPS MANAGEMENT I 0811OP6172226681 HSBC BANK NOT COMPLIANT Org Txn dated 2026 04 06 17:42:51.4 Edwin Santhis INR 15540 | F211: 15540 | G211: 2149025.1
A212: 06-Apr-2026 | B212: 06-Apr-2026 | C212: TRANSFER | D212: NEFT RETURN 0811OP6172226823 XT SHIPS MANAGEMENT I 0811OP6172226823 HDFC BANK NOT COMPLIANT Org Txn dated 2026 04 06 18:24:03.2 Parthkumar Kamleshbhai Darji INR 4350 | F212: 4350 | G212: 2153375.1
A213: 06-Apr-2026 | B213: 06-Apr-2026 | C213: TRANSFER | D213: NEFT 0811OP6172226768 Ankush kumar CANARA BANK CNRB0002063 REF Ankush kumar INR 3600 | E213: 3600 | G213: 2149775.1
A214: 06-Apr-2026 | B214: 06-Apr-2026 | C214: TRANSFER | D214: NEFT 0811OP6172226769 Ankush kumar CANARA BANK CNRB0002063 REF Ankush kumar INR 3600 | E214: 3600 | G214: 2146175.1
A215: 06-Apr-2026 | B215: 06-Apr-2026 | C215: TRANSFER | D215: NEFT 0811OP6172226701 Hitesh Kumar Ninganiya STATE BANK OF INDIA SBIN000239 REF Hitesh Kumar Ninganiya INR 4600 | E215: 4600 | G215: 2141575.1
A216: 06-Apr-2026 | B216: 06-Apr-2026 | C216: TRANSFER | D216: NEFT 0811OP6172226700 Hitesh Kumar Ninganiya STATE BANK OF INDIA SBIN000239 REF Hitesh Kumar Ninganiya INR 4600 | E216: 4600 | G216: 2136975.1
A217: 07-Apr-2026 | B217: 07-Apr-2026 | C217: TRANSFER | D217: NEFT 0811OP6172334374 Dilip Thore BANK OF INDIA BKID0000176 REF office shifting work And Sat Sunday attend f Dilip Thore INR 5000 | E217: 5000 | G217: 2131975.1
A218: 07-Apr-2026 | B218: 07-Apr-2026 | C218: TRANSFER | D218: NEFT 0811OP6172334377 Aaradhya Enterprises MAHANAGAR COOPERATIVE BANK MCB REF 070426 6MM acrylic box cover for XT Maritime Aaradhya Enterprises INR 10000 | E218: 10000 | G218: 2121975.1
A219: 07-Apr-2026 | B219: 07-Apr-2026 | C219: TRANSFER | D219: NEFT 0811OP6172334373 Sanjay Joshi BANK OF INDIA BKID0001202 REF office shifting work And Sat Sunday attend f Sanjay Joshi INR 5000 | E219: 5000 | G219: 2116975.1
A220: 07-Apr-2026 | B220: 07-Apr-2026 | C220: TRANSFER | D220: NEFT 0811OP6172334372 SCENIUZ INFORMATION TECHNOLO AXIS BANK UTIB0000328 REF SCENIUZ2627001 dt 010426 Data AnalystDesign A SCENIUZ INFORMATION TECHNOLOGY PRIV INR 139200 | E220: 139200 | G220: 1977775.1
A221: 07-Apr-2026 | B221: 07-Apr-2026 | C221: TRANSFER | D221: NEFT 0811OP6172334375 Tata Teleservices M Ltd STANDARD CHARTERED BANK SCBL00 REF Account number 991640709 is nearing 9446 of th Tata Teleservices M Ltd INR 26544 | E221: 26544 | G221: 1951231.1
A222: 07-Apr-2026 | B222: 07-Apr-2026 | C222: TRANSFER | D222: NEFT 0811OP6172334376 Anil Kumar Sood AXIS BANK UTIB0000455 REF Bharatkosh for renewing licence RPSL receipt n Anil Kumar Sood INR 40477.64 | E222: 40477.64 | G222: 1910753.4
A223: 07-Apr-2026 | B223: 07-Apr-2026 | C223: TRANSFER | D223: NEFT 0811OP6172334371 Max Computers SARASWAT COOPERATIVE BANK LIMI REF MAX20264503 dt 020326 monitor armsportsaccess Max Computers INR 524628 | E223: 524628 | G223: 1386125.4
A224: 08-Apr-2026 | B224: 08-Apr-2026 | C224: TRANSFER | D224: REMITTANCE CHARGES - GST ON Fx 0853IT0517991 IH0304003743479 XT SHIPS MANAG XT SHIPS MANAGEMENT INDIA PRIVATE L USD 661177.49 at INR92.2212000000 UETR Ref:18ff3daa-e309-4f86-8567-516a07923557 | E224: 10800 | G224: 1375325.4
... A232: 10-Apr-2026 | B232: 10-Apr-2026 | C232: TRANSFER | D232: NEFT 0811OP6172524584 Indian Register of Shipping BANK OF BARODA BARB0POWBOM REF RPSL Annual audit 2025 advance Invoice pendin Indian Register of Shipping INR 24190 | E232: 24190 | G232: 762106.74
A233: 10-Apr-2026 | B233: 10-Apr-2026 | C233: TRANSFER | D233: TRANSFER 0853RF0606406 XT SHIPS MANAGEMENT INDIA PRIV XT SHIPS MANAGEMENT INDIA PRIVATE L INR 3281127.35 at USD92.3195000000 | F233: 3281127.4 | G233: 4043234.1
...

Sheet Inter Company Transfer
A1: ="Inter-Company Transfer for the month of "&Master!C6 -> Inter-Company Transfer for the month of APR-26
A2: Account Head | B2: Company Name | C2: Receipt/Payment in the books of XT | D2: Amount (INR) | E2: Remarks | F2: Transaction Date
B3: ASManagement Operations India Pvt Ltd | C3: Opening balance | D3: 27363.04 | E3: Outstanding as on 31 Mar 26 (Dr - receivable from ASM) | F3: 46112
B5: Petrol expenses - Ciaz car (Journal 9) | C5: Credit | D5: -2574.87 | E5: Petrol expenses dt. 19.04.26 for Ciaz Car Bajrang Auto Service | F5: 46131
B6: Swiggy - Go Pro purchase (Journal 2) | C6: Credit | D6: -16011 | E6: Bill no P00417 dt. 24.04.26 Go pro purchase for parwinder singh , same has been handed over to CC ajinkya badekar at sea bird medicare Centre while PJM on 25.04.26 | F6: 46140
B7: Airtel group bill - ASM users (Journal 7) | C7: Debit | D7: 3896 | E7: Airtel group bill MF2727I001683891 dt. 24.04.26 from 23.03.26 to 22.04.26User - Rohit Suthar User - Nair User - Priya | F7: 46142
B8: Airtel mobile bills - XT users (Journal 8) | C8: Credit | D8: -4517.46 | E8: Bill no. MF2727I000557247 dt. 09.04.26 for the period 08.03.26 to 07.04.26 Bill no. MF2727I000557544 dt. 09.04.26 for the period 08.03.26 to 07.04.26 Bill no. MF2727I001620777 dt. 24.04.26 for the period 23.03.26 to 22.04.26Bill no. MF2727I001506786 dt. 21.04.26 for the period 20.03.26 to 19.04.26 Bill no. MF2727I001271617 dt. 18.04.26 for the period 17.03.26 to 16.04.26 Bill no. MF2727I001506785 dt. 21.04.26 for the period 20.03.26 to 19.04.26 Bill no. MF2727I001190211 dt. 18.04.26 for the period 17.03.26 to 16.04.26 | F8: 46142
B9: Amazon balance - Go Pro (Journal 10) | C9: Credit | D9: -14990 | E9: Go pro purchase for parwinder singh , same has been amount credited to amazon balance money towards product not available as per order id 408-4163378-1768332 ( total 14990 - Rs 980 ordered as below entry & balance 14010 in XT Ships Amazon account ) 14010-980 order 170607 dt.28.04.26 Toy Metal avenger water bottle for Bipin's Son towards Get well soon dt. 28.04.26 | F9: 46142
C16: Closing balance | D16: =SUM(D3:D10) -> -6834.29

Sheet General
B1: Expenses done for the month of JAN 2026
B2: ACCOUNT HEAD | C2: Company Name | D2: Gross Amt.(Including GST) | E2: REMARKS | F2: BILL RECEIVED DATE | G2: TYPE OF EXPENSES INCLUDED | H2: CGST | I2: SGST | J2: IGST | K2: Net Amt. (Exluding GST)
B4: PROFESSIONAL FEES | C4: GSC Edge Consultancy Pvt Ltd | D4: =K4+SUM(H4:J4) -> 97350 | E4: Bill no. APR2601/26-27 dt. 01.04.26 Professional fees for the month APR 26 | F4: 46113 | G4: Professional Fees - 9982 | H4: 7425 | I4: 7425 | K4: 82500
B5: PROFESSIONAL FEES | C5: GSC Edge Consultancy Pvt Ltd | D5: =K5+SUM(H5:J5) -> 20650 | E5: Bill no.MAR2603/2025-26 dt. 31.03.26 Professional fees for filling & certification PAS6 for half year end 30.09.24, 31.03.25 & 30.09.25, DSC charges for capt anil Sood | F5: 46113 | G5: Professional Fees - 9982 | H5: 1575 | I5: 1575 | K5: 17500
B6: PROFESSIONAL FEES | C6: GSC Edge Consultancy Pvt Ltd | D6: =K6+SUM(H6:J6) -> 17700 | E6: Bill no. APR2603/2026-27 dt. 03.04.2026 Profeesional fees for change in address of new office under shop & establishment act | F6: 46115 | G6: Professional Fees - 9982 | H6: 1350 | I6: 1350 | K6: 15000
B7: PROFESSIONAL FEES | C7: Sceniuz Information Technology Pvt Ltd | D7: =K7+SUM(H7:J7) -> 141600 | E7: SCENIUZ/2627/001 dt. 01.04.26 Data Analyst-Design & Development services for 4month basic 120000x2% = 2400 | F7: 46113 | G7: Professional Fees - 998311 | H7: 10800 | I7: 10800 | K7: 120000
B8: PROFESSIONAL FEES | C8: Bigshare Services Pvt Ltd | D8: =K8+SUM(H8:J8) -> 5900 | E8: Bill no. RT/AP/3195/26-27 dt. 17.04.25 NSDL services - 12month | F8: 46129 | G8: Professional Fees - 9971 | H8: 450 | I8: 450 | K8: 5000
B9: PROFESSIONAL FEES | C9: Bigshare Services Pvt Ltd | D9: =K9+SUM(H9:J9) -> 983 | E9: Bill no. RT/AP/4467/25-26 dt. 21.04.25 NSDL services - 2month | F9: 46133 | G9: Professional Fees - 9971 | H9: 75 | I9: 75 | K9: 833
C10: SUB TOTAL | D10: =SUM(D4:D9) -> 284183
B12: COURIER CHARGES | C12: We Fast | D12: =K12+SUM(H12:J12) -> 420 | E12: Paid in cash towards ASM conversion letter | F12: 46140 | G12: Postage & Courier Exp - 996812 | K12: 420
B14: HOUSEKEEPING CHARGES | C14: Shine Edge Facility Management | D14: =K14+SUM(H14:J14) -> 47985.06 | E14: Bill no SE/HK/008/26-27 dt. 30.04.26 Housekeeping charges for the month Apr 26 for housekeeping - 2 boys | F14: 46142 | G14: House Keeping Expenses - 9985 | H14: 3659.88 | I14: 3659.88 | K14: 40665.3
B16: SECURITY CHARGES | C16: Vibrant Management Solutions | D16: =K16+SUM(H16:J16) -> 25575 | E16: Bill no VMS/26-27/002 dt. 30.04.26 Security charges for the mongh Apr 26 | F16: 46142 | G16: Security Charges | H16: 1950.6 | I16: 1950.6 | K16: 21673.8
B18: ADVERTISMENT | C18: Marex Media Pvt. Ltd. | D18: =K18+SUM(H18:J18) -> 8116 | E18: Bill no 21 dt. 28.04.26 advertisement for Apr 26 | F18: 46140 | G18: Advertisement - 998361 | H18: 619 | I18: 619 | K18: 6878
B20: PANTRY EXPENSES | C20: K.B.C Enterprises | D20: =K20+SUM(H20:J20) -> 124090 | E20: Bill no. 25-26/S00091 dt. 30.04.26 pantry expenses for the month Apr 26 | F20: 46142 | G20: Pantry Expenses | K20: 124090
B22: PRINTING & STATIONERY | C22: K.B.C Enterprises | D22: =K22+SUM(H22:J22) -> 10089 | E22: Bill no. 26-27/S00090 dt. 30.04.26 Stationery , Standee for cook program, visiiting cards, capt anil, ravindra, bipin, gopal, kapil, Uday | F22: 46142 | G22: Printing and Stationery -18% | H22: 769.5 | I22: 769.5 | K22: 8550
B24: ELECTRICITY CHARGES | C24: Adani Electricity | D24: =K24+SUM(H24:J24) -> 60050 | E24: Bill no. 100581704220 dt. 13.04.26 for Mar 26 Atrium office | F24: 46125 | G24: Electricity Expenses | K24: 60050
B26: TRAVEL EXPENSES | C26: Kaushal Tours & Travels | D26: =K26+SUM(H26:J26) -> 7361 | E26: Bill no. KT2526-000016 dt. 17.04.26 Capt Anil - Cook program & local | F26: 46129 | G26: Local Travelling Expenses - 9985 | K26: 7361
B27: TRAVEL EXPENSES | C27: Riya Travels and Tours India Pvt Ltd | D27: =K27+SUM(H27:J27) -> 13240 | E27: Bill no. ADH0426T0010195 dt. 27.04.26 travel from BOM-AMD dt. 30.04.26 for Rohit Suthar office visit | F27: 46139 | G27: Local Travelling Expenses | H27: 13.5 | I27: 13.5 | K27: 13213
B28: TRAVEL EXPENSES | C28: Riya Travels and Tours India Pvt Ltd | D28: =K28+SUM(H28:J28) -> 6403 | E28: Bill no. ADH0426T0011120 dt. 27.04.26 travel from AMD-BOM dt. 290.04.26 for Rohit Suthar office visit | F28: 46139 | G28: Local Travelling Expenses | H28: 13.5 | I28: 13.5 | K28: 6376
B29: TRAVEL EXPENSES | C29: Universal Currency Exchange (I) Pvt Ltd | D29: =K29+SUM(H29:J29) -> 113050 | E29: Bill no. 6200155 dt. 20.04.26 USD 1200 for rate 93.90 to vessel visit - Cape med | F29: 46132 | G29: Travelling Expenses | K29: 113050
C30: SUB TOTAL | D30: =SUM(D26:D29) -> 140054
B32: Health Insurance | C32: Care Health Insurance | D32: =K32+SUM(H32:J32) -> 43598 | E32: Shahina Mother - Sajida / 30940 USD 340 company share & 12658 / 3 month emi | F32: 46119 | G32: Health Insurance for Employees | K32: 43598
B33: Health Insurance | C33: Shahina Mohite (recovery) | D33: =K33+SUM(H33:J33) -> -12658 | E33: Shahina Mother - Sajida / 30940 USD 340 company share & 12658 / 3 month emi | F33: 46119 | G33: Health Insurance for Employees | K33: -12658
C34: SUB TOTAL | D34: =SUM(D32:D33) -> 30940
B36: Society Maintainance | C36: 215 Atrium Co op Premises Society Ltd | D36: =K36+SUM(H36:J36) -> 120874 | E36: 185 dt. 01.04.26 society Maintenance from 01.04.26 to 30.06.26 | F36: 46113 | G36: Society Maintenance Exp | H36: 9219 | I36: 9219 | K36: 102436
B37: Society Maintainance | C37: 215 Atrium Co op Premises Society Ltd | D37: =K37+SUM(H37:J37) -> 7000 | E37: 185 dt. 01.04.26 society Maintenance from 01.04.26 to 30.06.26 | F37: 46113 | G37: Water Charges | K37: 7000
C38: SUB TOTAL | D38: =SUM(D36:D37) -> 127874
B40: PROPERTY TAX | C40: 215 Atrium Co op Premises Society Ltd | D40: =K40+SUM(H40:J40) -> 6000 | E40: 185 dt. 01.04.26 society Maintenance from 01.04.26 to 30.06.26 | F40: 46113 | G40: Property Tax | K40: 6000
B42: PETROL EXPENSES | C42: Bajrang Auto Service | D42: =K42+SUM(H42:J42) -> 1000 | E42: Petrol expenses dt. 12.04.26 Paid in cash | F42: 46124 | G42: Petrol Expenses | K42: 1000
B43: PETROL EXPENSES | C43: Bajrang Auto Service (via ASM) | D43: =K43+SUM(H43:J43) -> 2574.87 | E43: Petrol expenses dt. 19.04.26 for Ciaz Car Bajrang Auto Service | F43: 46131 | G43: Petrol Expenses | K43: 2574.87
C44: SUB TOTAL | D44: =SUM(D42:D43) -> 3574.87
B46: OFFICE GENERAL EXPENSES | C46: Sanjay Joshi | D46: =K46+SUM(H46:J46) -> 5000 | E46: office shifting work Sat Sunday | F46: 46119 | G46: Office Expenses - URD | K46: 5000
B47: OFFICE GENERAL EXPENSES | C47: Dilip | D47: =K47+SUM(H47:J47) -> 5000 | E47: office shifting work Sat Sunday | F47: 46119 | G47: Office Expenses - URD | K47: 5000
B48: OFFICE GENERAL EXPENSES | C48: Cash Paid | D48: =K48+SUM(H48:J48) -> 1151 | E48: Airtel sim service fee, lunch expenses paid towards chair old & new pick up on Saturday, sanjay towards MIDC for Knife pick up | F48: 46119 | G48: Office Expenses - URD | K48: 1151
B49: OFFICE GENERAL EXPENSES | C49: Rahul Pawar (reimb) | D49: =K49+SUM(H49:J49) -> 4116 | E49: Bill no. 1355 dt. 10.04.26 Lunch with purchase team towards Sagar sonawane Farewell | F49: 46125 | G49: Office Expenses - URD | K49: 4116
B50: OFFICE GENERAL EXPENSES | C50: Cash Paid | D50: =K50+SUM(H50:J50) -> 565 | E50: sanitary pad Siddhivinayak medical | F50: 46126 | G50: Office Expenses - URD | K50: 565
B51: OFFICE GENERAL EXPENSES | C51: Cash Paid | D51: =K51+SUM(H51:J51) -> 870 | E51: ambedkar jayanti closed tso sanjay brought fruits | F51: 46126 | G51: Office Expenses - URD | K51: 870
B52: OFFICE GENERAL EXPENSES | C52: Cash Paid | D52: =K52+SUM(H52:J52) -> 1201 | E52: dishwash salt & Liquid set | F52: 46126 | G52: Office Expenses - URD | K52: 1201
B53: OFFICE GENERAL EXPENSES | C53: Cash Paid | D53: =K53+SUM(H53:J53) -> 340 | E53: Lunch for officer | F53: 46128 | G53: Office Expenses - URD | K53: 340
B54: OFFICE GENERAL EXPENSES | C54: Sai Palace Hotel | D54: =K54+SUM(H54:J54) -> 624 | E54: Lunch for cadet & officer paid in cash | F54: 46132 | G54: Office Expenses - URD | K54: 624
...

Sheet CR
A1: XT Ships Management India Private Limited
A5: General Expenses - Profit and Loss Account
A6: Head of expenses | B6: =Master!C6 -> APR-26 | D6: Pivot for Man Day Exepnses (Excluding Assets Purchased) | G6: Pivot for other than Manday Expenses & Assets
A7: PROFESSIONAL FEES | B7: =SUMIF(General!$B$4:$B$172,A7,General!$K$4:$K$172) -> 240833 | D7: Source: live SUMIF links to General sheet (pivot tables replaced)
A8: COURIER CHARGES | B8: =SUMIF(General!$B$4:$B$172,A8,General!$K$4:$K$172) -> 420
A9: HOUSEKEEPING CHARGES | B9: =SUMIF(General!$B$4:$B$172,A9,General!$K$4:$K$172) -> 40665.3
A10: SECURITY CHARGES | B10: =SUMIF(General!$B$4:$B$172,A10,General!$K$4:$K$172) -> 21673.8
A11: ADVERTISMENT | B11: =SUMIF(General!$B$4:$B$172,A11,General!$K$4:$K$172) -> 6878
A12: PANTRY EXPENSES | B12: =SUMIF(General!$B$4:$B$172,A12,General!$K$4:$K$172) -> 124090
A13: PRINTING & STATIONERY | B13: =SUMIF(General!$B$4:$B$172,A13,General!$K$4:$K$172) -> 8550
A14: ELECTRICITY CHARGES | B14: =SUMIF(General!$B$4:$B$172,A14,General!$K$4:$K$172) -> 60050
A15: TRAVEL EXPENSES | B15: =SUMIF(General!$B$4:$B$172,A15,General!$K$4:$K$172) -> 140000
A16: Health Insurance | B16: =SUMIF(General!$B$4:$B$172,A16,General!$K$4:$K$172) -> 30940
A17: Society Maintainance | B17: =SUMIF(General!$B$4:$B$172,A17,General!$K$4:$K$172) -> 109436
A18: PROPERTY TAX | B18: =SUMIF(General!$B$4:$B$172,A18,General!$K$4:$K$172) -> 6000
A19: PETROL EXPENSES | B19: =SUMIF(General!$B$4:$B$172,A19,General!$K$4:$K$172) -> 3574.87
... A36: EMPLOYER CONTRIBUTION TO PF | B36: =SUMIF(General!$B$4:$B$172,A36,General!$K$4:$K$172) -> 66299
A39: UTLIZED FOR TAX PAYMENT (TDS) OF XT/ASM
A40: PF XT/ASM | B40: 0
A41: INCOME TAX OF XT
A42: Total | B42: =SUM(B7:B41) -> 8514846.2
A45: ASSETS
A46: Purchase of Asset (Other than Office) | B46: =General!C226 -> 31380
A47: Purchase of Asset (Office Interior)
A49: Sale of Asset (Office)
A51: Depreciation (on all Assets) | B51: =General!K181 -> 539519
A53: Direct Expenses | B53: =Master!C6 -> APR-26
A54: Company name | B54: Total
A55: ICE | B55: ='DE-ICE'!C9 -> 918550
A56: XT | B56: ='DE-XT'!C8 -> 3036049.3
A57: Grand Total | B57: =SUM(B55:B56) -> 3954599.3
A58: General Expenses - Cost(without Depreciation) | B58: =$B$42 -> 8514846.2
A59: Grand Total | B59: =B57+B58 -> 12469446
A61: Mandays | B61: No of crew days
A62: ICE | B62: =+#REF! -> #REF!
A63: XT | B63: =+#REF! -> #REF!
A64: Total | B64: =SUM(B62:B63) -> #REF!
A66: Cost / Mandays INR | B66: =IFERROR(B58/B64,"Pending CB") -> Pending CB
A68: Foreign Exchenge Rate1$ = INR | B68: =Forex!C2 -> 94.9432
A70: Total Cost / Mandays USD | B70: =IFERROR(B66/B68,"Pending CB") -> Pending CB

Sheet Consolidated CR
A1: XT Ships Management India Private Limited
A7: General Expenses - Profit and Loss Account
A8: Head of expenses/Month | B8: 45748 | C8: 45778 | D8: 45809 | E8: 45839 | F8: 45870 | G8: 45901 | H8: 45931 | I8: 45962 | J8: 45992 | K8: 46023 | L8: 46054 | M8: 46082 | N8: Total
A9: ADVERTISMENT | B9: 92183.5 | C9: 65878 | D9: 25628 | E9: 59378 | F9: 6878 | G9: 25628 | H9: 6878 | I9: 59378 | J9: 25628 | K9: 271878 | L9: 52978 | M9: 50628 | N9: =SUM(B9:M9) -> 742941.5
A10: AMC | H10: 158363.06 | N10: =SUM(B10:M10) -> 158363.06
A11: BANK CHARGES | B11: 4922 | C11: 37459.36 | D11: 4184.48 | E11: 4663.24 | F11: 162711.33 | G11: 3272.36 | H11: 4997.04 | I11: 3006.31 | J11: 13406.06 | K11: 5737.37 | L11: 3904.75 | M11: 6715.56 | N11: =SUM(B11:M11) -> 254979.86
A12: COMPUTER EXPENSE | B12: 2550 | F12: 3715.3 | N12: =SUM(B12:M12) -> 6265.3
A13: COURIER CHARGES | B13: 793 | C13: 14928.7 | D13: 1217 | E13: 47157.72 | F13: 669 | G13: 6425 | H13: 25814.763 | I13: 9156 | J13: 13441.441 | K13: 35231.39 | L13: 380 | M13: 26514.6 | N13: =SUM(B13:M13) -> 181728.61
A14: ELECTRICITY CHARGES | C14: 64940 | D14: 61970 | E14: 63232.64 | F14: 56676.27 | G14: 49720 | H14: 55460 | I14: 55450 | J14: 52840 | K14: 65940 | L14: 46160 | M14: 212530 | N14: =SUM(B14:M14) -> 784918.91
A15: HOUSEKEEPING CHARGES | B15: 40665.3 | C15: 40665.3 | D15: 40665.3 | E15: 40665.3 | F15: 40665.3 | G15: 40665.32 | H15: 40665.3 | I15: 40665.3 | J15: 39353.44 | K15: 40665.3 | L15: 40665.3 | M15: 40665.3 | N15: =SUM(B15:M15) -> 486671.76
A16: LEAVE ENCASHMENT | M16: 80136 | N16: =SUM(B16:M16) -> 80136
A17: MOBILE & TELEPHONE CHARGES | B17: 45008.34 | C17: 35309.04 | D17: 44166.24 | E17: 36764.55 | F17: 36819.898 | G17: 35338.49 | H17: 33827.23 | I17: 48612 | J17: 37320.87 | K17: 37049.42 | L17: 48298.79 | M17: 32772 | N17: =SUM(B17:M17) -> 471286.87
A18: OFFICE GENERAL EXPENSES | B18: 89900 | C18: 40893 | D18: 49996 | E18: 52820.49 | F18: 53495 | G18: 39907.3 | H18: 23149.5 | I18: 19727 | J18: 86911.9 | K18: 83850.09 | L18: 41416 | M18: 102591.92 | N18: =SUM(B18:M18) -> 684658.2
A19: OFFICE INTERNET CHARGES | B19: 228625 | E19: 228625 | H19: 228625 | K19: 228625 | L19: 6801 | M19: 173942 | N19: =SUM(B19:M19) -> 1095243
A20: OFFICE STAFF WELFARE | B20: 85381 | C20: 82507 | D20: 62189 | E20: 83841 | F20: 49695 | G20: 48789 | H20: =2660449-8844 -> 2651605 | I20: 191625 | J20: 293956 | K20: 102528 | L20: 93799 | M20: 315883 | N20: =SUM(B20:M20) -> 4061798
A21: PANTRY EXPENSES | B21: 101089 | C21: 86855 | D21: 115524 | E21: 126941 | F21: 127422 | G21: 107877 | H21: 108296 | I21: 102506 | J21: 110064 | K21: 108960 | L21: 106448 | M21: 99919 | N21: =SUM(B21:M21) -> 1301901
A22: PETROL EXPENSES | B22: 2827.67 | C22: 2455.9 | D22: 2797.65 | E22: 3682.73 | F22: 2960.74 | G22: 3164.54 | H22: 2928.67 | I22: 2864.19 | J22: 5266.04 | K22: 6360.96 | L22: 3329.84 | M22: 2812.14 | N22: =SUM(B22:M22) -> 41451.07
A23: PRINTING & STATIONERY | B23: 6176.54 | C23: 41897.1 | D23: 5542.44 | E23: 10434.5 | F23: 3725.3 | G23: 8822.44 | H23: 8000 | I23: 8979.6 | J23: 3714.48 | K23: 4160.2 | L23: 23544 | M23: 63592 | N23: =SUM(B23:M23) -> 188588.6
A24: PROFESSIONAL FEES | B24: 109860 | C24: 106690 | D24: 482955 | E24: 216626 | F24: 82500 | G24: 82500 | H24: 546287 | I24: 88500 | J24: 202500 | K24: 107500 | L24: 158751 | M24: 165000 | N24: =SUM(B24:M24) -> 2349669
A25: PROPERTY TAX | F25: 23887 | L25: 371807 | N25: =SUM(B25:M25) -> 395694
A26: REIMBURSMENT | B26: 30754 | C26: 38931 | D26: 23995 | E26: 76480 | F26: 36415 | G26: 56371 | H26: 60499 | I26: 79086 | J26: 94859 | K26: 68510 | L26: 46159 | M26: 67736 | N26: =SUM(B26:M26) -> 679795
A27: NOC CHARGES | N27: =SUM(B27:M27) -> 0
A28: SECURITY CHARGES | B28: 21673.8 | C28: 21673.8 | D28: 21673.8 | E28: 21673.8 | F28: 21673.8 | G28: 21673.8 | H28: 21673.8 | I28: 21673.8 | J28: 21673.8 | K28: 21673.8 | L28: 21673.3 | M28: 21673.3 | N28: =SUM(B28:M28) -> 260084.6
A29: STAFF SALARY | B29: 8373712.4 | C29: 5831990 | D29: 6195778 | E29: 6127899.7 | F29: 5865330 | G29: 5804141 | H29: 6267589 | I29: 6204827.3 | J29: 6786960.3 | K29: 7820976.5 | L29: 6948415 | M29: 6627749 | N29: =SUM(B29:M29) -> 78855368
A30: TRAVEL EXPENSES | B30: 21902 | C30: 188444 | D30: 32328 | E30: 34129 | F30: 5913 | G30: 15825 | H30: 89323.85 | I30: 161278 | J30: 35695 | K30: 8582 | L30: 10175 | M30: 125133 | N30: =SUM(B30:M30) -> 728727.85
A31: EMPLOYER CONTRIBUTION TO PF | B31: 69841 | C31: 66342 | D31: 73441 | E31: 72123 | F31: 70263 | G31: 69649 | H31: 64351 | I31: 68743 | J31: 64915 | K31: 61260 | L31: 68099 | M31: 66449 | N31: =SUM(B31:M31) -> 815476
A32: OFFICE EQUIPMENT EXPENSE | F32: 4250 | L32: 29546 | N32: =SUM(B32:M32) -> 33796
A33: COURSE FEES | C33: 33898 | F33: 11440.68 | H33: 11278 | I33: 55000 | J33: 20788.98 | L33: 55000 | M33: 91200 | N33: =SUM(B33:M33) -> 278605.66
A34: HOTEL EXPENSES | B34: 60900 | E34: 38500 | H34: 42051 | I34: 15965 | N34: =SUM(B34:M34) -> 157416
A35: Health Insurance | B35: -3224 | C35: 56856 | D35: -3224 | K35: 14229 | N35: =SUM(B35:M35) -> 64637
A36: REPAIR & MAINTANANCE | H36: 9953 | J36: 91698.36 | N36: =SUM(B36:M36) -> 101651.36
A37: COMPUTER Consumables | C37: 351.64 | E37: 3126.3 | G37: 16143.22 | I37: 1948.3 | J37: 37298.3 | K37: 750 | L37: 25597.04 | M37: 18786 | N37: =SUM(B37:M37) -> 104000.8
A38: BUSINESS PROMOTION | D38: 89954.5 | E38: 5342 | H38: 104184.27 | I38: 23584.02 | K38: 42554 | L38: 74892.84 | M38: 15169 | N38: =SUM(B38:M38) -> 355680.63
A39: OFFICE RENT | C39: 140000 | D39: 428500 | E39: 420000 | F39: 420000 | G39: 420000 | H39: 420000 | I39: 420000 | J39: 420000 | K39: 420000 | L39: 420000 | M39: 210000 | N39: =SUM(B39:M39) -> 4138500
A40: OFFICE INSURANCE | G40: 22032 | N40: =SUM(B40:M40) -> 22032
A41: STAFF MEDICAL INSURANCE | B41: -29625 | E41: 23860 | F41: -11474 | H41: 1159867 | L41: 27178 | N41: =SUM(B41:M41) -> 1169806
A42: STAFF BONUS | H42: 4604615.9
A43: PEST CONTROL | C43: 3000 | N43: =SUM(B43:M43) -> 3000
A44: PARKING | H44: 5000
A45: SOCIETY MAINTAINANCE | C45: 35188.27 | I45: 233752 | K45: 117045.98 | N45: =SUM(B45:M45) -> 385986.25
...

Sheet Employees Loan Repayment
B2: Employee Loan Repayment for the month of APR 2026
B3: ACCOUNT HEAD | C3: Employee Name | D3: AMOUNT (INR) | E3: REMARKS | F3: Transaction Date | G3: TYPE OF PAYMENT | H3: Remarks | I3: Original Loan amount | J3: Date of Loan | K3: Dedcution Month | L3: Number of installements | M3: Total amount dedcuted | N3: Outstanding amount | O3: REMARKS
B4: LOAN INSTALLMENT | C4: Shahina Mohite | D4: 13700 | E4: Deducted from Salary | F4: 46142 | G4: Monthly Loan Repayment | H4: Nil | I4: 500000 | J4: 45536 | K4: 46113 | L4: 19 | M4: =6800+(D4*L4) -> 267100 | N4: =I4-M4 -> 232900
B5: LOAN INSTALLMENT | C5: Amit Shinde | D5: 12000 | E5: Deducted from Salary | F5: 46142 | G5: Monthly Loan Repayment | H5: Nil | I5: 432000 | J5: 45505 | K5: 46113 | L5: 21 | M5: =L5*D5 -> 252000 | N5: =I5-M5 -> 180000
B6: LOAN INSTALLMENT | C6: Pratik Shiposkar | D6: 10000 | E6: Deducted from Salary | F6: 46142 | G6: Monthly Loan Repayment | H6: Nil | I6: 400000 | J6: 45505 | K6: 46113 | L6: 21 | M6: =L6*D6 -> 210000 | N6: =I6-M6 -> 190000
B7: LOAN INSTALLMENT | C7: Sumit Mandavkar | D7: 23400 | E7: Deducted from Salary | F7: 46142 | G7: Monthly Loan Repayment | H7: Nil | I7: =842400+342000 -> 1184400 | J7: 45627 | K7: 46113 | L7: 17 | M7: =L7*D7 -> 397800 | N7: =I7-M7 -> 786600 | O7: 36 monthly deductions of 23400/- Rs starting from December 2024 payroll.
B8: LOAN INSTALLMENT | C8: Sandesh Patil | D8: 10000 | E8: Deducted from Salary | F8: 46142 | G8: Monthly Loan Repayment | H8: Nil | I8: 200000 | J8: 45901 | K8: 46113 | L8: 8 | M8: =L8*D8 -> 80000 | N8: =I8-M8 -> 120000 | O8: Sandesh Patil was given a loan of 2 Lakh Rs, deductions in 20 instalments of 10,000/- Rs each. First instalment of 10,000/- Rs to be deducted in September 2025.
B9: LOAN INSTALLMENT | C9: Rahul Pawar | D9: 35000 | E9: Deducted from Salary | F9: 46142 | G9: Monthly Loan Repayment | H9: Nil | I9: 700000 | J9: 45992 | K9: 46113 | L9: 5 | M9: =L9*D9 -> 175000 | N9: =I9-M9 -> 525000 | O9: Rahul Pawar was given a loan of 7 Lakh Rs, loan to be paid back in 20 monthly instalments of 35000/- Rs each starting from December 2025
B10: LOAN INSTALLMENT | C10: Pratik Kondvilkar | D10: 10000 | E10: Deducted from Salary | F10: 46142 | G10: Monthly Loan Repayment | H10: Nil | I10: 300000 | J10: 45992 | K10: 46113 | L10: 5 | M10: =L10*D10 -> 50000 | N10: =I10-M10 -> 250000 | O10: Pratik Kondvilkar was given a loan of 3 Lakhs in November, monthly deductions of 10000/- Rs to start from December 2025.
B11: LOAN INSTALLMENT | C11: Shivram R. Singh | D11: 20000 | E11: Deducted from Salary | F11: 46142 | G11: Monthly Loan Repayment | H11: Nil | I11: 400000 | J11: 46023 | K11: 46113 | L11: 3 | M11: =L11*D11 -> 60000 | N11: =I11-M11 -> 340000 | O11: Loan of 4,00,000; 20 monthly instalments of 20,000 from Feb-26 (Tally Payroll 48 narration)
B12: LOAN INSTALLMENT | C12: Rohan Gawde | D12: 16600 | E12: Deducted from Salary | F12: 46142 | G12: Monthly Loan Repayment | H12: Nil | I12: 400000 | J12: 46023 | K12: 46113 | L12: 3 | M12: =18200+D12*(L12-1) -> 51400 | N12: =I12-M12 -> 348600 | O12: Loan of 4,00,000: first deduction 18,200 in Feb-26, balance in 23 instalments of 16,600 from Mar-26 (Tally Payroll 48 narration)
B13: LOAN INSTALLMENT | C13: Sampada Shimge | D13: 15000 | E13: Deducted from Salary | F13: 46142 | G13: Monthly Loan Repayment | H13: Nil | I13: 150000 | J13: 46080 | K13: 46113 | L13: 2 | M13: =L13*D13 -> 30000 | N13: =I13-M13 -> 120000 | O13: Sampada was given a loan of 150,000/- Rs. To be paid back in 10 instalments of 15,000/- Rs each, first deduction of 15,000/- Rs to start from March 2026. (Tally Payroll 45 narration; disbursed from DBS on 27.02.26)
C14: SUB TOTAL | D14: =SUM(D4:D13) -> 165700 | I14: =SUM(I4:I13) -> 4666400 | M14: =SUM(M4:M13) -> 1573300 | N14: =SUM(N4:N13) -> 3093100
C16: Source: Tally Payroll voucher 54 dt. 30.04.26 (narration: APR 26) - Loan to Employees Cr 1,65,700. No loan disbursed in Apr-26. Sunny Palav loan fully recovered in Mar-26.

Sheet Forex
B2: INR/$ | C2: 94.9432
B4: USD amounts for Apr-26 service-charge invoices not yet raised in Tally - to be entered
C5: $ | D5: Rs
B6: ICE | D6: =ROUND(C6*C2,0) -> 0
B7: XT | D7: =ROUND(C7*C2,0) -> 0
B10: RBI screenshot (USD, 04.05.2026 = 94.9432) saved at: C:\Users\Prasanna\AppData\Local\Temp\claude-chrome-screenshots-6P8S4V\screenshot-1790594104620-2.jpg - paste here (shows USD 04/05/2026 = 94.9432)
R28: =C2 -> 94.9432
