Workbook

Sheet 01_CLIENT_INFO
A2: TAXPAYER & ENGAGEMENT DETAILS
A3: 01 — Client Information | Start here for every new engagement
A5: Prepared by: Demo Preparer, Chartered Accountant | Sample Audit Firm | Blank layout
B7: FILING PERIOD
B8: Tax Period — From | E8: ℹ DD-MMM-YYYY format
B9: Tax Period — To | E9: ℹ DD-MMM-YYYY format
B10: Return Due Date | E10: ℹ 9 months from period end (Art. 53)
B11: Financial Year End
B12: Working Paper Reference | E12: ℹ e.g. WP/2026/CT/001
B13: Date of Preparation
B14: Date of Partner Approval
B15: ENTITY IDENTIFICATION
B16: Taxable Person Name (English) | E16: ℹ As per EmaraTax / TRN Certificate
B17: Tax Registration Number (TRN) | E17: ℹ 15-digit FTA-assigned TRN
B18: Entity Type | E18: ℹ LLC / Branch / Partnership / Natural Person
B19: Entity Sub-Type | E19: ℹ Mainland / Free Zone / Offshore
B20: Emirate | E20: ℹ Abu Dhabi / Dubai / Sharjah etc.
B21: Free Zone / Area | E21: ℹ If applicable
B22: Primary Business Activity | E22: ℹ As per trade licence
B23: Country of Incorporation
B24: Accounting Basis | E24: ℹ Accrual (mandatory if Revenue > AED 50M)
B25: Financial Statements Standard | E25: ℹ IFRS / IFRS for SMEs
B26: Audited Financial Statements? | E26: ℹ Mandatory for ALL QFZPs; required if Revenue > AED 50M
B27: Revenue (AED)
B28: Average Number of Employees
B29: Member of MNE Group? | E29: ℹ Relevant for Pillar Two / CbCR
B30: Free Zone Entity? | E30: ℹ Yes / No
B31: Qualifies as QFZP? | E31: ℹ Per Art. 18 & CD 100/2023
B32: ADVISOR DETAILS (NON-EDITABLE)
B33: Prepared by | C33: Demo Preparer, Chartered Accountant
B34: Firm Name | C34: Sample Audit Firm
B35: Email | C35: info@example.com
B36: Phone | C36: +971 4 000 0000

Sheet 02_ELECTIONS
A2: ELECTIONS & RELIEFS (FDL 47/2022)
A3: 02 — Review each carefully — some are IRREVOCABLE once filed
A4: A single wrong election can affect the entire period — verify with partner before submission
A5: Prepared by: Demo Preparer, Chartered Accountant | Sample Audit Firm | Blank layout
B7: # | C7: Election / Relief | D7: Answer | E7: Annex | F7: Law Reference & Key Condition
B8: 01 | C8: Small Business Relief (SBR) | D8: NO | E8: A | F8: Art. 21 / MD 73/2023 as amended by MD 131/2026 | Revenue ≤ AED 3M in current & ALL prior periods (from 1 Jun 2023). Available for tax periods ending on or before 31 Dec 2029 (was 31 Dec 2026). Not available to QFZPs or MNE-group members ≥ EUR 750M. Nil taxable income. TP arm's length still required.
B9: 02 | C9: Realisation Basis — All Assets & Liabilities | D9: NA | E9: B | F9: Art. 20(3) / MD 134/2023 | IRREVOCABLE after first CT return. Defers unrealised gains/losses until realisation.
B10: 03 | C10: Realisation Basis — Capital Account Only | D10: NA | E10: B | F10: Art. 20(3) / MD 134/2023 | Revenue-account unrealised G/L remain taxable. Capital account deferred.
B11: 04 | C11: Foreign PE Exemption | D11: NO | E11: C | F11: Art. 24 | Foreign PE taxed ≥9% in host jurisdiction. If elected: no FTC offset for that PE.
B12: 05 | C12: Pre-period Qualifying Immovable Property | D12: NO | E12: D | F12: MD 120/2023 (transitional rules) | Time-apportionment or valuation method. Irrevocable.
B13: 06 | C13: Pre-period Qualifying Intangible Asset | D13: NO | E13: E | F13: MD 120/2023 (transitional rules) | Time-apportionment method only. Irrevocable.
B14: 07 | C14: Pre-period Financial Asset / Liability | D14: NO | E14: F | F14: MD 120/2023 (transitional rules) | Valuation method only. Irrevocable.
B15: 08 | C15: Qualifying Group Relief (Intra-group Transfer) | D15: NO | E15: G | F15: Art. 26 / MD 132/2023 | ≥75% ownership, same FY-end, same GAAP, no QFZP/exempt persons involved.
B16: 09 | C16: Business Restructuring Relief | D16: NO | E16: H | F16: Art. 27 / MD 133/2023 | Whole/distinct business transferred for shares. Valid commercial reason required.

Sheet 22_BUSINESS_RESTRUCTURING
C2: BUSINESS RESTRUCTURING RELIEF SCHEDULE (ART. 27)
C3: 22 — Art. 27 FDL No. 47 of 2022 | MD 133/2023 | Activate when Election 09 in 02_ELECTIONS = YES
C4: IF ELECTION 09 = NO: This schedule is not applicable. If = YES: complete ALL sections below. Gain/loss deferred amount auto-feeds CT Computation Step 3 Row R2.
C5: Prepared by: Demo Preparer, Chartered Accountant | Sample Audit Firm | Blank layout
B7: =IF(UPPER(TRIM('02_ELECTIONS'!D16))="YES","✅ ELECTION 09 = YES — This schedule is ACTIVE. Complete all sections below.","⚠ ELECTION 09 = NO / NOT SET — This schedule is inactive. If restructuring occurred, set Election 09 to YES in sheet 02_ELECTIONS first.")
B8: LEGAL BASIS — Art. 27 FDL No. 47 of 2022 | Ministerial Decision No. 133 of 2023 Business Restructuring Relief: Where a taxpayer transfers a business or part of a business to another person in exchange for shares or other ownership interests — the resulting gain or loss may be EXCLUDED from taxable income (deferred, not exempt). CONDITIONS: (1) Transfer must be for valid commercial reasons, not tax avoidance (2) Both parties consent in writing (3) Consideration is ONLY shares/ownership interests — no cash component (4) No related party manipulation (5) Gain/loss recognised when shares subsequently disposed of (Art. 27(3)) | CLAWBACK: Relief withdrawn if shares disposed within 2 years of transfer unless exceptional circumstances exist (MD 133/2023 Art. 4)
B9: PART A — ELIGIBILITY CONDITIONS (Art. 27 / MD 133/2023 — ALL must be YES)
B10: # | C10: Condition | D10: Met? (YES/NO/NA) | E10: Law Reference
B11: E1 | C11: Transfer is of a whole or distinct part of a going-concern business | E11: Art. 27(1)(a) FDL 47/2022
B12: E2 | C12: Consideration received consists SOLELY of shares or ownership interest (no cash payment) | E12: Art. 27(1)(b) — MD 133/2023 Art. 2
B13: E3 | C13: The restructuring is undertaken for valid commercial reasons (not tax avoidance) | E13: Art. 27(1)(c) — GAAR Art. 50
B14: E4 | C14: Both transferor and transferee are taxable persons (or entities that would be if UAE resident) | E14: Art. 27(1) / MD 133/2023 Art. 1
B15: E5 | C15: Neither party is an Exempt Person (Art. 4) or a Qualifying Free Zone Person | E15: MD 133/2023 Art. 3(2)
B16: E6 | C16: Written consent/agreement exists between both parties confirming the relief election | E16: MD 133/2023 Art. 5
B17: E7 | C17: The shares/interests received are retained (not disposed) — or if disposed, 2-year rule noted | E17: Art. 27(3) — Clawback risk
B18: =IF(COUNTIF(D11:D17,"NO")>0,"❌ RELIEF NOT AVAILABLE — One or more conditions not met. Correct before claiming relief.","✅ All conditions met — Relief may be claimed. Complete Parts B-E below.")
B20: PART B — RESTRUCTURING TRANSACTION DETAILS
B21: T1 | C21: Date of Restructuring / Transfer
B22: T2 | C22: Name of Transferor (entity transferring the business)
B23: T3 | C23: TRN of Transferor
B24: T4 | C24: Name of Transferee (entity receiving the business)
B25: T5 | C25: TRN of Transferee (if UAE registered)
B26: T6 | C26: Nature of Restructuring (merger / demerger / acquisition / conversion)
B27: T7 | C27: Brief description of the business transferred
B28: T8 | C28: Regulatory / Commercial Approval reference (Ministry, DED, FZ Authority)
B30: PART C — ASSETS & LIABILITIES TRANSFERRED (Art. 27 / MD 133/2023)
B31: Ref | C31: Asset / Liability Category | D31: Book Value (AED) | E31: Tax Written-Down Value (AED) | F31: Gain / (Loss) (AED)
B32: A1 | C32: Property, Plant & Equipment | F32: =D32-E32
B33: A2 | C33: Intangible Assets (incl. Goodwill) | F33: =D33-E33
B34: A3 | C34: Financial Assets / Investments | F34: =D34-E34
B35: A4 | C35: Receivables & Debtors | F35: =D35-E35
B36: A5 | C36: Inventories / Stock | F36: =D36-E36
B37: A6 | C37: Other Current Assets | F37: =D37-E37
B38: A7 | C38: Total Assets Transferred | D38: =SUM(D32:D37) | E38: =SUM(E32:E37) | F38: =SUM(F32:F37)
B39: L1 | C39: Liabilities Assumed by Transferee | F39: =D39-E39
B40: L2 | C40: Other Liabilities Transferred | F40: =D40-E40
B41: L3 | C41: Total Liabilities Transferred | D41: =SUM(D39:D40) | E41: =SUM(E39:E40) | F41: =SUM(F39:F40)
B42: N1 | C42: NET ASSETS / (NET LIABILITIES) TRANSFERRED | D42: =D38-D41 | E42: =E38-E41 | F42: =F38-F41
B44: PART D — CONSIDERATION RECEIVED (Must be ONLY shares/ownership interests — no cash)
B45: S1 | C45: Number of shares / units received
...

Sheet 03_INCOME_SCHEDULE
A2: ACCOUNTING SCHEDULES (IFRS / IAS 1)
A3: 03 — Enter from audited or management financial statements
A4: Revenue > AED 50M: audited IFRS financial statements mandatory (Art. 54)
A5: Prepared by: Demo Preparer, Chartered Accountant | Sample Audit Firm | Blank layout
B7: Ref | C7: Description | D7: AED (Current) | E7: AED (Prior) | F7: Notes
B8: STATEMENT OF PROFIT OR LOSS
B9: S1.1 | C9: Operating Revenue / Turnover | F9: IFRS 15
B10: S1.2 | C10: Less: Cost of Revenue / COGS
C11: GROSS PROFIT / (LOSS) | D11: =D9-D10 | E11: =E9-E10
B12: S1.3 | C12: Salaries, Wages & Related Charges | F12: GOSI / DEWS / EoSB
B13: S1.4 | C13: Depreciation & Amortisation | F13: Incl. IFRS 16 ROU assets
B14: S1.5 | C14: Interest Income (enter as negative / credit) | F14: Taxable unless specifically exempt
B15: S1.6 | C15: Interest Expenditure | F15: Subject to Art. 30 cap
B16: S1.7 | C16: FX (Gains) / Losses
B17: S1.8 | C17: (Gains) / Losses on Disposal | F17: Art. 20 — cost basis
B18: S1.9 | C18: Entertainment Expenses | F18: 50% deductible — Art. 32
B19: S1.10 | C19: Fines & Penalties | F19: Non-deductible — Art. 33(1)(b)
B20: S1.11 | C20: Donations & Grants | F20: QPBE only — CD 37/2023
B21: S1.12 | C21: Other Operating Expenses
B22: S1.13 | C22: Non-Operating Income (Dividend Received, Other)
C23: NET PROFIT / (LOSS) BEFORE TAX | D23: =D11-SUM(D12:D21)+D22 | E23: =E11-SUM(E12:E21)+E22
C24: OCI: Items that will NOT be reclassified to profit or loss
C25: OCI: Items that MAY be reclassified to profit or loss
C26: TOTAL COMPREHENSIVE INCOME FOR THE YEAR | D26: =D23+D24+D25 | E26: =E23+E24+E25
B27: STATEMENT OF FINANCIAL POSITION
B28: S3.1 | C28: Total Current Assets
B29: S3.2 | C29: Total Non-Current Assets (PPE + Intangibles + Financial Assets + Other)
C30: TOTAL ASSETS | D30: =D28+D29 | E30: =E28+E29
B31: S3.3 | C31: Total Current Liabilities
B32: S3.4 | C32: Total Non-Current Liabilities
C33: TOTAL LIABILITIES | D33: =D31+D32 | E33: =E31+E32
B34: S3.5 | C34: Share Capital
B35: S3.6 | C35: Retained Earnings / (Deficit)
B36: S3.7 | C36: Other Equity
C37: TOTAL EQUITY | D37: =D34+D35+D36 | E37: =E34+E35+E36
C38: BS CHECK: Assets = Liabilities + Equity | D38: =IF(ABS(D30-D33-D37)<1,"✅ BALANCED","❌ MISMATCH") | E38: =IF(ABS(E30-E33-E37)<1,"✅ BALANCED","❌ MISMATCH")

Sheet 04_ADJUSTMENTS
A2: ADJUSTMENTS & EXEMPT INCOME
A3: 04 — Positive = ADD to taxable income | Negative = DEDUCT
A4: Art. 22-33 FDL 47/2022
A5: Prepared by: Demo Preparer, Chartered Accountant | Sample Audit Firm | Blank layout
B7: Ref | C7: Description / Statutory Basis | D7: AED Amount | E7: Law Reference
C8: A — EXEMPT INCOME (Enter as NEGATIVE)
B9: A1 | C9: Domestic Dividends (UAE resident entity) | E9: Art. 22 — 100% exempt, no conditions
B10: A2 | C10: Participation Exemption — Foreign Dividends | E10: Art. 23 — ≥5% hold, ≥12m, ≥9% CT, <50% passive
B11: A3 | C11: Participation Exemption — Disposal Gain | E11: Art. 23 — same conditions as A2
B12: A4 | C12: Foreign PE Exemption (if election made) | E12: Art. 24 — PE taxed ≥9% in host jurisdiction
B13: A5 | C13: Non-Resident Ships / Aircraft Income | E13: Art. 25 — reciprocal exemption
C14: TOTAL EXEMPT INCOME | D14: =SUM(D9:D13)
C15: B — NON-DEDUCTIBLE EXPENSES (Enter as POSITIVE)
B16: B1 | C16: Entertainment — 50% disallowed (client/customer entertainment only; staff 100% deductible) | E16: Art. 32
B17: B2 | C17: Net Interest > 30% EBITDA — see Sheet 06_INTEREST_CAP | E17: Art. 30
B18: B3 | C18: Related Party Interest Disallowance | E18: Art. 31
B19: B4 | C19: Fines & Penalties (regulatory / government) | E19: Art. 33(1)(b)
B20: B5 | C20: Bribes & Illicit Payments | E20: Art. 33(1)(c)
B21: B6 | C21: Dividends / Profit Distributions to Owners | E21: Art. 33(1)(d)
B22: B7 | C22: UAE Corporate Tax itself | E22: Art. 33(1)(e)
B23: B8 | C23: Recoverable Input VAT | E23: Art. 33(1)(f)
B24: B9 | C24: Foreign Taxes Paid | E24: Art. 33(1)(g)
B25: B10 | C25: Non-QPBE Donations | E25: Art. 33(1)(a) — CD 37/2023
B26: B11 | C26: Depreciation on Exempt-Income Assets | E26: Art. 28
B27: B12 | C27: Excess Pension Contributions (> 15% of salary) | E27: Art. 29
... B29: B14 | C29: Other Non-Deductible | E29: Art. 33(2)
B30: B15 | C30: Connected Persons — Non-Arm's Length Excess (Art. 36) → Sheet 21 | D30: 0 | E30: Art. 36 FDL 47/2022 | MD 97/2023 | AED 500K threshold per person
C31: TOTAL NON-DEDUCTIBLE | D31: =SUM(D16:D30)
C32: C — OTHER ADJUSTMENTS
B33: C1 | C33: Unrealised Gains/(Losses) — Realisation Basis NOT elected | E33: Art. 20(3) / MD 134/2023
B34: C2 | C34: Other Adjustments | E34: Art. 33(2) — MD specified. Includes MD 173/2025: depreciation adjustment (lower of 4% of original cost p.a. and tax WDV) on fair-valued investment property IF the irrevocable election is made; add back on realisation.
C35: TOTAL OTHER ADJUSTMENTS | D35: =SUM(D33:D34)

Sheet 05_CT_COMPUTATION
A2: CORPORATE TAX COMPUTATION (INDIRECT METHOD)
A3: 05 — FDL No. 47 of 2022 | Auto-populated — do NOT override formulas
A4: Links: Sheets 03 04 06 07 08 09
A5: Prepared by: Demo Preparer, Chartered Accountant | Sample Audit Firm | Blank layout
B7: Ref | C7: Description | F7: AED Add+ | G7: AED Less- | H7: AED Balance
B8: STEP 1 — STARTING POINT (Art. 20)
B9: N1 | C9: Accounting Profit / (Loss) per Financial Statements | H9: ='03_INCOME_SCHEDULE'!D23
B10: STEP 2 — EXEMPT INCOME (Art. 22-25) | DEDUCT
B11: A1 | C11: Domestic Dividends | G11: ='04_ADJUSTMENTS'!D9
B12: A2 | C12: Participation Exemption — Foreign Dividends | G12: ='04_ADJUSTMENTS'!D10
B13: A3 | C13: Participation Exemption — Disposal Gain | G13: ='04_ADJUSTMENTS'!D11
B14: A4 | C14: Foreign PE Exemption | G14: ='04_ADJUSTMENTS'!D12
C15: TOTAL EXEMPT INCOME | G15: =SUM(G11:G14)
B16: STEP 3 — RELIEFS (Art. 26-27)
B17: R1 | C17: Qualifying Group Transfer Relief
B18: R2 | C18: Business Restructuring Relief | G18: ='22_BUSINESS_RESTRUCTURING'!D58
C19: TOTAL RELIEFS | G19: =SUM(G17:G18)
B20: STEP 4 — NON-DEDUCTIBLE EXPENSES (Art. 28-33) | ADD BACK
B21: B1 | C21: Entertainment 50% Disallowed | F21: ='04_ADJUSTMENTS'!D16
B22: B2 | C22: Net Interest > 30% EBITDA (Art. 30) | F22: ='06_INTEREST_CAP'!D19
B23: B3 | C23: Related Party Interest (Art. 31) | F23: ='04_ADJUSTMENTS'!D18
B24: B4 | C24: Fines & Penalties | F24: ='04_ADJUSTMENTS'!D19
B25: B5 | C25: Bribes & Illicit Payments | F25: ='04_ADJUSTMENTS'!D20
B26: B6 | C26: Dividends to Owners | F26: ='04_ADJUSTMENTS'!D21
B27: B7 | C27: UAE Corporate Tax | F27: ='04_ADJUSTMENTS'!D22
B28: B8 | C28: Recoverable Input VAT | F28: ='04_ADJUSTMENTS'!D23
B29: B9 | C29: Foreign Taxes Paid | F29: ='04_ADJUSTMENTS'!D24
B30: B10 | C30: Non-QPBE Donations | F30: ='04_ADJUSTMENTS'!D25
B31: B11 | C31: Depreciation on Exempt Assets | F31: ='04_ADJUSTMENTS'!D26
B32: B12 | C32: Excess Pension > 15% | F32: ='04_ADJUSTMENTS'!D27
B33: B13 | C33: TP Arm's Length Adjustment | F33: ='07_TP_SCHEDULE'!D18
B34: B14 | C34: Other Non-Deductible | F34: ='04_ADJUSTMENTS'!D29
B35: B15 | C35: Connected Persons — Non-Arm's Length Excess → Sheet 21 | F35: ='04_ADJUSTMENTS'!D30
C36: TOTAL NON-DEDUCTIBLE EXPENSES | F36: =SUM(F21:F35)
B37: STEP 5 — OTHER ADJUSTMENTS
B38: C1 | C38: Unrealised Gains/(Losses) | F38: ='04_ADJUSTMENTS'!D33
B39: C2 | C39: Other Adjustments | F39: ='04_ADJUSTMENTS'!D34
C40: TOTAL OTHER ADJUSTMENTS | F40: =SUM(F38:F39)
B42: TAXABLE INCOME BEFORE TAX LOSSES | H42: =H9-G15-G19+F36+F40
B43: STEP 6 — TAX LOSS UTILISATION (Art. 37-39)
...

Sheet 06_INTEREST_CAP
A2: NET INTEREST EXPENDITURE CAP (ART. 30)
A3: 06 — 30% EBITDA annual cap | AED 12M safe harbour | Excess c/f 10 years
A4: Art. 30-31 FDL 47/2022
A5: Prepared by: Demo Preparer, Chartered Accountant | Sample Audit Firm | Blank layout
B7: Ref | C7: Description | D7: AED Amount | E7: Notes
B8: I1 | C8: Interest Income (all sources) | E8: Per P&L Sheet 03
B9: I2 | C9: Interest Expenditure (all sources) | E9: Per P&L Sheet 03
C10: NET INTEREST EXPENDITURE (NIE) | D10: =IFERROR(D9-D8,0) | E10: If NIE ≤ 0: no disallowance needed
B11: E1 | C11: Accounting Profit (Net Profit before Tax) | D11: ='03_INCOME_SCHEDULE'!D23 | E11: Auto from Sheet 03
B12: E2 | C12: Add: Net Interest Expenditure (NIE) — auto from I1 | D12: =D10 | E12: Auto from I2
B13: E3 | C13: Add: Depreciation & Amortisation | D13: ='03_INCOME_SCHEDULE'!D13 | E13: Auto from Sheet 03
B14: E4 | C14: Add: Corporate Tax in P&L (if included) | E14: Enter from FS notes
C15: EBITDA (for 30% cap calculation) | D15: =D11+D12+D13+D14
B16: C1 | C16: 30% of EBITDA (Art. 30 annual cap) | D16: ='06_INTEREST_CAP'!D15*30% | E16: Maximum NIE deductible — Art. 30(1)
B17: C2 | C17: AED 12M Safe Harbour (MD 126/2023) | D17: =12000000
C18: Applicable Cap (higher of above) | D18: =MAX(D16,D17)
C19: Excess NIE Disallowed → Sheet 05 B2 | D19: =MAX('06_INTEREST_CAP'!D10-'06_INTEREST_CAP'!D18,0) | E19: Transferred to CT Computation Sheet 05
B20: CF1 | C20: NIE Disallowed B/F from Prior Period | E20: Prior year working papers
C21: Total NIE Available | D21: ='06_INTEREST_CAP'!D19+D20
C22: NIE Allowed This Period | D22: =MIN(D21,'06_INTEREST_CAP'!D18)
C23: NIE C/F to Next Period (10-year limit) | D23: =D21-D22

Sheet 07_TP_SCHEDULE
A2: RELATED PARTY TRANSFER PRICING SCHEDULE (ART. 34)
A3: 07 — RELATED PARTIES only (Art. 34-35) | Disclosure: aggregate > AED 40M OR single category > AED 4M | NOTE: Connected Persons (Art. 36) → see Sheet 21_CONNECTED_PERSONS (AED 500K threshold)
A4: RELATED PARTY = any person with ≥50% ownership/control, or member of same qualifying group | Art. 34-35 FDL 47/2022 | MD 97/2023 | OECD TP Guidelines (2022)
A5: ⚠ Managerial Remuneration / Salaries / Director Fees are CONNECTED PERSON items (Art. 36) — enter in Sheet 21_CONNECTED_PERSONS (AED 500K threshold per person), NOT here.
B7: Transaction Category | C7: Related Party Name | D7: Value (AED) | E7: AED 4M Threshold | F7: Disclosure? | G7: TP Method | H7: Tax Residency | I7: Arm's Length Value (AED) | J7: Tax Adjustment (AED)
B8: Related Party Sales (Goods) | E8: 4000000 | F8: =IF(D8>E8,"⚠ Disclose","✅ Below Threshold") | J8: =IFERROR(D8-I8,0)
B9: Related Party Purchases (Goods) | E9: 4000000 | F9: =IF(D9>E9,"⚠ Disclose","✅ Below Threshold") | J9: =IFERROR(D9-I9,0)
B10: Intercompany Services (Received) | E10: 4000000 | F10: =IF(D10>E10,"⚠ Disclose","✅ Below Threshold") | J10: =IFERROR(D10-I10,0)
B11: Intercompany Services (Provided) | E11: 4000000 | F11: =IF(D11>E11,"⚠ Disclose","✅ Below Threshold") | J11: =IFERROR(D11-I11,0)
B12: Intercompany Loans (Received) | E12: 4000000 | F12: =IF(D12>E12,"⚠ Disclose","✅ Below Threshold") | J12: =IFERROR(D12-I12,0)
B13: Intercompany Loans (Given) | E13: 4000000 | F13: =IF(D13>E13,"⚠ Disclose","✅ Below Threshold") | J13: =IFERROR(D13-I13,0)
B14: Royalties / IP Licensing | E14: 4000000 | F14: =IF(D14>E14,"⚠ Disclose","✅ Below Threshold") | J14: =IFERROR(D14-I14,0)
B15: Dividend / Profit Distribution | E15: 4000000 | F15: =IF(D15>E15,"⚠ Disclose","✅ Below Threshold") | J15: =IFERROR(D15-I15,0)
B16: AGGREGATE TOTAL | D16: =SUM(D8:D15) | F16: =IF(D16>40000000,"⚠ AED 40M EXCEEDED — FULL TP DOCS REQUIRED","✅ Below AED 40M Aggregate")
B17: ℹ IMPORTANT: The above categories are for RELATED PARTY transactions only (Art. 34-35 FDL 47/2022). Do NOT include Connected Person payments (Managerial Remuneration, Director Fees, Salaries, Management Fees, etc.) here. Those are disclosed separately in Sheet 21_CONNECTED_PERSONS under Art. 35 with a separate AED 500,000 threshold per person.
B18: TOTAL ARM'S LENGTH ADJUSTMENT (+ = add-back required) | D18: =SUM(J8:J15)

Sheet 08_TAX_LOSSES
A2: TAX LOSS UTILISATION (ART. 37-39)
A3: 08 — Carry forward indefinitely | 75% of taxable income cap per year
A4: No time limit on carry-forward | Group transfer permitted (Art. 42)
A5: Prepared by: Demo Preparer, Chartered Accountant | Sample Audit Firm | Blank layout
B7: Ref | C7: Description | D7: AED Amount | E7: Notes
B8: L1 | C8: Tax Losses B/F — Opening Balance | E8: Per prior year CT return
B9: L2 | C9: Losses Generated This Period (if TI < 0) | E9: Only if taxable income is negative
B10: L3 | C10: Losses Received from Group (Art. 42) | E10: Qualifying / Tax Group only
C11: TOTAL TAX LOSSES AVAILABLE | D11: =D8+D9+D10
B12: L4 | C12: Less: Losses Transferred Out | E12: Art. 26/42
C13: Losses Available for Use | D13: =D11-D12
B14: C1 | C14: Taxable Income Before Losses (Sheet 05) | D14: ='05_CT_COMPUTATION'!H42 | E14: Auto-linked from CT Computation
B15: C2 | C15: 75% Utilisation Cap (Art. 37(3)) | D15: =MAX('05_CT_COMPUTATION'!H42*75%,0)
C16: TAX LOSSES UTILISED (75% cap) | D16: =MIN(D15,D13)
C17: TAX LOSSES CARRIED FORWARD | D17: =D13-D16

Sheet 09_TAX_LIABILITY
A2: FINAL TAX LIABILITY, CREDITS & PAYMENT
A3: 09 — Art. 46-47 FDL 47/2022 | FTC: lesser-of test applies
A4: Return due 9 months from period end | CT payable by return due date
A5: Prepared by: Demo Preparer, Chartered Accountant | Sample Audit Firm | Blank layout
B7: Ref | C7: Description | D7: AED Amount | E7: Notes
B8: T1 | C8: Gross CT Liability | D8: ='05_CT_COMPUTATION'!H54 | E8: Auto from CT Computation Sheet 05
B9: CR1 | C9: Withholding Tax Credit (Art. 46) | E9: WHT suffered on UAE-source income
B10: CR2 | C10: Foreign Tax Credit (Art. 47) | E10: Lesser of: FTC suffered OR UAE CT attributable to same income
B11: CR3 | C11: CT Paid (advance / provisional) | E11: Per EmaraTax payment records
C12: TOTAL CREDITS | D12: =SUM(D9:D11)
C13: NET CT PAYABLE / (REFUND) | D13: =MAX('09_TAX_LIABILITY'!D8-'09_TAX_LIABILITY'!D12,0)
C14: REFUND DUE | D14: =MAX('09_TAX_LIABILITY'!D12-'09_TAX_LIABILITY'!D8,0) | E14: Art. 46(4)
B15: P1 | C15: Return Due Date | D15: ='01_CLIENT_INFO'!C10 | E15: 9 months from period end (Art. 53)
B16: P2 | C16: Actual Filing Date | E16: Enter actual date filed
C17: Late Filing Risk | D17: =IF(D16>D15,"⚠ LATE — PENALTY RISK","✅ ON TIME") | E17: CD 75/2023 as amended — AED 500 per month (or part) for first 12 months; AED 1,000 per month from month 13

Sheet 10_FREE_ZONE
A2: FREE ZONE / QFZP QUALIFYING INCOME
A3: 10 — Art. 18 & CD 100/2023 (qualifying income) & MD 229/2025 (activities) | 0% Qualifying Income | 9% Non-Qualifying
A4: De Minimis: Non-qualifying revenue ≤ LOWER of AED 5M OR 5% of total revenue
A5: Prepared by: Demo Preparer, Chartered Accountant | Sample Audit Firm | Blank layout
B7: Ref | C7: Description | D7: AED Amount | E7: Notes
B8: Q1 | C8: Total Revenue | E8: Per P&L Sheet 03
B9: Q2 | C9: Qualifying Income (0% rate) | E9: MD 229/2025 qualifying activities (replaces MD 265/2023)
C10: Non-Qualifying Revenue | D10: =IFERROR(D8-D9,0)
B11: DM1 | C11: De Minimis Threshold 1: AED 5,000,000 | D11: =5000000 | E11: Art. 18(3)
B12: DM2 | C12: De Minimis Threshold 2: 5% of Revenue | D12: =IFERROR(D8*5%,0) | E12: Art. 18(3)
C13: Applicable De Minimis (lower) | D13: =MIN(D11,D12)
C14: De Minimis Test | D14: =IF(D10<=D13,"✅ PASS — QFZP maintained","❌ FAIL — QFZP status lost for this and the next 4 tax periods; ALL income taxed at 9%")
B15: T1 | C15: CT on Qualifying Income (0%) | D15: =D9*0%
B16: T2 | C16: CT on Non-Qualifying Income (9%) | D16: =IFERROR(D10*9%,0)
C17: TOTAL CT — QFZP Entity | D17: =D15+D16
B19: FTA CT RETURN SCHEDULE — FREE ZONE ADDITIONAL DISCLOSURES
B20: # | C20: Question / Disclosure Item | D20: Answer / Amount | E20: Notes
B21: FZ1 | C21: Are all employees located in a free zone? | D21: Yes / No | E21: CD 100/2023
B22: FZ2 | C22: Total average number of full-time employees in the free zone | E22: CD 100/2023 — Adequate substance
B23: FZ3 | C23: Total operating expenditure incurred in deriving qualifying income (AED) | E23: CD 100/2023 — Substance test
B24: FZ4 | C24: Total capital expenditure incurred in deriving qualifying income (AED) | E24: CD 100/2023 — Substance test
B25: FZ5 | C25: Have any core income-generating activities been outsourced to an outsourcing provider? | D25: Yes / No | E25: CD 100/2023 — outsourcing / core income-generating activities
B26: FZ6 | C26: Total revenue per financial statement (AED) | E26: ='03_INCOME_SCHEDULE'!D9
B27: FZ7 | C27: Does the free zone person have a domestic or foreign permanent establishment? | D27: Yes / No | E27: Art. 14 FDL 47/2022
B28: FZ8 | C28: Does the FZP derive revenue from transactions with non-free zone persons in respect of commercial property in a free zone? | D28: Yes / No | E28: MD 229/2025 excluded activities
B29: FZ9 | C29: Does the FZP derive revenue from immovable property in a free zone that is NOT commercial property? | D29: Yes / No | E29: MD 229/2025 excluded activities
B30: FZ10 | C30: Does the FZP derive revenue from ownership or exploitation of intellectual property? | D30: Yes / No | E30: CD 100/2023 — Qualifying IP
B31: FZ11 | C31: Total revenue for the de minimis requirement (AED) | E31: Art. 18(3) FDL 47/2022
B32: FZ12 | C32: Revenue derived from excluded activities (AED) | E32: MD 229/2025 excluded activities
B33: FZ13 | C33: Revenue derived from activities that are NOT qualifying activities (where counterparty is a non-free zone person) (AED) | E33: CD 100/2023 / MD 229/2025
B34: FZ14 | C34: Revenue derived from transactions with free zone persons that are NOT the beneficial recipient of relevant services or goods (AED) | E34: CD 100/2023 / MD 229/2025
B35: FZ15 | C35: Total non-qualifying revenue (AED) | E35: =FZ12+FZ13+FZ14
B36: FZ16 | C36: Is the de minimis requirement met? | D36: Yes / No | E36: Art. 18(3) — ≤AED 5M AND ≤5% total rev
B37: FZ17 | C37: Revenue derived from free zone persons (excl. income from excluded activities) (AED) | E37: CD 100/2023
B38: FZ18 | C38: Revenue derived from non-free zone persons in respect of qualifying activities (AED) | E38: MD 229/2025 qualifying activities
B39: FZ19 | C39: Revenue attributable to qualifying income in respect of qualifying intellectual property (AED) | E39: CD 100/2023 — Qualifying IP
B40: FZ20 | C40: Does the QFZP distribute goods/materials in or from a Designated Zone? (If YES, an agreed-upon-procedures (ISRS 4400) report is required) | D40: Yes / No | E40: FTA Decision 6/2026 — periods starting on/after 1 Jan 2026
B41: FZ21 | C41: AUP report obtained and filed with FTA within 30 days after the CT return due date? (Yes / No / NA) | D41: Yes / No | E41: FTA Decision 6/2026 — if not filed, qualifying conditions treated as unmet: QFZP status lost for the period and following 4 periods

Sheet 14_QFZP_ELIGIBILITY
A2: QFZP ELIGIBILITY CHECKER
A3: 14 — Art. 18 FDL 47/2022 & Cabinet Decision No. 100/2023 (as replacing CD 55/2023) & MD 229/2025
A4: A single NO = QFZP status LOST for the entire tax period — all conditions mandatory
A5: Prepared by: Demo Preparer, Chartered Accountant | Sample Audit Firm | Blank layout
B7: # | C7: Condition (All Mandatory) | D7: Met? YES/NO/NA | E7: Law Reference
B8: C1 | C8: Entity incorporated/registered in a recognised UAE Free Zone | D8: NO | E8: Art. 18(1) FDL 47/2022
B9: C2 | C9: Entity has NOT elected to be subject to standard 9% CT regime | D9: NO | E9: Art. 18(6) FDL 47/2022
B10: C3 | C10: Entity maintains adequate substance in the Free Zone | D10: NO | E10: Art. 18(1)(a) / CD 100/2023
B11: C4 | C11: Entity derives Qualifying Income (subject to de minimis test) | D11: NO | E11: Art. 18(1)(b) / CD 100/2023
B12: C5 | C12: Entity has NOT derived income from Excluded Activities | D12: NO | E12: MD 229/2025 excluded activities
B13: C6 | C13: Entity complies with UAE Transfer Pricing rules (Art. 34-35) | D13: NO | E13: Art. 18(1)(c) FDL 47/2022
B14: C7 | C14: Entity prepares AUDITED financial statements | D14: NO | E14: Art. 18(1)(d) — MANDATORY for ALL QFZPs
B15: C8 | C15: No tainted mainland RP transactions outside Qualifying Activities | D15: NO | E15: Art. 18(2) / CD 100/2023 / MD 229/2025
B16: C9 | C16: Income maps to MD 229/2025 Qualifying Activities list | D16: NO | E16: MD 229/2025 qualifying activities
B17: C10 | C17: De Minimis Test: PASS (see Sheet 10_FREE_ZONE) | D17: NO | E17: Art. 18(3) — auto-check Sheet 10
B18: C11 | C18: Designated-Zone distributor: AUP report (ISRS 4400) obtained & filed within 30 days after return due date (NA if not a distributor) | D18: NA | E18: FTA Decision 6/2026
B19: =IF(COUNTIF(D8:D18,"NO")=0,"✅ QFZP ELIGIBLE — All conditions met","❌ QFZP STATUS NOT MET — Review failed conditions")
