Workbook
Name \: #REF!
Name \: #REF!
Name \0: #REF!
Name \0: #REF!
Name \1: #REF!
Name \1: #REF!
Name \A: #REF!
Name \A: #REF!
Name \A: #REF!
Name \A: #REF!
Name \A: #REF!
Name \B: #REF!
Name \c: #REF!
Name \D: #REF!
Name \E: #REF!
Name \F: #REF!
Name \G: #REF!
Name \H: #REF!
Name \i: #REF!
Name \J: #REF!
Name \K: #REF!
Name \L: #REF!
Name \m: #REF!
Name \n: #REF!
Name \o: #REF!
Name \P: #REF!
Name \P: #REF!
Name \P: #REF!
Name \P: #REF!
Name \P: #REF!
Name \Q: #REF!
Name \R: #REF!
Name \s: #REF!
Name \T: #REF!
Name \u: #REF!
Name \v: #REF!
Name \w: #REF!
Name \X: #REF!
Name \Y: #REF!
Name \Z: #REF!
Name _: #REF!
Name _: #REF!
Name _: #REF!
Name _: #REF!
Name _: #REF!
Name _..: #REF!
Name ________ANX315: #N/A
Name ________Dim1: #REF!
Name ________Dim2: #REF!
Name ________isb1: #REF!
Name ________SUM1: #REF!
Name ________SUM2: #REF!
Name ________SUM3: #REF!
Name _______ANX315: #N/A
Name _______Dim1: #REF!
Name _______Dim2: #REF!
Name _______isb1: #REF!
Name _______SUM1: #REF!
Name _______SUM2: #REF!
Name _______SUM3: #REF!

Sheet Assumptions
B2: Company Name
B3: Year ended: 31 December 2025
B5: Assumptions and Confirmations from Management
B6: The following assumptions and confirmations from management form the basis for the Corporate Tax computation presented in the following pages:
B8: Qualifying Free Zone Person | C8: The management has elected to avail the Qualifying Free Zone Person (QFZP) regime, under the UAE Corporate Tax Law.
B9: Realisation Basis | C9: The management has opted for the realisation basis Option 1.
B10: Transitional Rules | C10: The management has opted for Transitional Rules under the Corporate Tax Law.
B11: Expense Documentation | C11: The management has been informed of the requirement to maintain proper supporting documents for all expenses incurred by the company and recorded in the statement of profit and loss.
B12: Business Purpose of Expenses | C12: The management has confirmed that all expenses debited to the profit and loss account during the relevant tax period have been incurred wholly and exclusively for business purposes.
B13: Disallowed Expenses | C13: The management has confirmed that no expenses of a disallowed nature have been recorded in the books of accounts, other than those already disallowed in the tax computation.
B14: Exempt Income | C14: The management has confirmed that no exempt income has been recorded in the books of accounts.
B15: Related Party Transactions | C15: The management has confirmed that all related party transactions disclosed in the financial statements have been conducted at arm’s length in accordance with applicable transfer pricing regulations. However, no supporting documentation has been provided for verification. Management has also been made aware of the legal consequences of non-compliance with transfer pricing regulations and has agreed to maintain all necessary supporting documentation in place.
B16: Investments in Subsidiary | C16: The company has investments in subsidiaries; however, its books of accounts are not prepared in accordance with Ministerial Decision No. 134 of 2023 and IFRS. Non-compliance with these standards may result in administrative penalties imposed by the FTA.Accordingly, the computation has been prepared.
B18: Disclaimer This Corporate Tax computation has been prepared based on the information, documents, and explanations made available to us as of the date of this report. In the absence of formal confirmations and supporting evidence from the management, certain assumptions have been made in good faith to facilitate the preparation of this computation. These assumptions are outlined above. This computation is intended solely for internal use by the company for preliminary assessment purposes and does not constitute a final or binding tax filing with the Federal Tax Authority. We have not independently verified the completeness or accuracy of the financial information or the factual representations provided by the management. We do not express an audit or assurance opinion on the financial information or tax positions. Any deviation from the stated assumptions or changes in the applicable laws, guidance, or interpretations by the authorities may impact the final tax liability of the company. The responsibility for ensuring the accuracy and completeness of the information submitted to the FTA, including compliance with Corporate Tax regulations, rests solely with the company’s management. We recommend that the company obtain formal tax advice where necessary and maintain adequate documentation to support its tax positions in line with the requirements of the UAE Corporate Tax Law and relevant Executive Regulations.

Sheet Calculation of CT
C2: =+Assumptions!B2 -> Company Name
C3: =+Assumptions!B3 -> Year ended: 31 December 2025
C5: Basis of Accounting | D5: Accrual Basis
C6: Accounting Standards | D6: IFRS
C7: Related Party Transactions | D7: At Arm’s Length
C9: COMPUTATION OF TAXABLE INCOME/(LOSS) (based on draft FS provided by the management) | E9: Realisation Basis Option 1 (AED) | F9: Realisation Basis Option 2 (AED) | G9: Current Basis Option 3 (AED) | I9: Comments
C11: Accounting Net Profit/(Loss) | D11: A | E11: =Notes!C8 -> 99957686 | F11: 9858388 | G11: 9858388 | I11: Realisation Basis - Option 1
I12: Transitional Rule - No
B13: Deduct: | C13: Exempt Income/Other adjustments | I13: Business Activity
C14: Unrealised gains on capital items (Options 1 & 2) | E14: =Notes!C10 -> 71652138 | F14: 0 | G14: 0 | I14: PY: Business Activity - Sale of Motot Vehicles
C15: Unrealised gains on revenue items (Option 1): | E15: 0 | F15: 0 | G15: 0 | I15: In 2025, Activities of Holding Companies - So 100% Provided there.
C16: Income from Qualifying Activity (Holding of shares for investment purposes) | E16: 0
C17: Dividends & profit distributions received from resident juridical person | E17: 0 | F17: 0 | G17: 0
C18: Income from Participating Interest (Dividend / Capital Gains) | E18: 0 | F18: 0 | G18: 0 | I18: Realised gain from sale of shares
C19: Income form foreign Permanent Establishment (subject to election) | E19: 0 | F19: 0 | G19: 0
C20: Income from operating aircraft/ships in international transportation (For Non-residents only) | E20: 0 | F20: 0 | G20: 0
C21: Gain from transfers within a qualifying group | E21: 0 | F21: 0 | G21: 0
C22: Gain from qualified business restructuring | E22: 0 | F22: 0 | G22: 0
C23: Other Adjustments to the Accounting Income for Determining the Taxable Income specified in MD No. 134 | E23: 0 | F23: 0 | G23: 0
E24: 0 | F24: 0 | G24: 0
C25: Total Deductions | D25: B | E25: =SUM(E14:E24) -> 71652138 | F25: =SUM(F14:F24) -> 0 | G25: =SUM(G14:G24) -> 0
B27: Add: | C27: Non-deductible Expenses/Other adjustments:
C28: Unrealised loss on capital items (Options 1 & 2) | E28: 0 | F28: 0 | G28: 0
C29: Unrealised loss on revenue items (Option 1) | E29: =+Provision!F20 -> 0 | F29: 0 | G29: 0
C30: Loss from Qualifying Activity (Holding of shares for investment purposes) | E30: 0
C31: Expenses of capital nature | E31: 0 | F31: 0 | G31: 0
C32: Expenses incurred in deriving Exempt Income | E32: 0 | F32: 0 | G32: 0
C33: Expenses not incurred for the purposes of the Taxable Person’s Business | E33: 0 | F33: 0 | G33: 0
C34: Losses not connected with or arising out of the Taxable Person’s Business | E34: 0 | F34: 0 | G34: 0
C35: Interest charged in excess of allowable limit | E35: 0 | F35: 0 | G35: 0
C36: Non-deductible interest | E36: 0 | F36: 0 | G36: 0
C37: 50% of any entertainment, amusement or recreation expenses incurred for Taxable Person’s customers, shareholders, suppliers or other business partners | E37: 0 | F37: 0 | G37: ='Disallowed Expenses'!$D$10 -> 0
C38: Donations, grants or gifts made to a non-Qualifying Public Benefit Entity | E38: 0 | F38: 0 | G38: =+'Disallowed Expenses'!$D$16 -> 0
C39: Fines and penalties, other than amounts awarded as compensation for damages or breach of contract | E39: 0 | F39: 0 | G39: 0
C40: Expenses without Supporting Documents | E40: 0 | F40: 0
C41: Dividends, profit distributions or benefits of a similar nature paid to an owner of the Taxable Person | E41: 0 | F41: 0 | G41: 0
C42: Amounts withdrawn from the business by a natural person who is a Taxable Person or a partner in an Unincorporated Partnership | E42: 0 | F42: 0 | G42: 0
C43: Corporate Tax imposed on a Taxable Person as per the applicable Law | E43: 0 | F43: 0 | G43: 0
C44: Input Value Added Tax incurred by a Taxable Person that is recoverable as per the applicable Law | E44: 0 | F44: 0 | G44: 0
C45: Tax on income imposed on the Taxable Person outside UAE | E45: 0 | F45: 0 | G45: 0
...

Sheet UGUL
A1: ='Calculation of CT'!$C$2 -> Company Name
A2: ='Calculation of CT'!$C$3 -> Year ended: 31 December 2025
F3: Realisation Basis Option 1 (AED)
A4: Computation of Unrealised Gain / (Unrealised Loss) of Previous Tax Period that has been realised in the current tax period
A5: Description of Asset/Liability | B5: Date of Realisation Event | C5: Tax Period(s) in which the unrealised gain(s) / loss(es) was deferred? | D5: Was the unrealised gain(s) / loss(es) previously recognised through the Income Statement? | E5: Amount of previously unrealised gains which have been realised in the current Tax Period (AED) | F5: Amount of previously unrealised losses which have been realised in the current Tax Period (AED) | G5: 2024 Unrealised gain | H5: Total Shares | I5: Sold shares | J5: Realised Gain
A6: ABC | B6: 45667 | C6: 01/01/2024 - 31/12/2024 | D6: Yes | E6: 528840 | G6: 528840 | H6: 1500 | I6: 1500 | J6: =G6/H6*I6 -> 528840
A7: DEF | B7: 45658 | C7: 01/01/2024 - 31/12/2024 | D7: Yes | E7: 781691 | G7: 3908455 | H7: 2500 | I7: 500 | J7: =G7/H7*I7 -> 781691
A9: Total | E9: =SUM(E6:E8) -> 1310531
A11: Computation of Gain or Loss on sale of shares (Qualifying Activity)
A12: Description of Asset/Liability | B12: Date of Realisation Event | C12: No of shares at beginning of year | D12: No of shares sold | E12: No of shares at the end of year | F12: Realised gain or (loss) on sale of share
A13: ABC | B13: 45667 | C13: 1500 | D13: 1500 | E13: =C13-D13 -> 0 | F13: =306506.34*3.6725 -> 1125644.5
A14: DEF | B14: 45658 | C14: 2500 | D14: 500 | E14: =C14-D14 -> 2000 | F14: =-(415454.2*3.6725) -> -1525755.5
A16: Total | F16: =SUM(F13:F14) -> -400111.02

Sheet Provision
B1: =+'Calculation of CT'!C2 -> Company Name
B2: =+'Calculation of CT'!C3 -> Year ended: 31 December 2025
B3: Movement in Provisions
H4: (Amounts in AED)
A5: S/N | B5: Provision | C5: Ref. | D5: Provisions balance at the beginning of the period | E5: Provisions made during the year | F5: Provisions utilized during the year | G5: Adjustments | H5: Provisions balance at the end of the period
A6: 1 | B6: Provision for Incentive | H6: =+D6+E6-F6-G6 -> 0
A7: 2 | B7: Provision for Inventory | H7: =+D7+E7-F7-G7 -> 0
A8: 4 | B8: Provision for Leave | H8: =+D8+E8-F8-G8 -> 0
A9: 5 | B9: Provision for Doubtful Debts | H9: =+D9+E9-F9-G9 -> 0
A10: 3 | B10: Provision for Indemnity | H10: =+D10+E10-F10-G10 -> 0
A11: Total | D11: =SUM(D6:D10) -> 0 | E11: =SUM(E6:E10) -> 0 | F11: =SUM(F6:F10) -> 0 | G11: =SUM(G6:G10) -> 0 | H11: =SUM(H6:H10) -> 0
B13: Calculation of disallowed Provisions
A15: S/N | B15: Provision | C15: Ref. | D15: Provisions made during the year | E15: Adjustments | F15: Total Provision
A16: 1 | B16: Provision for Incentive | D16: =+E6 -> 0 | F16: =D16-E16 -> 0
A17: 2 | B17: Provision for Inventory | D17: =+E7 -> 0 | E17: =+G7 -> 0 | F17: =D17-E17 -> 0
A18: 3 | B18: Provision for Leave | D18: =+E8 -> 0 | F18: =D18-E18 -> 0
A19: 4 | B19: Provision for Doubtful Debts | D19: =+E9 -> 0 | F19: =D19-E19 -> 0
A20: Total | D20: =SUM(D16:D19) -> 0 | E20: =SUM(E16:E19) -> 0 | F20: =SUM(F16:F19) -> 0
B22: Disallowed (Provisions other than Provision for Idemnity) | F22: =+F20 -> 0

Sheet DTA & DTL Working
B1: ='Calculation of CT'!$C$2 -> Company Name
B2: ='Calculation of CT'!$C$3 -> Year ended: 31 December 2025
B4: Computation of Deferred Tax Asset/Liability [DTA/(DTL)] | D4: =+'Calculation of CT'!E9 -> Realisation Basis Option 1 (AED)
F5: (Amounts in AED)
B6: Assest/Liabilities | C6: Carrying Value | D6: Tax Base | E6: Difference | F6: CT rate | G6: DTA/(DTL)
B7: Property and equipment | C7: 0 | D7: =C7 -> 0 | E7: =D7-C7 -> 0 | F7: 0.09 | G7: =E7*F7 -> 0
B8: Inventories | C8: 0 | D8: =C8 -> 0 | E8: =D8-C8 -> 0 | F8: 0.09 | G8: =E8*F8 -> 0
B9: Due from Related Parties | C9: 0 | D9: =C9 -> 0 | E9: =D9-C9 -> 0 | F9: 0.09 | G9: =E9*F9 -> 0
B10: Trade and other receivables | C10: 0 | D10: =C10 -> 0 | E10: =D10-C10 -> 0 | F10: 0.09 | G10: =E10*F10 -> 0
B11: Cash and cash equivalents | C11: 0 | D11: =C11 -> 0 | E11: =D11-C11 -> 0 | F11: 0.09 | G11: =E11*F11 -> 0
B12: Share Capital | C12: 0 | D12: =C12 -> 0 | E12: =D12-C12 -> 0 | F12: 0.09 | G12: =E12*F12 -> 0
B13: Statutory Reserve | C13: 0 | D13: =C13 -> 0 | E13: =D13-C13 -> 0 | F13: 0.09 | G13: =E13*F13 -> 0
B14: Retained Earnings | C14: 0 | D14: =C14 -> 0 | E14: =D14-C14 -> 0 | F14: 0.09 | G14: =E14*F14 -> 0
B15: Shareholder's Current Account | C15: 0 | D15: =C15 -> 0 | E15: =D15-C15 -> 0 | F15: 0.09 | G15: =E15*F15 -> 0
B16: Provision for employees' end of service benefits | C16: 0 | D16: =C16 -> 0 | E16: =D16-C16 -> 0 | F16: 0.09 | G16: =E16*F16 -> 0
B17: Borrowings | C17: 0 | D17: =C17 -> 0 | E17: =D17-C17 -> 0 | F17: 0.09 | G17: =E17*F17 -> 0
B18: Due to Related Parties | C18: 0 | D18: =C18 -> 0 | E18: =D18-C18 -> 0 | F18: 0.09 | G18: =E18*F18 -> 0
B19: Trade and other payables | C19: 0 | D19: =C19 -> 0 | E19: =D19-C19 -> 0 | F19: 0.09 | G19: =ROUND((E19*F19),0) -> 0
B21: Tax Loss carried forward | C21: 0 | D21: =-'Calculation of CT'!G63 -> -9858388 | E21: =D21 -> -9858388 | F21: 0.09 | G21: =ROUND((E21*F21),0) -> -887255
B23: DTA/(DTL) to be recognised for the period | G23: =SUM(G11:G22) -> -887255

Sheet Tax Loss Carried Forward
A1: ='Calculation of CT'!$C$2 -> Company Name
A2: ='Calculation of CT'!$C$3 -> Year ended: 31 December 2025
A4: Tax Losses Carried Forward | E4: =+'DTA & DTL Working'!D4 -> Realisation Basis Option 1 (AED)
E5: (Amounts in AED)
A6: Year | B6: Tax Loss Brought Forward | C6: Taxable Income /(Loss) for the period | D6: Tax Loss Relief (Upto 75% of Taxable Income) | E6: Tax Loss Carried Forward
A7: 2024 | B7: 0 | C7: =-'Calculation of CT'!$E$63 -> -29616079 | E7: =C7-D7 -> -29616079

Sheet Disallowed Expenses
A1: ='Calculation of CT'!$C$2 -> Company Name
A2: ='Calculation of CT'!$C$3 -> Year ended: 31 December 2025
A4: Details of Non-Deductible Expenses
A6: Account ID | B6: G/L Account | C6: Description | D6: Amount (AED) | E6: Treatment
A7: 50% of any entertainment, amusement or recreation expenses incurred for Taxable Person’s customers, shareholders, suppliers or other business partners
A8: 1 | C8: Ramadan Events | D8: 0 | E8: 50% Disallowed
A9: Sub Total | D9: =SUM(D8:D8) -> 0
A10: Disallowed | D10: 0
A12: Donations, grants or gifts made to a non-Qualifying Public Benefit Entity
A13: 1 | C13: Gifts | D13: 0 | E13: 100% Disallowed
A14: Sub Total | D14: =SUM(D13:D13) -> 0
A16: Disallowed Expense | D16: =+D14 -> 0

Sheet Freezone
A1: ='Calculation of CT'!$C$2 -> Company Name
A2: ='Calculation of CT'!$C$3 -> Year ended: 31 December 2025
A4: Details of Non-Qualifying Revenue
A6: Account ID | B6: Description | C6: Reference | D6: Amount (AED) | E6: Treatment
A7: 1 | B7: Profit on Sale of Property, Plant and Equipment | C7: Note 26 of FS 2025 | D7: 76190
A8: 2 | B8: Miscellaneous Income | C8: Note 26 of FS 2025 | D8: 51416
A9: Total | D9: =SUM(D7:D8) -> 127606
A12: Revenue derived from Free Zone Persons (except for income derived from Excluded Activities)
A14: Account ID | B14: Description | C14: Reference | D14: Amount (AED) | E14: Treatment
A15: 1 | B15: Revenue derived from Free Zone Persons | C15: Provided by management | D15: 1.2304003e+08
A16: Total | D16: =SUM(D15:D15) -> 1.2304003e+08
A19: Revenue derived from Non-Free Zone Persons in respect of Qualifying Activities
A21: Account ID | B21: Description | C21: Reference | D21: Amount (AED) | E21: Treatment
A22: 1 | B22: Revenue derived from Non-Free Zone Persons | C22: Note 24 of FS 2025 | D22: 146653293
A23: Total | D23: =SUM(D22:D22) -> 146653293
A26: Qualifying Activities Undertaken
A28: Account ID | B28: Description | E28: Treatment
A29: 1 | B29: Treasury and financing services to Related Parties.
A30: 2 | B30: Distribution of goods or materials in or from a Designated Zone
A31: 3 | B31: Any Activities that are ancillary to the Qualifying Activities specified above
A33: Total operating expenditure incurred in deriving Qualifying Income
A35: Account ID | B35: Description | C35: Reference | D35: Amount (AED) | E35: Treatment
A36: 1 | B36: Indirect Expenditure | C36: Provided by Management | D36: 23638652
A37: 2 | B37: Cost of Sales | C37: FS 2025 | D37: 232506777
A38: Total | D38: =SUM(D36:D37) -> 256145429
A41: Total capital expenditure incurred in deriving Qualifying Income
A43: Account ID | B43: Description | C43: Reference | D43: Amount (AED) | E43: Treatment
A44: 1 | B44: Capital Expenditure | C44: Provided by Management | D44: 3817108
A45: Total | D45: =SUM(D44:D44) -> 3817108
A48: EBITDA
A50: S.No. | B50: Description | C50: Amount (AED)
B51: Profit for the year before Tax | C51: 9858388
B52: Finance Cost | C52: 290528
B53: Interest Income | C53: -6790800
B54: Depreciation of Property, Plant and Equipment | C54: 3817108
B55: Amortisation of Intangible Assets | C55: 10497
A56: EBITDA | C56: =SUM(C51:C55) -> 7185721

Sheet Notes
D1: 3.6725
B2: USD | C2: AED
A3: Total Revenue | B3: 7946627
B4: 19510453
B5: =B4+B3 -> 27457080
A6: Revenue in AED | C6: =B5*D1 -> 1.0083613e+08
A8: Accounting Profit | B8: 27217886 | C8: =B8*D1 -> 99957686
A10: Unrealised gains on revenue items (Option 1): | B10: =-'TB 2025'!C35 -> 19510453 | C10: =B10*D1 -> 71652138
A12: Operating Expense | B12: 146458 | C12: =B12*D1 -> 537867.01
A15: EBITDA | B15: =C8 -> 99957686
A16: Finance Cost | B16: =92736*D1 -> 340572.96
B17: =B15+B16 -> 1.0029826e+08

Sheet TB 2025
A1: Elitser Holding revised TB shared on 20th Aug 2026 | F1: 3.6725
A2: Account | B2: Debit | C2: Credit | D2: Net | E2: Classification | F2: Debit | G2: Credit | H2: Net
A3: Commercial Bank of Dubai-AED | B3: 0 | C3: -0.05 | D3: =+B3+C3 -> -0.05 | E3: Asset | G3: =C3*$F$1 -> -0.183625 | H3: =D3*$F$1 -> -0.183625
A4: East Rising ltd | B4: 3600000 | C4: 0 | D4: =+B4+C4 -> 3600000 | E4: Asset | F4: =B4*$F$1 -> 13221000 | G4: =C4*$F$1 -> 0 | H4: =D4*$F$1 -> 13221000
A5: Fiduciary Deposit | B5: 5465815.2 | C5: 0 | D5: =+B5+C5 -> 5465815.2 | E5: Asset | F5: =B5*$F$1 -> 20073206 | G5: =C5*$F$1 -> 0 | H5: =D5*$F$1 -> 20073206
A6: Fixed Deposit-Rak Bank AED account | B6: 2722940.9 | C6: 0 | D6: =+B6+C6 -> 2722940.9 | E6: Asset | F6: =B6*$F$1 -> 10000000 | G6: =C6*$F$1 -> 0 | H6: =D6*$F$1 -> 10000000
A7: Investment -Elitser Technologies LLC | B7: 81688.22 | C7: 0 | D7: =+B7+C7 -> 81688.22 | E7: Asset | F7: =B7*$F$1 -> 299999.99 | G7: =C7*$F$1 -> 0 | H7: =D7*$F$1 -> 299999.99
A8: Investment in other Asset - Bull Value Incor shs | B8: 2010590 | C8: 0 | D8: =+B8+C8 -> 2010590 | E8: Asset | F8: =B8*$F$1 -> 7383891.8 | G8: =C8*$F$1 -> 0 | H8: =D8*$F$1 -> 7383891.8
A9: Investment in Other Asset-Eminence Global Fund | B9: 37098776 | C9: 0 | D9: =+B9+C9 -> 37098776 | E9: Asset | F9: =B9*$F$1 -> 1.3624526e+08 | G9: =C9*$F$1 -> 0 | H9: =D9*$F$1 -> 1.3624526e+08
A10: Investment in Other Assets - Howen Intl Investments | B10: 0 | C10: -0.34 | D10: =+B10+C10 -> -0.34 | E10: Asset | F10: =B10*$F$1 -> 0 | G10: =C10*$F$1 -> -1.24865 | H10: =D10*$F$1 -> -1.24865
A11: Investment in Other Assets - Urizen Fund | B11: 1255472.6 | C11: 0 | D11: =+B11+C11 -> 1255472.6 | E11: Asset | F11: =B11*$F$1 -> 4610723.2 | G11: =C11*$F$1 -> 0 | H11: =D11*$F$1 -> 4610723.2
A12: Investment in Other Assets-Abundantia Fund | B12: 2601487.2 | C12: 0 | D12: =+B12+C12 -> 2601487.2 | E12: Asset | F12: =B12*$F$1 -> 9553961.7 | G12: =C12*$F$1 -> 0 | H12: =D12*$F$1 -> 9553961.7
A13: Investment in Other Assets-Pinn Inc VCC SF | B13: 5154420 | C13: 0 | D13: =+B13+C13 -> 5154420 | E13: Asset | F13: =B13*$F$1 -> 18929607 | G13: =C13*$F$1 -> 0 | H13: =D13*$F$1 -> 18929607
A14: Investment in Shares- Biliti Inc | B14: 500000 | C14: 0 | D14: =+B14+C14 -> 500000 | E14: Asset | F14: =B14*$F$1 -> 1836250 | G14: =C14*$F$1 -> 0 | H14: =D14*$F$1 -> 1836250
A15: Julius Baer AED | B15: 2756297.2 | C15: 0 | D15: =+B15+C15 -> 2756297.2 | E15: Asset | F15: =B15*$F$1 -> 10122501 | G15: =C15*$F$1 -> 0 | H15: =D15*$F$1 -> 10122501
... A20: Undeposited Funds | B20: 11.41 | C20: 0 | D20: =+B20+C20 -> 11.41 | E20: Asset | F20: =B20*$F$1 -> 41.903225 | G20: =C20*$F$1 -> 0 | H20: =D20*$F$1 -> 41.903225
A21: Elitser Technologies LLC | C21: -14500.89 | D21: =+B21+C21 -> -14500.89 | E21: Liability | F21: =B21*$F$1 -> 0 | G21: =C21*$F$1 -> -53254.519 | H21: =D21*$F$1 -> -53254.519
A22: Interest Payable- loan | C22: -687628.64 | D22: =+B22+C22 -> -687628.64 | E22: Liability | F22: =B22*$F$1 -> 0 | G22: =C22*$F$1 -> -2525316.2 | H22: =D22*$F$1 -> -2525316.2
A23: Retained Earnings | C23: -38195543 | D23: =+B23+C23 -> -38195543 | E23: Equity | F23: =B23*$F$1 -> 0 | G23: =C23*$F$1 -> -1.4027313e+08 | H23: =D23*$F$1 -> -1.4027313e+08
A24: Share Capital- Jignasu Rathod | C24: -5000 | D24: =+B24+C24 -> -5000 | E24: Equity | F24: =B24*$F$1 -> 0 | G24: =C24*$F$1 -> -18362.5 | H24: =D24*$F$1 -> -18362.5
A25: Share Capital-Avenue Holdings | C25: -5000 | D25: =+B25+C25 -> -5000 | E25: Equity | F25: =B25*$F$1 -> 0 | G25: =C25*$F$1 -> -18362.5 | H25: =D25*$F$1 -> -18362.5
A26: Share Holder's current Account | C26: -1545593.7 | D26: =+B26+C26 -> -1545593.7 | E26: Equity | F26: =B26*$F$1 -> 0 | G26: =C26*$F$1 -> -5676193 | H26: =D26*$F$1 -> -5676193
A27: Dividend Income- Elitser Technologies LLC | C27: -6981504 | D27: =+B27+C27 -> -6981504 | E27: Income | F27: =B27*$F$1 -> 0 | G27: =C27*$F$1 -> -25639573 | H27: =D27*$F$1 -> -25639573
A28: Interest Income | C28: -186461.36 | D28: =+B28+C28 -> -186461.36 | E28: Income | F28: =B28*$F$1 -> 0 | G28: =C28*$F$1 -> -684779.34 | H28: =D28*$F$1 -> -684779.34
A29: Profit on Sale of Investments - Abundantia Fund | B29: 415454.2 | C29: 0 | D29: =+B29+C29 -> 415454.2 | E29: Income | F29: =B29*$F$1 -> 1525755.5 | G29: =C29*$F$1 -> 0 | H29: =D29*$F$1 -> 1525755.5
A30: Profit on Sale of Investments - Howen Intl investments | C30: -306506 | D30: =+B30+C30 -> -306506 | E30: Income | F30: =B30*$F$1 -> 0 | G30: =C30*$F$1 -> -1125643.3 | H30: =D30*$F$1 -> -1125643.3
A31: Audit Fees | B31: 10848 | D31: =+B31+C31 -> 10848 | E31: Expense | F31: =B31*$F$1 -> 39839.28 | G31: =C31*$F$1 -> 0 | H31: =D31*$F$1 -> 39839.28
A32: Bank Fees and Charges | B32: 130175.75 | D32: =+B32+C32 -> 130175.75 | E32: Expense | F32: =B32*$F$1 -> 478070.44 | G32: =C32*$F$1 -> 0 | H32: =D32*$F$1 -> 478070.44
A33: Consultant Expense | B33: 3651.33 | D33: =+B33+C33 -> 3651.33 | E33: Expense | F33: =B33*$F$1 -> 13409.509 | G33: =C33*$F$1 -> 0 | H33: =D33*$F$1 -> 13409.509
A34: Exchange Gain/Losses | B34: 12715.41 | D34: =+B34+C34 -> 12715.41 | E34: Expense | F34: =B34*$F$1 -> 46697.343 | G34: =C34*$F$1 -> 0 | H34: =D34*$F$1 -> 46697.343
A35: Fair Value Gain/Loss on Investment in Hedge Fund | B35: 0 | C35: -19510453 | D35: =+B35+C35 -> -19510453 | E35: Expense | F35: =B35*$F$1 -> 0 | G35: =C35*$F$1 -> -71652138 | H35: =D35*$F$1 -> -71652138
A36: Interest on Loan | B36: 452735.64 | D36: =+B36+C36 -> 452735.64 | E36: Expense | F36: =B36*$F$1 -> 1662671.6 | G36: =C36*$F$1 -> 0 | H36: =D36*$F$1 -> 1662671.6
B37: =SUM(B3:B36) -> 67449388 | C37: =SUM(C3:C36) -> -67449388 | D37: =SUM(D3:D36) -> 6.868504e-09
B40: =SUM(B27:B36) -> 1025580.3 | C40: =SUM(C27:C36) -> -26984924
C41: =C40-B40 -> -28010505

Sheet Taxes Paid Abroad
A1: ='Calculation of CT'!$C$2 -> Company Name
A2: ='Calculation of CT'!$C$3 -> Year ended: 31 December 2025
A4: Details of Taxes Paid Abroad
A6: S/N | B6: Country | C6: Nature of Income | D6: Amount (AED) | E6: Tax Rate | F6: Tax Paid (AED) | G6: Proof of payment available?
