Workbook

Sheet Cover
A1: Vanraj Furniture Industries Private Limited
A2: CIN: U36101MH2009PTC194327
A3: Projected financial statements for five years: FY 2026-27 to FY 2030-31
A4: Prepared by management for the purpose of valuation as at 1 June 2026
A5: Amounts in Rs. Lakhs
A7: Contents: Assumptions, Projected P&L, Projected Balance Sheet, Projected Cash Flow, Fixed Assets, Debt Schedule, Working Capital, Stub Period.
A8: The model is fully formula-driven: changing any assumption on the Assumptions sheet flows through all statements. The balance sheet balances through the cash flow statement; a check row on the Projected Balance Sheet should read nil in every year.
A9: Projections are management's estimates and have not been examined by the statutory auditors. Actual results may differ materially.
A10: All data in this workbook is imaginary and has been prepared solely for testing a valuation model.

Sheet Assumptions
A1: Vanraj Furniture Industries Private Limited
A2: Key assumptions for projected financial statements FY 2026-27 to FY 2030-31 (management projections)
A3: Amounts in Rs. Lakhs unless stated otherwise; percentages stored as fractions
A5: Assumption | B5: Basis / unit | C5: FY 2026-27 | D5: FY 2027-28 | E5: FY 2028-29 | F5: FY 2029-30 | G5: FY 2030-31
A6: Revenue and operating costs
A7: Revenue growth (year on year) | B7: % growth | C7: 0.18 | D7: 0.16 | E7: 0.14 | F7: 0.12 | G7: 0.1
A8: Material cost (cost of materials consumed net of inventory change) | B8: % of revenue | C8: 0.528 | D8: 0.526 | E8: 0.525 | F8: 0.524 | G8: 0.523
A9: Employee benefits expense | B9: % of revenue | C9: 0.123 | D9: 0.122 | E9: 0.121 | F9: 0.12 | G9: 0.12
A10: Other expenses | B10: % of revenue | C10: 0.21 | D10: 0.208 | E10: 0.206 | F10: 0.205 | G10: 0.204
A11: Other income (interest) on opening cash and bank balances | B11: % p.a. | C11: 0.05 | D11: 0.05 | E11: 0.05 | F11: 0.05 | G11: 0.05
A12: Capital expenditure and depreciation
A13: Capital expenditure on property, plant and equipment (cash) | B13: Rs. Lakhs | C13: 650 | D13: 450 | E13: 500 | F13: 400 | G13: 450
A14: Opening capital work-in-progress capitalised during the year | B14: Rs. Lakhs | C14: 260 | D14: 0 | E14: 0 | F14: 0 | G14: 0
A15: Depreciation on opening net block of PPE | B15: % of opening net block | C15: 0.105 | D15: 0.105 | E15: 0.105 | F15: 0.105 | G15: 0.105
A16: Depreciation on additions (half-year convention) | B16: % of additions | C16: 0.0525 | D16: 0.0525 | E16: 0.0525 | F16: 0.0525 | G16: 0.0525
A17: Additions to intangible assets (software) | B17: Rs. Lakhs | C17: 12 | D17: 12 | E17: 12 | F17: 12 | G17: 12
A18: Amortisation of intangible assets | B18: Rs. Lakhs | C18: 12 | D18: 12 | E18: 12 | F18: 12 | G18: 12
A19: Borrowings
A20: Fresh term loan drawdown (Bhiwandi capacity expansion) | B20: Rs. Lakhs | C20: 400 | D20: 0 | E20: 0 | F20: 0 | G20: 0
A21: Scheduled repayment of term borrowings | B21: Rs. Lakhs | C21: 280 | D21: 280 | E21: 280 | F21: 280 | G21: 280
A22: Interest rate on term borrowings (on average balance) | B22: % p.a. | C22: 0.0925 | D22: 0.0925 | E22: 0.0925 | F22: 0.0925 | G22: 0.0925
A23: Cash credit utilisation | B23: % of (inventories + receivables) | C23: 0.25 | D23: 0.23 | E23: 0.21 | F23: 0.19 | G23: 0.17
A24: Interest rate on cash credit (on average balance) | B24: % p.a. | C24: 0.1 | D24: 0.1 | E24: 0.1 | F24: 0.1 | G24: 0.1
A25: Working capital
A26: Trade receivables | B26: days of revenue | C26: 52 | D26: 52 | E26: 51 | F26: 50 | G26: 50
A27: Inventories | B27: days of material cost | C27: 108 | D27: 106 | E27: 104 | F27: 102 | G27: 100
A28: Trade payables | B28: days of material cost | C28: 75 | D28: 74 | E28: 73 | F28: 72 | G28: 72
A29: Short-term loans and advances and other current assets | B29: % of revenue | C29: 0.032 | D29: 0.032 | E29: 0.032 | F29: 0.032 | G29: 0.032
A30: Long-term loans and advances and other non-current assets | B30: Rs. Lakhs (closing) | C30: 220 | D30: 220 | E30: 220 | F30: 220 | G30: 220
A31: Other current liabilities (excluding current maturities of borrowings) | B31: % of revenue | C31: 0.018 | D31: 0.018 | E31: 0.018 | F31: 0.018 | G31: 0.018
A32: Long-term provisions (gratuity and leave) | B32: % of employee cost | C32: 0.06 | D32: 0.06 | E32: 0.06 | F32: 0.06 | G32: 0.06
A33: Short-term provisions | B33: Rs. Lakhs (closing) | C33: 115 | D33: 115 | E33: 115 | F33: 115 | G33: 115
A34: Deferred tax liability (net) | B34: Rs. Lakhs (closing) | C34: 130 | D34: 130 | E34: 130 | F34: 130 | G34: 130
A35: Taxation and other
A36: Effective income tax rate (section 115BAA) | B36: % of profit before tax | C36: 0.25168 | D36: 0.25168 | E36: 0.25168 | F36: 0.25168 | G36: 0.25168
A37: Days in year | B37: days | C37: 365 | D37: 365 | E37: 365 | F37: 365 | G37: 365
A38: Dividend payout | B38: % of profit after tax | C38: 0 | D38: 0.15 | E38: 0.2 | F38: 0.25 | G38: 0.25
A40: Basis: management projections prepared in August 2026 and approved by the Board on 20 August 2026. Growth is driven by the Bhiwandi capacity expansion (commissioned June 2026), new dealer network in South India and growth in institutional and e-commerce channels.
A41: Opening balances are taken from the audited financial statements for FY 2025-26. Term borrowings are shown gross of current maturities in these projections.
A42: All data is imaginary and prepared solely for testing a valuation model.
...

Sheet Projected P&L
A1: Vanraj Furniture Industries Private Limited
A2: Projected Statement of Profit and Loss
A3: Amounts in Rs. Lakhs
A5: Particulars | B5: FY 2025-26 (Actual, audited) | C5: FY 2026-27 (Projected) | D5: FY 2027-28 (Projected) | E5: FY 2028-29 (Projected) | F5: FY 2029-30 (Projected) | G5: FY 2030-31 (Projected)
A6: Revenue from operations | B6: 11400 | C6: =B6*(1+Assumptions!C7) -> 13452 | D6: =C6*(1+Assumptions!D7) -> 15604.32 | E6: =D6*(1+Assumptions!E7) -> 17788.925 | F6: =E6*(1+Assumptions!F7) -> 19923.596 | G6: =F6*(1+Assumptions!G7) -> 21915.955
A7: Other income | B7: 55 | C7: ='Projected Balance Sheet'!B26*Assumptions!C11 -> 44.65 | D7: ='Projected Balance Sheet'!C26*Assumptions!D11 -> 72.143523 | E7: ='Projected Balance Sheet'!D26*Assumptions!E11 -> 91.936369 | F7: ='Projected Balance Sheet'!E26*Assumptions!F11 -> 119.75457 | G7: ='Projected Balance Sheet'!F26*Assumptions!G11 -> 160.71581
A8: Total income | B8: =B6+B7 -> 11455 | C8: =C6+C7 -> 13496.65 | D8: =D6+D7 -> 15676.464 | E8: =E6+E7 -> 17880.861 | F8: =F6+F7 -> 20043.35 | G8: =G6+G7 -> 22076.671
A10: Material cost (cost of materials consumed net of change in inventories) | B10: 6010 | C10: =C6*Assumptions!C8 -> 7102.656 | D10: =D6*Assumptions!D8 -> 8207.8723 | E10: =E6*Assumptions!E8 -> 9339.1855 | F10: =F6*Assumptions!F8 -> 10439.964 | G10: =G6*Assumptions!G8 -> 11462.045
A11: Employee benefits expense | B11: 1410 | C11: =C6*Assumptions!C9 -> 1654.596 | D11: =D6*Assumptions!D9 -> 1903.727 | E11: =E6*Assumptions!E9 -> 2152.4599 | F11: =F6*Assumptions!F9 -> 2390.8315 | G11: =G6*Assumptions!G9 -> 2629.9146
A12: Other expenses | B12: 2420 | C12: =C6*Assumptions!C10 -> 2824.92 | D12: =D6*Assumptions!D10 -> 3245.6986 | E12: =E6*Assumptions!E10 -> 3664.5185 | F12: =F6*Assumptions!F10 -> 4084.3371 | G12: =G6*Assumptions!G10 -> 4470.8549
A13: EBITDA (excluding other income) | B13: =B6-B10-B11-B12 -> 1560 | C13: =C6-C10-C11-C12 -> 1869.828 | D13: =D6-D10-D11-D12 -> 2247.0221 | E13: =E6-E10-E11-E12 -> 2632.7609 | F13: =F6-F10-F11-F12 -> 3008.463 | G13: =G6-G10-G11-G12 -> 3353.1412
A14: Depreciation and amortisation expense | B14: ='Fixed Assets'!B22 -> 360 | C14: ='Fixed Assets'!C22 -> 418.875 | D14: ='Fixed Assets'!D22 -> 447.55313 | E14: ='Fixed Assets'!E22 -> 451.69505 | F14: ='Fixed Assets'!F22 -> 452.77707 | G14: ='Fixed Assets'!G22 -> 451.12047
A15: EBIT | B15: =B13-B14 -> 1200 | C15: =C13-C14 -> 1450.953 | D15: =D13-D14 -> 1799.469 | E15: =E13-E14 -> 2181.0658 | F15: =F13-F14 -> 2555.6859 | G15: =G13-G14 -> 2902.0207
A16: Finance costs | B16: 290 | C16: ='Debt Schedule'!C17 -> 244.61321 | D16: ='Debt Schedule'!D17 -> 245.19069 | E16: ='Debt Schedule'!E17 -> 223.10432 | F16: ='Debt Schedule'!F17 -> 197.87077 | G16: ='Debt Schedule'!G17 -> 170.14244
A17: Profit before tax | B17: =B15-B16+B7 -> 965 | C17: =C15-C16+C7 -> 1250.9898 | D17: =D15-D16+D7 -> 1626.4218 | E17: =E15-E16+E7 -> 2049.8979 | F17: =F15-F16+F7 -> 2477.5697 | G17: =G15-G16+G7 -> 2892.5941
A18: Tax expense | B18: 270 | C18: =MAX(0,C17)*Assumptions!C36 -> 314.84911 | D18: =MAX(0,D17)*Assumptions!D36 -> 409.33783 | E18: =MAX(0,E17)*Assumptions!E36 -> 515.9183 | F18: =MAX(0,F17)*Assumptions!F36 -> 623.55474 | G18: =MAX(0,G17)*Assumptions!G36 -> 728.00808
A19: Profit after tax | B19: =B17-B18 -> 695 | C19: =C17-C18 -> 936.14068 | D19: =D17-D18 -> 1217.084 | E19: =E17-E18 -> 1533.9796 | F19: =F17-F18 -> 1854.015 | G19: =G17-G18 -> 2164.586
A20: Dividend (including tax, if any) | B20: 0 | C20: =C19*Assumptions!C38 -> 0 | D20: =D19*Assumptions!D38 -> 182.56259 | E20: =E19*Assumptions!E38 -> 306.79592 | F20: =F19*Assumptions!F38 -> 463.50374 | G20: =G19*Assumptions!G38 -> 541.1465
A21: Profit retained | B21: =B19-B20 -> 695 | C21: =C19-C20 -> 936.14068 | D21: =D19-D20 -> 1034.5214 | E21: =E19-E20 -> 1227.1837 | F21: =F19-F20 -> 1390.5112 | G21: =G19-G20 -> 1623.4395
A23: Margins and growth
A24: Revenue growth | C24: =IF(B6=0,0,C6/B6-1) -> 0.18 | D24: =IF(C6=0,0,D6/C6-1) -> 0.16 | E24: =IF(D6=0,0,E6/D6-1) -> 0.14 | F24: =IF(E6=0,0,F6/E6-1) -> 0.12 | G24: =IF(F6=0,0,G6/F6-1) -> 0.1
A25: EBITDA margin | B25: =IF(B6=0,0,B13/B6) -> 0.13684211 | C25: =IF(C6=0,0,C13/C6) -> 0.139 | D25: =IF(D6=0,0,D13/D6) -> 0.144 | E25: =IF(E6=0,0,E13/E6) -> 0.148 | F25: =IF(F6=0,0,F13/F6) -> 0.151 | G25: =IF(G6=0,0,G13/G6) -> 0.153
A26: PAT margin | B26: =IF(B6=0,0,B19/B6) -> 0.060964912 | C26: =IF(C6=0,0,C19/C6) -> 0.069591189 | D26: =IF(D6=0,0,D19/D6) -> 0.077996603 | E26: =IF(E6=0,0,E19/E6) -> 0.086232282 | F26: =IF(F6=0,0,F19/F6) -> 0.093056242 | G26: =IF(G6=0,0,G19/G6) -> 0.098767586
A28: Legend: blue figures are hardcoded inputs; black figures are formulas within the sheet; green figures are links to other sheets.
A29: All figures are illustrative and imaginary, prepared solely for testing a valuation model. Amounts in Rs. Lakhs unless stated otherwise.
A30: FY 2025-26 column shows audited figures entered as inputs; material cost of Rs. 6,010 Lakhs is cost of materials consumed (Rs. 6,150) net of the increase in inventories (Rs. 140).

Sheet Projected Balance Sheet
A1: Vanraj Furniture Industries Private Limited
A2: Projected Balance Sheet
A3: Amounts in Rs. Lakhs
A5: Particulars | B5: FY 2025-26 (Actual, audited) | C5: FY 2026-27 (Projected) | D5: FY 2027-28 (Projected) | E5: FY 2028-29 (Projected) | F5: FY 2029-30 (Projected) | G5: FY 2030-31 (Projected)
A6: EQUITY AND LIABILITIES
A7: Share capital (equity Rs. 500 Lakhs and CCPS Rs. 300 Lakhs) | B7: 800 | C7: =B7 -> 800 | D7: =C7 -> 800 | E7: =D7 -> 800 | F7: =E7 -> 800 | G7: =F7 -> 800
A8: Reserves and surplus | B8: 3613 | C8: =B8+'Projected P&L'!C21 -> 4549.1407 | D8: =C8+'Projected P&L'!D21 -> 5583.662 | E8: =D8+'Projected P&L'!E21 -> 6810.8457 | F8: =E8+'Projected P&L'!F21 -> 8201.3569 | G8: =F8+'Projected P&L'!G21 -> 9824.7964
A9: Total shareholders' funds | B9: =B7+B8 -> 4413 | C9: =C7+C8 -> 5349.1407 | D9: =D7+D8 -> 6383.662 | E9: =E7+E8 -> 7610.8457 | F9: =F7+F8 -> 9001.3569 | G9: =G7+G8 -> 10624.796
A10: Term borrowings (including current maturities) | B10: ='Debt Schedule'!B10 -> 1555 | C10: ='Debt Schedule'!C10 -> 1675 | D10: ='Debt Schedule'!D10 -> 1395 | E10: ='Debt Schedule'!E10 -> 1115 | F10: ='Debt Schedule'!F10 -> 835 | G10: ='Debt Schedule'!G10 -> 555
A11: Deferred tax liabilities (net) | B11: ='Working Capital'!B14 -> 130 | C11: ='Working Capital'!C14 -> 130 | D11: ='Working Capital'!D14 -> 130 | E11: ='Working Capital'!E14 -> 130 | F11: ='Working Capital'!F14 -> 130 | G11: ='Working Capital'!G14 -> 130
A12: Long-term provisions | B12: ='Working Capital'!B12 -> 85 | C12: ='Working Capital'!C12 -> 99.27576 | D12: ='Working Capital'!D12 -> 114.22362 | E12: ='Working Capital'!E12 -> 129.14759 | F12: ='Working Capital'!F12 -> 143.44989 | G12: ='Working Capital'!G12 -> 157.79488
A13: Short-term borrowings (cash credit) | B13: ='Debt Schedule'!B14 -> 900 | C13: ='Debt Schedule'!C14 -> 1004.5143 | D13: ='Debt Schedule'!D14 -> 1059.5496 | E13: ='Debt Schedule'!E14 -> 1080.7868 | F13: ='Debt Schedule'!F14 -> 1072.8785 | G13: ='Debt Schedule'!G14 -> 1044.2202
A14: Trade payables | B14: ='Working Capital'!B10 -> 1260 | C14: ='Working Capital'!C10 -> 1459.4499 | D14: ='Working Capital'!D10 -> 1664.0618 | E14: ='Working Capital'!E10 -> 1867.8371 | F14: ='Working Capital'!F10 -> 2059.3902 | G14: ='Working Capital'!G10 -> 2261.0061
A15: Other current liabilities (excluding current maturities) | B15: ='Working Capital'!B11 -> 205 | C15: ='Working Capital'!C11 -> 242.136 | D15: ='Working Capital'!D11 -> 280.87776 | E15: ='Working Capital'!E11 -> 320.20065 | F15: ='Working Capital'!F11 -> 358.62472 | G15: ='Working Capital'!G11 -> 394.4872
A16: Short-term provisions | B16: ='Working Capital'!B13 -> 115 | C16: ='Working Capital'!C13 -> 115 | D16: ='Working Capital'!D13 -> 115 | E16: ='Working Capital'!E13 -> 115 | F16: ='Working Capital'!F13 -> 115 | G16: ='Working Capital'!G13 -> 115
A17: TOTAL EQUITY AND LIABILITIES | B17: =B9+SUM(B10:B16) -> 8663 | C17: =C9+SUM(C10:C16) -> 10074.517 | D17: =D9+SUM(D10:D16) -> 11142.375 | E17: =E9+SUM(E10:E16) -> 12368.818 | F17: =F9+SUM(F10:F16) -> 13715.7 | G17: =G9+SUM(G10:G16) -> 15282.305
A19: ASSETS
A20: Property, plant and equipment (net) | B20: ='Fixed Assets'!B11 -> 3420 | C20: ='Fixed Assets'!C11 -> 3923.125 | D20: ='Fixed Assets'!D11 -> 3937.5719 | E20: ='Fixed Assets'!E11 -> 3997.8768 | F20: ='Fixed Assets'!F11 -> 3957.0998 | G20: ='Fixed Assets'!G11 -> 3967.9793
A21: Capital work-in-progress | B21: ='Fixed Assets'!B15 -> 260 | C21: ='Fixed Assets'!C15 -> 0 | D21: ='Fixed Assets'!D15 -> 0 | E21: ='Fixed Assets'!E15 -> 0 | F21: ='Fixed Assets'!F15 -> 0 | G21: ='Fixed Assets'!G15 -> 0
A22: Intangible assets | B22: ='Fixed Assets'!B20 -> 40 | C22: ='Fixed Assets'!C20 -> 40 | D22: ='Fixed Assets'!D20 -> 40 | E22: ='Fixed Assets'!E20 -> 40 | F22: ='Fixed Assets'!F20 -> 40 | G22: ='Fixed Assets'!G20 -> 40
A23: Long-term loans and advances and other non-current assets | B23: ='Working Capital'!B9 -> 220 | C23: ='Working Capital'!C9 -> 220 | D23: ='Working Capital'!D9 -> 220 | E23: ='Working Capital'!E9 -> 220 | F23: ='Working Capital'!F9 -> 220 | G23: ='Working Capital'!G9 -> 220
A24: Inventories | B24: ='Working Capital'!B7 -> 1810 | C24: ='Working Capital'!C7 -> 2101.6078 | D24: ='Working Capital'!D7 -> 2383.6561 | E24: ='Working Capital'!E7 -> 2661.0282 | F24: ='Working Capital'!F7 -> 2917.4694 | G24: ='Working Capital'!G7 -> 3140.2862
A25: Trade receivables | B25: ='Working Capital'!B6 -> 1650 | C25: ='Working Capital'!C6 -> 1916.4493 | D25: ='Working Capital'!D6 -> 2223.0812 | E25: ='Working Capital'!E6 -> 2485.5758 | F25: ='Working Capital'!F6 -> 2729.2597 | G25: ='Working Capital'!G6 -> 3002.1857
A26: Cash and bank balances | B26: 893 | C26: ='Projected Cash Flow'!C38 -> 1442.8705 | D26: ='Projected Cash Flow'!D38 -> 1838.7274 | E26: ='Projected Cash Flow'!E38 -> 2395.0915 | F26: ='Projected Cash Flow'!F38 -> 3214.3163 | G26: ='Projected Cash Flow'!G38 -> 4210.543
A27: Short-term loans and advances and other current assets | B27: ='Working Capital'!B8 -> 370 | C27: ='Working Capital'!C8 -> 430.464 | D27: ='Working Capital'!D8 -> 499.33824 | E27: ='Working Capital'!E8 -> 569.24559 | F27: ='Working Capital'!F8 -> 637.55506 | G27: ='Working Capital'!G8 -> 701.31057
A28: TOTAL ASSETS | B28: =SUM(B20:B27) -> 8663 | C28: =SUM(C20:C27) -> 10074.517 | D28: =SUM(D20:D27) -> 11142.375 | E28: =SUM(E20:E27) -> 12368.818 | F28: =SUM(F20:F27) -> 13715.7 | G28: =SUM(G20:G27) -> 15282.305
A30: Check: total assets less total equity and liabilities (should be nil) | B30: =ROUND(B28-B17,2) -> 0 | C30: =ROUND(C28-C17,2) -> 0 | D30: =ROUND(D28-D17,2) -> 0 | E30: =ROUND(E28-E17,2) -> 0 | F30: =ROUND(F28-F17,2) -> 0 | G30: =ROUND(G28-G17,2) -> 0
A32: Memorandum
A33: Net debt (total borrowings less cash and bank balances) | B33: =B10+B13-B26 -> 1562 | C33: =C10+C13-C26 -> 1236.6438 | D33: =D10+D13-D26 -> 615.82219 | E33: =E10+E13-E26 -> -199.30462 | F33: =F10+F13-F26 -> -1306.4378 | G33: =G10+G13-G26 -> -2611.3228
A34: Debt to equity (total borrowings / shareholders' funds) | B34: =IF(B9=0,0,(B10+B13)/B9) -> 0.5563109 | C34: =IF(C9=0,0,(C10+C13)/C9) -> 0.50092425 | D34: =IF(D9=0,0,(D10+D13)/D9) -> 0.38450494 | E34: =IF(E9=0,0,(E10+E13)/E9) -> 0.2885076 | F34: =IF(F9=0,0,(F10+F13)/F9) -> 0.21195455 | G34: =IF(G9=0,0,(G10+G13)/G9) -> 0.15051773
A35: Return on capital employed (EBIT / (shareholders' funds + borrowings)) | B35: =IF((B9+B10+B13)=0,0,'Projected P&L'!B15/(B9+B10+B13)) -> 0.17472335 | C35: =IF((C9+C10+C13)=0,0,'Projected P&L'!C15/(C9+C10+C13)) -> 0.1807218 | D35: =IF((D9+D10+D13)=0,0,'Projected P&L'!D15/(D9+D10+D13)) -> 0.20360103 | E35: =IF((E9+E10+E13)=0,0,'Projected P&L'!E15/(E9+E10+E13)) -> 0.22240721 | F35: =IF((F9+F10+F13)=0,0,'Projected P&L'!F15/(F9+F10+F13)) -> 0.2342681 | G35: =IF((G9+G10+G13)=0,0,'Projected P&L'!G15/(G9+G10+G13)) -> 0.2374032
A36: Interest coverage (EBITDA / finance costs) | B36: =IF('Projected P&L'!B16=0,0,'Projected P&L'!B13/'Projected P&L'!B16) -> 5.3793103 | C36: =IF('Projected P&L'!C16=0,0,'Projected P&L'!C13/'Projected P&L'!C16) -> 7.6440188 | D36: =IF('Projected P&L'!D16=0,0,'Projected P&L'!D13/'Projected P&L'!D16) -> 9.1643857 | E36: =IF('Projected P&L'!E16=0,0,'Projected P&L'!E13/'Projected P&L'!E16) -> 11.800582 | F36: =IF('Projected P&L'!F16=0,0,'Projected P&L'!F13/'Projected P&L'!F16) -> 15.204181 | G36: =IF('Projected P&L'!G16=0,0,'Projected P&L'!G13/'Projected P&L'!G16) -> 19.707847
A38: Legend: blue figures are hardcoded inputs; black figures are formulas within the sheet; green figures are links to other sheets.
A39: All figures are illustrative and imaginary, prepared solely for testing a valuation model. Amounts in Rs. Lakhs unless stated otherwise.
A40: FY 2025-26 column reconciles to the audited balance sheet (total Rs. 8,663 Lakhs) with current maturities regrouped into term borrowings.

Sheet Projected Cash Flow
A1: Vanraj Furniture Industries Private Limited
A2: Projected Cash Flow Statement
A3: Amounts in Rs. Lakhs
A5: Particulars | B5: FY 2025-26 (Actual, audited) | C5: FY 2026-27 (Projected) | D5: FY 2027-28 (Projected) | E5: FY 2028-29 (Projected) | F5: FY 2029-30 (Projected) | G5: FY 2030-31 (Projected)
A6: A. Cash flow from operating activities
A7: Profit before tax | C7: ='Projected P&L'!C17 -> 1250.9898 | D7: ='Projected P&L'!D17 -> 1626.4218 | E7: ='Projected P&L'!E17 -> 2049.8979 | F7: ='Projected P&L'!F17 -> 2477.5697 | G7: ='Projected P&L'!G17 -> 2892.5941
A8: Add: depreciation and amortisation | C8: ='Projected P&L'!C14 -> 418.875 | D8: ='Projected P&L'!D14 -> 447.55313 | E8: ='Projected P&L'!E14 -> 451.69505 | F8: ='Projected P&L'!F14 -> 452.77707 | G8: ='Projected P&L'!G14 -> 451.12047
A9: Add: finance costs | C9: ='Projected P&L'!C16 -> 244.61321 | D9: ='Projected P&L'!D16 -> 245.19069 | E9: ='Projected P&L'!E16 -> 223.10432 | F9: ='Projected P&L'!F16 -> 197.87077 | G9: ='Projected P&L'!G16 -> 170.14244
A10: Less: other income | C10: =-'Projected P&L'!C7 -> -44.65 | D10: =-'Projected P&L'!D7 -> -72.143523 | E10: =-'Projected P&L'!E7 -> -91.936369 | F10: =-'Projected P&L'!F7 -> -119.75457 | G10: =-'Projected P&L'!G7 -> -160.71581
A11: Operating profit before working capital changes | C11: =SUM(C7:C10) -> 1869.828 | D11: =SUM(D7:D10) -> 2247.0221 | E11: =SUM(E7:E10) -> 2632.7609 | F11: =SUM(F7:F10) -> 3008.463 | G11: =SUM(G7:G10) -> 3353.1412
A12: (Increase) / decrease in inventories | C12: ='Working Capital'!B7-'Working Capital'!C7 -> -291.6078 | D12: ='Working Capital'!C7-'Working Capital'!D7 -> -282.04827 | E12: ='Working Capital'!D7-'Working Capital'!E7 -> -277.37213 | F12: ='Working Capital'!E7-'Working Capital'!F7 -> -256.44124 | G12: ='Working Capital'!F7-'Working Capital'!G7 -> -222.81676
A13: (Increase) / decrease in trade receivables | C13: ='Working Capital'!B6-'Working Capital'!C6 -> -266.44932 | D13: ='Working Capital'!C6-'Working Capital'!D6 -> -306.63189 | E13: ='Working Capital'!D6-'Working Capital'!E6 -> -262.49459 | F13: ='Working Capital'!E6-'Working Capital'!F6 -> -243.6839 | G13: ='Working Capital'!F6-'Working Capital'!G6 -> -272.92597
A14: (Increase) / decrease in other current assets and short-term loans and advances | C14: ='Working Capital'!B8-'Working Capital'!C8 -> -60.464 | D14: ='Working Capital'!C8-'Working Capital'!D8 -> -68.87424 | E14: ='Working Capital'!D8-'Working Capital'!E8 -> -69.907354 | F14: ='Working Capital'!E8-'Working Capital'!F8 -> -68.309471 | G14: ='Working Capital'!F8-'Working Capital'!G8 -> -63.755506
A15: (Increase) / decrease in non-current loans, advances and other assets | C15: ='Working Capital'!B9-'Working Capital'!C9 -> 0 | D15: ='Working Capital'!C9-'Working Capital'!D9 -> 0 | E15: ='Working Capital'!D9-'Working Capital'!E9 -> 0 | F15: ='Working Capital'!E9-'Working Capital'!F9 -> 0 | G15: ='Working Capital'!F9-'Working Capital'!G9 -> 0
A16: Increase / (decrease) in trade payables | C16: ='Working Capital'!C10-'Working Capital'!B10 -> 199.44986 | D16: ='Working Capital'!D10-'Working Capital'!C10 -> 204.61192 | E16: ='Working Capital'!E10-'Working Capital'!D10 -> 203.77532 | F16: ='Working Capital'!F10-'Working Capital'!E10 -> 191.55309 | G16: ='Working Capital'!G10-'Working Capital'!F10 -> 201.61587
A17: Increase / (decrease) in other current liabilities | C17: ='Working Capital'!C11-'Working Capital'!B11 -> 37.136 | D17: ='Working Capital'!D11-'Working Capital'!C11 -> 38.74176 | E17: ='Working Capital'!E11-'Working Capital'!D11 -> 39.322886 | F17: ='Working Capital'!F11-'Working Capital'!E11 -> 38.424078 | G17: ='Working Capital'!G11-'Working Capital'!F11 -> 35.862472
A18: Increase / (decrease) in provisions | C18: =('Working Capital'!C12+'Working Capital'!C13)-('Working Capital'!B12+'Working Capital'!B13) -> 14.27576 | D18: =('Working Capital'!D12+'Working Capital'!D13)-('Working Capital'!C12+'Working Capital'!C13) -> 14.947862 | E18: =('Working Capital'!E12+'Working Capital'!E13)-('Working Capital'!D12+'Working Capital'!D13) -> 14.923972 | F18: =('Working Capital'!F12+'Working Capital'!F13)-('Working Capital'!E12+'Working Capital'!E13) -> 14.302296 | G18: =('Working Capital'!G12+'Working Capital'!G13)-('Working Capital'!F12+'Working Capital'!F13) -> 14.344989
A19: Cash generated from operations | C19: =C11+SUM(C12:C18) -> 1502.1685 | D19: =D11+SUM(D12:D18) -> 1847.7692 | E19: =E11+SUM(E12:E18) -> 2281.009 | F19: =F11+SUM(F12:F18) -> 2684.3078 | G19: =G11+SUM(G12:G18) -> 3045.4663
A20: Less: income taxes paid | C20: =-'Projected P&L'!C18 -> -314.84911 | D20: =-'Projected P&L'!D18 -> -409.33783 | E20: =-'Projected P&L'!E18 -> -515.9183 | F20: =-'Projected P&L'!F18 -> -623.55474 | G20: =-'Projected P&L'!G18 -> -728.00808
A21: Net cash from operating activities (A) | C21: =C19+C20 -> 1187.3194 | D21: =D19+D20 -> 1438.4314 | E21: =E19+E20 -> 1765.0907 | F21: =F19+F20 -> 2060.7531 | G21: =G19+G20 -> 2317.4582
A23: B. Cash flow from investing activities
A24: Purchase of property, plant and equipment and intangibles | C24: =-'Fixed Assets'!C23 -> -662 | D24: =-'Fixed Assets'!D23 -> -462 | E24: =-'Fixed Assets'!E23 -> -512 | F24: =-'Fixed Assets'!F23 -> -412 | G24: =-'Fixed Assets'!G23 -> -462
A25: Interest and other income received | C25: ='Projected P&L'!C7 -> 44.65 | D25: ='Projected P&L'!D7 -> 72.143523 | E25: ='Projected P&L'!E7 -> 91.936369 | F25: ='Projected P&L'!F7 -> 119.75457 | G25: ='Projected P&L'!G7 -> 160.71581
A26: Net cash used in investing activities (B) | C26: =C24+C25 -> -617.35 | D26: =D24+D25 -> -389.85648 | E26: =E24+E25 -> -420.06363 | F26: =F24+F25 -> -292.24543 | G26: =G24+G25 -> -301.28419
A28: C. Cash flow from financing activities
A29: Proceeds from term borrowings | C29: ='Debt Schedule'!C8 -> 400 | D29: ='Debt Schedule'!D8 -> 0 | E29: ='Debt Schedule'!E8 -> 0 | F29: ='Debt Schedule'!F8 -> 0 | G29: ='Debt Schedule'!G8 -> 0
A30: Repayment of term borrowings | C30: =-'Debt Schedule'!C9 -> -280 | D30: =-'Debt Schedule'!D9 -> -280 | E30: =-'Debt Schedule'!E9 -> -280 | F30: =-'Debt Schedule'!F9 -> -280 | G30: =-'Debt Schedule'!G9 -> -280
A31: Increase / (decrease) in cash credit (net) | C31: ='Debt Schedule'!C14-'Debt Schedule'!B14 -> 104.51428 | D31: ='Debt Schedule'!D14-'Debt Schedule'!C14 -> 55.035294 | E31: ='Debt Schedule'!E14-'Debt Schedule'!D14 -> 21.237266 | F31: ='Debt Schedule'!F14-'Debt Schedule'!E14 -> -7.9083029 | G31: ='Debt Schedule'!G14-'Debt Schedule'!F14 -> -28.658319
A32: Finance costs paid | C32: =-'Projected P&L'!C16 -> -244.61321 | D32: =-'Projected P&L'!D16 -> -245.19069 | E32: =-'Projected P&L'!E16 -> -223.10432 | F32: =-'Projected P&L'!F16 -> -197.87077 | G32: =-'Projected P&L'!G16 -> -170.14244
A33: Dividend paid | C33: =-'Projected P&L'!C20 -> 0 | D33: =-'Projected P&L'!D20 -> -182.56259 | E33: =-'Projected P&L'!E20 -> -306.79592 | F33: =-'Projected P&L'!F20 -> -463.50374 | G33: =-'Projected P&L'!G20 -> -541.1465
A34: Net cash from / (used in) financing activities (C) | C34: =SUM(C29:C33) -> -20.098935 | D34: =SUM(D29:D33) -> -652.71799 | E34: =SUM(E29:E33) -> -788.66297 | F34: =SUM(F29:F33) -> -949.28281 | G34: =SUM(G29:G33) -> -1019.9473
A36: Net increase / (decrease) in cash and bank balances (A+B+C) | C36: =C21+C26+C34 -> 549.87046 | D36: =D21+D26+D34 -> 395.85692 | E36: =E21+E26+E34 -> 556.36408 | F36: =F21+F26+F34 -> 819.22483 | G36: =G21+G26+G34 -> 996.22675
A37: Opening cash and bank balances | C37: ='Projected Balance Sheet'!B26 -> 893 | D37: ='Projected Balance Sheet'!C26 -> 1442.8705 | E37: ='Projected Balance Sheet'!D26 -> 1838.7274 | F37: ='Projected Balance Sheet'!E26 -> 2395.0915 | G37: ='Projected Balance Sheet'!F26 -> 3214.3163
A38: Closing cash and bank balances | B38: 893 | C38: =C36+C37 -> 1442.8705 | D38: =D36+D37 -> 1838.7274 | E38: =E36+E37 -> 2395.0915 | F38: =F36+F37 -> 3214.3163 | G38: =G36+G37 -> 4210.543
A40: Free cash flow (memorandum, for valuation)
A41: Free cash flow to the firm (EBIT x (1 - tax rate) + D&A - capex - increase in net working capital) | C41: ='Projected P&L'!C15*(1-Assumptions!C36)+'Projected P&L'!C14-'Fixed Assets'!C23-'Working Capital'!C17 -> 460.71689 | D41: ='Projected P&L'!D15*(1-Assumptions!D36)+'Projected P&L'!D14-'Fixed Assets'!D23-'Working Capital'!D17 -> 917.93102 | E41: ='Projected P&L'!E15*(1-Assumptions!E36)+'Projected P&L'!E14-'Fixed Assets'!E23-'Working Capital'!E17 -> 1205.1544 | F41: ='Projected P&L'!F15*(1-Assumptions!F36)+'Projected P&L'!F14-'Fixed Assets'!F23-'Working Capital'!F17 -> 1614.7905 | G41: ='Projected P&L'!G15*(1-Assumptions!G36)+'Projected P&L'!G14-'Fixed Assets'!G23-'Working Capital'!G17 -> 1838.7407
A42: Free cash flow to equity (net cash from operations + investing + net borrowings - finance costs) | C42: =C21+C26+C29+C30+C31+C32 -> 549.87046 | D42: =D21+D26+D29+D30+D31+D32 -> 578.41952 | E42: =E21+E26+E29+E30+E31+E32 -> 863.15999 | F42: =F21+F26+F29+F30+F31+F32 -> 1282.7286 | G42: =G21+G26+G29+G30+G31+G32 -> 1537.3732
A44: Legend: blue figures are hardcoded inputs; black figures are formulas within the sheet; green figures are links to other sheets.
A45: All figures are illustrative and imaginary, prepared solely for testing a valuation model. Amounts in Rs. Lakhs unless stated otherwise.

Sheet Fixed Assets
A1: Vanraj Furniture Industries Private Limited
A2: Fixed assets and depreciation schedule
A3: Amounts in Rs. Lakhs
A5: Particulars | B5: FY 2025-26 (Actual, audited) | C5: FY 2026-27 (Projected) | D5: FY 2027-28 (Projected) | E5: FY 2028-29 (Projected) | F5: FY 2029-30 (Projected) | G5: FY 2030-31 (Projected)
A6: Property, plant and equipment
A7: Opening net block | C7: =B11 -> 3420 | D7: =C11 -> 3923.125 | E7: =D11 -> 3937.5719 | F7: =E11 -> 3997.8768 | G7: =F11 -> 3957.0998
A8: Add: capital work-in-progress capitalised | C8: =Assumptions!C14 -> 260 | D8: =Assumptions!D14 -> 0 | E8: =Assumptions!E14 -> 0 | F8: =Assumptions!F14 -> 0 | G8: =Assumptions!G14 -> 0
A9: Add: capital expenditure during the year | C9: =Assumptions!C13 -> 650 | D9: =Assumptions!D13 -> 450 | E9: =Assumptions!E13 -> 500 | F9: =Assumptions!F13 -> 400 | G9: =Assumptions!G13 -> 450
A10: Less: depreciation for the year | B10: 348 | C10: =C7*Assumptions!C15+(C8+C9)*Assumptions!C16 -> 406.875 | D10: =D7*Assumptions!D15+(D8+D9)*Assumptions!D16 -> 435.55313 | E10: =E7*Assumptions!E15+(E8+E9)*Assumptions!E16 -> 439.69505 | F10: =F7*Assumptions!F15+(F8+F9)*Assumptions!F16 -> 440.77707 | G10: =G7*Assumptions!G15+(G8+G9)*Assumptions!G16 -> 439.12047
A11: Closing net block | B11: 3420 | C11: =C7+C8+C9-C10 -> 3923.125 | D11: =D7+D8+D9-D10 -> 3937.5719 | E11: =E7+E8+E9-E10 -> 3997.8768 | F11: =F7+F8+F9-F10 -> 3957.0998 | G11: =G7+G8+G9-G10 -> 3967.9793
A12: Capital work-in-progress
A13: Opening balance | C13: =B15 -> 260 | D13: =C15 -> 0 | E13: =D15 -> 0 | F13: =E15 -> 0 | G13: =F15 -> 0
A14: Less: capitalised to PPE | C14: =Assumptions!C14 -> 260 | D14: =Assumptions!D14 -> 0 | E14: =Assumptions!E14 -> 0 | F14: =Assumptions!F14 -> 0 | G14: =Assumptions!G14 -> 0
A15: Closing balance | B15: 260 | C15: =C13-C14 -> 0 | D15: =D13-D14 -> 0 | E15: =E13-E14 -> 0 | F15: =F13-F14 -> 0 | G15: =G13-G14 -> 0
A16: Intangible assets
A17: Opening net carrying amount | C17: =B20 -> 40 | D17: =C20 -> 40 | E17: =D20 -> 40 | F17: =E20 -> 40 | G17: =F20 -> 40
A18: Add: additions | C18: =Assumptions!C17 -> 12 | D18: =Assumptions!D17 -> 12 | E18: =Assumptions!E17 -> 12 | F18: =Assumptions!F17 -> 12 | G18: =Assumptions!G17 -> 12
A19: Less: amortisation | B19: 12 | C19: =Assumptions!C18 -> 12 | D19: =Assumptions!D18 -> 12 | E19: =Assumptions!E18 -> 12 | F19: =Assumptions!F18 -> 12 | G19: =Assumptions!G18 -> 12
A20: Closing net carrying amount | B20: 40 | C20: =C17+C18-C19 -> 40 | D20: =D17+D18-D19 -> 40 | E20: =E17+E18-E19 -> 40 | F20: =F17+F18-F19 -> 40 | G20: =G17+G18-G19 -> 40
A22: Total depreciation and amortisation | B22: =B10+B19 -> 360 | C22: =C10+C19 -> 418.875 | D22: =D10+D19 -> 447.55313 | E22: =E10+E19 -> 451.69505 | F22: =F10+F19 -> 452.77707 | G22: =G10+G19 -> 451.12047
A23: Total cash capital expenditure (PPE and intangibles) | C23: =C9+C18 -> 662 | D23: =D9+D18 -> 462 | E23: =E9+E18 -> 512 | F23: =F9+F18 -> 412 | G23: =G9+G18 -> 462
A25: Legend: blue figures are hardcoded inputs; black figures are formulas within the sheet; green figures are links to other sheets.
A26: All figures are illustrative and imaginary, prepared solely for testing a valuation model. Amounts in Rs. Lakhs unless stated otherwise.
A27: FY 2025-26 column shows audited closing balances entered as inputs.

Sheet Debt Schedule
A1: Vanraj Furniture Industries Private Limited
A2: Borrowings and finance cost schedule
A3: Amounts in Rs. Lakhs
A5: Particulars | B5: FY 2025-26 (Actual, audited) | C5: FY 2026-27 (Projected) | D5: FY 2027-28 (Projected) | E5: FY 2028-29 (Projected) | F5: FY 2029-30 (Projected) | G5: FY 2030-31 (Projected)
A6: Term borrowings (term loans, vehicle loans and unsecured loans from directors, including current maturities)
A7: Opening balance | C7: =B10 -> 1555 | D7: =C10 -> 1675 | E7: =D10 -> 1395 | F7: =E10 -> 1115 | G7: =F10 -> 835
A8: Add: fresh drawdown | C8: =Assumptions!C20 -> 400 | D8: =Assumptions!D20 -> 0 | E8: =Assumptions!E20 -> 0 | F8: =Assumptions!F20 -> 0 | G8: =Assumptions!G20 -> 0
A9: Less: repayments | C9: =Assumptions!C21 -> 280 | D9: =Assumptions!D21 -> 280 | E9: =Assumptions!E21 -> 280 | F9: =Assumptions!F21 -> 280 | G9: =Assumptions!G21 -> 280
A10: Closing balance | B10: 1555 | C10: =C7+C8-C9 -> 1675 | D10: =D7+D8-D9 -> 1395 | E10: =E7+E8-E9 -> 1115 | F10: =F7+F8-F9 -> 835 | G10: =G7+G8-G9 -> 555
A11: Interest on term borrowings | C11: =(C7+C10)/2*Assumptions!C22 -> 149.3875 | D11: =(D7+D10)/2*Assumptions!D22 -> 141.9875 | E11: =(E7+E10)/2*Assumptions!E22 -> 116.0875 | F11: =(F7+F10)/2*Assumptions!F22 -> 90.1875 | G11: =(G7+G10)/2*Assumptions!G22 -> 64.2875
A12: Cash credit and working capital borrowings
A13: Opening balance | C13: =B14 -> 900 | D13: =C14 -> 1004.5143 | E13: =D14 -> 1059.5496 | F13: =E14 -> 1080.7868 | G13: =F14 -> 1072.8785
A14: Closing balance | B14: 900 | C14: =('Working Capital'!C7+'Working Capital'!C6)*Assumptions!C23 -> 1004.5143 | D14: =('Working Capital'!D7+'Working Capital'!D6)*Assumptions!D23 -> 1059.5496 | E14: =('Working Capital'!E7+'Working Capital'!E6)*Assumptions!E23 -> 1080.7868 | F14: =('Working Capital'!F7+'Working Capital'!F6)*Assumptions!F23 -> 1072.8785 | G14: =('Working Capital'!G7+'Working Capital'!G6)*Assumptions!G23 -> 1044.2202
A15: Interest on cash credit | C15: =(C13+C14)/2*Assumptions!C24 -> 95.225714 | D15: =(D13+D14)/2*Assumptions!D24 -> 103.20319 | E15: =(E13+E14)/2*Assumptions!E24 -> 107.01682 | F15: =(F13+F14)/2*Assumptions!F24 -> 107.68327 | G15: =(G13+G14)/2*Assumptions!G24 -> 105.85494
A17: Total finance costs | B17: 290 | C17: =C11+C15 -> 244.61321 | D17: =D11+D15 -> 245.19069 | E17: =E11+E15 -> 223.10432 | F17: =F11+F15 -> 197.87077 | G17: =G11+G15 -> 170.14244
A18: Total borrowings (closing) | B18: =B10+B14 -> 2455 | C18: =C10+C14 -> 2679.5143 | D18: =D10+D14 -> 2454.5496 | E18: =E10+E14 -> 2195.7868 | F18: =F10+F14 -> 1907.8785 | G18: =G10+G14 -> 1599.2202
A20: Legend: blue figures are hardcoded inputs; black figures are formulas within the sheet; green figures are links to other sheets.
A21: All figures are illustrative and imaginary, prepared solely for testing a valuation model. Amounts in Rs. Lakhs unless stated otherwise.
A22: FY 2025-26 term borrowings of Rs. 1,555 Lakhs comprise long-term borrowings of Rs. 1,350 Lakhs and current maturities of Rs. 205 Lakhs per the audited balance sheet.

Sheet Working Capital
A1: Vanraj Furniture Industries Private Limited
A2: Working capital schedule
A3: Amounts in Rs. Lakhs
A5: Particulars | B5: FY 2025-26 (Actual, audited) | C5: FY 2026-27 (Projected) | D5: FY 2027-28 (Projected) | E5: FY 2028-29 (Projected) | F5: FY 2029-30 (Projected) | G5: FY 2030-31 (Projected)
A6: Trade receivables | B6: 1650 | C6: ='Projected P&L'!C6*Assumptions!C26/Assumptions!C37 -> 1916.4493 | D6: ='Projected P&L'!D6*Assumptions!D26/Assumptions!D37 -> 2223.0812 | E6: ='Projected P&L'!E6*Assumptions!E26/Assumptions!E37 -> 2485.5758 | F6: ='Projected P&L'!F6*Assumptions!F26/Assumptions!F37 -> 2729.2597 | G6: ='Projected P&L'!G6*Assumptions!G26/Assumptions!G37 -> 3002.1857
A7: Inventories | B7: 1810 | C7: ='Projected P&L'!C10*Assumptions!C27/Assumptions!C37 -> 2101.6078 | D7: ='Projected P&L'!D10*Assumptions!D27/Assumptions!D37 -> 2383.6561 | E7: ='Projected P&L'!E10*Assumptions!E27/Assumptions!E37 -> 2661.0282 | F7: ='Projected P&L'!F10*Assumptions!F27/Assumptions!F37 -> 2917.4694 | G7: ='Projected P&L'!G10*Assumptions!G27/Assumptions!G37 -> 3140.2862
A8: Short-term loans and advances and other current assets | B8: 370 | C8: ='Projected P&L'!C6*Assumptions!C29 -> 430.464 | D8: ='Projected P&L'!D6*Assumptions!D29 -> 499.33824 | E8: ='Projected P&L'!E6*Assumptions!E29 -> 569.24559 | F8: ='Projected P&L'!F6*Assumptions!F29 -> 637.55506 | G8: ='Projected P&L'!G6*Assumptions!G29 -> 701.31057
A9: Long-term loans and advances and other non-current assets | B9: 220 | C9: =Assumptions!C30 -> 220 | D9: =Assumptions!D30 -> 220 | E9: =Assumptions!E30 -> 220 | F9: =Assumptions!F30 -> 220 | G9: =Assumptions!G30 -> 220
A10: Trade payables | B10: 1260 | C10: ='Projected P&L'!C10*Assumptions!C28/Assumptions!C37 -> 1459.4499 | D10: ='Projected P&L'!D10*Assumptions!D28/Assumptions!D37 -> 1664.0618 | E10: ='Projected P&L'!E10*Assumptions!E28/Assumptions!E37 -> 1867.8371 | F10: ='Projected P&L'!F10*Assumptions!F28/Assumptions!F37 -> 2059.3902 | G10: ='Projected P&L'!G10*Assumptions!G28/Assumptions!G37 -> 2261.0061
A11: Other current liabilities (excluding current maturities of borrowings) | B11: 205 | C11: ='Projected P&L'!C6*Assumptions!C31 -> 242.136 | D11: ='Projected P&L'!D6*Assumptions!D31 -> 280.87776 | E11: ='Projected P&L'!E6*Assumptions!E31 -> 320.20065 | F11: ='Projected P&L'!F6*Assumptions!F31 -> 358.62472 | G11: ='Projected P&L'!G6*Assumptions!G31 -> 394.4872
A12: Long-term provisions | B12: 85 | C12: ='Projected P&L'!C11*Assumptions!C32 -> 99.27576 | D12: ='Projected P&L'!D11*Assumptions!D32 -> 114.22362 | E12: ='Projected P&L'!E11*Assumptions!E32 -> 129.14759 | F12: ='Projected P&L'!F11*Assumptions!F32 -> 143.44989 | G12: ='Projected P&L'!G11*Assumptions!G32 -> 157.79488
A13: Short-term provisions | B13: 115 | C13: =Assumptions!C33 -> 115 | D13: =Assumptions!D33 -> 115 | E13: =Assumptions!E33 -> 115 | F13: =Assumptions!F33 -> 115 | G13: =Assumptions!G33 -> 115
A14: Deferred tax liability (net) | B14: 130 | C14: =Assumptions!C34 -> 130 | D14: =Assumptions!D34 -> 130 | E14: =Assumptions!E34 -> 130 | F14: =Assumptions!F34 -> 130 | G14: =Assumptions!G34 -> 130
A16: Net working capital (receivables + inventories + other current assets - payables - other current liabilities - short-term provisions) | B16: =B6+B7+B8-B10-B11-B13 -> 2250 | C16: =C6+C7+C8-C10-C11-C13 -> 2631.9353 | D16: =D6+D7+D8-D10-D11-D13 -> 3046.136 | E16: =E6+E7+E8-E10-E11-E13 -> 3412.8118 | F16: =F6+F7+F8-F10-F11-F13 -> 3751.2693 | G16: =G6+G7+G8-G10-G11-G13 -> 4073.2892
A17: Increase / (decrease) in net working capital | C17: =C16-B16 -> 381.93525 | D17: =D16-C16 -> 414.20072 | E17: =E16-D16 -> 366.67587 | F17: =F16-E16 -> 338.45744 | G17: =G16-F16 -> 322.01989
A18: Net working capital as % of revenue | B18: =IF('Projected P&L'!B6=0,0,B16/'Projected P&L'!B6) -> 0.19736842 | C18: =IF('Projected P&L'!C6=0,0,C16/'Projected P&L'!C6) -> 0.19565383 | D18: =IF('Projected P&L'!D6=0,0,D16/'Projected P&L'!D6) -> 0.19521107 | E18: =IF('Projected P&L'!E6=0,0,E16/'Projected P&L'!E6) -> 0.19185037 | F18: =IF('Projected P&L'!F6=0,0,F16/'Projected P&L'!F6) -> 0.18828274 | G18: =IF('Projected P&L'!G6=0,0,G16/'Projected P&L'!G6) -> 0.18585953
A20: Legend: blue figures are hardcoded inputs; black figures are formulas within the sheet; green figures are links to other sheets.
A21: All figures are illustrative and imaginary, prepared solely for testing a valuation model. Amounts in Rs. Lakhs unless stated otherwise.
A22: FY 2025-26 other current liabilities of Rs. 410 Lakhs are shown net of current maturities of borrowings of Rs. 205 Lakhs, which are included in term borrowings in the debt schedule.

Sheet Stub Period
A1: Vanraj Furniture Industries Private Limited
A2: Stub period derivation: 2 June 2026 to 31 March 2027 (valuation date 1 June 2026)
A3: Amounts in Rs. Lakhs
A5: Particulars | B5: FY 2026-27 (full year projected) | C5: 1 Apr 2026 to 1 Jun 2026 (provisional actual) | D5: Stub: 2 Jun 2026 to 31 Mar 2027
A6: Revenue from operations | B6: ='Projected P&L'!C6 -> 13452 | C6: 2050 | D6: =B6-C6 -> 11402
A7: Other income | B7: ='Projected P&L'!C7 -> 44.65 | C7: 9 | D7: =B7-C7 -> 35.65
A8: Material cost (net of change in inventories) | B8: ='Projected P&L'!C10 -> 7102.656 | C8: 1075 | D8: =B8-C8 -> 6027.656
A9: Employee benefits expense | B9: ='Projected P&L'!C11 -> 1654.596 | C9: 255 | D9: =B9-C9 -> 1399.596
A10: Other expenses | B10: ='Projected P&L'!C12 -> 2824.92 | C10: 445 | D10: =B10-C10 -> 2379.92
A11: EBITDA (excluding other income) | B11: ='Projected P&L'!C13 -> 1869.828 | C11: =C6-C8-C9-C10 -> 275 | D11: =D6-D8-D9-D10 -> 1594.828
A12: Depreciation and amortisation | B12: ='Projected P&L'!C14 -> 418.875 | C12: 65 | D12: =B12-C12 -> 353.875
A13: EBIT | B13: ='Projected P&L'!C15 -> 1450.953 | C13: =C11-C12 -> 210 | D13: =D11-D12 -> 1240.953
A14: Finance costs | B14: ='Projected P&L'!C16 -> 244.61321 | C14: 50 | D14: =B14-C14 -> 194.61321
A15: Profit before tax | B15: ='Projected P&L'!C17 -> 1250.9898 | C15: =C13-C14+C7 -> 169 | D15: =D13-D14+D7 -> 1081.9898
A16: Tax expense | B16: ='Projected P&L'!C18 -> 314.84911 | C16: 44 | D16: =B16-C16 -> 270.84911
A17: Profit after tax | B17: ='Projected P&L'!C19 -> 936.14068 | C17: =C15-C16 -> 125 | D17: =D15-D16 -> 811.14068
A19: Capital expenditure (PPE and intangibles) | B19: ='Fixed Assets'!C23 -> 662 | C19: 39 | D19: =B19-C19 -> 623
A20: Increase in net working capital | B20: ='Working Capital'!C17 -> 381.93525 | C20: =(1870+1720+380)-(1810+1650+370)-((1290+380-190+60)-(1260+410-205+115)) -> 180 | D20: =B20-C20 -> 201.93525
A21: Time fraction of the year (for mid-period discounting) | B21: 1 | C21: =62/365 -> 0.16986301 | D21: =B21-C21 -> 0.83013699
A23: The 2-month provisional column is taken from the provisional financial statements as at 1 June 2026 (separate file) and entered as inputs. Provisional 'change in net working capital' is computed from the provisional and audited balance sheets on the same basis as the working capital schedule (current maturities of Rs. 205 Lakhs at 31 March 2026 and Rs. 190 Lakhs at 1 June 2026 excluded from other current liabilities).
A24: The stub column is the balance of FY 2026-27 after the valuation date and is intended to be the first discounting period in a DCF model.
A26: Legend: blue figures are hardcoded inputs; black figures are formulas within the sheet; green figures are links to other sheets.
A27: All figures are illustrative and imaginary, prepared solely for testing a valuation model. Amounts in Rs. Lakhs unless stated otherwise.
