Workbook
Name TOT_Cash: Note_5_3_CashBank!$B$14
Name TOT_Cash_PY: Note_5_3_CashBank!$C$14
Name TOT_CashEquiv: Note_5_3_CashBank!$B$14
Name TOT_CashEquiv_PY: Note_5_3_CashBank!$C$14
Name TOT_Contingencies: Note_8_2_Contingencies!$B$6
Name TOT_Contingencies_PY: Note_8_2_Contingencies!$C$6
Name TOT_CWIP: Note_4_2_CWIP!$F$7
Name TOT_CWIP_PY: Note_4_2_CWIP!$C$7
Name TOT_Depreciation: Note_7_4_Depreciation!$B$9
Name TOT_Depreciation_PY: Note_7_4_Depreciation!$C$9
Name TOT_Employee: Note_7_2_Employee!$B$11
Name TOT_Employee_PY: Note_7_2_Employee!$C$11
Name TOT_Finance: Note_7_3_Finance!$B$10
Name TOT_Finance_PY: Note_7_3_Finance!$C$10
Name TOT_InterestIncome: Note_6_2_OtherIncome!$B$6
Name TOT_InterestIncome_PY: Note_6_2_OtherIncome!$C$6
Name TOT_Inventory: Note_5_1_Inventories!$B$10
Name TOT_Inventory_PY: Note_5_1_Inventories!$C$10
Name TOT_Investments: Note_4_3_Investments!$B$9
Name TOT_Investments_PY: Note_4_3_Investments!$C$9
Name TOT_LTBorrow: Note_2_1_LTBorrow!$B$7
Name TOT_LTBorrow_PY: Note_2_1_LTBorrow!$C$7
Name TOT_LTLA: Note_4_4_LTLA!$B$9
Name TOT_LTLA_PY: Note_4_4_LTLA!$C$9
Name TOT_LTProv: Note_2_2_LTProv!$B$8
Name TOT_LTProv_PY: Note_2_2_LTProv!$C$8
Name TOT_Material: Note_7_1_Material!$B$16
Name TOT_Material_PY: Note_7_1_Material!$C$16
Name TOT_OtherCA: Note_5_5_OtherCA!$B$8
Name TOT_OtherCA_PY: Note_5_5_OtherCA!$C$8
Name TOT_OtherCL: Note_3_3_OtherCL!$B$11
Name TOT_OtherCL_PY: Note_3_3_OtherCL!$C$11
Name TOT_OtherExp: Note_7_5_OtherExp!$B$17
Name TOT_OtherExp_PY: Note_7_5_OtherExp!$C$17
Name TOT_OtherIncome: Note_6_2_OtherIncome!$B$10
Name TOT_OtherIncome_PY: Note_6_2_OtherIncome!$C$10
Name TOT_Payables: Note_3_2_TradePayables!$G$8
Name TOT_Payables_PY: Note_3_2_TradePayables!$C$8
Name TOT_PPE: Note_4_1_PPE!$J$12
Name TOT_PPE_PY: Note_4_1_PPE!$K$12
Name TOT_Receivables: Note_5_2_Receivables!$H$9
Name TOT_Receivables_PY: Note_5_2_Receivables!$C$9
Name TOT_Reserves: Note_1_2_Reserves!$B$14
Name TOT_Reserves_PY: Note_1_2_Reserves!$C$14
Name TOT_Revenue: Note_6_1_Revenue!$B$11
Name TOT_Revenue_PY: Note_6_1_Revenue!$C$11
Name TOT_RPT: Note_8_1_RPT!$B$6
Name TOT_RPT_PY: Note_8_1_RPT!$C$6
Name TOT_ShareCapital: Note_1_1_ShareCapital!$B$10
Name TOT_ShareCapital_PY: Note_1_1_ShareCapital!$C$10
Name TOT_STBorrow: Note_3_1_STBorrow!$B$7
Name TOT_STBorrow_PY: Note_3_1_STBorrow!$C$7
Name TOT_STLA: Note_5_4_STLA!$B$11
Name TOT_STLA_PY: Note_5_4_STLA!$C$11
Name TOT_STProv: Note_3_4_STProv!$B$9
Name TOT_STProv_PY: Note_3_4_STProv!$C$9
Name TOT_Tax: Note_7_6_Tax!$B$9
Name TOT_Tax_PY: Note_7_6_Tax!$C$9

Sheet 01_Cover_Page
A1: APEX ENGINEERING INDUSTRIES LIMITED
A2: FINANCIAL STATEMENTS FOR THE YEAR ENDED MARCH 31, 2025
A3: PREPARED UNDER IGAAP SCHEDULE III DIVISION I OF COMPANIES ACT, 2013
A5: Client Name: | B5: Apex Engineering Industries Limited
A6: Entity Constitution: | B6: Public Limited Company
A7: Reporting Period: | B7: FY 2024-25
A8: Previous Year Period: | B8: FY 2023-24
A9: Currency / Denomination: | B9: INR (in Lakhs)
A10: Accounting Framework: | B10: IGAAP
A11: Prepared By: | B11: CA Senior Auditor
A12: Reviewed By: | B12: CA Managing Partner
A13: Generation Date: | B13: 2026-08-15 10:48:34
A15: PUBLISHED FINANCIAL REPORT CONTENTS & SITEMAP INDEX
A16: Sec # | B16: Published Section Title | C16: Interactive Navigation Link
A18: S01 | B18: 01. Cover Page & Financial Metadata | C18: =HYPERLINK("#'01_Cover_Page'!A1", "Open 01. Cover Page & Financial Metadata") -> Open 01. Cover Page & Financial Metadata
A19: S02 | B19: 02. Schedule III Balance Sheet | C19: =HYPERLINK("#'02_Balance_Sheet'!A1", "Open 02. Schedule III Balance Sheet") -> Open 02. Schedule III Balance Sheet
A20: S03 | B20: 03. Statement of Profit and Loss | C20: =HYPERLINK("#'03_Profit_and_Loss'!A1", "Open 03. Statement of Profit and Loss") -> Open 03. Statement of Profit and Loss
A21: S04 | B21: 04. AS 3 Cash Flow Statement (Indirect Method) | C21: =HYPERLINK("#'04_Cash_Flow_Statement'!A1", "Open 04. AS 3 Cash Flow Statement (Indirect Method)") -> Open 04. AS 3 Cash Flow Statement (Indirect Method)
A22: S05 | B22: 05. Significant Accounting Policies (AP-01 to AP-21) | C22: =HYPERLINK("#'05_Accounting_Policies'!A1", "Open 05. Significant Accounting Policies (AP-01 to AP-21)") -> Open 05. Significant Accounting Policies (AP-01 to AP-21)
A23: S06 | B23: 06. Notes Forming Part of Financial Statements (Consolidated) | C23: =HYPERLINK("#'06_Notes_to_Accounts'!A1", "Open 06. Notes Forming Part of Financial Statements (Consolidated)") -> Open 06. Notes Forming Part of Financial Statements (Consolidated)
A24: S07 | B24: 07. Schedule III Mandatory Financial Ratios | C24: =HYPERLINK("#'07_Financial_Ratios'!A1", "Open 07. Schedule III Mandatory Financial Ratios") -> Open 07. Schedule III Mandatory Financial Ratios

Sheet 02_Balance_Sheet
A1: APEX ENGINEERING INDUSTRIES LIMITED
A2: BALANCE SHEET AS AT MARCH 31, 2025
A3: (All amounts in INR Lakhs unless otherwise stated)
A5: Particulars | B5: Note No. | C5: As at March 31, 2025 | D5: As at March 31, 2024
A6: EQUITY AND LIABILITIES
A7: 1. Shareholders' Funds
A8: (a) Share Capital | B8: =HYPERLINK("#'Note_1_1_ShareCapital'!A1", "1.1") -> 1.1 | C8: =-TOT_ShareCapital -> -100 | D8: =-TOT_ShareCapital_PY -> -100
A9: (b) Reserves and Surplus | B9: =HYPERLINK("#'Note_1_2_Reserves'!A1", "1.2") -> 1.2 | C9: =-TOT_Reserves -> 2505 | D9: =-TOT_Reserves_PY -> 1015
A10: Total Shareholders' Funds | C10: =SUM(C8:C9) -> 2405 | D10: =SUM(D8:D9) -> 915
A11: 2. Non-Current Liabilities
A12: (a) Long-term Borrowings | B12: =HYPERLINK("#'Note_2_1_LTBorrow'!A1", "2.1") -> 2.1 | C12: =-TOT_LTBorrow -> -250 | D12: =-TOT_LTBorrow_PY -> -300
A13: (b) Long-term Provisions | B13: =HYPERLINK("#'Note_2_2_LTProv'!A1", "2.2") -> 2.2 | C13: =-TOT_LTProv -> 0 | D13: =-TOT_LTProv_PY -> 0
A14: Total Non-Current Liabilities | C14: =SUM(C12:C13) -> -250 | D14: =SUM(D12:D13) -> -300
A15: 3. Current Liabilities
A16: (a) Short-term Borrowings | B16: =HYPERLINK("#'Note_3_1_STBorrow'!A1", "3.1") -> 3.1 | C16: =-TOT_STBorrow -> -80 | D16: =-TOT_STBorrow_PY -> -60
A17: (b) Trade Payables | B17: =HYPERLINK("#'Note_3_2_TradePayables'!A1", "3.2") -> 3.2 | C17: =-TOT_Payables -> -185 | D17: =-TOT_Payables_PY -> -185
A18: (c) Other Current Liabilities | B18: =HYPERLINK("#'Note_3_3_OtherCL'!A1", "3.3") -> 3.3 | C18: =-TOT_OtherCL -> -25 | D18: =-TOT_OtherCL_PY -> -20
A19: (d) Short-term Provisions | B19: =HYPERLINK("#'Note_3_4_STProv'!A1", "3.4") -> 3.4 | C19: =-TOT_STProv -> 0 | D19: =-TOT_STProv_PY -> 0
A20: Total Current Liabilities | C20: =SUM(C16:C19) -> -290 | D20: =SUM(D16:D19) -> -265
A21: TOTAL EQUITY AND LIABILITIES | C21: =C10+C14+C20 -> 1865 | D21: =D10+D14+D20 -> 350
A23: ASSETS
A24: 1. Non-Current Assets
A25: (a) Property, Plant and Equipment | B25: =HYPERLINK("#'Note_4_1_PPE'!A1", "4.1") -> 4.1 | C25: =TOT_PPE -> 749.75 | D25: =TOT_PPE_PY -> 743.22
A26: (b) Capital Work-in-Progress | B26: =HYPERLINK("#'Note_4_2_CWIP'!A1", "4.2") -> 4.2 | C26: =TOT_CWIP -> 45 | D26: =TOT_CWIP_PY -> 0
A27: (c) Non-current Investments | B27: =HYPERLINK("#'Note_4_3_Investments'!A1", "4.3") -> 4.3 | C27: =TOT_Investments -> 0 | D27: =TOT_Investments_PY -> 0
A28: (d) Long-term Loans and Advances | B28: =HYPERLINK("#'Note_4_4_LTLA'!A1", "4.4") -> 4.4 | C28: =TOT_LTLA -> 0 | D28: =TOT_LTLA_PY -> 0
A29: Total Non-Current Assets | C29: =SUM(C25:C28) -> 794.75 | D29: =SUM(D25:D28) -> 743.22
A30: 2. Current Assets
A31: (a) Inventories | B31: =HYPERLINK("#'Note_5_1_Inventories'!A1", "5.1") -> 5.1 | C31: =TOT_Inventory -> 145 | D31: =TOT_Inventory_PY -> 120
A32: (b) Trade Receivables | B32: =HYPERLINK("#'Note_5_2_Receivables'!A1", "5.2") -> 5.2 | C32: =TOT_Receivables -> 175 | D32: =TOT_Receivables_PY -> 175
A33: (c) Cash and Bank Balances | B33: =HYPERLINK("#'Note_5_3_CashBank'!A1", "5.3") -> 5.3 | C33: =TOT_Cash -> 175 | D33: =TOT_Cash_PY -> 155
A34: (d) Short-term Loans and Advances | B34: =HYPERLINK("#'Note_5_4_STLA'!A1", "5.4") -> 5.4 | C34: =TOT_STLA -> 0 | D34: =TOT_STLA_PY -> 0
A35: (e) Other Current Assets | B35: =HYPERLINK("#'Note_5_5_OtherCA'!A1", "5.5") -> 5.5 | C35: =TOT_OtherCA -> 0 | D35: =TOT_OtherCA_PY -> 0
A36: Total Current Assets | C36: =SUM(C31:C35) -> 495 | D36: =SUM(D31:D35) -> 450
A37: TOTAL ASSETS | C37: =C29+C36 -> 1289.75 | D37: =D29+D36 -> 1193.22
A38: Balance Check (Total Assets - Total Equity & Liabilities) | C38: =C37-C21 -> -575.25 | D38: =D37-D21 -> 843.22

Sheet 03_Profit_and_Loss
A1: APEX ENGINEERING INDUSTRIES LIMITED
A2: STATEMENT OF PROFIT AND LOSS FOR THE YEAR ENDED MARCH 31, 2025
A3: (All amounts in INR Lakhs unless otherwise stated)
A5: Particulars | B5: Note No. | C5: Current Year | D5: Previous Year
A6: I. Revenue from Operations | B6: =HYPERLINK("#'Note_6_1_Revenue'!A1", "6.1") -> 6.1 | C6: =-TOT_Revenue -> -850 | D6: =-TOT_Revenue_PY -> -700
A7: II. Other Income | B7: =HYPERLINK("#'Note_6_2_OtherIncome'!A1", "6.2") -> 6.2 | C7: =-TOT_OtherIncome -> -15 | D7: =-TOT_OtherIncome_PY -> -10
A8: III. Total Income (I + II) | C8: =SUM(C6:C7) -> -865 | D8: =SUM(D6:D7) -> -710
A9: IV. Expenses:
A10: Cost of Materials Consumed | B10: =HYPERLINK("#'Note_7_1_Material'!A1", "7.1") -> 7.1 | C10: =TOT_Material -> 420 | D10: =TOT_Material_PY -> 350
A11: Employee Benefit Expenses | B11: =HYPERLINK("#'Note_7_2_Employee'!A1", "7.2") -> 7.2 | C11: =TOT_Employee -> 140 | D11: =TOT_Employee_PY -> 120
A12: Finance Costs | B12: =HYPERLINK("#'Note_7_3_Finance'!A1", "7.3") -> 7.3 | C12: =TOT_Finance -> 32 | D12: =TOT_Finance_PY -> 38
A13: Depreciation and Amortisation Expense | B13: =HYPERLINK("#'Note_7_4_Depreciation'!A1", "7.4") -> 7.4 | C13: =TOT_Depreciation -> 28 | D13: =TOT_Depreciation_PY -> 25
A14: Other Expenses | B14: =HYPERLINK("#'Note_7_5_OtherExp'!A1", "7.5") -> 7.5 | C14: =TOT_OtherExp -> 45 | D14: =TOT_OtherExp_PY -> 32
A15: Total Expenses (IV) | C15: =SUM(C10:C14) -> 665 | D15: =SUM(D10:D14) -> 565
A16: V. Profit Before Tax (III - IV) | C16: =C8-C15 -> -1530 | D16: =D8-D15 -> -1275
A17: VI. Tax Expense | B17: =HYPERLINK("#'Note_7_6_Tax'!A1", "7.6") -> 7.6 | C17: =-TOT_Tax -> -40 | D17: =-TOT_Tax_PY -> -30
A18: VII. Profit After Tax (V - VI) | C18: =C16-C17 -> -1490 | D18: =D16-D17 -> -1245
A19: Earnings Per Equity Share (Basic & Diluted in Rs.) | C19: =C18/10 -> -149 | D19: =D18/10 -> -124.5

Sheet 04_Cash_Flow_Statement
A1: APEX ENGINEERING INDUSTRIES LIMITED
A2: AS 3 CASH FLOW STATEMENT (INDIRECT METHOD) FOR THE YEAR ENDED MARCH 31, 2025
A3: (All amounts in INR Lakhs unless otherwise stated)
A5: Particulars | B5: Current Year | C5: Previous Year
A6: A. CASH FLOW FROM OPERATING ACTIVITIES
A7: Profit Before Tax | B7: ='03_Profit_and_Loss'!C16 -> -1530 | C7: ='03_Profit_and_Loss'!D16 -> -1275
A8: Adjustments for Non-Cash & Non-Operating Items:
A9: Add: Depreciation & Amortisation Expense | B9: =TOT_Depreciation -> 28 | C9: =TOT_Depreciation_PY -> 25
A10: Add: Finance Costs | B10: =TOT_Finance -> 32 | C10: =TOT_Finance_PY -> 38
A11: Less: Interest Income / Non-Operating Gain | B11: =-TOT_InterestIncome -> -10.5 | C11: =-TOT_InterestIncome_PY -> -7
A12: Operating Profit before Working Capital Changes | B12: =SUM(B7:B11) -> -1480.5 | C12: =SUM(C7:C11) -> -1219
A13: Adjustments for Working Capital Movements:
A14: (Increase) / Decrease in Inventories | B14: =-(TOT_Inventory - TOT_Inventory_PY) -> -25 | C14: 0
A15: (Increase) / Decrease in Trade Receivables | B15: =-(TOT_Receivables - TOT_Receivables_PY) -> 0 | C15: 0
A16: Increase / (Decrease) in Trade Payables | B16: =(-TOT_Payables) - (-TOT_Payables_PY) -> 0 | C16: 0
A17: Increase / (Decrease) in Other Current Liabilities | B17: =(-TOT_OtherCL) - (-TOT_OtherCL_PY) -> -5 | C17: 0
A18: Increase / (Decrease) in Short-term Provisions | B18: =(-TOT_STProv) - (-TOT_STProv_PY) -> 0 | C18: 0
A19: Cash Generated from Operations | B19: =B12+SUM(B14:B18) -> -1510.5 | C19: =C12+SUM(C14:C18) -> -1219
A20: Less: Income Taxes Paid | B20: ='29_Cash_Flow_Adjustments'!C2 -> -40 | C20: ='29_Cash_Flow_Adjustments'!D2 -> -30
A21: NET CASH FROM OPERATING ACTIVITIES (A) | B21: =B19+B20 -> -1550.5 | C21: =C19+C20 -> -1249
A23: B. CASH FLOW FROM INVESTING ACTIVITIES
A24: Purchase of Property, Plant & Equipment & CWIP | B24: ='29_Cash_Flow_Adjustments'!C6 -> -79.53 | C24: ='29_Cash_Flow_Adjustments'!D6 -> 0
A25: Proceeds from Sale of Fixed Assets / Investments | B25: 0 | C25: 0
A26: Interest / Dividend Received | B26: ='29_Cash_Flow_Adjustments'!C5 -> 10.5 | C26: ='29_Cash_Flow_Adjustments'!D5 -> 7
A27: NET CASH FROM INVESTING ACTIVITIES (B) | B27: =SUM(B24:B26) -> -69.03 | C27: =SUM(C24:C26) -> 7
A29: C. CASH FLOW FROM FINANCING ACTIVITIES
A30: Net Proceeds / (Repayment) of Borrowings | B30: =((-TOT_LTBorrow)+(-TOT_STBorrow)) - ((-TOT_LTBorrow_PY)+(-TOT_STBorrow_PY)) -> 30 | C30: 0
A31: Proceeds from Issuance of Share Capital | B31: =((-TOT_ShareCapital)-(-TOT_ShareCapital_PY)) -> 0 | C31: 0
A32: Finance Cost Paid | B32: ='29_Cash_Flow_Adjustments'!C4 -> -32 | C32: ='29_Cash_Flow_Adjustments'!D4 -> -38
A33: Dividends Paid | B33: ='29_Cash_Flow_Adjustments'!C3 -> 0 | C33: ='29_Cash_Flow_Adjustments'!D3 -> 0
A34: NET CASH FROM FINANCING ACTIVITIES (C) | B34: =SUM(B30:B33) -> -2 | C34: =SUM(C30:C33) -> -38
A36: NET INCREASE / (DECREASE) IN CASH & CASH EQUIVALENTS (A + B + C) | B36: =B21+B27+B34 -> -1621.53 | C36: =C21+C27+C34 -> -1280
A37: Cash and Cash Equivalents at Beginning of the Year | B37: =TOT_CashEquiv_PY -> 155 | C37: =TOT_CashEquiv_PY -> 155
A38: Computed Closing Cash & Cash Equivalents | B38: =B36+B37 -> -1466.53 | C38: =C36+C37 -> -1125
A39: Closing Cash & Cash Equivalents per Balance Sheet | B39: =TOT_CashEquiv -> 175 | C39: =TOT_CashEquiv -> 175
A40: Reconciliation Difference (Computed Closing - BS Closing) | B40: =B38-B39 -> -1641.53 | C40: =C38-C39 -> -1300

Sheet 05_Accounting_Policies
A1: APEX ENGINEERING INDUSTRIES LIMITED
A2: SIGNIFICANT ACCOUNTING POLICIES (IGAAP)
A4: POLICY # | B4: TITLE | C4: SIGNIFICANT ACCOUNTING POLICY DISCLOSURE | D4: APPLICABILITY
A5: AP-01 | B5: Basis of preparation | C5: The financial statements have been prepared in accordance with Generally Accepted Accounting Principles in India (Indian GAAP) under the historical cost convention on an accrual basis. The financial statements comply in all material respects with the Accounting Standards specified under Section 133 of the Companies Act, 2013, read with Rule 7 of the Companies (Accounts) Rules, 2014, and the relevant provisions of the Companies Act, 2013, including Schedule III Division I. | D5: Applicable
A6: AP-02 | B6: Use of estimates | C6: The preparation of financial statements in conformity with Indian GAAP requires management to make estimates and assumptions that affect the reported amounts of assets and liabilities, disclosures of contingent liabilities as at the date of financial statements, and the reported amounts of revenues and expenses during the reporting period. Actual results could differ from those estimates. Any revision to accounting estimates is recognized prospectively in current and future periods. | D6: Applicable
A7: AP-03 | B7: Property, plant and equipment | C7: Property, plant and equipment are stated at cost of acquisition or construction less accumulated depreciation and accumulated impairment losses, if any. The cost comprises purchase price, borrowing costs if capitalization criteria are met, and directly attributable costs of bringing the asset to its working condition for intended use. Subsequent expenditure relating to property, plant and equipment is capitalized only when it increases the future economic benefits from the asset. | D7: Applicable
A8: AP-04 | B8: Capital work-in-progress | C8: Capital work-in-progress (CWIP) includes cost of property, plant and equipment that are not ready for their intended use as at the reporting date. CWIP is carried at cost, comprising direct costs, attributable borrowing costs, and directly allocated expenses incurred during the construction/erection period. Capital advances given towards acquisition of fixed assets are disclosed under long-term loans and advances. | D8: Applicable
A9: AP-05 | B9: Depreciation and amortisation | C9: Depreciation on property, plant and equipment is provided on the Straight Line Method (SLM) based on the useful lives of assets prescribed under Schedule II of the Companies Act, 2013. Intangible assets are amortized over their estimated useful economic life on a straight-line basis, not exceeding five years. Assets costing individually up to Rs 5,000 are fully depreciated in the year of acquisition. | D9: Applicable
A10: AP-06 | B10: Impairment of assets | C10: The carrying amounts of assets are reviewed at each Balance Sheet date to determine whether there is any indication of impairment. If any such indication exists, the asset's recoverable amount is estimated. An impairment loss is recognized whenever the carrying amount of an asset exceeds its recoverable amount. Recoverable amount is the higher of net selling price and value in use. | D10: Applicable
A11: AP-07 | B11: Inventories | C11: Inventories are valued at the lower of cost and net realizable value. Cost of raw materials, components, stores and spares is determined on First-In-First-Out (FIFO) basis. Cost of finished goods and work-in-progress includes direct material, direct labor, and an appropriate proportion of fixed and variable overheads incurred in bringing inventories to their present location and condition. | D11: Applicable
A12: AP-08 | B12: Revenue recognition | C12: Revenue is recognized to the extent that it is probable that the economic benefits will flow to the Company and revenue can be reliably measured. Revenue from domestic and export sale of goods is recognized upon transfer of significant risks and rewards of ownership to the buyer, which generally coincides with dispatch or delivery of goods. Sales are net of trade discounts, returns, GST, and applicable indirect taxes. | D12: Applicable
A13: AP-09 | B13: Other income | C13: Interest income is recognized on a time proportion basis taking into account the amount outstanding and the applicable interest rate. Dividend income is recognized when the right to receive payment is established by the balance sheet date. Profit or loss on sale of investments is recognized on trade date basis. | D13: Applicable
A14: AP-10 | B14: Employee benefits | C14: Short-term employee benefits are recognized as an expense in the Statement of Profit and Loss for the year in which services are rendered. Post-employment benefits such as Provident Fund and ESIC are defined contribution plans and charged to Profit and Loss as incurred. Gratuity and Leave Encashment liabilities are defined benefit obligations determined based on actuarial valuation as at the year end. | D14: Applicable
A15: AP-11 | B15: Borrowing costs | C15: Borrowing costs directly attributable to the acquisition, construction, or production of qualifying assets are capitalized as part of the cost of such asset until the asset is substantially ready for its intended use. A qualifying asset is one that necessarily takes a substantial period of time to get ready for its intended use. Other borrowing costs are recognized as an expense in the period in which they are incurred. | D15: Applicable
... A25: AP-21 | B25: Previous year comparatives and regrouping | C25: Previous year figures have been regrouped, reclassified, and rearranged wherever necessary to conform with the current year's presentation and Schedule III Division I classification requirements. | D25: Applicable

Sheet 06_Notes_to_Accounts
A1: Apex Engineering Industries Limited | B1: NOTES FORMING PART OF FINANCIAL STATEMENTS | C1: =HYPERLINK("#'01_Cover_Page'!A1", "[<- Back to Index Sitemap]") -> [<- Back to Index Sitemap]
A2: Figures in INR (in Lakhs)
A4: NOTE 1.1: SHARE CAPITAL | B4: =HYPERLINK("#'Note_1_1_ShareCapital'!A1", "[Open Note Tab]") -> [Open Note Tab]
A5: Particulars | B5: As at FY 2024-25 | C5: As at FY 2023-24
A6: Authorised Share Capital:
A7: 10,00,000 Equity Shares of Rs. 10/- each | B7: 100.00 | C7: 100.00
A8: Issued, Subscribed & Paid-up Capital:
A9: Equity Shares of Rs. 10/- each fully paid | B9: 100.00 | C9: 100.00
A10: TOTAL SHARE CAPITAL | B10: 100.00 | C10: 100.00
A12: NOTE 1.2: RESERVES AND SURPLUS | B12: =HYPERLINK("#'Note_1_2_Reserves'!A1", "[Open Note Tab]") -> [Open Note Tab]
A13: Particulars | B13: As at FY 2024-25 | C13: As at FY 2023-24
A14: (a) General Reserve:
A15: Opening Balance | B15: 230.00 | C15: 230.00
A16: Add: Transfer during the year | B16: 0.00 | C16: 0.00
A17: Closing General Reserve (A) | B17: 230.00 | C17: 230.00
A18: (b) Surplus in Statement of Profit & Loss:
A19: Opening Balance | B19: 175.00 | C19: 0.00
A20: Add: Profit After Tax for the year | B20: 240.00 | C20: 175.00
A21: Closing Surplus in P&L (B) | B21: 240.00 | C21: 175.00
A22: TOTAL RESERVES AND SURPLUS (A + B) | B22: 570.00 | C22: 405.00
A24: NOTE 2.1: LONG-TERM BORROWINGS | B24: =HYPERLINK("#'Note_2_1_LTBorrow'!A1", "[Open Note Tab]") -> [Open Note Tab]
A25: Particulars | B25: As at FY 2024-25 | C25: As at FY 2023-24
A26: HDFC Bank Limited - Rupee Term Loan (Secured) | B26: 250.00 | C26: 300.00
A27: TOTAL LONG-TERM BORROWINGS | B27: 250.00 | C27: 300.00
A29: NOTE 2.2: LONG-TERM PROVISIONS | B29: =HYPERLINK("#'Note_2_2_LTProv'!A1", "[Open Note Tab]") -> [Open Note Tab]
A30: Particulars | B30: As at FY 2024-25 | C30: As at FY 2023-24
A31: Provision for Gratuity (AS 15 - Defined Benefit) | B31: 0.00 | C31: 0.00
A32: Provision for Leave Encashment (Long-term portion) | B32: 0.00 | C32: 0.00
A33: TOTAL LONG-TERM PROVISIONS | B33: 0.00 | C33: 0.00
A35: NOTE 3.1: SHORT-TERM BORROWINGS | B35: =HYPERLINK("#'Note_3_1_STBorrow'!A1", "[Open Note Tab]") -> [Open Note Tab]
A36: Particulars | B36: As at FY 2024-25 | C36: As at FY 2023-24
A37: ICICI Bank Limited - Working Capital Cash Credit Limit | B37: 80.00 | C37: 60.00
A38: TOTAL SHORT-TERM BORROWINGS | B38: 80.00 | C38: 60.00
A40: NOTE 3.2: TRADE PAYABLES | B40: =HYPERLINK("#'Note_3_2_TradePayables'!A1", "[Open Note Tab]") -> [Open Note Tab]
A41: Vendor Name | B41: MSME | C41: < 1 Year | D41: 1-2 Years | E41: 2-3 Years | F41: > 3 Years | G41: Total Outstanding
A42: Shree Metals & Alloys Pvt Ltd (MSME) | B42: Yes | C42: 60.00 | D42: 5.00 | E42: 0.00 | F42: 0.00 | G42: 65.00
A43: Global Industrial Suppliers Inc | B43: No | C43: 110.00 | D43: 10.00 | E43: 0.00 | F43: 0.00 | G43: 120.00
A44: TOTAL TRADE PAYABLES | C44: 185.00 | G44: 185.00
A46: NOTE 3.3: OTHER CURRENT LIABILITIES | B46: =HYPERLINK("#'Note_3_3_OtherCL'!A1", "[Open Note Tab]") -> [Open Note Tab]
A47: Particulars | B47: As at FY 2024-25 | C47: As at FY 2023-24
...

Sheet Note_1_1_ShareCapital
A1: APEX ENGINEERING INDUSTRIES LIMITED
A2: NOTE 1.1: SHARE CAPITAL | B2: =HYPERLINK("#'02_Balance_Sheet'!A1", "[<- Back to Balance Sheet]") -> [<- Back to Balance Sheet]
A3: (All amounts in INR Lakhs unless otherwise stated)
A5: Particulars | B5: As at FY 2024-25 | C5: As at FY 2023-24
A6: Authorised Share Capital:
A7: 10,00,000 Equity Shares of Rs. 10/- each | B7: 100 | C7: 100
A8: Issued, Subscribed & Paid-up Capital:
A9: Equity Shares of Rs. 10/- each fully paid | B9: 100 | C9: 100
A10: TOTAL SHARE CAPITAL | B10: 100 | C10: 100
A11: TOTAL NOTE 1.1 (SHARE CAPITAL) | B11: =B10 -> 100 | C11: =C10 -> 100
A12: Per Trial Balance (Control Total) | B12: =-SUMIFS('91_Mapping'!H:H, '91_Mapping'!F:F, "1.1") -> 100 | C12: =-SUMIFS('91_Mapping'!I:I, '91_Mapping'!F:F, "1.1") -> 100
A13: Difference (Total - Per TB Control) | B13: =B11-B12 -> 0 | C13: =C11-C12 -> 0
A15: 1. Rights, Preferences & Restrictions: The Company has only one class of equity shares of par value Rs 10/- each. Each equity shareholder is entitled to one vote per share. In the event of liquidation, equity shareholders receive remaining assets after all preferential amounts are distributed. 2. Shareholders holding more than 5% shares: Promoters & Key Management Personnel - 100% holding as at the end of the reporting period.

Sheet Note_1_2_Reserves
A1: APEX ENGINEERING INDUSTRIES LIMITED
A2: NOTE 1.2: RESERVES AND SURPLUS | B2: =HYPERLINK("#'02_Balance_Sheet'!A1", "[<- Back to Balance Sheet]") -> [<- Back to Balance Sheet]
A3: (All amounts in INR Lakhs unless otherwise stated)
A5: Particulars | B5: As at March 31, 2025 | C5: As at March 31, 2024
A6: (a) General Reserve:
A7: Opening Balance | B7: =ABS(SUMIFS('91_Mapping'!I:I, '91_Mapping'!F:F, "1.2")) -> 230 | C7: =ABS(SUMIFS('91_Mapping'!I:I, '91_Mapping'!F:F, "1.2")) -> 230
A8: Add: Transfer during the year | B8: 0 | C8: 0
A9: Closing General Reserve (A) | B9: =SUM(B7:B8) -> 230 | C9: =SUM(C7:C8) -> 230
A10: (b) Surplus in Statement of Profit & Loss:
A11: Opening Balance | B11: ='03_Profit_and_Loss'!D18 -> -1245 | C11: 0
A12: Add: Profit After Tax for the year | B12: ='03_Profit_and_Loss'!C18 -> -1490 | C12: ='03_Profit_and_Loss'!D18 -> -1245
A13: Closing Surplus in P&L (B) | B13: =SUM(B11:B12) -> -2735 | C13: =SUM(C11:C12) -> -1245
A14: TOTAL RESERVES AND SURPLUS (A + B) | B14: =B9+B13 -> -2505 | C14: =C9+C13 -> -1015
A15: TOTAL NOTE 1.2 (RESERVES AND SURPLUS) | B15: =B14 -> -2505 | C15: =C14 -> -1015
A16: Per Trial Balance (Control Total) | B16: =-SUMIFS('91_Mapping'!H:H, '91_Mapping'!F:F, "1.2") + '03_Profit_and_Loss'!C18 -> -1160 | C16: =-SUMIFS('91_Mapping'!I:I, '91_Mapping'!F:F, "1.2") + '03_Profit_and_Loss'!D18 -> -1015
A17: Difference (Total - Per TB Control) | B17: =B15-B16 -> -1345 | C17: =C15-C16 -> 0
A19: Reserves & Surplus includes General Reserve carried forward from prior years and current-year Surplus in the Statement of Profit and Loss.

Sheet Note_2_1_LTBorrow
A1: APEX ENGINEERING INDUSTRIES LIMITED
A2: NOTE 2.1: LONG-TERM BORROWINGS | B2: =HYPERLINK("#'02_Balance_Sheet'!A1", "[<- Back to Balance Sheet]") -> [<- Back to Balance Sheet]
A3: (All amounts in INR Lakhs unless otherwise stated)
A5: Particulars | B5: As at FY 2024-25 | C5: As at FY 2023-24
A6: HDFC Bank Limited - Rupee Term Loan (Secured) | B6: 250 | C6: 300
A7: TOTAL LONG-TERM BORROWINGS | B7: 250 | C7: 300
A8: TOTAL NOTE 2.1 (LONG-TERM BORROWINGS) | B8: =B7 -> 250 | C8: =C7 -> 300
A9: Per Trial Balance (Control Total) | B9: =-SUMIFS('91_Mapping'!H:H, '91_Mapping'!F:F, "2.1") -> 250 | C9: =-SUMIFS('91_Mapping'!I:I, '91_Mapping'!F:F, "2.1") -> 300
A10: Difference (Total - Per TB Control) | B10: =B8-B9 -> 0 | C10: =C8-C9 -> 0
A12: Security Details: Term loans from banks are secured by primary charge on Fixed Assets (Land, Building & Plant and Machinery). Repayment: Structured monthly instalments over 60 months at 8.50% p.a. (floating). Defaults: The Company has not defaulted in repayment of principal or interest during the year.

Sheet Note_2_2_LTProv
A1: APEX ENGINEERING INDUSTRIES LIMITED
A2: NOTE 2.2: LONG-TERM PROVISIONS | B2: =HYPERLINK("#'02_Balance_Sheet'!A1", "[<- Back to Balance Sheet]") -> [<- Back to Balance Sheet]
A3: (All amounts in INR Lakhs unless otherwise stated)
A5: Particulars | B5: As at FY 2024-25 | C5: As at FY 2023-24
A6: Provision for Gratuity (AS 15 - Defined Benefit) | B6: 0 | C6: 0
A7: Provision for Leave Encashment (Long-term portion) | B7: 0 | C7: 0
A8: TOTAL LONG-TERM PROVISIONS | B8: 0 | C8: 0
A9: TOTAL NOTE 2.2 (LONG-TERM PROVISIONS) | B9: =B8 -> 0 | C9: =C8 -> 0
A10: Per Trial Balance (Control Total) | B10: =-SUMIFS('91_Mapping'!H:H, '91_Mapping'!F:F, "2.2") -> 0 | C10: =-SUMIFS('91_Mapping'!I:I, '91_Mapping'!F:F, "2.2") -> 0
A11: Difference (Total - Per TB Control) | B11: =B9-B10 -> 0 | C11: =C9-C10 -> 0
A13: Provision for Gratuity is made based on actuarial valuation as per AS 15 (Revised 2005). Leave encashment long-term portion represents unavailed leaves expected to be encashed after 12 months.

Sheet Note_3_1_STBorrow
A1: APEX ENGINEERING INDUSTRIES LIMITED
A2: NOTE 3.1: SHORT-TERM BORROWINGS | B2: =HYPERLINK("#'02_Balance_Sheet'!A1", "[<- Back to Balance Sheet]") -> [<- Back to Balance Sheet]
A3: (All amounts in INR Lakhs unless otherwise stated)
A5: Particulars | B5: As at FY 2024-25 | C5: As at FY 2023-24
A6: ICICI Bank Limited - Working Capital Cash Credit Limit | B6: 80 | C6: 60
A7: TOTAL SHORT-TERM BORROWINGS | B7: 80 | C7: 60
A8: TOTAL NOTE 3.1 (SHORT-TERM BORROWINGS) | B8: =B7 -> 80 | C8: =C7 -> 60
A9: Per Trial Balance (Control Total) | B9: =-SUMIFS('91_Mapping'!H:H, '91_Mapping'!F:F, "3.1") -> 80 | C9: =-SUMIFS('91_Mapping'!I:I, '91_Mapping'!F:F, "3.1") -> 60
A10: Difference (Total - Per TB Control) | B10: =B8-B9 -> 0 | C10: =C8-C9 -> 0
A12: Working capital cash credit facilities from banks are secured by hypothecation of current assets (inventories and trade receivables) at 9.25% p.a. (floating). Facility is repayable on demand.

Sheet Note_3_2_TradePayables
A1: APEX ENGINEERING INDUSTRIES LIMITED
A2: NOTE 3.2: TRADE PAYABLES | B2: =HYPERLINK("#'02_Balance_Sheet'!A1", "[<- Back to Balance Sheet]") -> [<- Back to Balance Sheet]
A3: (All amounts in INR Lakhs unless otherwise stated)
A5: Vendor Name | B5: MSME | C5: < 1 Year | D5: 1-2 Years | E5: 2-3 Years | F5: > 3 Years | G5: Total Outstanding
A6: Shree Metals & Alloys Pvt Ltd (MSME) | B6: Yes | C6: 60 | D6: 5 | E6: 0 | F6: 0 | G6: 65
A7: Global Industrial Suppliers Inc | B7: No | C7: 110 | D7: 10 | E7: 0 | F7: 0 | G7: 120
A8: TOTAL TRADE PAYABLES | C8: 185 | G8: 185
A9: TOTAL NOTE 3.2 (TRADE PAYABLES) | B9: =G8 -> 185 | C9: =C8 -> 185
A10: Per Trial Balance (Control Total) | B10: =-SUMIFS('91_Mapping'!H:H, '91_Mapping'!F:F, "3.2") -> 185 | C10: =-SUMIFS('91_Mapping'!I:I, '91_Mapping'!F:F, "3.2") -> 145
A11: Difference (Total - Per TB Control) | B11: =B9-B10 -> 0 | C11: =C9-C10 -> 40
A13: Trade Payables Ageing - as per Companies (Accounts) Amendment Rules 2021. MSME Disclosure: Outstanding dues payable to Micro and Small Enterprises (as certified by management) are disclosed separately. As at FY 2024-25: Dues to MSME vendors - Rs Nil (Previous Year: Rs Nil).

Sheet Note_3_3_OtherCL
A1: APEX ENGINEERING INDUSTRIES LIMITED
A2: NOTE 3.3: OTHER CURRENT LIABILITIES | B2: =HYPERLINK("#'02_Balance_Sheet'!A1", "[<- Back to Balance Sheet]") -> [<- Back to Balance Sheet]
A3: (All amounts in INR Lakhs unless otherwise stated)
A5: Particulars | B5: As at FY 2024-25 | C5: As at FY 2023-24
A6: Current Maturities of Long-term Borrowings | B6: 11.25 | C6: 9
A7: Interest Accrued but not Due on Borrowings | B7: 3.75 | C7: 3
A8: Advance Received from Customers | B8: 5 | C8: 4
A9: Statutory Liabilities (GST, TDS, PF Payable) | B9: 3.75 | C9: 3
A10: Other Payables - Security Deposits / Accruals | B10: 1.25 | C10: 1
A11: TOTAL OTHER CURRENT LIABILITIES | B11: 25 | C11: 20
A12: TOTAL NOTE 3.3 (OTHER CURRENT LIABILITIES) | B12: =B11 -> 25 | C12: =C11 -> 20
A13: Per Trial Balance (Control Total) | B13: =-SUMIFS('91_Mapping'!H:H, '91_Mapping'!F:F, "3.3") -> 25 | C13: =-SUMIFS('91_Mapping'!I:I, '91_Mapping'!F:F, "3.3") -> 20
A14: Difference (Total - Per TB Control) | B14: =B12-B13 -> 0 | C14: =C12-C13 -> 0
A16: Other Current Liabilities include current maturities of long-term debt, statutory liabilities payable within 12 months, and advance from customers.

Sheet Note_3_4_STProv
A1: APEX ENGINEERING INDUSTRIES LIMITED
A2: NOTE 3.4: SHORT-TERM PROVISIONS | B2: =HYPERLINK("#'02_Balance_Sheet'!A1", "[<- Back to Balance Sheet]") -> [<- Back to Balance Sheet]
A3: (All amounts in INR Lakhs unless otherwise stated)
A5: Particulars | B5: As at FY 2024-25 | C5: As at FY 2023-24
A6: Provision for Income Tax (Net of Advance Tax) | B6: 0 | C6: 0
A7: Provision for Employee Benefits (Leave & Gratuity - Current) | B7: 0 | C7: 0
A8: Provision for Bonus / Ex-gratia | B8: 0 | C8: 0
A9: TOTAL SHORT-TERM PROVISIONS | B9: 0 | C9: 0
A10: TOTAL NOTE 3.4 (SHORT-TERM PROVISIONS) | B10: =B9 -> 0 | C10: =C9 -> 0
A11: Per Trial Balance (Control Total) | B11: =-SUMIFS('91_Mapping'!H:H, '91_Mapping'!F:F, "3.4") -> 0 | C11: =-SUMIFS('91_Mapping'!I:I, '91_Mapping'!F:F, "3.4") -> 0
A12: Difference (Total - Per TB Control) | B12: =B10-B11 -> 0 | C12: =C10-C11 -> 0
A14: Short-term provisions represent amounts expected to be settled within 12 months of the Balance Sheet date.

Sheet Note_4_1_PPE
A1: APEX ENGINEERING INDUSTRIES LIMITED
A2: NOTE 4.1: PROPERTY, PLANT AND EQUIPMENT | B2: =HYPERLINK("#'02_Balance_Sheet'!A1", "[<- Back to Balance Sheet]") -> [<- Back to Balance Sheet]
A3: (All amounts in INR Lakhs unless otherwise stated)
A5: Asset Category | B5: Opening Gross Block | C5: Additions | D5: Disposals | E5: Closing Gross Block | F5: Accum. Dep (Open) | G5: Dep for Year | H5: Dep on Disposal | I5: Accum. Dep (Close) | J5: Net Block FY 2024-25 | K5: Net Block FY 2023-24
A6: Freehold Land | B6: 160.26 | C6: 13.94 | D6: 0 | E6: 174.2 | F6: 0 | G6: 0 | H6: 0 | I6: 0 | J6: 174.2 | K6: 160.26
A7: Buildings | B7: 200.33 | C7: 17.42 | D7: 0 | E7: 217.75 | F7: 10.02 | G7: 10.89 | H7: 0 | I7: 20.91 | J7: 196.84 | K7: 190.31
A8: Plant & Machinery | B8: 280.46 | C8: 24.39 | D8: 0 | E8: 304.85 | F8: 28.05 | G8: 30.49 | H8: 0 | I8: 58.54 | J8: 246.31 | K8: 252.41
A9: Furniture & Fixtures | B9: 80.13 | C9: 6.97 | D9: 0 | E9: 87.1 | F9: 8.01 | G9: 8.71 | H9: 0 | I9: 16.72 | J9: 70.38 | K9: 72.12
A10: Office Equipment | B10: 40.07 | C10: 3.48 | D10: 0 | E10: 43.55 | F10: 6.01 | G10: 6.53 | H10: 0 | I10: 12.54 | J10: 31.01 | K10: 34.06
A11: Vehicles | B11: 40.07 | C11: 3.48 | D11: 0 | E11: 43.55 | F11: 6.01 | G11: 6.53 | H11: 0 | I11: 12.54 | J11: 31.01 | K11: 34.06
A12: TOTAL PROPERTY, PLANT & EQUIPMENT | B12: 801.32 | C12: 69.68 | D12: 0 | E12: 871 | F12: 58.1 | G12: 63.15 | H12: 0 | I12: 121.25 | J12: 749.75 | K12: 743.22
A13: TOTAL NOTE 4.1 (PROPERTY, PLANT AND EQUIPMENT) | B13: =J12 -> 749.75 | C13: =K12 -> 743.22
A14: Per Trial Balance (Control Total) | B14: =SUMIFS('91_Mapping'!H:H, '91_Mapping'!F:F, "4.1") -> 670 | C14: =SUMIFS('91_Mapping'!I:I, '91_Mapping'!F:F, "4.1") -> 630
A15: Difference (Total - Per TB Control) | B15: =B13-B14 -> 79.75 | C15: =C13-C14 -> 113.22
A17: 1. Depreciation Method: Depreciation on PPE is provided on Straight Line Method (SLM) based on useful lives under Schedule II of the Companies Act, 2013. 2. Impairment: No impairment loss recognised during the year as per AS 28. 3. Additions include capital expenditure incurred during the year and transferred from CWIP upon commissioning. 4. Title to Land is held by the Company without encumbrances other than those disclosed under borrowings.

Sheet Note_4_2_CWIP
A1: APEX ENGINEERING INDUSTRIES LIMITED
A2: NOTE 4.2: CAPITAL WORK-IN-PROGRESS | B2: =HYPERLINK("#'02_Balance_Sheet'!A1", "[<- Back to Balance Sheet]") -> [<- Back to Balance Sheet]
A3: (All amounts in INR Lakhs unless otherwise stated)
A5: Project Name | B5: < 1 Year | C5: 1-2 Years | D5: 2-3 Years | E5: > 3 Years | F5: Total CWIP
A6: Rooftop Captive Solar Power Plant (500 KW) | B6: 30 | C6: 15 | D6: 0 | E6: 0 | F6: 45
A7: TOTAL CAPITAL WORK-IN-PROGRESS | B7: 45 | F7: 45
A8: TOTAL NOTE 4.2 (CAPITAL WORK-IN-PROGRESS) | B8: =F7 -> 45 | C8: =C7 -> 0
A9: Per Trial Balance (Control Total) | B9: =SUMIFS('91_Mapping'!H:H, '91_Mapping'!F:F, "4.2") -> 45 | C9: =SUMIFS('91_Mapping'!I:I, '91_Mapping'!F:F, "4.2") -> 15
A10: Difference (Total - Per TB Control) | B10: =B8-B9 -> 0 | C10: =C8-C9 -> -15
A12: CWIP Ageing Schedule as per Companies (Accounts) Amendment Rules, 2021. All CWIP projects are within normal expected completion timelines. No project is stalled or disputed. CWIP is expected to be capitalised to PPE upon commissioning in the next financial year.

Sheet Note_4_3_Investments
A1: APEX ENGINEERING INDUSTRIES LIMITED
A2: NOTE 4.3: NON-CURRENT INVESTMENTS | B2: =HYPERLINK("#'02_Balance_Sheet'!A1", "[<- Back to Balance Sheet]") -> [<- Back to Balance Sheet]
A3: (All amounts in INR Lakhs unless otherwise stated)
A5: Particulars | B5: No. of Units | C5: As at FY 2024-25 | D5: As at FY 2023-24
A6: Unquoted Equity Instruments - at cost:
A7: Investment in Associate Companies | B7: - | C7: 0 | D7: 0
A8: Investment in Other Companies | B8: - | C8: 0 | D8: 0
A9: TOTAL NON-CURRENT INVESTMENTS | C9: 0 | D9: 0
A10: TOTAL NOTE 4.3 (NON-CURRENT INVESTMENTS) | B10: =B9 -> 0 | C10: =C9 -> 0
A11: Per Trial Balance (Control Total) | B11: =SUMIFS('91_Mapping'!H:H, '91_Mapping'!F:F, "4.3") -> 0 | C11: =SUMIFS('91_Mapping'!I:I, '91_Mapping'!F:F, "4.3") -> 0
A12: Difference (Total - Per TB Control) | B12: =B10-B11 -> 0 | C12: =C10-C11 -> 0
A14: Non-current investments are stated at cost less provision for diminution in value, if any, as per AS 13. Aggregate amount of unquoted investments: Rs 0.00 Lakhs (PY: Rs 0.00 Lakhs). Aggregate provision for diminution in value of investments: Rs Nil.

Sheet Note_4_4_LTLA
A1: APEX ENGINEERING INDUSTRIES LIMITED
A2: NOTE 4.4: LONG-TERM LOANS AND ADVANCES | B2: =HYPERLINK("#'02_Balance_Sheet'!A1", "[<- Back to Balance Sheet]") -> [<- Back to Balance Sheet]
A3: (All amounts in INR Lakhs unless otherwise stated)
A5: Particulars | B5: As at FY 2024-25 | C5: As at FY 2023-24
A6: Security Deposits - Considered Good (Unsecured) | B6: 0 | C6: 0
A7: Capital Advances - Considered Good | B7: 0 | C7: 0
A8: Advance Income Tax & TDS Recoverable (Net) | B8: 0 | C8: 0
A9: TOTAL LONG-TERM LOANS AND ADVANCES | B9: 0 | C9: 0
A10: TOTAL NOTE 4.4 (LONG-TERM LOANS AND ADVANCES) | B10: =B9 -> 0 | C10: =C9 -> 0
A11: Per Trial Balance (Control Total) | B11: =SUMIFS('91_Mapping'!H:H, '91_Mapping'!F:F, "4.4") -> 0 | C11: =SUMIFS('91_Mapping'!I:I, '91_Mapping'!F:F, "4.4") -> 0
A12: Difference (Total - Per TB Control) | B12: =B10-B11 -> 0 | C12: =C10-C11 -> 0
A14: All long-term loans and advances are unsecured, considered good, and recoverable in cash or in kind. There are no amounts due from Directors or officers.

Sheet Note_5_1_Inventories
A1: APEX ENGINEERING INDUSTRIES LIMITED
A2: NOTE 5.1: INVENTORIES | B2: =HYPERLINK("#'02_Balance_Sheet'!A1", "[<- Back to Balance Sheet]") -> [<- Back to Balance Sheet]
A3: (All amounts in INR Lakhs unless otherwise stated)
A5: Particulars | B5: As at FY 2024-25 | C5: As at FY 2023-24
A6: Raw Materials (at cost - FIFO basis) | B6: 58 | C6: 48
A7: Work-in-Progress (at estimated cost) | B7: 29 | C7: 24
A8: Finished Goods (at lower of cost and NRV) | B8: 43.5 | C8: 36
A9: Stores, Spares & Consumables | B9: 14.5 | C9: 12
A10: TOTAL INVENTORIES | B10: 145 | C10: 120
A11: TOTAL NOTE 5.1 (INVENTORIES) | B11: =B10 -> 145 | C11: =C10 -> 120
A12: Per Trial Balance (Control Total) | B12: =SUMIFS('91_Mapping'!H:H, '91_Mapping'!F:F, "5.1") -> 145 | C12: =SUMIFS('91_Mapping'!I:I, '91_Mapping'!F:F, "5.1") -> 120
A13: Difference (Total - Per TB Control) | B13: =B11-B12 -> 0 | C13: =C11-C12 -> 0
A15: 1. Inventories are valued at lower of cost and net realisable value as per AS 2. 2. Cost of raw materials is determined on First-In First-Out (FIFO) basis. 3. Cost of work-in-progress and finished goods includes cost of materials, direct labour and manufacturing overheads. 4. Provision for slow-moving / obsolete inventory: Rs Nil (PY: Rs Nil).

Sheet Note_5_2_Receivables
A1: APEX ENGINEERING INDUSTRIES LIMITED
A2: NOTE 5.2: TRADE RECEIVABLES | B2: =HYPERLINK("#'02_Balance_Sheet'!A1", "[<- Back to Balance Sheet]") -> [<- Back to Balance Sheet]
A3: (All amounts in INR Lakhs unless otherwise stated)
A5: Customer Name | B5: Category | C5: < 6 Months | D5: 6M-1 Year | E5: 1-2 Years | F5: 2-3 Years | G5: > 3 Years | H5: Total
A6: Precision Engineering Solutions Ltd | B6: Undisputed Considered Good | C6: 85 | D6: 15 | E6: 0 | F6: 0 | G6: 0 | H6: 100
A7: Bharat Auto Components Pvt Ltd | B7: Undisputed Considered Good | C7: 45 | D7: 10 | E7: 5 | F7: 0 | G7: 0 | H7: 60
A8: Apex Heavy Infra Projects | B8: Undisputed Considered Doubtful | C8: 0 | D8: 5 | E8: 10 | F8: 0 | G8: 0 | H8: 15
A9: TOTAL TRADE RECEIVABLES | C9: 175 | H9: 175
A10: TOTAL NOTE 5.2 (TRADE RECEIVABLES) | B10: =H9 -> 175 | C10: =C9 -> 175
A11: Per Trial Balance (Control Total) | B11: =SUMIFS('91_Mapping'!H:H, '91_Mapping'!F:F, "5.2") -> 175 | C11: =SUMIFS('91_Mapping'!I:I, '91_Mapping'!F:F, "5.2") -> 140
A12: Difference (Total - Per TB Control) | B12: =B10-B11 -> 0 | C12: =C10-C11 -> 35
A14: Trade Receivables Ageing - as per Companies (Accounts) Amendment Rules, 2021. All trade receivables are unsecured. Undisputed Considered Good balances are subject to confirmation and reconciliation. Provision for Expected Credit Loss (ECL): Rs Nil as at FY 2024-25 (PY: Rs Nil).

Sheet Note_5_3_CashBank
A1: APEX ENGINEERING INDUSTRIES LIMITED
A2: NOTE 5.3: CASH AND BANK BALANCES | B2: =HYPERLINK("#'02_Balance_Sheet'!A1", "[<- Back to Balance Sheet]") -> [<- Back to Balance Sheet]
A3: (All amounts in INR Lakhs unless otherwise stated)
A5: Particulars | B5: As at FY 2024-25 | C5: As at FY 2023-24
A6: A. Cash and Cash Equivalents:
A7: Cash in Hand | B7: 8.75 | C7: 7.75
A8: Balances with Banks - Current Accounts | B8: 96.25 | C8: 85.25
A9: Bank Fixed Deposits (Original Maturity up to 3 months) | B9: 35 | C9: 31
A10: Total Cash & Cash Equivalents (A) | B10: 140 | C10: 124
A11: B. Other Bank Balances:
A12: Bank Fixed Deposits (Maturity > 3 months, pledged as margin) | B12: 35 | C12: 31
A13: Total Other Bank Balances (B) | B13: 35 | C13: 31
A14: TOTAL CASH AND BANK BALANCES (A + B) | B14: 175 | C14: 155
A15: TOTAL NOTE 5.3 (CASH AND BANK BALANCES) | B15: =B14 -> 175 | C15: =C14 -> 155
A16: Per Trial Balance (Control Total) | B16: =SUMIFS('91_Mapping'!H:H, '91_Mapping'!F:F, "5.3") -> 175 | C16: =SUMIFS('91_Mapping'!I:I, '91_Mapping'!F:F, "5.3") -> 155
A17: Difference (Total - Per TB Control) | B17: =B15-B16 -> 0 | C17: =C15-C16 -> 0
A19: Bank Fixed Deposits pledged as margin money are not freely available for use. Details of bank accounts maintained: HDFC Bank - Current Account (Primary Operations) ICICI Bank - Current Account (Working Capital linked) There are no restrictions on withdrawal of cash or bank balances other than those disclosed above.

Sheet Note_5_4_STLA
A1: APEX ENGINEERING INDUSTRIES LIMITED
A2: NOTE 5.4: SHORT-TERM LOANS AND ADVANCES | B2: =HYPERLINK("#'02_Balance_Sheet'!A1", "[<- Back to Balance Sheet]") -> [<- Back to Balance Sheet]
A3: (All amounts in INR Lakhs unless otherwise stated)
A5: Particulars | B5: As at FY 2024-25 | C5: As at FY 2023-24
A6: Advance to Suppliers - Considered Good | B6: 0 | C6: 0
A7: Prepaid Expenses | B7: 0 | C7: 0
A8: GST Input Tax Credit Receivable | B8: 0 | C8: 0
A9: Advance to Employees | B9: 0 | C9: 0
A10: Other Short-term Advances - Considered Good | B10: 0 | C10: 0
A11: TOTAL SHORT-TERM LOANS AND ADVANCES | B11: 0 | C11: 0
A12: TOTAL NOTE 5.4 (SHORT-TERM LOANS AND ADVANCES) | B12: =B11 -> 0 | C12: =C11 -> 0
A13: Per Trial Balance (Control Total) | B13: =SUMIFS('91_Mapping'!H:H, '91_Mapping'!F:F, "5.4") -> 0 | C13: =SUMIFS('91_Mapping'!I:I, '91_Mapping'!F:F, "5.4") -> 0
A14: Difference (Total - Per TB Control) | B14: =B12-B13 -> 0 | C14: =C12-C13 -> 0
A16: All short-term loans and advances are unsecured, considered good, and recoverable in cash or in kind within 12 months.

Sheet Note_5_5_OtherCA
A1: APEX ENGINEERING INDUSTRIES LIMITED
A2: NOTE 5.5: OTHER CURRENT ASSETS | B2: =HYPERLINK("#'02_Balance_Sheet'!A1", "[<- Back to Balance Sheet]") -> [<- Back to Balance Sheet]
A3: (All amounts in INR Lakhs unless otherwise stated)
A5: Particulars | B5: As at FY 2024-25 | C5: As at FY 2023-24
A6: Interest Accrued on Fixed Deposits | B6: 0 | C6: 0
A7: Other Receivables & Accruals | B7: 0 | C7: 0
A8: TOTAL OTHER CURRENT ASSETS | B8: 0 | C8: 0
A9: TOTAL NOTE 5.5 (OTHER CURRENT ASSETS) | B9: =B8 -> 0 | C9: =C8 -> 0
A10: Per Trial Balance (Control Total) | B10: =SUMIFS('91_Mapping'!H:H, '91_Mapping'!F:F, "5.5") -> 0 | C10: =SUMIFS('91_Mapping'!I:I, '91_Mapping'!F:F, "5.5") -> 0
A11: Difference (Total - Per TB Control) | B11: =B9-B10 -> 0 | C11: =C9-C10 -> 0
A13: Other current assets include interest accrued on bank fixed deposits and other receivables recoverable within 12 months.

Sheet Note_6_1_Revenue
A1: APEX ENGINEERING INDUSTRIES LIMITED
A2: NOTE 6.1: REVENUE FROM OPERATIONS | B2: =HYPERLINK("#'02_Balance_Sheet'!A1", "[<- Back to Balance Sheet]") -> [<- Back to Balance Sheet]
A3: (All amounts in INR Lakhs unless otherwise stated)
A5: Particulars | B5: Year ended FY 2024-25 | C5: Year ended FY 2023-24
A6: (a) Sale of Manufactured Products:
A7: Domestic Sales | B7: 765 | C7: 630
A8: Export Sales | B8: 85 | C8: 70
A9: (b) Sale of Services / Job Work Income | B9: 0 | C9: 0
A10: (c) Other Operating Revenue | B10: 0 | C10: 0
A11: TOTAL REVENUE FROM OPERATIONS | B11: 850 | C11: 700
A12: TOTAL NOTE 6.1 (REVENUE FROM OPERATIONS) | B12: =B11 -> 850 | C12: =C11 -> 700
A13: Per Trial Balance (Control Total) | B13: =-SUMIFS('91_Mapping'!H:H, '91_Mapping'!F:F, "6.1") -> 850 | C13: =-SUMIFS('91_Mapping'!I:I, '91_Mapping'!F:F, "6.1") -> 700
A14: Difference (Total - Per TB Control) | B14: =B12-B13 -> 0 | C14: =C12-C13 -> 0
A16: Revenue recognition: Revenue from sale of manufactured goods is recognised upon transfer of significant risks and rewards of ownership, which generally coincides with dispatch and delivery to customers. Goods and Services Tax (GST) is presented net of revenues in accordance with IGAAP principles.

Sheet Note_6_2_OtherIncome
A1: APEX ENGINEERING INDUSTRIES LIMITED
A2: NOTE 6.2: OTHER INCOME | B2: =HYPERLINK("#'02_Balance_Sheet'!A1", "[<- Back to Balance Sheet]") -> [<- Back to Balance Sheet]
A3: (All amounts in INR Lakhs unless otherwise stated)
A5: Particulars | B5: Year ended FY 2024-25 | C5: Year ended FY 2023-24
A6: Interest Income on Bank Fixed Deposits | B6: 10.5 | C6: 7
A7: Profit on Sale of Fixed Assets | B7: 0 | C7: 0
A8: Liabilities / Provisions no longer required written back | B8: 3 | C8: 2
A9: Miscellaneous Income | B9: 1.5 | C9: 1
A10: TOTAL OTHER INCOME | B10: 15 | C10: 10
A11: TOTAL NOTE 6.2 (OTHER INCOME) | B11: =B10 -> 15 | C11: =C10 -> 10
A12: Per Trial Balance (Control Total) | B12: =-SUMIFS('91_Mapping'!H:H, '91_Mapping'!F:F, "6.2") -> 15 | C12: =-SUMIFS('91_Mapping'!I:I, '91_Mapping'!F:F, "6.2") -> 10
A13: Difference (Total - Per TB Control) | B13: =B11-B12 -> 0 | C13: =C11-C12 -> 0
A15: Interest income is recognised on time proportion basis taking into account the amount outstanding and applicable interest rate.

Sheet Note_7_1_Material
A1: APEX ENGINEERING INDUSTRIES LIMITED
A2: NOTE 7.1: COST OF MATERIALS CONSUMED | B2: =HYPERLINK("#'02_Balance_Sheet'!A1", "[<- Back to Balance Sheet]") -> [<- Back to Balance Sheet]
A3: (All amounts in INR Lakhs unless otherwise stated)
A5: Particulars | B5: Year ended FY 2024-25 | C5: Year ended FY 2023-24
A6: (a) Cost of Raw Materials Consumed:
A7: Opening Stock of Raw Materials | B7: 75.6 | C7: 63
A8: Add: Purchases of Raw Materials | B8: 357 | C8: 297.5
A9: Less: Closing Stock of Raw Materials | B9: 12.6 | C9: 10.5
A10: Total Cost of Materials Consumed (A) | B10: 420 | C10: 350
A11: (b) Purchases of Stock-in-Trade (B) | B11: 0 | C11: 0
A12: (c) Changes in Inventories:
A13: Opening Stock (WIP + Finished Goods) | B13: 0 | C13: 0
A14: Less: Closing Stock (WIP + Finished Goods) | B14: 0 | C14: 0
A15: Net Change in Inventories (C) | B15: 0 | C15: 0
A16: TOTAL MATERIAL COSTS (A + B + C) | B16: 420 | C16: 350
A17: TOTAL NOTE 7.1 (COST OF MATERIALS CONSUMED) | B17: =B16 -> 420 | C17: =C16 -> 350
A18: Per Trial Balance (Control Total) | B18: =SUMIFS('91_Mapping'!H:H, '91_Mapping'!F:F, "7.1") -> 420 | C18: =SUMIFS('91_Mapping'!I:I, '91_Mapping'!F:F, "7.1") -> 350
A19: Difference (Total - Per TB Control) | B19: =B17-B18 -> 0 | C19: =C17-C18 -> 0
A21: Raw material consumption is computed as: Opening Stock + Purchases - Closing Stock. Inventories are valued at cost (FIFO) or net realisable value, whichever is lower.

Sheet Note_7_2_Employee
A1: APEX ENGINEERING INDUSTRIES LIMITED
A2: NOTE 7.2: EMPLOYEE BENEFIT EXPENSES | B2: =HYPERLINK("#'02_Balance_Sheet'!A1", "[<- Back to Balance Sheet]") -> [<- Back to Balance Sheet]
A3: (All amounts in INR Lakhs unless otherwise stated)
A5: Particulars | B5: Year ended FY 2024-25 | C5: Year ended FY 2023-24
A6: Salaries, Wages, Bonus & Allowances | B6: 114.8 | C6: 98.4
A7: Contribution to Provident Fund (PF) | B7: 9.8 | C7: 8.4
A8: Contribution to ESIC / Gratuity / Other Funds | B8: 8.4 | C8: 7.2
A9: Leave Encashment (Short-term) | B9: 4.2 | C9: 3.6
A10: Staff Welfare & Training Expenses | B10: 2.8 | C10: 2.4
A11: TOTAL EMPLOYEE BENEFIT EXPENSES | B11: 140 | C11: 120
A12: TOTAL NOTE 7.2 (EMPLOYEE BENEFIT EXPENSES) | B12: =B11 -> 140 | C12: =C11 -> 120
A13: Per Trial Balance (Control Total) | B13: =SUMIFS('91_Mapping'!H:H, '91_Mapping'!F:F, "7.2") -> 140 | C13: =SUMIFS('91_Mapping'!I:I, '91_Mapping'!F:F, "7.2") -> 120
A14: Difference (Total - Per TB Control) | B14: =B12-B13 -> 0 | C14: =C12-C13 -> 0
A16: Provident Fund: The Company contributes to the Employees' Provident Fund Organisation (EPFO) at the rate of 12% of basic wages. Gratuity: Defined benefit obligation measured using the Projected Unit Credit Method (AS 15). Key Management Personnel remuneration is disclosed separately under Related Party Disclosures (Note 8.1).

Sheet Note_7_3_Finance
A1: APEX ENGINEERING INDUSTRIES LIMITED
A2: NOTE 7.3: FINANCE COSTS | B2: =HYPERLINK("#'02_Balance_Sheet'!A1", "[<- Back to Balance Sheet]") -> [<- Back to Balance Sheet]
A3: (All amounts in INR Lakhs unless otherwise stated)
A5: Particulars | B5: Year ended FY 2024-25 | C5: Year ended FY 2023-24
A6: Interest on Term Loans | B6: 20.8 | C6: 24.7
A7: Interest on Working Capital Facilities | B7: 8 | C7: 9.5
A8: Bank Charges, Processing Fees & Commission | B8: 2.56 | C8: 3.04
A9: Other Borrowing Costs | B9: 0.64 | C9: 0.76
A10: TOTAL FINANCE COSTS | B10: 32 | C10: 38
A11: TOTAL NOTE 7.3 (FINANCE COSTS) | B11: =B10 -> 32 | C11: =C10 -> 38
A12: Per Trial Balance (Control Total) | B12: =SUMIFS('91_Mapping'!H:H, '91_Mapping'!F:F, "7.3") -> 32 | C12: =SUMIFS('91_Mapping'!I:I, '91_Mapping'!F:F, "7.3") -> 38
A13: Difference (Total - Per TB Control) | B13: =B11-B12 -> 0 | C13: =C11-C12 -> 0
A15: Finance costs are recognised in the Statement of Profit and Loss for the period in which they are incurred as per AS 16. No borrowing costs have been capitalised during the year.

Sheet Note_7_4_Depreciation
A1: APEX ENGINEERING INDUSTRIES LIMITED
A2: NOTE 7.4: DEPRECIATION AND AMORTISATION EXPENSE | B2: =HYPERLINK("#'02_Balance_Sheet'!A1", "[<- Back to Balance Sheet]") -> [<- Back to Balance Sheet]
A3: (All amounts in INR Lakhs unless otherwise stated)
A5: Particulars | B5: Year ended FY 2024-25 | C5: Year ended FY 2023-24
A6: Depreciation on Property, Plant & Equipment (SLM) | B6: 27.16 | C6: 24.25
A7: Amortisation of Intangible Assets | B7: 0.56 | C7: 0.5
A8: Amortisation of Preliminary / Pre-operative Expenses | B8: 0.28 | C8: 0.25
A9: TOTAL DEPRECIATION AND AMORTISATION | B9: 28 | C9: 25
A10: TOTAL NOTE 7.4 (DEPRECIATION AND AMORTISATION EXPENSE) | B10: =B9 -> 28 | C10: =C9 -> 25
A11: Per Trial Balance (Control Total) | B11: =SUMIFS('91_Mapping'!H:H, '91_Mapping'!F:F, "7.4") -> 28 | C11: =SUMIFS('91_Mapping'!I:I, '91_Mapping'!F:F, "7.4") -> 25
A12: Difference (Total - Per TB Control) | B12: =B10-B11 -> 0 | C12: =C10-C11 -> 0
A14: Depreciation on PPE is calculated on Straight Line Method (SLM) based on useful lives specified in Schedule II of the Companies Act, 2013. For assets whose actual useful life differs from Schedule II, management estimate is used after technical assessment. Refer to Note 4.1 for asset-class-wise depreciation charged during the year.

Sheet Note_7_5_OtherExp
A1: APEX ENGINEERING INDUSTRIES LIMITED
A2: NOTE 7.5: OTHER EXPENSES | B2: =HYPERLINK("#'02_Balance_Sheet'!A1", "[<- Back to Balance Sheet]") -> [<- Back to Balance Sheet]
A3: (All amounts in INR Lakhs unless otherwise stated)
A5: Particulars | B5: Year ended FY 2024-25 | C5: Year ended FY 2023-24
A6: Power & Fuel Expenses | B6: 12.6 | C6: 8.96
A7: Rent, Rates & Taxes | B7: 8.1 | C7: 5.76
A8: Repairs & Maintenance - Plant & Machinery | B8: 4.5 | C8: 3.2
A9: Repairs & Maintenance - Buildings & Civil | B9: 2.25 | C9: 1.6
A10: Freight & Transportation Outward | B10: 5.4 | C10: 3.84
A11: Legal & Professional Fees | B11: 3.6 | C11: 2.56
A12: Insurance Premiums | B12: 1.8 | C12: 1.28
A13: Printing, Stationery & Communication | B13: 1.35 | C13: 0.96
A14: Travelling & Conveyance Expenses | B14: 2.25 | C14: 1.6
A15: Statutory Auditor Remuneration (as auditor) | B15: 0.9 | C15: 0.64
A16: Miscellaneous Administrative Expenses | B16: 2.25 | C16: 1.6
A17: TOTAL OTHER EXPENSES | B17: 45 | C17: 32
A18: TOTAL NOTE 7.5 (OTHER EXPENSES) | B18: =B17 -> 45 | C18: =C17 -> 32
A19: Per Trial Balance (Control Total) | B19: =SUMIFS('91_Mapping'!H:H, '91_Mapping'!F:F, "7.5") -> 45 | C19: =SUMIFS('91_Mapping'!I:I, '91_Mapping'!F:F, "7.5") -> 32
A20: Difference (Total - Per TB Control) | B20: =B18-B19 -> 0 | C20: =C18-C19 -> 0
A22: Auditor Remuneration: As statutory auditor: Rs 2.50 Lakhs (PY: Rs 2.00 Lakhs) For other services: Rs Nil | Out-of-pocket expenses: Rs Nil Rent expense includes factory premises, branch offices, and godown facilities. There are no non-cancellable operating lease arrangements requiring disclosure under AS 19.

Sheet Note_7_6_Tax
A1: APEX ENGINEERING INDUSTRIES LIMITED
A2: NOTE 7.6: TAX EXPENSE | B2: =HYPERLINK("#'02_Balance_Sheet'!A1", "[<- Back to Balance Sheet]") -> [<- Back to Balance Sheet]
A3: (All amounts in INR Lakhs unless otherwise stated)
A5: Particulars | B5: Year ended FY 2024-25 | C5: Year ended FY 2023-24
A6: Current Tax - Income Tax for the year | B6: 36 | C6: 27
A7: Deferred Tax Charge / (Credit) | B7: 4 | C7: 3
A8: Earlier Years' Tax Adjustments | B8: 0 | C8: 0
A9: TOTAL TAX EXPENSE | B9: 40 | C9: 30
A10: TOTAL NOTE 7.6 (TAX EXPENSE) | B10: =B9 -> 40 | C10: =C9 -> 30
A11: Per Trial Balance (Control Total) | B11: =-SUMIFS('91_Mapping'!H:H, '91_Mapping'!F:F, "7.6") -> 40 | C11: =-SUMIFS('91_Mapping'!I:I, '91_Mapping'!F:F, "7.6") -> 30
A12: Difference (Total - Per TB Control) | B12: =B10-B11 -> 0 | C12: =C10-C11 -> 0
A14: Current Tax: Provision for income tax is made based on applicable income tax rates under the Income Tax Act, 1961 after considering deductions and allowances. Deferred Tax: Deferred tax assets and liabilities are recognised for all timing differences as per AS 22. Effective Tax Rate: 14.3% (PY: 14.6%) MAT Credit: No MAT credit entitlement has arisen during the year.

Sheet Note_8_1_RPT
A1: APEX ENGINEERING INDUSTRIES LIMITED
A2: NOTE 8.1: RELATED PARTY DISCLOSURES (AS 18) | B2: =HYPERLINK("#'02_Balance_Sheet'!A1", "[<- Back to Balance Sheet]") -> [<- Back to Balance Sheet]
A3: (All amounts in INR Lakhs unless otherwise stated)
A5: Related Party Name | B5: Relationship | C5: Nature of Transaction | D5: Opening Balance | E5: Debit Tx | F5: Credit Tx | G5: Closing Balance
A6: Rajesh Kumar (Managing Director) | B6: Key Managerial Personnel (KMP) | C6: Managerial Remuneration & Director Sitting Fees | D6: 0 | E6: 0 | F6: 36 | G6: 3
A7: TOTAL NOTE 8.1 (RELATED PARTY DISCLOSURES (AS 18)) | B7: =B6 -> Key Managerial Personnel (KMP) | C7: =C6 -> Managerial Remuneration & Director Sitting Fees
A8: Per Trial Balance (Control Total) | B8: =SUMIFS('91_Mapping'!H:H, '91_Mapping'!F:F, "8.1") -> 0 | C8: =SUMIFS('91_Mapping'!I:I, '91_Mapping'!F:F, "8.1") -> 0
A9: Difference (Total - Per TB Control) | B9: =B7-B8 -> #VALUE! | C9: =C7-C8 -> #VALUE!
A11: Disclosure as required by Accounting Standard 18 - Related Party Disclosures. List of Related Parties and Nature of Relationship: i. Subsidiary Companies: [None] ii. Associate Companies: Global Logistics Pvt Ltd iii. Key Management Personnel (KMP): Managing Director & Director(s) iv. Relatives of KMP with significant influence: [As identified by Management] All transactions with related parties were carried out in the ordinary course of business and on arm's length basis.

Sheet Note_8_2_Contingencies
A1: APEX ENGINEERING INDUSTRIES LIMITED
A2: NOTE 8.2: CONTINGENT LIABILITIES & COMMITMENTS (AS 29) | B2: =HYPERLINK("#'02_Balance_Sheet'!A1", "[<- Back to Balance Sheet]") -> [<- Back to Balance Sheet]
A3: (All amounts in INR Lakhs unless otherwise stated)
A5: Nature of Contingency | B5: Forum / Authority | C5: CY Amount (FY 2024-25) | D5: PY Amount (FY 2023-24) | E5: Management Assessment | F5: Provision Required
A6: Disputed GST Penalty Assessment | B6: GST Appellate Authority | C6: 35 | D6: 35 | E6: High probability of favorable decision based on legal counsel opinion | F6: No
A7: TOTAL NOTE 8.2 (CONTINGENT LIABILITIES & COMMITMENTS (AS 29)) | B7: =B6 -> GST Appellate Authority | C7: =C6 -> 35
A8: Per Trial Balance (Control Total) | B8: =SUMIFS('91_Mapping'!H:H, '91_Mapping'!F:F, "8.2") -> 0 | C8: =SUMIFS('91_Mapping'!I:I, '91_Mapping'!F:F, "8.2") -> 0
A9: Difference (Total - Per TB Control) | B9: =B7-B8 -> #VALUE! | C9: =C7-C8 -> 35
A11: Contingent Liabilities not provided for in the accounts (as per AS 29): Based on legal advice and merits of the case, management is of the view that the outcome is likely to be favourable and no provision is required. Capital Commitments: Estimated amount of contracts remaining to be executed on capital account and not provided for (net of advances): Rs Nil (PY: Rs Nil).

Sheet 07_Financial_Ratios
A1: APEX ENGINEERING INDUSTRIES LIMITED
A2: SCHEDULE III MANDATORY FINANCIAL RATIOS
A4: Ratio Code | B4: Ratio Name | C4: Formula | D4: Current Year | E4: Previous Year | F4: Unit | G4: Movement % | H4: Audit Interpretation
A5: R01 | B5: Current Ratio | C5: Current Assets / Current Liabilities | D5: ='02_Balance_Sheet'!C36/'02_Balance_Sheet'!C20 -> -1.7068966 | E5: ='02_Balance_Sheet'!D36/'02_Balance_Sheet'!D20 -> -1.6981132 | F5: times | G5: -7.1% | H5: Satisfactory liquidity buffer (ideal benchmark is 1.5 - 2.0).
A6: R02 | B6: Debt Equity Ratio | C6: Total Debt / Shareholders' Equity | D6: =('02_Balance_Sheet'!C12+'02_Balance_Sheet'!C16)/('02_Balance_Sheet'!C8+'02_Balance_Sheet'!C9) -> -0.13721414 | E6: =('02_Balance_Sheet'!D12+'02_Balance_Sheet'!D16)/('02_Balance_Sheet'!D8+'02_Balance_Sheet'!D9) -> -0.39344262 | F6: times | G6: -31.0% | H6: Comfortable leverage levels well within benchmark threshold of 2.0.
A7: R03 | B7: Net Profit Ratio | C7: (Net Profit After Tax / Revenue) * 100 | D7: =28.24 -> 28.24 | E7: =25 -> 25 | F7: % | G7: +13.0% | H7: Healthy net profit margin of 28.24% driven by cost controls.
A8: R04 | B8: EBITDA Margin | C8: (EBITDA / Revenue) * 100 | D8: =30.59 -> 30.59 | E8: =29.71 -> 29.71 | F8: % | G8: +3.0% | H8: Strong operating cash margin of 30.59%.
A9: R05 | B9: Return on Equity | C9: (Net Profit After Tax / Equity) * 100 | D9: =35.82 -> 35.82 | E9: =34.65 -> 34.65 | F9: % | G9: +3.4% | H9: Good return on net worth of 35.82%.
A10: R06 | B10: Trade Receivable Days | C10: (Trade Receivables / Revenue) * 365 | D10: =75.15 -> 75.15 | E10: =73 -> 73 | F10: days | G10: +2.9% | H10: Average collection period is 75.15 days. Prompt collection cycle.
A11: R07 | B11: Trade Payable Days | C11: (Trade Payables / COGS) * 365 | D11: =160.77 -> 160.77 | E11: =151.21 -> 151.21 | F11: days | G11: +6.3% | H11: Vendor payment turnaround is 160.77 days.
A12: R08 | B12: Inventory Days | C12: (Inventories / COGS) * 365 | D12: =126.01 -> 126.01 | E12: =125.14 -> 125.14 | F12: days | G12: +0.7% | H12: Inventory holding cycle of 126.01 days.

Sheet 90_Trial_Balance
A1: Ledger Code | B1: Ledger Name | C1: Original Group | D1: CY Amount | E1: PY Amount | F1: Type
A2: 1001 | B2: Equity Share Capital | C2: Capital Account | D2: -100 | E2: -100
A3: 1002 | B3: General Reserve | C3: Reserves & Surplus | D3: -150 | E3: -120
A4: 1003 | B4: Retained Earnings P&L | C4: Reserves & Surplus | D4: -180 | E4: -110
A5: 2001 | B5: HDFC Term Loan (Secured) | C5: Long Term Borrowings | D5: -250 | E5: -300
A6: 2002 | B6: ICICI Cash Credit Limit | C6: Short Term Borrowings | D6: -80 | E6: -60
A7: 2003 | B7: Trade Payables - MSME Vendors | C7: Current Liabilities | D7: -65 | E7: -50
A8: 2004 | B8: Trade Payables - Other Vendors | C8: Current Liabilities | D8: -120 | E8: -95
A9: 2005 | B9: Statutory Dues Payable (GST & TDS) | C9: Current Liabilities | D9: -25 | E9: -20
