Workbook

Sheet Balance Sheet
A1: Sample Engineering Private Limited
A2: Balance Sheet as at 31st March 2026
A3: (Schedule III, Division I - Accounting Standards, Companies Act 2013) | Amounts in Rupees
A4: CIN / LLPIN: U00000KL2015PTC000000 | PAN: AAAAA0000A | Sample Industrial Estate, Kochi, Kerala
A5: Particulars | B5: Note | C5: As at 31-Mar-2026 (Rs) | D5: As at 31-Mar-2025 (Rs)
A6: I. EQUITY AND LIABILITIES
A7: (1) Shareholders' Funds
A8: (a) Share capital | B8: 1 | C8: =SUMIFS('Trial Balance Mapping'!$F$6:$F$62,'Trial Balance Mapping'!$C$6:$C$62,"Share Capital") -> 2500000 | D8: =SUMIFS('Trial Balance Mapping PY'!$F$6:$F$59,'Trial Balance Mapping PY'!$C$6:$C$59,"Share Capital") -> 2500000
A9: (b) Reserves and surplus | B9: 2 | C9: =SUMIFS('Trial Balance Mapping'!$F$6:$F$62,'Trial Balance Mapping'!$C$6:$C$62,"Reserves and Surplus")+'Profit & Loss'!C23 -> 7801401.6 | D9: =SUMIFS('Trial Balance Mapping PY'!$F$6:$F$59,'Trial Balance Mapping PY'!$C$6:$C$59,"Reserves and Surplus")+'Profit & Loss'!D23 -> 4317000
A10: Total Shareholders' Funds | C10: =C8+C9 -> 10301402 | D10: =D8+D9 -> 6817000
A11: (2) Non-current liabilities
A12: (a) Long-term borrowings | B12: 3 | C12: =SUMIFS('Trial Balance Mapping'!$F$6:$F$62,'Trial Balance Mapping'!$C$6:$C$62,"Long-term Borrowings") -> 3800000 | D12: =SUMIFS('Trial Balance Mapping PY'!$F$6:$F$59,'Trial Balance Mapping PY'!$C$6:$C$59,"Long-term Borrowings") -> 4350000
A13: (b) Other long-term liabilities and provisions | B13: 4 | C13: =SUMIFS('Trial Balance Mapping'!$F$6:$F$62,'Trial Balance Mapping'!$C$6:$C$62,"Other Non-current Liabilities") -> 0 | D13: =SUMIFS('Trial Balance Mapping PY'!$F$6:$F$59,'Trial Balance Mapping PY'!$C$6:$C$59,"Other Non-current Liabilities") -> 0
A14: Total Non-current Liabilities | C14: =C12+C13 -> 3800000 | D14: =D12+D13 -> 4350000
A15: (3) Current Liabilities
A16: (a) Short-term borrowings | B16: 5 | C16: =SUMIFS('Trial Balance Mapping'!$F$6:$F$62,'Trial Balance Mapping'!$C$6:$C$62,"Short-term Borrowings") -> 1450000 | D16: =SUMIFS('Trial Balance Mapping PY'!$F$6:$F$59,'Trial Balance Mapping PY'!$C$6:$C$59,"Short-term Borrowings") -> 1100000
A17: (b) Trade payables | B17: 6 | C17: =SUMIFS('Trial Balance Mapping'!$F$6:$F$62,'Trial Balance Mapping'!$C$6:$C$62,"Trade Payables") -> 2640000 | D17: =SUMIFS('Trial Balance Mapping PY'!$F$6:$F$59,'Trial Balance Mapping PY'!$C$6:$C$59,"Trade Payables") -> 2230000
A18: (c) Other current liabilities | B18: 7 | C18: =SUMIFS('Trial Balance Mapping'!$F$6:$F$62,'Trial Balance Mapping'!$C$6:$C$62,"Other Current Liabilities (Statutory Dues)")+SUMIFS('Trial Balance Mapping'!$F$6:$F$62,'Trial Balance Mapping'!$C$6:$C$62,"Other Current Liabilities") -> 1205000 | D18: =SUMIFS('Trial Balance Mapping PY'!$F$6:$F$59,'Trial Balance Mapping PY'!$C$6:$C$59,"Other Current Liabilities (Statutory Dues)")+SUMIFS('Trial Balance Mapping PY'!$F$6:$F$59,'Trial Balance Mapping PY'!$C$6:$C$59,"Other Current Liabilities") -> 843000
A19: (d) Short-term provisions | B19: 8 | C19: =SUMIFS('Trial Balance Mapping'!$F$6:$F$62,'Trial Balance Mapping'!$C$6:$C$62,"Short-term Provisions")+'Trial Balance Mapping'!$F$64 -> 180000 | D19: =SUMIFS('Trial Balance Mapping PY'!$F$6:$F$59,'Trial Balance Mapping PY'!$C$6:$C$59,"Short-term Provisions")+'Trial Balance Mapping PY'!$F$61 -> 140000
A20: Total Current Liabilities | C20: =C16+C17+C18+C19 -> 5475000 | D20: =D16+D17+D18+D19 -> 4313000
A21: TOTAL EQUITY AND LIABILITIES | C21: =C10+C14+C20 -> 19576402 | D21: =D10+D14+D20 -> 15480000
A23: II. ASSETS
A24: (1) Non-current assets
A25: (a) Property, plant and equipment | B25: 9 | C25: =SUMIFS('Trial Balance Mapping'!$F$6:$F$62,'Trial Balance Mapping'!$C$6:$C$62,"Property, Plant & Equipment") -> 6929401.6 | D25: =SUMIFS('Trial Balance Mapping PY'!$F$6:$F$59,'Trial Balance Mapping PY'!$C$6:$C$59,"Property, Plant & Equipment") -> 6713000
A26: (b) Investments | B26: 10 | C26: =SUMIFS('Trial Balance Mapping'!$F$6:$F$62,'Trial Balance Mapping'!$C$6:$C$62,"Investments") -> 0 | D26: =SUMIFS('Trial Balance Mapping PY'!$F$6:$F$59,'Trial Balance Mapping PY'!$C$6:$C$59,"Investments") -> 0
A27: (c) Other non-current assets | B27: 11 | C27: =SUMIFS('Trial Balance Mapping'!$F$6:$F$62,'Trial Balance Mapping'!$C$6:$C$62,"Other Non-Current Assets") -> 0 | D27: =SUMIFS('Trial Balance Mapping PY'!$F$6:$F$59,'Trial Balance Mapping PY'!$C$6:$C$59,"Other Non-Current Assets") -> 0
A28: Total Non-current Assets | C28: =C25+C26+C27 -> 6929401.6 | D28: =D25+D26+D27 -> 6713000
A29: (2) Current assets
A30: (a) Inventories | B30: 12 | C30: =SUMIFS('Trial Balance Mapping'!$F$6:$F$62,'Trial Balance Mapping'!$C$6:$C$62,"Inventories") -> 2250000 | D30: =SUMIFS('Trial Balance Mapping PY'!$F$6:$F$59,'Trial Balance Mapping PY'!$C$6:$C$59,"Inventories") -> 1900000
A31: (b) Trade receivables | B31: 13 | C31: =SUMIFS('Trial Balance Mapping'!$F$6:$F$62,'Trial Balance Mapping'!$C$6:$C$62,"Trade Receivables") -> 4670000 | D31: =SUMIFS('Trial Balance Mapping PY'!$F$6:$F$59,'Trial Balance Mapping PY'!$C$6:$C$59,"Trade Receivables") -> 3890000
A32: (c) Cash and cash equivalents | B32: 14 | C32: =SUMIFS('Trial Balance Mapping'!$F$6:$F$62,'Trial Balance Mapping'!$C$6:$C$62,"Cash & Cash Equivalents") -> 4654000 | D32: =SUMIFS('Trial Balance Mapping PY'!$F$6:$F$59,'Trial Balance Mapping PY'!$C$6:$C$59,"Cash & Cash Equivalents") -> 2076000
A33: (d) Short-term loans and advances | B33: 15 | C33: =SUMIFS('Trial Balance Mapping'!$F$6:$F$62,'Trial Balance Mapping'!$C$6:$C$62,"Short-term Loans and Advances") -> 635000 | D33: =SUMIFS('Trial Balance Mapping PY'!$F$6:$F$59,'Trial Balance Mapping PY'!$C$6:$C$59,"Short-term Loans and Advances") -> 550000
A34: (e) Other current assets | B34: 16 | C34: =SUMIFS('Trial Balance Mapping'!$F$6:$F$62,'Trial Balance Mapping'!$C$6:$C$62,"Other Current Assets") -> 438000 | D34: =SUMIFS('Trial Balance Mapping PY'!$F$6:$F$59,'Trial Balance Mapping PY'!$C$6:$C$59,"Other Current Assets") -> 351000
A35: Total Current Assets | C35: =C30+C31+C32+C33+C34 -> 12647000 | D35: =D30+D31+D32+D33+D34 -> 8767000
A36: TOTAL ASSETS | C36: =C28+C35 -> 19576402 | D36: =D28+D35 -> 15480000 | F36: Balance check (not printed) | G36: =ROUND(C36-C21,2) -> 0 | H36: =ROUND(D36-D21,2) -> 0
A43: As per our report of even date attached | C43: For and on behalf of the Board of Directors of Sample Engineering Private Limited
A44: For Sample and Associates
A45: Chartered Accountants
A46: Firm Registration No.: 000000S | C46: Director One
C47: Director | DIN 00000001
...

Sheet Profit & Loss
A1: Sample Engineering Private Limited
A2: Statement of Profit and Loss for the year ended 31st March 2026
A3: (Schedule III, Division I - Accounting Standards, Companies Act 2013) | Amounts in Rupees
A4: CIN / LLPIN: U00000KL2015PTC000000 | PAN: AAAAA0000A | Sample Industrial Estate, Kochi, Kerala
A5: Particulars | B5: Note | C5: Year ended 31-Mar-2026 (Rs) | D5: Year ended 31-Mar-2025 (Rs)
A6: I. Revenue from operations | B6: 17 | C6: =SUMIFS('Trial Balance Mapping'!$F$6:$F$62,'Trial Balance Mapping'!$C$6:$C$62,"Revenue from Operations") -> 20400000 | D6: =SUMIFS('Trial Balance Mapping PY'!$F$6:$F$59,'Trial Balance Mapping PY'!$C$6:$C$59,"Revenue from Operations") -> 17300000
A7: II. Other income | B7: 18 | C7: =SUMIFS('Trial Balance Mapping'!$F$6:$F$62,'Trial Balance Mapping'!$C$6:$C$62,"Other Income") -> 86000 | D7: =SUMIFS('Trial Balance Mapping PY'!$F$6:$F$59,'Trial Balance Mapping PY'!$C$6:$C$59,"Other Income") -> 70000
A8: III. Total Income (I + II) | C8: =C6+C7 -> 20486000 | D8: =D6+D7 -> 17370000
A10: IV. Expenses
A11: Purchases of stock-in-trade | B11: 19 | C11: =SUMIFS('Trial Balance Mapping'!$F$6:$F$62,'Trial Balance Mapping'!$C$6:$C$62,"Purchases of Stock-in-Trade") -> 9600000 | D11: =SUMIFS('Trial Balance Mapping PY'!$F$6:$F$59,'Trial Balance Mapping PY'!$C$6:$C$59,"Purchases of Stock-in-Trade") -> 8300000
A12: Changes in inventories of stock-in-trade | B12: 20 | C12: =SUMIFS('Trial Balance Mapping'!$F$6:$F$62,'Trial Balance Mapping'!$C$6:$C$62,"Opening Stock")-'Trial Balance Mapping'!$F$62+SUMIFS('Trial Balance Mapping'!$F$6:$F$62,'Trial Balance Mapping'!$C$6:$C$62,"Changes in Inventories") -> -350000 | D12: =SUMIFS('Trial Balance Mapping PY'!$F$6:$F$59,'Trial Balance Mapping PY'!$C$6:$C$59,"Opening Stock")-'Trial Balance Mapping PY'!$F$59+SUMIFS('Trial Balance Mapping PY'!$F$6:$F$59,'Trial Balance Mapping PY'!$C$6:$C$59,"Changes in Inventories") -> -400000
A13: Employee benefits expense | B13: 21 | C13: =SUMIFS('Trial Balance Mapping'!$F$6:$F$62,'Trial Balance Mapping'!$C$6:$C$62,"Employee Benefits Expense") -> 3680000 | D13: =SUMIFS('Trial Balance Mapping PY'!$F$6:$F$59,'Trial Balance Mapping PY'!$C$6:$C$59,"Employee Benefits Expense") -> 3168000
A14: Finance costs | B14: 22 | C14: =SUMIFS('Trial Balance Mapping'!$F$6:$F$62,'Trial Balance Mapping'!$C$6:$C$62,"Finance Costs") -> 545000 | D14: =SUMIFS('Trial Balance Mapping PY'!$F$6:$F$59,'Trial Balance Mapping PY'!$C$6:$C$59,"Finance Costs") -> 580000
A15: Depreciation and amortisation expense | B15: 23 | C15: =SUMIFS('Trial Balance Mapping'!$F$6:$F$62,'Trial Balance Mapping'!$C$6:$C$62,"Depreciation & Amortisation") -> 738598.43 | D15: =SUMIFS('Trial Balance Mapping PY'!$F$6:$F$59,'Trial Balance Mapping PY'!$C$6:$C$59,"Depreciation & Amortisation") -> 820000
A16: Other expenses | B16: 24 | C16: =SUMIFS('Trial Balance Mapping'!$F$6:$F$62,'Trial Balance Mapping'!$C$6:$C$62,"Other Expenses") -> 2788000 | D16: =SUMIFS('Trial Balance Mapping PY'!$F$6:$F$59,'Trial Balance Mapping PY'!$C$6:$C$59,"Other Expenses") -> 2435000
A17: Total Expenses (IV) | C17: =C11+C12+C13+C14+C15+C16 -> 17001598 | D17: =D11+D12+D13+D14+D15+D16 -> 14903000
A19: V. Profit / (Loss) before exceptional items and tax (III - IV) | C19: =C8-C17 -> 3484401.6 | D19: =D8-D17 -> 2467000
A20: VI. Exceptional items | C20: =0 -> 0 | D20: =0 -> 0
A21: VII. Profit / (Loss) before tax (V - VI) | C21: =C19-C20 -> 3484401.6 | D21: =D19-D20 -> 2467000
A22: VIII. Tax expense | B22: 25 | C22: =SUMIFS('Trial Balance Mapping'!$F$6:$F$62,'Trial Balance Mapping'!$C$6:$C$62,"Tax Expense")+'Trial Balance Mapping'!$F$64 -> 0 | D22: =SUMIFS('Trial Balance Mapping PY'!$F$6:$F$59,'Trial Balance Mapping PY'!$C$6:$C$59,"Tax Expense")+'Trial Balance Mapping PY'!$F$61 -> 0
A23: IX. Profit / (Loss) for the year (VII - VIII) | C23: =C21-C22 -> 3484401.6 | D23: =D21-D22 -> 2467000
A25: Earnings per share (Rs) - Basic / Diluted | B25: 26 | C25: n.a. | D25: n.a.
A30: As per our report of even date attached | C30: For and on behalf of the Board of Directors of Sample Engineering Private Limited
A31: For Sample and Associates
A32: Chartered Accountants
A33: Firm Registration No.: 000000S | C33: Director One
C34: Director | DIN 00000001
A36: A. Sample
A37: Partner | C37: Director Two
A38: Membership No.: 000000 | C38: Director | DIN 00000002
A39: UDIN: (to be generated)
A40: Place: Kochi | C40: Date of approval: 28-Oct-2026
A41: Date: 28-Oct-2026

Sheet Accounting Policies
A1: Sample Engineering Private Limited
A2: Notes forming part of the Financial Statements for the year ended 31st March 2026
A3: (Schedule III, Division I - Accounting Standards, Companies Act 2013) | Amounts in Rupees
A6: A. | B6: General information
B7: Sample Engineering Private Limited is a company incorporated under the Companies Act. CIN / LLPIN: U00000KL2015PTC000000. Registered office / place of business: Sample Industrial Estate, Kochi, Kerala. These financial statements are for the year ended 31st March 2026.
A9: B. | B9: Significant accounting policies
B10: Basis of preparation
B11: The financial statements have been prepared on the historical cost convention, on the accrual basis of accounting and on a going-concern basis, in accordance with the Accounting Standards notified under section 133 of the Companies Act, 2013 read with the Companies (Accounting Standards) Rules, and Schedule III (Division I). The figures are taken from the books of account maintained in Tally Prime.
B12: Use of estimates
B13: The preparation of financial statements requires management to make estimates and assumptions that affect the reported amounts of assets, liabilities, income and expenses. Differences between actual results and estimates are recognised in the period in which the results are known.
B14: Property, plant and equipment and depreciation
B15: Property, plant and equipment are stated at cost less accumulated depreciation and impairment, if any. Depreciation: calculated under Schedule II of the Companies Act 2013 (SLM, residual 5.0%); see the Depreciation Schedule sheet.
B16: Inventories
B17: Inventories are valued at the lower of cost and net realisable value. Cost is determined on the basis followed consistently by the Company (first-in-first-out or weighted average).
B18: Revenue recognition
B19: Revenue from sale of goods is recognised when the significant risks and rewards of ownership pass to the buyer; revenue from services is recognised as the services are rendered. Revenue is stated net of GST and returns.
B20: Employee benefits
B21: Short-term employee benefits are recognised as an expense at the undiscounted amount in the period in which the related service is rendered. Post-employment benefits, where applicable, are provided as per the applicable standard.
... B29: Basic earnings per share is computed by dividing the profit for the year attributable to equity shareholders by the number of equity shares outstanding.

Sheet Notes - Balance Sheet
A1: Sample Engineering Private Limited
A2: Notes forming part of the Financial Statements for the year ended 31st March 2026
A3: (Schedule III, Division I - Accounting Standards, Companies Act 2013) | Amounts in Rupees
A6: 1. | B6: Share capital
B7: Particulars | C7: As at 31-Mar-2026 | D7: As at 31-Mar-2025 | H7: Check (not printed)
B8: Equity Share Capital | C8: ='Trial Balance Mapping'!F6 -> 2500000 | D8: ='Trial Balance Mapping PY'!F6 -> 2500000
B9: Total | C9: =SUM(C8:C8) -> 2500000 | D9: =SUM(D8:D8) -> 2500000 | H9: =IF(AND(ABS(C9-'Balance Sheet'!C8)<1,ABS(D9-'Balance Sheet'!D8)<1),"Agrees","CHECK") -> Agrees
A12: 2. | B12: Reserves and surplus
B13: Particulars | C13: As at 31-Mar-2026 | D13: As at 31-Mar-2025 | H13: Check (not printed)
B14: Surplus in Statement of Profit and Loss: opening balance | C14: ='Trial Balance Mapping'!F61 -> 4317000 | D14: ='Trial Balance Mapping PY'!F58 -> 1850000
B15: Profit for the year | C15: ='Profit & Loss'!C23 -> 3484401.6 | D15: ='Profit & Loss'!D23 -> 2467000
B16: Total | C16: =SUM(C14:C15) -> 7801401.6 | D16: =SUM(D14:D15) -> 4317000 | H16: =IF(AND(ABS(C16-'Balance Sheet'!C9)<1,ABS(D16-'Balance Sheet'!D9)<1),"Agrees","CHECK") -> Agrees
A19: 3. | B19: Long-term borrowings
B20: Particulars | C20: As at 31-Mar-2026 | D20: As at 31-Mar-2025 | H20: Check (not printed)
B21: Secured Loans
B22: Term Loan - Sample Bank | C22: ='Trial Balance Mapping'!F8 -> 3200000 | D22: ='Trial Balance Mapping PY'!F8 -> 3900000
B23: Unsecured Loans
B24: Loan from Director | C24: ='Trial Balance Mapping'!F7 -> 600000 | D24: ='Trial Balance Mapping PY'!F7 -> 450000
B25: Total | C25: =SUM(C21:C24) -> 3800000 | D25: =SUM(D21:D24) -> 4350000 | H25: =IF(AND(ABS(C25-'Balance Sheet'!C12)<1,ABS(D25-'Balance Sheet'!D12)<1),"Agrees","CHECK") -> Agrees
A28: 4. | B28: Other long-term liabilities and provisions
B29: Particulars | C29: As at 31-Mar-2026 | D29: As at 31-Mar-2025 | H29: Check (not printed)
B30: No balances | C30: 0 | D30: 0
B31: Total | C31: =SUM(C30:C30) -> 0 | D31: =SUM(D30:D30) -> 0 | H31: =IF(AND(ABS(C31-'Balance Sheet'!C13)<1,ABS(D31-'Balance Sheet'!D13)<1),"Agrees","CHECK") -> Agrees
A34: 5. | B34: Short-term borrowings
B35: Particulars | C35: As at 31-Mar-2026 | D35: As at 31-Mar-2025 | H35: Check (not printed)
B36: Cash Credit - Sample Bank | C36: ='Trial Balance Mapping'!F9 -> 1450000 | D36: ='Trial Balance Mapping PY'!F9 -> 1100000
B37: Total | C37: =SUM(C36:C36) -> 1450000 | D37: =SUM(D36:D36) -> 1100000 | H37: =IF(AND(ABS(C37-'Balance Sheet'!C16)<1,ABS(D37-'Balance Sheet'!D16)<1),"Agrees","CHECK") -> Agrees
A40: 6. | B40: Trade payables
B41: Particulars | C41: As at 31-Mar-2026 | D41: As at 31-Mar-2025 | H41: Check (not printed)
B42: Alpha Components Pvt Ltd | C42: ='Trial Balance Mapping'!F10 -> 1380000 | D42: ='Trial Balance Mapping PY'!F10 -> 1190000
B43: Beta Metals Traders | C43: ='Trial Balance Mapping'!F11 -> 920000 | D43: ='Trial Balance Mapping PY'!F11 -> 760000
B44: Gamma Logistics | C44: ='Trial Balance Mapping'!F12 -> 340000 | D44: ='Trial Balance Mapping PY'!F12 -> 280000
B45: Total | C45: =SUM(C42:C44) -> 2640000 | D45: =SUM(D42:D44) -> 2230000 | H45: =IF(AND(ABS(C45-'Balance Sheet'!C17)<1,ABS(D45-'Balance Sheet'!D17)<1),"Agrees","CHECK") -> Agrees
A48: 7. | B48: Other current liabilities
B49: Particulars | C49: As at 31-Mar-2026 | D49: As at 31-Mar-2025 | H49: Check (not printed)
B50: GST Output Payable | C50: ='Trial Balance Mapping'!F13 -> 410000 | D50: ='Trial Balance Mapping PY'!F13 -> 350000
B51: TDS Payable | C51: ='Trial Balance Mapping'!F15 -> 86000 | D51: ='Trial Balance Mapping PY'!F15 -> 71000
B52: PF Payable | C52: ='Trial Balance Mapping'!F14 -> 54000 | D52: ='Trial Balance Mapping PY'!F14 -> 47000
B53: Current Liabilities
B54: Advance from Customers | C54: ='Trial Balance Mapping'!F16 -> 275000 | D54: ='Trial Balance Mapping PY'!F16 -> 120000
...

Sheet Fixed Assets Schedule
A1: Sample Engineering Private Limited
A2: Property, Plant and Equipment: schedule as at 31st March 2026
A3: (Schedule III, Division I - Accounting Standards, Companies Act 2013) | Amounts in Rupees
A6: 9. | B6: Property, Plant and Equipment
B7: Asset class | C7: Gross block as at 31-Mar-2025 | D7: Additions | E7: Deductions | F7: Gross block as at 31-Mar-2026 | G7: Depreciation as at 31-Mar-2025 | H7: For the year | I7: On deductions | J7: Depreciation as at 31-Mar-2026 | K7: Net block as at 31-Mar-2026 | L7: Net block as at 31-Mar-2025
B8: Plant and machinery - general | C8: =SUMIFS('Depreciation Schedule'!$E$11:$E$14,'Depreciation Schedule'!$B$11:$B$14,$B8) -> 6890000 | D8: =SUMIFS('Depreciation Schedule'!$G$11:$G$14,'Depreciation Schedule'!$B$11:$B$14,$B8) -> 700000 | E8: =SUMIFS('Depreciation Schedule'!$I$11:$I$14,'Depreciation Schedule'!$B$11:$B$14,$B8) -> 0 | F8: =C8+D8-E8 -> 7590000 | G8: =SUMIFS('Depreciation Schedule'!$F$11:$F$14,'Depreciation Schedule'!$B$11:$B$14,$B8) -> 1590000 | H8: =SUMIFS('Depreciation Schedule'!$P$11:$P$14,'Depreciation Schedule'!$B$11:$B$14,$B8) -> 471590.41 | I8: =SUMIFS('Depreciation Schedule'!$J$11:$J$14,'Depreciation Schedule'!$B$11:$B$14,$B8)+SUMIFS('Depreciation Schedule'!$O$11:$O$14,'Depreciation Schedule'!$B$11:$B$14,$B8) -> 0 | J8: =G8+H8-I8 -> 2061590.4 | K8: =F8-J8 -> 5528409.6 | L8: =C8-G8 -> 5300000
B9: Furniture and fittings | C9: =SUMIFS('Depreciation Schedule'!$E$11:$E$14,'Depreciation Schedule'!$B$11:$B$14,$B9) -> 474500 | D9: =SUMIFS('Depreciation Schedule'!$G$11:$G$14,'Depreciation Schedule'!$B$11:$B$14,$B9) -> 0 | E9: =SUMIFS('Depreciation Schedule'!$I$11:$I$14,'Depreciation Schedule'!$B$11:$B$14,$B9) -> 0 | F9: =C9+D9-E9 -> 474500 | G9: =SUMIFS('Depreciation Schedule'!$F$11:$F$14,'Depreciation Schedule'!$B$11:$B$14,$B9) -> 109500 | H9: =SUMIFS('Depreciation Schedule'!$P$11:$P$14,'Depreciation Schedule'!$B$11:$B$14,$B9) -> 45077.5 | I9: =SUMIFS('Depreciation Schedule'!$J$11:$J$14,'Depreciation Schedule'!$B$11:$B$14,$B9)+SUMIFS('Depreciation Schedule'!$O$11:$O$14,'Depreciation Schedule'!$B$11:$B$14,$B9) -> 0 | J9: =G9+H9-I9 -> 154577.5 | K9: =F9-J9 -> 319922.5 | L9: =C9-G9 -> 365000
B10: Computers - end-user devices (desktops, laptops) | C10: =SUMIFS('Depreciation Schedule'!$E$11:$E$14,'Depreciation Schedule'!$B$11:$B$14,$B10) -> 192400 | D10: =SUMIFS('Depreciation Schedule'!$G$11:$G$14,'Depreciation Schedule'!$B$11:$B$14,$B10) -> 120000 | E10: =SUMIFS('Depreciation Schedule'!$I$11:$I$14,'Depreciation Schedule'!$B$11:$B$14,$B10) -> 0 | F10: =C10+D10-E10 -> 312400 | G10: =SUMIFS('Depreciation Schedule'!$F$11:$F$14,'Depreciation Schedule'!$B$11:$B$14,$B10) -> 44400 | H10: =SUMIFS('Depreciation Schedule'!$P$11:$P$14,'Depreciation Schedule'!$B$11:$B$14,$B10) -> 79874.61 | I10: =SUMIFS('Depreciation Schedule'!$J$11:$J$14,'Depreciation Schedule'!$B$11:$B$14,$B10)+SUMIFS('Depreciation Schedule'!$O$11:$O$14,'Depreciation Schedule'!$B$11:$B$14,$B10) -> 0 | J10: =G10+H10-I10 -> 124274.61 | K10: =F10-J10 -> 188125.39 | L10: =C10-G10 -> 148000
B11: Motor vehicles - cars | C11: =SUMIFS('Depreciation Schedule'!$E$11:$E$14,'Depreciation Schedule'!$B$11:$B$14,$B11) -> 1170000 | D11: =SUMIFS('Depreciation Schedule'!$G$11:$G$14,'Depreciation Schedule'!$B$11:$B$14,$B11) -> 135000 | E11: =SUMIFS('Depreciation Schedule'!$I$11:$I$14,'Depreciation Schedule'!$B$11:$B$14,$B11) -> 0 | F11: =C11+D11-E11 -> 1305000 | G11: =SUMIFS('Depreciation Schedule'!$F$11:$F$14,'Depreciation Schedule'!$B$11:$B$14,$B11) -> 270000 | H11: =SUMIFS('Depreciation Schedule'!$P$11:$P$14,'Depreciation Schedule'!$B$11:$B$14,$B11) -> 142055.91 | I11: =SUMIFS('Depreciation Schedule'!$J$11:$J$14,'Depreciation Schedule'!$B$11:$B$14,$B11)+SUMIFS('Depreciation Schedule'!$O$11:$O$14,'Depreciation Schedule'!$B$11:$B$14,$B11) -> 0 | J11: =G11+H11-I11 -> 412055.91 | K11: =F11-J11 -> 892944.09 | L11: =C11-G11 -> 900000
B12: Total | C12: =SUM(C8:C11) -> 8726900 | D12: =SUM(D8:D11) -> 955000 | E12: =SUM(E8:E11) -> 0 | F12: =SUM(F8:F11) -> 9681900 | G12: =SUM(G8:G11) -> 2013900 | H12: =SUM(H8:H11) -> 738598.43 | I12: =SUM(I8:I11) -> 0 | J12: =SUM(J8:J11) -> 2752498.4 | ... L12: =SUM(L8:L11) -> 6713000 | N12: Net block less Balance Sheet note | O12: =K12-'Notes - Balance Sheet'!C78 -> 0
B14: Depreciation for the year includes depreciation on assets sold up to the date of sale; it is removed with the accumulated depreciation of those assets under 'On deductions'.
B15: Schedule II, SLM method, residual value 5.0% of cost, 365 days. Additions and disposals are depreciated pro rata by days; depreciation on assets sold runs to the date of sale.

Sheet Notes - Profit and Loss
A1: Sample Engineering Private Limited
A2: Notes forming part of the Financial Statements for the year ended 31st March 2026
A3: (Schedule III, Division I - Accounting Standards, Companies Act 2013) | Amounts in Rupees
A6: 17. | B6: Revenue from operations
B7: Particulars | C7: Year ended 31-Mar-2026 | D7: Year ended 31-Mar-2025 | H7: Check (not printed)
B8: Sales - Products | C8: ='Trial Balance Mapping'!F37 -> 17800000 | D8: ='Trial Balance Mapping PY'!F35 -> 15200000
B9: Sales - Services | C9: ='Trial Balance Mapping'!F38 -> 2600000 | D9: ='Trial Balance Mapping PY'!F36 -> 2100000
B10: Total | C10: =SUM(C8:C9) -> 20400000 | D10: =SUM(D8:D9) -> 17300000 | H10: =IF(AND(ABS(C10-'Profit & Loss'!C6)<1,ABS(D10-'Profit & Loss'!D6)<1),"Agrees","CHECK") -> Agrees
A13: 18. | B13: Other income
B14: Particulars | C14: Year ended 31-Mar-2026 | D14: Year ended 31-Mar-2025 | H14: Check (not printed)
B15: Interest Received | C15: ='Trial Balance Mapping'!F40 -> 64000 | D15: ='Trial Balance Mapping PY'!F38 -> 52000
B16: Discount Received | C16: ='Trial Balance Mapping'!F39 -> 22000 | D16: ='Trial Balance Mapping PY'!F37 -> 18000
B17: Total | C17: =SUM(C15:C16) -> 86000 | D17: =SUM(D15:D16) -> 70000 | H17: =IF(AND(ABS(C17-'Profit & Loss'!C7)<1,ABS(D17-'Profit & Loss'!D7)<1),"Agrees","CHECK") -> Agrees
A20: 19. | B20: Purchases of stock-in-trade
B21: Particulars | C21: Year ended 31-Mar-2026 | D21: Year ended 31-Mar-2025 | H21: Check (not printed)
B22: Purchase of Raw Materials | C22: ='Trial Balance Mapping'!F41 -> 9600000 | D22: ='Trial Balance Mapping PY'!F39 -> 8300000
B23: Total | C23: =SUM(C22:C22) -> 9600000 | D23: =SUM(D22:D22) -> 8300000 | H23: =IF(AND(ABS(C23-'Profit & Loss'!C11)<1,ABS(D23-'Profit & Loss'!D11)<1),"Agrees","CHECK") -> Agrees
A26: 20. | B26: Changes in inventories of stock-in-trade
B27: Particulars | C27: Year ended 31-Mar-2026 | D27: Year ended 31-Mar-2025 | H27: Check (not printed)
B28: Opening Stock | C28: ='Trial Balance Mapping'!F26 -> 1900000 | D28: ='Trial Balance Mapping PY'!F24 -> 1500000
B29: Less: Closing stock | C29: =-'Trial Balance Mapping'!$F$62 -> -2250000 | D29: =-'Trial Balance Mapping PY'!$F$59 -> -1900000
B30: Total | C30: =SUM(C28:C29) -> -350000 | D30: =SUM(D28:D29) -> -400000 | H30: =IF(AND(ABS(C30-'Profit & Loss'!C12)<1,ABS(D30-'Profit & Loss'!D12)<1),"Agrees","CHECK") -> Agrees
A33: 21. | B33: Employee benefits expense
B34: Particulars | C34: Year ended 31-Mar-2026 | D34: Year ended 31-Mar-2025 | H34: Check (not printed)
B35: Salaries and Wages | C35: ='Trial Balance Mapping'!F43 -> 3250000 | D35: ='Trial Balance Mapping PY'!F41 -> 2800000
B36: PF Employer Contribution | C36: ='Trial Balance Mapping'!F42 -> 310000 | D36: ='Trial Balance Mapping PY'!F40 -> 270000
B37: Staff Welfare | C37: ='Trial Balance Mapping'!F44 -> 120000 | D37: ='Trial Balance Mapping PY'!F42 -> 98000
B38: Total | C38: =SUM(C35:C37) -> 3680000 | D38: =SUM(D35:D37) -> 3168000 | H38: =IF(AND(ABS(C38-'Profit & Loss'!C13)<1,ABS(D38-'Profit & Loss'!D13)<1),"Agrees","CHECK") -> Agrees
A41: 22. | B41: Finance costs
B42: Particulars | C42: Year ended 31-Mar-2026 | D42: Year ended 31-Mar-2025 | H42: Check (not printed)
B43: Interest on Term Loan | C43: ='Trial Balance Mapping'!F46 -> 380000 | D43: ='Trial Balance Mapping PY'!F44 -> 450000
B44: Interest on Cash Credit | C44: ='Trial Balance Mapping'!F45 -> 165000 | D44: ='Trial Balance Mapping PY'!F43 -> 130000
B45: Total | C45: =SUM(C43:C44) -> 545000 | D45: =SUM(D43:D44) -> 580000 | H45: =IF(AND(ABS(C45-'Profit & Loss'!C14)<1,ABS(D45-'Profit & Loss'!D14)<1),"Agrees","CHECK") -> Agrees
A48: 23. | B48: Depreciation and amortisation expense
B49: Particulars | C49: Year ended 31-Mar-2026 | D49: Year ended 31-Mar-2025 | H49: Check (not printed)
B50: Depreciation calculator
B51: Depreciation per calculator - difference to books (expense) | C51: ='Trial Balance Mapping'!F48 -> 38598.43 | D51: 0
B52: Indirect Expenses
B53: Depreciation | C53: ='Trial Balance Mapping'!F47 -> 700000 | D53: ='Trial Balance Mapping PY'!F45 -> 820000
B54: Total | C54: =SUM(C50:C53) -> 738598.43 | D54: =SUM(D50:D53) -> 820000 | H54: =IF(AND(ABS(C54-'Profit & Loss'!C15)<1,ABS(D54-'Profit & Loss'!D15)<1),"Agrees","CHECK") -> Agrees
...

Sheet Notes - Ratios
A1: Sample Engineering Private Limited
A2: Notes forming part of the Financial Statements for the year ended 31st March 2026
A3: (Schedule III, Division I - Accounting Standards, Companies Act 2013) | Amounts in Rupees
A6: 27. | B6: Analytical ratios
B7: Ratio | C7: Numerator | D7: Denominator | E7: Current year | F7: Previous year | G7: % variance
B8: Current ratio (times) | C8: Current assets | D8: Current liabilities | E8: =IFERROR('Balance Sheet'!C35/'Balance Sheet'!C20,"n.a.") -> 2.3099543 | F8: =IFERROR('Balance Sheet'!D35/'Balance Sheet'!D20,"n.a.") -> 2.0326919 | G8: =IFERROR((E8-F8)/ABS(F8)*100,"n.a.") -> 13.640163
B9: Debt-equity ratio (times) | C9: Total borrowings | D9: Shareholders' funds | E9: =IFERROR(('Balance Sheet'!C12+'Balance Sheet'!C16)/'Balance Sheet'!C10,"n.a.") -> 0.50963939 | F9: =IFERROR(('Balance Sheet'!D12+'Balance Sheet'!D16)/'Balance Sheet'!D10,"n.a.") -> 0.79947191 | G9: =IFERROR((E9-F9)/ABS(F9)*100,"n.a.") -> -36.252996
B10: Return on equity (%) | C10: Profit for the year | D10: Average shareholders' funds | E10: =IFERROR('Profit & Loss'!C23/AVERAGE('Balance Sheet'!C10,'Balance Sheet'!D10)*100,"n.a.") -> 40.709427 | F10: =IFERROR('Profit & Loss'!D23/'Balance Sheet'!D10*100,"n.a.") -> 36.188939 | G10: =IFERROR((E10-F10)/ABS(F10)*100,"n.a.") -> 12.491351
B11: Inventory turnover (times) | C11: Cost of goods sold | D11: Average inventories | E11: =IFERROR(('Profit & Loss'!C11+'Profit & Loss'!C12)/AVERAGE('Balance Sheet'!C30,'Balance Sheet'!D30),"n.a.") -> 4.4578313 | F11: =IFERROR(('Profit & Loss'!D11+'Profit & Loss'!D12)/'Balance Sheet'!D30,"n.a.") -> 4.1578947 | G11: =IFERROR((E11-F11)/ABS(F11)*100,"n.a.") -> 7.2136648
B12: Trade receivables turnover (times) | C12: Revenue from operations | D12: Average trade receivables | E12: =IFERROR('Profit & Loss'!C6/AVERAGE('Balance Sheet'!C31,'Balance Sheet'!D31),"n.a.") -> 4.7663551 | F12: =IFERROR('Profit & Loss'!D6/'Balance Sheet'!D31,"n.a.") -> 4.4473008 | G12: =IFERROR((E12-F12)/ABS(F12)*100,"n.a.") -> 7.1741127
B13: Trade payables turnover (times) | C13: Purchases | D13: Average trade payables | E13: =IFERROR('Profit & Loss'!C11/AVERAGE('Balance Sheet'!C17,'Balance Sheet'!D17),"n.a.") -> 3.9425051 | F13: =IFERROR('Profit & Loss'!D11/'Balance Sheet'!D17,"n.a.") -> 3.7219731 | G13: =IFERROR((E13-F13)/ABS(F13)*100,"n.a.") -> 5.9251379
B14: Net capital turnover (times) | C14: Revenue from operations | D14: Average working capital | E14: =IFERROR('Profit & Loss'!C6/AVERAGE('Balance Sheet'!C35-'Balance Sheet'!C20,'Balance Sheet'!D35-'Balance Sheet'!D20),"n.a.") -> 3.5093755 | F14: =IFERROR('Profit & Loss'!D6/('Balance Sheet'!D35-'Balance Sheet'!D20),"n.a.") -> 3.8841491 | G14: =IFERROR((E14-F14)/ABS(F14)*100,"n.a.") -> -9.648794
B15: Net profit ratio (%) | C15: Profit for the year | D15: Revenue from operations | E15: =IFERROR('Profit & Loss'!C23/'Profit & Loss'!C6*100,"n.a.") -> 17.0804 | F15: =IFERROR('Profit & Loss'!D23/'Profit & Loss'!D6*100,"n.a.") -> 14.260116 | G15: =IFERROR((E15-F15)/ABS(F15)*100,"n.a.") -> 19.777429
B16: Return on capital employed (%) | C16: Profit before tax + finance costs | D16: Capital employed | E16: =IFERROR(('Profit & Loss'!C21+'Profit & Loss'!C14)/('Balance Sheet'!C10+'Balance Sheet'!C12+'Balance Sheet'!C16)*100,"n.a.") -> 25.910215 | F16: =IFERROR(('Profit & Loss'!D21+'Profit & Loss'!D14)/('Balance Sheet'!D10+'Balance Sheet'!D12+'Balance Sheet'!D16)*100,"n.a.") -> 24.838999 | G16: =IFERROR((E16-F16)/ABS(F16)*100,"n.a.") -> 4.3126375

Sheet Trial Balance Mapping
A1: Sample Engineering Private Limited
A2: Ledger-to-statement mapping (01-Apr-2025 to 31-Mar-2026) | Source: Tally Prime / uploaded trial balance
A3: Sign: -1 for Dr-natured heads (assets, expenses), +1 for Cr-natured heads (capital, liabilities, income).
A5: Ledger | B5: Tally Group | C5: Statement Head | D5: Sign | E5: Closing Balance | F5: Presented Amount | G5: Dr / Cr
A6: Equity Share Capital | B6: Capital Account | C6: Share Capital | D6: 1 | E6: 2500000 | F6: =E6*D6 -> 2500000 | G6: =IF(E6<0,"Dr","Cr") -> Cr
A7: Loan from Director | B7: Unsecured Loans | C7: Long-term Borrowings | D7: 1 | E7: 600000 | F7: =E7*D7 -> 600000 | G7: =IF(E7<0,"Dr","Cr") -> Cr
A8: Term Loan - Sample Bank | B8: Secured Loans | C8: Long-term Borrowings | D8: 1 | E8: 3200000 | F8: =E8*D8 -> 3200000 | G8: =IF(E8<0,"Dr","Cr") -> Cr
A9: Cash Credit - Sample Bank | B9: Bank OD A/c | C9: Short-term Borrowings | D9: 1 | E9: 1450000 | F9: =E9*D9 -> 1450000 | G9: =IF(E9<0,"Dr","Cr") -> Cr
A10: Alpha Components Pvt Ltd | B10: Sundry Creditors | C10: Trade Payables | D10: 1 | E10: 1380000 | F10: =E10*D10 -> 1380000 | G10: =IF(E10<0,"Dr","Cr") -> Cr
A11: Beta Metals Traders | B11: Sundry Creditors | C11: Trade Payables | D11: 1 | E11: 920000 | F11: =E11*D11 -> 920000 | G11: =IF(E11<0,"Dr","Cr") -> Cr
A12: Gamma Logistics | B12: Sundry Creditors | C12: Trade Payables | D12: 1 | E12: 340000 | F12: =E12*D12 -> 340000 | G12: =IF(E12<0,"Dr","Cr") -> Cr
A13: GST Output Payable | B13: Duties & Taxes | C13: Other Current Liabilities (Statutory Dues) | D13: 1 | E13: 410000 | F13: =E13*D13 -> 410000 | G13: =IF(E13<0,"Dr","Cr") -> Cr
A14: PF Payable | B14: Duties & Taxes | C14: Other Current Liabilities (Statutory Dues) | D14: 1 | E14: 54000 | F14: =E14*D14 -> 54000 | G14: =IF(E14<0,"Dr","Cr") -> Cr
A15: TDS Payable | B15: Duties & Taxes | C15: Other Current Liabilities (Statutory Dues) | D15: 1 | E15: 86000 | F15: =E15*D15 -> 86000 | G15: =IF(E15<0,"Dr","Cr") -> Cr
A16: Advance from Customers | B16: Current Liabilities | C16: Other Current Liabilities | D16: 1 | E16: 275000 | F16: =E16*D16 -> 275000 | G16: =IF(E16<0,"Dr","Cr") -> Cr
A17: Audit Fee Payable | B17: Current Liabilities | C17: Other Current Liabilities | D17: 1 | E17: 60000 | F17: =E17*D17 -> 60000 | G17: =IF(E17<0,"Dr","Cr") -> Cr
... A60: Travelling Expenses | B60: Indirect Expenses | C60: Other Expenses | D60: -1 | E60: -238000 | F60: =E60*D60 -> 238000 | G60: =IF(E60<0,"Dr","Cr") -> Dr
A61: Opening reserves (derived: balancing figure of the ledgers above) | B61: Profit & Loss A/c | C61: Reserves and Surplus | D61: 1 | E61: =-SUM(E6:E60) -> 4317000 | F61: =E61*D61 -> 4317000 | G61: =IF(E61<0,"Dr","Cr") -> Cr
A62: Closing stock (from Stock Summary / derived; not a Tally ledger) | B62: Stock-in-trade | C62: Inventories | D62: -1 | E62: -2250000 | F62: =E62*D62 -> 2250000 | G62: =IF(E62<0,"Dr","Cr") -> Dr
A64: Income-tax provision for the year (entered in the application; not computed) | F64: 0
A66: Check: sum of ledger closing balances above (excl. P&L A/c). Its negative is the opening reserves. | E66: =SUM(E6:E60) -> -4317000
A67: Memo: Profit & Loss A/c ledger closing balance (credit; not in totals) | E67: 7840000
A68: Check: P&L A/c ledger = opening reserves + profit before tax (+ calculator adjustment) | F68: =IF(ABS(E67-(F61+'Profit & Loss'!C21-SUMIFS('Trial Balance Mapping'!$F$6:$F$62,'Trial Balance Mapping'!$C$6:$C$62,"Tax Expense")+SUMIFS('Trial Balance Mapping'!$F$6:$F$62,'Trial Balance Mapping'!$C$6:$C$62,"Depreciation & Amortisation",'Trial Balance Mapping'!$B$6:$B$62,"Depreciation calculator")))<1,"OK",IF(ABS(E67-F61)<1,"OK (opening only)","CHECK")) -> OK

Sheet Trial Balance Mapping PY
A1: Sample Engineering Private Limited
A2: Ledger-to-statement mapping (01-Apr-2024 to 31-Mar-2025) | Source: Tally Prime / uploaded trial balance
A3: Sign: -1 for Dr-natured heads (assets, expenses), +1 for Cr-natured heads (capital, liabilities, income).
A5: Ledger | B5: Tally Group | C5: Statement Head | D5: Sign | E5: Closing Balance | F5: Presented Amount | G5: Dr / Cr
A6: Equity Share Capital | B6: Capital Account | C6: Share Capital | D6: 1 | E6: 2500000 | F6: =E6*D6 -> 2500000 | G6: =IF(E6<0,"Dr","Cr") -> Cr
A7: Loan from Director | B7: Unsecured Loans | C7: Long-term Borrowings | D7: 1 | E7: 450000 | F7: =E7*D7 -> 450000 | G7: =IF(E7<0,"Dr","Cr") -> Cr
A8: Term Loan - Sample Bank | B8: Secured Loans | C8: Long-term Borrowings | D8: 1 | E8: 3900000 | F8: =E8*D8 -> 3900000 | G8: =IF(E8<0,"Dr","Cr") -> Cr
A9: Cash Credit - Sample Bank | B9: Bank OD A/c | C9: Short-term Borrowings | D9: 1 | E9: 1100000 | F9: =E9*D9 -> 1100000 | G9: =IF(E9<0,"Dr","Cr") -> Cr
A10: Alpha Components Pvt Ltd | B10: Sundry Creditors | C10: Trade Payables | D10: 1 | E10: 1190000 | F10: =E10*D10 -> 1190000 | G10: =IF(E10<0,"Dr","Cr") -> Cr
A11: Beta Metals Traders | B11: Sundry Creditors | C11: Trade Payables | D11: 1 | E11: 760000 | F11: =E11*D11 -> 760000 | G11: =IF(E11<0,"Dr","Cr") -> Cr
A12: Gamma Logistics | B12: Sundry Creditors | C12: Trade Payables | D12: 1 | E12: 280000 | F12: =E12*D12 -> 280000 | G12: =IF(E12<0,"Dr","Cr") -> Cr
A13: GST Output Payable | B13: Duties & Taxes | C13: Other Current Liabilities (Statutory Dues) | D13: 1 | E13: 350000 | F13: =E13*D13 -> 350000 | G13: =IF(E13<0,"Dr","Cr") -> Cr
A14: PF Payable | B14: Duties & Taxes | C14: Other Current Liabilities (Statutory Dues) | D14: 1 | E14: 47000 | F14: =E14*D14 -> 47000 | G14: =IF(E14<0,"Dr","Cr") -> Cr
A15: TDS Payable | B15: Duties & Taxes | C15: Other Current Liabilities (Statutory Dues) | D15: 1 | E15: 71000 | F15: =E15*D15 -> 71000 | G15: =IF(E15<0,"Dr","Cr") -> Cr
A16: Advance from Customers | B16: Current Liabilities | C16: Other Current Liabilities | D16: 1 | E16: 120000 | F16: =E16*D16 -> 120000 | G16: =IF(E16<0,"Dr","Cr") -> Cr
A17: Audit Fee Payable | B17: Current Liabilities | C17: Other Current Liabilities | D17: 1 | E17: 50000 | F17: =E17*D17 -> 50000 | G17: =IF(E17<0,"Dr","Cr") -> Cr
... A57: Travelling Expenses | B57: Indirect Expenses | C57: Other Expenses | D57: -1 | E57: -196000 | F57: =E57*D57 -> 196000 | G57: =IF(E57<0,"Dr","Cr") -> Dr
A58: Opening reserves (derived: balancing figure of the ledgers above) | B58: Profit & Loss A/c | C58: Reserves and Surplus | D58: 1 | E58: =-SUM(E6:E57) -> 1850000 | F58: =E58*D58 -> 1850000 | G58: =IF(E58<0,"Dr","Cr") -> Cr
A59: Closing stock (from Stock Summary / derived; not a Tally ledger) | B59: Stock-in-trade | C59: Inventories | D59: -1 | E59: -1900000 | F59: =E59*D59 -> 1900000 | G59: =IF(E59<0,"Dr","Cr") -> Dr
A61: Income-tax provision for the year (entered in the application; not computed) | F61: 0
A63: Check: sum of ledger closing balances above (excl. P&L A/c). Its negative is the opening reserves. | E63: =SUM(E6:E57) -> -1850000
A64: Memo: Profit & Loss A/c ledger closing balance (credit; not in totals) | E64: 4317000
A65: Check: P&L A/c ledger = opening reserves + profit before tax (+ calculator adjustment) | F65: =IF(ABS(E64-(F58+'Profit & Loss'!D21-SUMIFS('Trial Balance Mapping PY'!$F$6:$F$59,'Trial Balance Mapping PY'!$C$6:$C$59,"Tax Expense")+SUMIFS('Trial Balance Mapping PY'!$F$6:$F$59,'Trial Balance Mapping PY'!$C$6:$C$59,"Depreciation & Amortisation",'Trial Balance Mapping PY'!$B$6:$B$59,"Depreciation calculator")))<1,"OK",IF(ABS(E64-F58)<1,"OK (opening only)","CHECK")) -> OK

Sheet Depreciation Schedule
A1: Sample Engineering Private Limited
A2: Depreciation schedule - Schedule II, Companies Act 2013
A3: Inputs (blue) are editable; the depreciation columns are formulas.
A4: Method | C4: SLM
A5: Residual value (% of cost) | C5: 5
A6: Days in the year | C6: =C8-C7+1 -> 365
A7: Period start | C7: 45748
A8: Period end | C8: 46112
A10: Tally ledger | B10: Asset class | C10: Useful life (years) | D10: Remaining life override (years) | E10: Opening gross block | F10: Opening accumulated depreciation | G10: Additions (cost) | H10: Date put to use (additions) | I10: Disposals (original cost) | J10: Accumulated depreciation on disposals | K10: Sale proceeds | L10: Date of sale | M10: Days in use (additions) | N10: Days in use (disposals) | O10: Depreciation on assets sold | P10: Depreciation for the year | Q10: Closing gross block | R10: Closing accumulated depreciation | S10: Closing net block | T10: Profit / (loss) on disposal
A11: Plant and Machinery | B11: Plant and machinery - general | C11: 15 | D11: 0 | E11: 6890000 | F11: 1590000 | G11: 700000 | H11: 45823 | I11: 0 | J11: 0 | K11: 0 | M11: =IF(OR(G11=0,H11=""),0,MAX(0,MIN($C$6,$C$8-H11+1))) -> 290 | N11: =IF(OR(I11=0,L11=""),0,MAX(0,MIN($C$6,L11-$C$7+1))) -> 0 | O11: =IF(C11<=0,0,MIN(I11*((1-($C$5/100))/C11)*N11/$C$6,MAX(0,I11*(1-($C$5/100))-J11))) -> 0 | P11: =IF(C11<=0,0,ROUND(MAX(0,IF(D11>0,MIN(MAX(0,(E11-I11)-(F11-J11)-(E11-I11)*($C$5/100))/D11,MAX(0,(E11-I11)-(F11-J11)-(E11-I11)*($C$5/100))),MIN((E11-I11)*((1-($C$5/100))/C11),MAX(0,(E11-I11)*(1-($C$5/100))-(F11-J11))))+O11+G11*((1-($C$5/100))/C11)*M11/$C$6),2)) -> 471590.41 | Q11: =E11+G11-I11 -> 7590000 | R11: =F11-J11+P11-O11 -> 2061590.4 | S11: =Q11-R11 -> 5528409.6 | T11: =IF(I11>0,K11-((I11-J11)-O11),0) -> 0
A12: Furniture and Fixtures | B12: Furniture and fittings | C12: 10 | D12: 0 | E12: 474500 | F12: 109500 | G12: 0 | I12: 0 | J12: 0 | K12: 0 | M12: =IF(OR(G12=0,H12=""),0,MAX(0,MIN($C$6,$C$8-H12+1))) -> 0 | N12: =IF(OR(I12=0,L12=""),0,MAX(0,MIN($C$6,L12-$C$7+1))) -> 0 | O12: =IF(C12<=0,0,MIN(I12*((1-($C$5/100))/C12)*N12/$C$6,MAX(0,I12*(1-($C$5/100))-J12))) -> 0 | P12: =IF(C12<=0,0,ROUND(MAX(0,IF(D12>0,MIN(MAX(0,(E12-I12)-(F12-J12)-(E12-I12)*($C$5/100))/D12,MAX(0,(E12-I12)-(F12-J12)-(E12-I12)*($C$5/100))),MIN((E12-I12)*((1-($C$5/100))/C12),MAX(0,(E12-I12)*(1-($C$5/100))-(F12-J12))))+O12+G12*((1-($C$5/100))/C12)*M12/$C$6),2)) -> 45077.5 | Q12: =E12+G12-I12 -> 474500 | R12: =F12-J12+P12-O12 -> 154577.5 | S12: =Q12-R12 -> 319922.5 | T12: =IF(I12>0,K12-((I12-J12)-O12),0) -> 0
A13: Computers and Printers | B13: Computers - end-user devices (desktops, laptops) | C13: 3 | D13: 0 | E13: 192400 | F13: 44400 | G13: 120000 | H13: 45931 | I13: 0 | J13: 0 | K13: 0 | M13: =IF(OR(G13=0,H13=""),0,MAX(0,MIN($C$6,$C$8-H13+1))) -> 182 | N13: =IF(OR(I13=0,L13=""),0,MAX(0,MIN($C$6,L13-$C$7+1))) -> 0 | O13: =IF(C13<=0,0,MIN(I13*((1-($C$5/100))/C13)*N13/$C$6,MAX(0,I13*(1-($C$5/100))-J13))) -> 0 | P13: =IF(C13<=0,0,ROUND(MAX(0,IF(D13>0,MIN(MAX(0,(E13-I13)-(F13-J13)-(E13-I13)*($C$5/100))/D13,MAX(0,(E13-I13)-(F13-J13)-(E13-I13)*($C$5/100))),MIN((E13-I13)*((1-($C$5/100))/C13),MAX(0,(E13-I13)*(1-($C$5/100))-(F13-J13))))+O13+G13*((1-($C$5/100))/C13)*M13/$C$6),2)) -> 79874.61 | Q13: =E13+G13-I13 -> 312400 | R13: =F13-J13+P13-O13 -> 124274.61 | S13: =Q13-R13 -> 188125.39 | T13: =IF(I13>0,K13-((I13-J13)-O13),0) -> 0
A14: Vehicles | B14: Motor vehicles - cars | C14: 8 | D14: 0 | E14: 1170000 | F14: 270000 | G14: 135000 | H14: 46042 | I14: 0 | J14: 0 | K14: 0 | M14: =IF(OR(G14=0,H14=""),0,MAX(0,MIN($C$6,$C$8-H14+1))) -> 71 | N14: =IF(OR(I14=0,L14=""),0,MAX(0,MIN($C$6,L14-$C$7+1))) -> 0 | O14: =IF(C14<=0,0,MIN(I14*((1-($C$5/100))/C14)*N14/$C$6,MAX(0,I14*(1-($C$5/100))-J14))) -> 0 | P14: =IF(C14<=0,0,ROUND(MAX(0,IF(D14>0,MIN(MAX(0,(E14-I14)-(F14-J14)-(E14-I14)*($C$5/100))/D14,MAX(0,(E14-I14)-(F14-J14)-(E14-I14)*($C$5/100))),MIN((E14-I14)*((1-($C$5/100))/C14),MAX(0,(E14-I14)*(1-($C$5/100))-(F14-J14))))+O14+G14*((1-($C$5/100))/C14)*M14/$C$6),2)) -> 142055.91 | Q14: =E14+G14-I14 -> 1305000 | R14: =F14-J14+P14-O14 -> 412055.91 | S14: =Q14-R14 -> 892944.09 | T14: =IF(I14>0,K14-((I14-J14)-O14),0) -> 0
A15: Total | E15: =SUM(E11:E14) -> 8726900 | F15: =SUM(F11:F14) -> 2013900 | G15: =SUM(G11:G14) -> 955000 | I15: =SUM(I11:I14) -> 0 | J15: =SUM(J11:J14) -> 0 | K15: =SUM(K11:K14) -> 0 | O15: =SUM(O11:O14) -> 0 | P15: =SUM(P11:P14) -> 738598.43 | Q15: =SUM(Q11:Q14) -> 9681900 | R15: =SUM(R11:R14) -> 2752498.4 | S15: =SUM(S11:S14) -> 6929401.6 | T15: =SUM(T11:T14) -> 0
A17: Depreciation per calculator | C17: =P15 -> 738598.43
A18: Booked in Tally (ledgers under Depreciation & Amortisation) | C18: =SUMIFS('Trial Balance Mapping'!$F$6:$F$62,'Trial Balance Mapping'!$C$6:$C$62,"Depreciation & Amortisation",'Trial Balance Mapping'!$B$6:$B$62,"<>Depreciation calculator") -> 700000
A19: Difference (calculator less books) | C19: =C17-C18 -> 38598.43
A20: Adjustment carried in the statements (mapping sheet) | C20: =SUMIFS('Trial Balance Mapping'!$F$6:$F$62,'Trial Balance Mapping'!$C$6:$C$62,"Depreciation & Amortisation",'Trial Balance Mapping'!$B$6:$B$62,"Depreciation calculator") -> 38598.43
A21: Status | C21: =IF(ABS(C19)<0.5,"Books agree to calculator",IF(ABS(C19-C20)<0.5,"Applied to statements","NOT applied to statements")) -> Applied to statements
A23: Fixed assets per inputs, before this year's depreciation (opening + additions - disposals, net) | C23: =E15-F15+G15-(I15-J15) -> 7668000
A24: Fixed assets per Tally before this calculator + depreciation booked in Tally | C24: =SUMIFS('Trial Balance Mapping'!$F$6:$F$62,'Trial Balance Mapping'!$C$6:$C$62,"Property, Plant & Equipment",'Trial Balance Mapping'!$B$6:$B$62,"<>Depreciation calculator")+C18 -> 7668000
A25: Unexplained difference (should be nil when the inputs are complete) | C25: =C23-C24 -> 0
A27: Basis: Schedule II, SLM method, residual value 5.0% of cost, 365 days. Additions and disposals are depreciated pro rata by days; depreciation on assets sold runs to the date of sale.
