Workbook

Sheet Points to check
A1: Royal Orchid | K1: =35/2000 -> 0.0175
A3: Issues | D3: Strength | K3: 35000000
A4: 1 | B4: Case filed by Kamat hotels for use of its Brand name | D4: 1 | K4: =K3*13 -> 455000000
A5: =A4+1 -> 2 | B5: Increase in salary of chairmand by 15% despite no major performance of the company (AR 2019-20)- Salary Rs 2.73 crores | D5: =D4+1 -> 2 | K5: =K3*600 -> 21000000000
A6: =A5+1 -> 3 | B6: Loan from related party of Rs 1.05 crores @18% (AR 2019-20) | D6: 3 | K6: =K4/K5 -> 0.021666667
A7: =A6+1 -> 4 | B7: Complex ownership structure with multiple subsidiaries and risk in impairment in valueof investments | D7: =D6+1 -> 4
A8: =A7+1 -> 5 | D8: =D7+1 -> 5
A10: Threats | D10: Opportunities
A11: 1 | B11: Case filed by Kamat hotels for use of its Brand name | D11: 1 | E11: Indian domestic tourism to touch 2.8 bn by 2022 (AR 2019-20)
A12: =A11+1 -> 2 | B12: Age of promoter CK Baljee ( around 74), though younger family members have joined | D12: =D11+1 -> 2 | E12: Tourism sector to touch USD 460 bn by 2028
A13: =A12+1 -> 3 | D13: 3
A14: =A13+1 -> 4 | D14: =D13+1 -> 4
A15: =A14+1 -> 5 | D15: =D14+1 -> 5
D16: =D15+1 -> 6
A17: Revenue model
A18: 1 | B18: JV, leased and owned
A19: =A18+1 -> 2 | B19: Mangement contracts
A23: Other points
A24: 1 | B24: Total employees 1079 and contractual : 287
A26: Questions
A27: 1 | B27: Check subsidiaries balance sheet for any potential dimmuniation in value of investment and also loans given to subsidiaries
B28: a) Impairment of Rs 6 crores in subsidiaries in AR 2020-21
A29: =A27+1 -> 2 | B29: Recheck - other expenses details growth year on year
A30: =A29+1 -> 3 | B30: What is FD held for trade payable in FY 2019-20
A31: =A30+1 -> 4 | B31: Understand note 50 related to bifurcation of total assets in consolidated FS ( AR 2019-20)
A32: =A31+1 -> 5 | B32: Check status of "Ksheer Sagar Developers Private Limited" which has accumulated losses of around 60 crores as on March 31, 2022

Sheet Quarterly call
A1: Royal Orchid | D1: Check quarterly
A3: Q-2 - FY 2023-24 | E3: Hotel growth | F3: Hotels | G3: Keys
E4: FY 2019-20 | F4: 60 | G4: 4000
A5: S.No. | C5: Actual | E5: FY 2020-21 | F5: 70
A6: 1 | B6: Decrease in profits due to incresae in a) payroll cost, b) electrcity and gas expenses | E6: FY 2021-22 | F6: 75 | G6: 4600
A7: =A6+1 -> 2 | B7: 10-15% increase inn food and beverages business | E7: FY 2022-23 | F7: 95 | G7: 5600
A8: =A7+1 -> 3 | B8: a) Average room rate (JLO) - Rs 5,087 , average occupancy : 73% b) Average room rate (managed) - Rs 3,747, average occupancy : 54%
A9: =A8+1 -> 4 | B9: Revenue guidance of around 375 crores in FY 2023-24 | C9: 313 crores, 340 crores including jaipur
A10: =A9+1 -> 5 | B10: Revenue increase of 25 to 30% per annum
A11: =A10+1 -> 6 | B11: Negative point related to debentures and related party loan @ 14%
A13: Q-3 - FY 2023-24
A15: 1 | B15: a) Average room rate (JLO) - Rs 5,656 , average occupancy : 76% b) Average room rate (managed) - Rs 4,184, average occupancy : 63%
A16: =A15+1 -> 2 | B16: Total Keys : 5795
A17: =A16+1 -> 3 | B17: Renovation in Bangalore and goa
A20: Q-1 - FY 2024-25
A21: 1 | B21: Revenue guidance of around 375 crores in FY 2024-25 Rs 500 crores in fy 2025-26
A22: =A21+1 -> 2 | B22: Room renovations to continue till December 2024
A23: =A22+1 -> 3 | B23: Target to hit 200 hotels by Feb 2026, 100 crores PAT
A24: =A23+1 -> 4 | B24: Mumbai will be 300 room hotel and surat 288 room hotel
A25: =A24+1 -> 5

Sheet Summary
A1: Endurance Technologies
A3: S.No. | B3: Particulars
A4: 1 | B4: Quantitative Analysis
A5: a) | B5: Financials_Consol
B6: Financials_Standalone!A1
A8: b) | B8: Common Size Analysis - BS Conso
B9: Common Size Analysis - BS'!A1
A11: c) | B11: Common Size Analysis - PL Conso
B12: Common Size Analysis - PL'!A1
A14: d) | B14: Common Size Analysis - CFS Conso
B15: Common Size Analysis - CFS'!A1
A17: e) | B17: Ratio Analysis Conso
B18: Ratio Analysis'!A1
A20: f) | B20: Valuation Models DCF Conso
B21: Valuation Models DCF'!A1
A23: I | B23: Do reverse DCF to understand how stock market is valuing the company
A24: II | B24: Growth rate not above 20% in first 5 years and 10% for next 5 years
A25: III | B25: Terminal growth rate not above 2%
A26: IV | B26: Discount rate 12 % for stable companies and 15% for growth companies
A27: V | B27: Intrinsic value - share price should be 50-60% of Intrinsic value (MOS) | C27: Conso | D27: ='Valuation Models DCF_Conso'!$G$24 -> 0.23959941
C28: Standalone | D28: ='Valuation Models DCF'!$G$23 -> 0.42987019
A29: g) | B29: Valuation Models Residual eanin
A30: h) | B30: Valuation Models EPV
A31: i) | B31: Relative valuation Models (page 3, page 11 of module 41)
A33: =A4+1 -> 2 | B33: Read 5 years annual reports (module 21)
A34: a) | B34: Financials along with ratios and quantitative
A35: b) | B35: Chairman letter
A36: c) | B36: Financial results and highlights
A37: d) | B37: Segment revenue
A38: e) | B38: Director report
A39: f) | B39: Management discussion and analysis
A40: g) | B40: Reserves reconciliation
A42: =A33+1 -> 3 | B42: Notes inconsistencies in ratios - Module 26, 27 , 28
A43: a) | B43: Inventory high or low reason | C43: Ratio Analysis_Conso'!A1
A44: b) | B44: DTR- high or low reason | C44: Ratio Analysis'!A1
A45: c) | B45: Check current and quick ratio with inventory turnover ratio
A46: d) | B46: Compare ratio with competitors
A47: e) | B47: Page 6 - Module 27
A49: =A42+1 -> 4 | B49: Cash flow analysis
A50: a) | B50: Analyse where cash is generated and used in last 3-5 years
...

Sheet SWOT
A1: Endurance Technologies | E1: To check
E2: 1
A3: Strength | C3: Weakness | E3: =E2+1 -> 2
A4: 1 | C4: 1 | E4: 3
A5: =A4+1 -> 2 | E5: =E4+1 -> 4
A6: 3 | E6: =E5+1 -> 5
A7: =A6+1 -> 4 | E7: 6
A8: =A7+1 -> 5 | E8: =E7+1 -> 7
E9: =E8+1 -> 8
E10: =E9+1 -> 9
E11: =E10+1 -> 10
A12: Opportunities | C12: Threats | E12: =E11+1 -> 11
A13: 1 | C13: 1
A14: =A13+1 -> 2 | C14: =C13+1 -> 2
A15: =A14+1 -> 3 | C15: =C14+1 -> 3
C16: =C15+1 -> 4
C17: =C16+1 -> 5

Sheet Quarterly reporting
A1: Endurance Technologies
A3: Q-4 Fy 2024-25
A4: 1
A5: =A4+1 -> 2
A7: =A5+1 -> 3
A8: =A7+1 -> 4
A9: =A8+1 -> 5
A10: =A9+1 -> 6
A11: =A10+1 -> 7
A12: =A11+1 -> 8
A13: =A12+1 -> 9
A17: Q-1 Fy 2025-26
A18: 1
A19: =A18+1 -> 2
A20: =A19+1 -> 3
A21: =A20+1 -> 4
A23: =A21+1 -> 5
A24: =A23+1 -> 6

Sheet Financials_Standalone
A1: Endurance Technologies
A3: Standalone Balance Sheet
A5: EQUITIES AND LIABILITIES
A6: SHAREHOLDER'S FUNDS | B6: Mar 25 | C6: Mar 24 | D6: 45016 | E6: 44651 | F6: 44286 | G6: 43921 | H6: 43555 | I6: 43190 | J6: 42825 | K6: 42460 | L6: 42094
A7: Equity Share Capital | B7: 140.66 | C7: 140.66 | D7: 140.66 | E7: 140.66 | F7: 140.66 | G7: 140.66 | H7: 140.66 | I7: 140.66 | J7: 140.66 | K7: 17.58
A8: Total Share Capital | B8: =SUM(B7) -> 140.66 | C8: =SUM(C7) -> 140.66 | D8: =SUM(D7) -> 140.66 | E8: =SUM(E7) -> 140.66 | F8: =SUM(F7) -> 140.66 | G8: =SUM(G7) -> 140.66 | H8: =SUM(H7) -> 140.66 | I8: =SUM(I7) -> 140.66 | ... L8: =SUM(L7) -> 0
A9: Reserves and Surplus | B9: 4207.35 | C9: 3664.66 | D9: 3190.28 | E9: 2866.19 | F9: 2567.59 | G9: 2176.1 | H9: 1939.29 | I9: 1651.6 | J9: 1422.4 | K9: 1324.88
A10: Total Reserves and Surplus | B10: =SUM(B9) -> 4207.35 | C10: =SUM(C9) -> 3664.66 | D10: =SUM(D9) -> 3190.28 | E10: =SUM(E9) -> 2866.19 | F10: =SUM(F9) -> 2567.59 | G10: =SUM(G9) -> 2176.1 | H10: =SUM(H9) -> 1939.29 | I10: =SUM(I9) -> 1651.6 | ... L10: =SUM(L9) -> 0
A11: Employees Stock Options/ share application money pending allotment
A12: Total Shareholders Funds | B12: =SUM(B10,B8) -> 4348.01 | C12: =SUM(C10,C8) -> 3805.32 | D12: =SUM(D10,D8) -> 3330.94 | E12: =SUM(E10,E8) -> 3006.85 | F12: =SUM(F10,F8) -> 2708.25 | G12: =SUM(G10,G8) -> 2316.76 | H12: =SUM(H10,H8)+H11 -> 2079.95 | I12: =SUM(I10,I8)+I11 -> 1792.26 | J12: =SUM(J10,J8)+J11 -> 1563.06 | K12: =SUM(K10,K8)+K11 -> 1342.46 | L12: =SUM(L10,L8)+L11 -> 0
A13: NON-CURRENT LIABILITIES
A14: Long Term Borrowings | B14: 0 | C14: 0 | D14: 0 | E14: 0 | F14: 2.73 | G14: 4.28 | H14: 2.98 | I14: 4.96 | J14: 19.85 | K14: 78.02
A15: Deferred Tax Liabilities [Net] | B15: 13.35 | C15: 13.8 | D15: 0 | E15: 0 | F15: 0 | G15: 7.37 | H15: 15.61 | I15: 1.08 | J15: 0 | K15: 0
A16: Other Long Term Liabilities | B16: 32.77 | C16: 18.79 | D16: 31.94 | E16: 29.94 | F16: 8.96 | G16: 10.75 | H16: 4.68 | I16: 3.08 | J16: 2.26 | K16: 2.79
A17: Long Term Provisions | B17: 3.6 | C17: 4.07 | D17: 6.04 | E17: 8.85 | F17: 21.07 | G17: 15.82 | H17: 6.28 | I17: 2.16 | J17: 16.54 | K17: 22.65
A18: Total Non-Current Liabilities | B18: =SUM(B14:B17) -> 49.72 | C18: =SUM(C14:C17) -> 36.66 | D18: =SUM(D14:D17) -> 37.98 | E18: =SUM(E14:E17) -> 38.79 | F18: =SUM(F14:F17) -> 32.76 | G18: =SUM(G14:G17) -> 38.22 | H18: =SUM(H14:H17) -> 29.55 | I18: =SUM(I14:I17) -> 11.28 | ... L18: =SUM(L14:L17) -> 0
A19: CURRENT LIABILITIES
A20: Short Term Borrowings | B20: 0 | C20: 0 | D20: 20 | E20: 31.7 | F20: 45 | G20: 146.1 | H20: 212 | I20: 178.27 | J20: 142.49 | K20: 68.78
A21: Trade Payables | B21: 815.01 | C21: 676.21 | D21: 566.45 | E21: 529.93 | F21: 526.84 | G21: 395.6 | H21: 520.76 | I21: 483.23 | J21: 347.95 | K21: 312.1
A22: Other Current Liabilities | B22: 157.15 | C22: 142.91 | D22: 121.04 | E22: 103.83 | F22: 94.9 | G22: 56.93 | H22: 91.27 | I22: 121.43 | J22: 135.67 | K22: 148.43
A23: Short Term Provisions | B23: 26.01 | C23: 24.21 | D23: 32.64 | E23: 28.25 | F23: 29.89 | G23: 29.25 | H23: 25.03 | I23: 19.04 | J23: 22.28 | K23: 16.5
A24: Total Current Liabilities | B24: =SUM(B20:B23) -> 998.17 | C24: =SUM(C20:C23) -> 843.33 | D24: =SUM(D20:D23) -> 740.13 | E24: =SUM(E20:E23) -> 693.71 | F24: =SUM(F20:F23) -> 696.63 | G24: =SUM(G20:G23) -> 627.88 | H24: =SUM(H20:H23) -> 849.06 | I24: =SUM(I20:I23) -> 801.97 | ... L24: =SUM(L20:L23) -> 0
A25: Total Capital And Liabilities | B25: =B12+B18+B24 -> 5395.9 | C25: =C12+C18+C24 -> 4685.31 | D25: =D12+D18+D24 -> 4109.05 | E25: =E12+E18+E24 -> 3739.35 | F25: =F12+F18+F24 -> 3437.64 | G25: =G12+G18+G24 -> 2982.86 | H25: =H12+H18+H24 -> 2958.56 | I25: =I12+I18+I24 -> 2605.51 | ... L25: =L12+L18+L24 -> 0
A27: ASSETS
A28: NON-CURRENT ASSETS
A29: Tangible Assets | B29: 1964.46 | C29: 1756.7 | D29: 1624.85 | E29: 1508.39 | F29: 1368.37 | G29: 1455.65 | H29: 1157.49 | I29: 957.13 | J29: 838.81 | K29: 916.52
A30: Intangible Assets | B30: 60.85 | C30: 44.45 | D30: 51.47 | E30: 56.56 | F30: 26.67 | G30: 3.25 | H30: 4.16 | I30: 5.7 | J30: 7.45 | K30: 6.83
A31: Capital Work-In-Progress | B31: 206.97 | C31: 102.27 | D31: 119.11 | E31: 83.78 | F31: 88.92 | G31: 61.22 | H31: 89.78 | I31: 50.52 | J31: 33.22 | K31: 46.39
A32: Intangible Assets Under Development | B32: 2.82 | C32: 17.69 | D32: 12.38 | E32: 5.4 | F32: 3.17 | G32: 19.5 | H32: 11.5 | I32: 4.78 | J32: 0.4 | K32: 0.55
A33: Fixed Assets | B33: =SUM(B29:B32) -> 2235.1 | C33: =SUM(C29:C32) -> 1921.11 | D33: =SUM(D29:D32) -> 1807.81 | E33: =SUM(E29:E32) -> 1654.13 | F33: =SUM(F29:F32) -> 1487.13 | G33: =SUM(G29:G32) -> 1539.62 | H33: =SUM(H29:H32) -> 1262.93 | I33: =SUM(I29:I32) -> 1018.13 | ... L33: =SUM(L29:L32) -> 0
A34: Non-Current Investments | B34: 521.97 | C34: 533.82 | D34: 524.82 | E34: 364.91 | F34: 364.91 | G34: 364.91 | H34: 365 | I34: 364.77 | J34: 364.71 | K34: 364.67
A35: Deferred Tax Assets [Net] | B35: 0 | C35: 0 | D35: 1.11 | E35: 3.82 | F35: 1.96 | G35: 0 | H35: 0 | I35: 0 | J35: 9.54 | K35: 10.53
A36: Long Term Loans And Advances | B36: 13.7 | C36: 10 | D36: 0 | E36: 0 | F36: 0 | G36: 0 | H36: 0 | I36: 0 | J36: 0 | K36: 26.09
A37: Other Non-Current Assets | B37: 76.06 | C37: 53.31 | D37: 48.67 | E37: 50.08 | F37: 37.25 | G37: 117.76 | H37: 225 | I37: 190.26 | J37: 171.41 | K37: 0.64
A38: Total Non-Current Assets | B38: =SUM(B34:B37) -> 611.73 | C38: =SUM(C34:C37) -> 597.13 | D38: =SUM(D34:D37) -> 574.6 | E38: =SUM(E34:E37) -> 418.81 | F38: =SUM(F34:F37) -> 404.12 | G38: =SUM(G34:G37) -> 482.67 | H38: =SUM(H34:H37) -> 590 | I38: =SUM(I34:I37) -> 555.03 | ... L38: =SUM(L34:L37) -> 0
A39: CURRENT ASSETS | B39: =B33+B38 -> 2846.83 | C39: =C33+C38 -> 2518.24 | D39: =D33+D38 -> 2382.41 | E39: =E33+E38 -> 2072.94 | F39: =F33+F38 -> 1891.25 | G39: =G33+G38 -> 2022.29 | H39: =H33+H38 -> 1852.93 | I39: =I33+I38 -> 1573.16 | ... L39: =L33+L38 -> 0
A40: Current Investments | B40: 518.37 | C40: 402.22 | D40: 267.87 | E40: 209.45 | F40: 169.93 | G40: 37.32 | H40: 34.82 | I40: 44.91 | J40: 31.64 | K40: 45.58
A41: Inventories | B41: 562.08 | C41: 481.71 | D41: 428.92 | E41: 366.68 | F41: 329.53 | G41: 265.83 | H41: 282.98 | I41: 246.62 | J41: 249.07 | K41: 195.31
A42: Trade Receivables | B42: 1132.25 | C42: 1068.44 | D42: 848.8 | E42: 801.09 | F42: 812.51 | G42: 473.76 | H42: 694.76 | I42: 706.57 | J42: 484.64 | K42: 316.51
A43: Cash And Cash Equivalents | B43: 92.19 | C43: 15.74 | D43: 42.73 | E43: 103.14 | F43: 34.29 | G43: 125.33 | H43: 30.43 | I43: 8.69 | J43: 2.98 | K43: 7.58
...

Sheet Standalone bs
A1: Endurance Technologies | B1: Previous Years � | G1: � Next Years Previous Years �
A2: Standalone Balance Sheet | B2: ------------------- in Rs. Cr. ------------------- | G2: ------------------- in Rs. Cr. -------------------
B3: Mar 25 | C3: 45352 | D3: 44986 | E3: 44621 | F3: 44256 | G3: Mar 20 | H3: 43525 | I3: 43160 | J3: 42795 | K3: 42430
A4: #VALUE!
B5: 12 mths | C5: 12 mths | D5: 12 mths | E5: 12 mths | F5: 12 mths | G5: 12 mths | H5: 12 mths | I5: 12 mths | J5: 12 mths | K5: 12 mths
A6: #VALUE!
A7: EQUITIES AND LIABILITIES
A8: SHAREHOLDER'S FUNDS
A9: Equity Share Capital | B9: 140.66 | C9: 140.66 | D9: 140.66 | E9: 140.66 | F9: 140.66 | G9: 140.66 | H9: 140.66 | I9: 140.66 | J9: 140.66 | K9: 17.58
A10: Total Share Capital | B10: 140.66 | C10: 140.66 | D10: 140.66 | E10: 140.66 | F10: 140.66 | G10: 140.66 | H10: 140.66 | I10: 140.66 | J10: 140.66 | K10: 17.58
A11: Reserves and Surplus | B11: 4207.35 | C11: 3664.66 | D11: 3190.28 | E11: 2866.19 | F11: 2567.59 | G11: 2176.1 | H11: 1939.29 | I11: 1651.6 | J11: 1422.4 | K11: 1324.88
A12: Total Reserves and Surplus | B12: 4207.35 | C12: 3664.66 | D12: 3190.28 | E12: 2866.19 | F12: 2567.59 | G12: 2176.1 | H12: 1939.29 | I12: 1651.6 | J12: 1422.4 | K12: 1324.88
A13: Total Shareholders Funds | B13: 4348.01 | C13: 3805.32 | D13: 3330.94 | E13: 3006.85 | F13: 2708.26 | G13: 2316.76 | H13: 2079.95 | I13: 1792.26 | J13: 1563.06 | K13: 1342.46
A14: NON-CURRENT LIABILITIES
A15: Long Term Borrowings | B15: 0 | C15: 0 | D15: 0 | E15: 0 | F15: 2.73 | G15: 4.28 | H15: 2.98 | I15: 4.96 | J15: 19.85 | K15: 78.02
A16: Deferred Tax Liabilities [Net] | B16: 13.35 | C16: 13.8 | D16: 0 | E16: 0 | F16: 0 | G16: 7.37 | H16: 15.61 | I16: 1.08 | J16: 0 | K16: 0
A17: Other Long Term Liabilities | B17: 32.77 | C17: 18.79 | D17: 31.94 | E17: 29.94 | F17: 8.96 | G17: 10.75 | H17: 4.68 | I17: 3.08 | J17: 2.26 | K17: 2.79
A18: Long Term Provisions | B18: 3.6 | C18: 4.07 | D18: 6.04 | E18: 8.85 | F18: 21.07 | G18: 15.82 | H18: 6.28 | I18: 2.16 | J18: 16.54 | K18: 22.65
A19: Total Non-Current Liabilities | B19: 49.72 | C19: 36.67 | D19: 37.98 | E19: 38.78 | F19: 32.76 | G19: 38.22 | H19: 29.54 | I19: 11.28 | J19: 38.64 | K19: 103.46
A20: CURRENT LIABILITIES
A21: Short Term Borrowings | B21: 0 | C21: 0 | D21: 20 | E21: 31.7 | F21: 45 | G21: 146.1 | H21: 212 | I21: 178.27 | J21: 142.49 | K21: 68.78
A22: Trade Payables | B22: 815.01 | C22: 676.21 | D22: 566.45 | E22: 529.93 | F22: 526.84 | G22: 395.6 | H22: 520.76 | I22: 483.23 | J22: 347.95 | K22: 312.1
A23: Other Current Liabilities | B23: 157.15 | C23: 142.91 | D23: 121.04 | E23: 103.83 | F23: 94.9 | G23: 56.93 | H23: 91.27 | I23: 121.43 | J23: 135.67 | K23: 148.43
A24: Short Term Provisions | B24: 26.01 | C24: 24.21 | D24: 32.64 | E24: 28.25 | F24: 29.89 | G24: 29.25 | H24: 25.03 | I24: 19.04 | J24: 22.28 | K24: 16.5
A25: Total Current Liabilities | B25: 998.17 | C25: 843.32 | D25: 740.13 | E25: 693.71 | F25: 696.63 | G25: 627.88 | H25: 849.06 | I25: 801.97 | J25: 648.39 | K25: 545.81
A26: Total Capital And Liabilities | B26: 5395.9 | C26: 4685.3 | D26: 4109.05 | E26: 3739.34 | F26: 3437.65 | G26: 2982.87 | H26: 2958.55 | I26: 2605.51 | J26: 2250.1 | K26: 1991.73
A27: ASSETS
A28: NON-CURRENT ASSETS
A29: Tangible Assets | B29: 1964.46 | C29: 1756.7 | D29: 1624.85 | E29: 1508.39 | F29: 1368.37 | G29: 1455.65 | H29: 1157.49 | I29: 957.13 | J29: 838.81 | K29: 916.52
A30: Intangible Assets | B30: 60.85 | C30: 44.45 | D30: 51.47 | E30: 56.56 | F30: 26.67 | G30: 3.25 | H30: 4.16 | I30: 5.7 | J30: 7.45 | K30: 6.83
A31: Capital Work-In-Progress | B31: 206.97 | C31: 102.27 | D31: 119.11 | E31: 83.78 | F31: 88.92 | G31: 61.22 | H31: 89.78 | I31: 50.52 | J31: 33.22 | K31: 46.39
A32: Intangible Assets Under Development | B32: 2.82 | C32: 17.69 | D32: 12.38 | E32: 5.4 | F32: 3.17 | G32: 19.5 | H32: 11.5 | I32: 4.78 | J32: 0.4 | K32: 0.55
A33: Fixed Assets | B33: 2235.09 | C33: 1921.11 | D33: 1807.81 | E33: 1654.14 | F33: 1487.12 | G33: 1539.61 | H33: 1262.94 | I33: 1018.13 | J33: 879.88 | K33: 970.28
A34: Non-Current Investments | B34: 521.97 | C34: 533.82 | D34: 524.82 | E34: 364.91 | F34: 364.91 | G34: 364.91 | H34: 365 | I34: 364.77 | J34: 364.71 | K34: 364.67
A35: Deferred Tax Assets [Net] | B35: 0 | C35: 0 | D35: 1.11 | E35: 3.82 | F35: 1.96 | G35: 0 | H35: 0 | I35: 0 | J35: 9.54 | K35: 10.53
A36: Long Term Loans And Advances | B36: 13.7 | C36: 10 | D36: 0 | E36: 0 | F36: 0 | G36: 0 | H36: 0 | I36: 0 | J36: 0 | K36: 26.09
A37: Other Non-Current Assets | B37: 76.06 | C37: 53.31 | D37: 48.67 | E37: 50.08 | F37: 37.25 | G37: 117.76 | H37: 225 | I37: 190.26 | J37: 171.41 | K37: 0.64
A38: Total Non-Current Assets | B38: 2846.82 | C38: 2518.24 | D38: 2382.41 | E38: 2072.95 | F38: 1891.23 | G38: 2022.28 | H38: 1852.94 | I38: 1573.15 | J38: 1425.54 | K38: 1372.21
A39: CURRENT ASSETS
A40: Current Investments | B40: 518.37 | C40: 402.22 | D40: 267.87 | E40: 209.45 | F40: 169.93 | G40: 37.32 | H40: 34.82 | I40: 44.91 | J40: 31.64 | K40: 45.58
...

Sheet Sheet2
A1: Endurance Technologies | B1: Previous Years � | G1: � Next Years Previous Years �
A2: Standalone Profit & Loss account | B2: ------------------- in Rs. Cr. ------------------- | G2: ------------------- in Rs. Cr. -------------------
B3: Mar 25 | C3: 45352 | D3: 44986 | E3: 44621 | F3: 44256 | G3: Mar 20 | H3: 43525 | I3: 43160 | J3: 42795 | K3: 42430
A4: #VALUE!
B5: 12 mths | C5: 12 mths | D5: 12 mths | E5: 12 mths | F5: 12 mths | G5: 12 mths | H5: 12 mths | I5: 12 mths | J5: 12 mths | K5: 12 mths
A6: #VALUE!
A7: INCOME
A8: Revenue From Operations [Gross] | B8: 8730.32 | C8: 7757.77 | D8: 6674.81 | E8: 5604.43 | F8: 4658.97 | G8: 4820.16 | H8: 5341.43 | I8: 4680.17 | J8: 4194.28 | K8: 3987.37
A9: Less: Excise/Sevice Tax/Other Levies | G9: 0 | H9: 0 | I9: 127.91 | J9: 400.33 | K9: 387.25
A10: Revenue From Operations [Net] | B10: 8730.32 | C10: 7757.77 | D10: 6674.81 | E10: 5604.43 | F10: 4658.97 | G10: 4820.16 | H10: 5341.43 | I10: 4552.25 | J10: 3793.95 | K10: 3600.13
A11: Other Operating Revenues | B11: 115.83 | C11: 113.23 | D11: 92.7 | E11: 92.66 | F11: 114.07 | G11: 118.41 | H11: 76.03 | I11: 88.85 | J11: 85.87 | K11: 73.78
A12: Total Operating Revenues | B12: 8846.15 | C12: 7871 | D12: 6767.51 | E12: 5697.09 | F12: 4773.03 | G12: 4938.57 | H12: 5417.46 | I12: 4641.1 | J12: 3879.82 | K12: 3673.91
A13: Other Income | B13: 66.58 | C13: 49.47 | D13: 28.2 | E13: 24.39 | F13: 13.55 | G13: 36.19 | H13: 16.22 | I13: 18.39 | J13: 12.55 | K13: 21.98
A14: Total Revenue | B14: 8912.73 | C14: 7920.47 | D14: 6795.71 | E14: 5721.48 | F14: 4786.58 | G14: 4974.76 | H14: 5433.68 | I14: 4659.49 | J14: 3892.37 | K14: 3695.89
A15: EXPENSES
A16: Cost Of Materials Consumed | B16: 5686.35 | C16: 5086.76 | D16: 4511.09 | E16: 3745.18 | F16: 2969.19 | G16: 3000.67 | H16: 3508.03 | I16: 3011.06 | J16: 2511.41 | K16: 2392.5
A17: Purchase Of Stock-In Trade | B17: 70.67 | C17: 60.38 | D17: 63.91 | E17: 54.07 | F17: 44.6 | G17: 27.84 | H17: 23.08 | I17: 9.09 | J17: 9.81 | K17: 7.86
A18: Changes In Inventories Of FG,WIP And Stock-In Trade | B18: -28.57 | C18: -6.44 | D18: -42.4 | E18: -40.93 | F18: -44.43 | G18: 18.81 | H18: -7.38 | I18: 9.43 | J18: -43.22 | K18: -16.2
A19: Employee Benefit Expenses | B19: 435.78 | C19: 380.12 | D19: 324.18 | E19: 290.31 | F19: 286.56 | G19: 296.13 | H19: 277.74 | I19: 254.7 | J19: 242.18 | K19: 207.71
A20: Finance Costs | B20: 2.56 | C20: 2.99 | D20: 4.27 | E20: 1.82 | F20: 4.8 | G20: 10.82 | H20: 17.07 | I20: 10.25 | J20: 17.86 | K20: 32.55
A21: Depreciation And Amortisation Expenses | B21: 289.65 | C21: 262.52 | D21: 240.71 | E21: 203.74 | F21: 203.42 | G21: 199.25 | H21: 175.7 | I21: 169.63 | J21: 166.86 | K21: 150.48
A22: Other Expenses | B22: 1530.87 | C22: 1343.86 | D22: 1131.49 | E22: 919.79 | F22: 785.53 | G22: 861.06 | H22: 895.9 | I22: 766.46 | J22: 688.6 | K22: 639.78
A23: Less: Amounts Transfer To Capital Accounts | G23: 8.26 | H23: 11.92 | I23: 0 | J23: 0 | K23: 0
A24: Total Expenses | B24: 7987.31 | C24: 7130.2 | D24: 6233.25 | E24: 5173.99 | F24: 4249.66 | G24: 4406.32 | H24: 4878.22 | I24: 4230.61 | J24: 3593.49 | K24: 3414.66
B25: 45717 | C25: 45352 | D25: 44986 | E25: 44621 | F25: 44256 | G25: 43891 | H25: 43525 | I25: 43160 | J25: 42795 | K25: 42430
A26: #VALUE!
B27: 12 mths | C27: 12 mths | D27: 12 mths | E27: 12 mths | F27: 12 mths | G27: 12 mths | H27: 12 mths | I27: 12 mths | J27: 12 mths | K27: 12 mths
A28: #VALUE!
A29: Profit/Loss Before Exceptional, ExtraOrdinary Items And Tax | B29: 925.42 | C29: 790.27 | D29: 562.46 | E29: 547.49 | F29: 536.92 | G29: 568.44 | H29: 555.46 | I29: 428.88 | J29: 298.88 | K29: 281.22
A30: Exceptional Items | B30: -17.36 | C30: 0 | D30: -10.29 | E30: -31.45 | F30: -11.23 | G30: 0 | H30: -20.8 | I30: -26.88 | J30: 0 | K30: 0
A31: Profit/Loss Before Tax | B31: 908.06 | C31: 790.27 | D31: 552.17 | E31: 516.04 | F31: 525.7 | G31: 568.44 | H31: 534.66 | I31: 402 | J31: 298.88 | K31: 281.22
A32: Tax Expenses-Continued Operations
A33: Current Tax | B33: 229.68 | C33: 194.76 | D33: 141.4 | E33: 136.59 | F33: 142.59 | G33: 147.53 | H33: 159.5 | I33: 126.12 | J33: 75.78 | K33: 71.3
A34: Deferred Tax | B34: 1.88 | C34: 19.46 | D34: 1.86 | E34: -2.29 | F34: -9.09 | G34: -6.78 | H34: 15.79 | I34: 10.67 | J34: 1.48 | K34: 4.33
A35: Tax For Earlier Years | B35: -2.16 | C35: -11.75 | D35: 0 | E35: 0 | F35: 0 | G35: 0 | H35: 1.51 | I35: -6.4 | J35: 0.13 | K35: 0
A36: Total Tax Expenses | B36: 229.4 | C36: 202.48 | D36: 143.25 | E36: 134.3 | F36: 133.5 | G36: 140.75 | H36: 176.8 | I36: 130.4 | J36: 77.38 | K36: 75.63
A37: Profit/Loss After Tax And Before ExtraOrdinary Items | B37: 678.66 | C37: 587.79 | D37: 408.92 | E37: 381.74 | F37: 392.2 | G37: 427.69 | H37: 357.86 | I37: 271.6 | J37: 221.5 | K37: 205.6
A38: Profit/Loss From Continuing Operations | B38: 678.66 | C38: 587.79 | D38: 408.92 | E38: 381.74 | F38: 392.2 | G38: 427.69 | H38: 357.86 | I38: 271.6 | J38: 221.5 | K38: 205.6
A39: Profit/Loss For The Period | B39: 678.66 | C39: 587.79 | D39: 408.92 | E39: 381.74 | F39: 392.2 | G39: 427.69 | H39: 357.86 | I39: 271.6 | J39: 221.5 | K39: 205.6
B40: 45717 | C40: 45352 | D40: 44986 | E40: 44621 | F40: 44256 | G40: 43891 | H40: 43525 | I40: 43160 | J40: 42795 | K40: 42430
...

Sheet Financials_Consol
A1: Endurance Technologies
A3: Consol Balance Sheet
A5: EQUITIES AND LIABILITIES
A6: SHAREHOLDER'S FUNDS | B6: Mar 25 | C6: Mar 24 | D6: 45016 | E6: 44651 | F6: 44286 | G6: 43921 | H6: 43555 | I6: 43190 | J6: 42825 | K6: 42460 | L6: 42094
A7: Equity Share Capital | B7: 140.66 | C7: 140.66 | D7: 140.66 | E7: 140.66 | F7: 140.66 | G7: 140.66 | H7: 140.66 | I7: 140.66 | J7: 140.66 | K7: 17.58
A8: Total Share Capital | B8: =SUM(B7) -> 140.66 | C8: =SUM(C7) -> 140.66 | D8: =SUM(D7) -> 140.66 | E8: =SUM(E7) -> 140.66 | F8: =SUM(F7) -> 140.66 | G8: =SUM(G7) -> 140.66 | H8: =SUM(H7) -> 140.66 | I8: =SUM(I7) -> 140.66 | ... L8: =SUM(L7) -> 0
A9: Reserves and Surplus | B9: 5576.75 | C9: 4836.78 | D9: 4271.47 | E9: 3779.33 | F9: 3421.45 | G9: 2865.38 | H9: 2424.02 | I9: 2032.19 | J9: 1588.67 | K9: 1432.23
A10: Total Reserves and Surplus | B10: =SUM(B8:B9) -> 5717.41 | C10: =SUM(C8:C9) -> 4977.44 | D10: =SUM(D8:D9) -> 4412.13 | E10: =SUM(E8:E9) -> 3919.99 | F10: =SUM(F8:F9) -> 3562.11 | G10: =SUM(G8:G9) -> 3006.04 | H10: =SUM(H8:H9) -> 2564.68 | I10: =SUM(I8:I9) -> 2172.85 | ... L10: =SUM(L8:L9) -> 0
A11: Employees Stock Options
A12: Total Shareholders Funds | B12: =SUM(B10:B11) -> 5717.41 | C12: =SUM(C10:C11) -> 4977.44 | D12: =SUM(D10:D11) -> 4412.13 | E12: =SUM(E10:E11) -> 3919.99 | F12: =SUM(F10:F11) -> 3562.11 | G12: =SUM(G10:G11) -> 3006.04 | H12: =SUM(H10:H11) -> 2564.68 | I12: =SUM(I10:I11) -> 2172.85 | ... L12: =SUM(L10:L11) -> 0
A13: Minority Interest | B13: 0 | C13: 0 | D13: 0 | E13: 0 | F13: 0.02
A14: NON-CURRENT LIABILITIES
A15: Long Term Borrowings | B15: 594.64 | C15: 480.25 | D15: 278.15 | E15: 193.92 | F15: 379.18 | G15: 402.09 | H15: 346.4 | I15: 380.33 | J15: 342.23 | K15: 416.27
A16: Deferred Tax Liabilities [Net] | B16: 13.35 | C16: 14.43 | D16: 0.52 | E16: 0.63 | F16: 0.51 | G16: 7.87 | H16: 16.13 | I16: 1.73 | J16: 0.78 | K16: 1.1
A17: Other Long Term Liabilities | B17: 48.6 | C17: 115.97 | D17: 116.4 | E17: 26.73 | F17: 8.98 | G17: 11.82 | H17: 8.42 | I17: 9.58 | J17: 6.35 | K17: 8.48
A18: Long Term Provisions | B18: 73.46 | C18: 60.18 | D18: 64.53 | E18: 59.15 | F18: 73.36 | G18: 77.67 | H18: 66.11 | I18: 19.65 | J18: 30.7 | K18: 30.31
A19: Total Non-Current Liabilities | B19: =SUM(B15:B18) -> 730.05 | C19: =SUM(C15:C18) -> 670.83 | D19: =SUM(D15:D18) -> 459.6 | E19: =SUM(E15:E18) -> 280.43 | F19: =SUM(F15:F18) -> 462.03 | G19: =SUM(G15:G18) -> 499.45 | H19: =SUM(H15:H18) -> 437.06 | I19: =SUM(I15:I18) -> 411.29 | ... L19: =SUM(L15:L18) -> 0
A20: CURRENT LIABILITIES
A21: Short Term Borrowings | B21: 309.22 | C21: 259.53 | D21: 205.18 | E21: 205.53 | F21: 45 | G21: 146.1 | H21: 212 | I21: 178.27 | J21: 173.59 | K21: 186.91
A22: Trade Payables | B22: 1974.26 | C22: 1604.47 | D22: 1425.74 | E22: 1241.35 | F22: 1278.33 | G22: 1066.23 | H22: 1173.46 | I22: 1128.42 | J22: 864.19 | K22: 738.53
A23: Other Current Liabilities | B23: 381.98 | C23: 348.98 | D23: 267.08 | E23: 182.07 | F23: 370.16 | G23: 318.69 | H23: 369.92 | I23: 431.35 | J23: 341.7 | K23: 434.38
A24: Short Term Provisions | B24: 26.35 | C24: 24.45 | D24: 32.74 | E24: 28.25 | F24: 29.89 | G24: 33.41 | H24: 28.92 | I24: 19.1 | J24: 22.38 | K24: 16.08
A25: Total Current Liabilities | B25: =SUM(B21:B24) -> 2691.81 | C25: =SUM(C21:C24) -> 2237.43 | D25: =SUM(D21:D24) -> 1930.74 | E25: =SUM(E21:E24) -> 1657.2 | F25: =SUM(F21:F24) -> 1723.38 | G25: =SUM(G21:G24) -> 1564.43 | H25: =SUM(H21:H24) -> 1784.3 | I25: =SUM(I21:I24) -> 1757.14 | ... L25: =SUM(L21:L24) -> 0
A26: Total Capital And Liabilities | B26: =B12+B13+B19+B25 -> 9139.27 | C26: =C12+C13+C19+C25 -> 7885.7 | D26: =D12+D13+D19+D25 -> 6802.47 | E26: =E12+E13+E19+E25 -> 5857.62 | F26: =F12+F13+F19+F25 -> 5747.54 | G26: =G12+G13+G19+G25 -> 5069.92 | H26: =H12+H13+H19+H25 -> 4786.04 | I26: =I12+I13+I19+I25 -> 4341.28 | ... L26: =L12+L13+L19+L25 -> 0
A28: ASSETS
A29: NON-CURRENT ASSETS
A30: Tangible Assets | B30: 3612.46 | C30: 3133.65 | D30: 2634.68 | E30: 2455.82 | F30: 2350.93 | G30: 2410.42 | H30: 1994.58 | I30: 1670.62 | J30: 1473.43 | K30: 1432.27
A31: Intangible Assets | B31: 105.18 | C31: 104.29 | D31: 118.16 | E31: 83.18 | F31: 77.66 | G31: 33.44 | H31: 16.57 | I31: 22.62 | J31: 24.78 | K31: 7.67
A32: Capital Work-In-Progress | B32: 290.15 | C32: 156.72 | D32: 168.36 | E32: 119.05 | F32: 92.99 | G32: 106.45 | H32: 106.29 | I32: 54.39 | J32: 43.42 | K32: 93.48
A33: Intangible Assets Under Development | B33: 2.82 | C33: 2.55 | D33: 2.53 | E33: 0.26 | F33: 3.17 | G33: 19.5 | H33: 11.51 | I33: 4.78 | J33: 0.4 | K33: 9.92
A34: Fixed Assets | B34: =SUM(B30:B33) -> 4010.61 | C34: =SUM(C30:C33) -> 3397.21 | D34: =SUM(D30:D33) -> 2923.73 | E34: =SUM(E30:E33) -> 2658.31 | F34: =SUM(F30:F33) -> 2524.75 | G34: =SUM(G30:G33) -> 2569.81 | H34: =SUM(H30:H33) -> 2128.95 | I34: =SUM(I30:I33) -> 1752.41 | ... L34: =SUM(L30:L33) -> 0
A35: Goodwill
A36: Non-Current Investments | B36: 15.68 | C36: 27.52 | D36: 25.47 | E36: 1.19 | F36: 1.2 | G36: 1.19 | H36: 1.28 | I36: 1.01 | J36: 1.02 | K36: 1.02
A37: Deferred Tax Assets [Net] | B37: 69.51 | C37: 78.27 | D37: 71.98 | E37: 75.14 | F37: 60.24 | G37: 32.08 | H37: 31.13 | I37: 11.99 | J37: 18.95 | K37: 19.65
A38: Long Term Loans And Advances | B38: 0 | C38: 0 | D38: 0 | E38: 0 | F38: 2.68 | G38: 156.83 | H38: 307.19 | I38: 268.03 | J38: 212.15 | K38: 228.76
A39: Other Non-Current Assets | B39: 109.07 | C39: 200.47 | D39: 199.38 | E39: 97.92 | F39: 80.5
A40: Total Non-Current Assets | B40: =SUM(B34:B39) -> 4204.87 | C40: =SUM(C34:C39) -> 3703.47 | D40: =SUM(D34:D39) -> 3220.56 | E40: =SUM(E34:E39) -> 2832.56 | F40: =SUM(F34:F39) -> 2669.37 | G40: =SUM(G34:G39) -> 2759.91 | H40: =SUM(H34:H39) -> 2468.55 | I40: =SUM(I34:I39) -> 2033.44 | ... L40: =SUM(L34:L39) -> 0
A41: CURRENT ASSETS
A42: Current Investments | B42: 787.93 | C42: 765.07 | D42: 646.37 | E42: 485.59 | F42: 443.14 | G42: 164.83 | H42: 34.82 | I42: 44.91 | J42: 31.64 | K42: 47.16
A43: Inventories | B43: 936.37 | C43: 872.21 | D43: 820.58 | E43: 701.14 | F43: 611.85 | G43: 550.1 | H43: 540.01 | I43: 493.85 | J43: 443.83 | K43: 409.86
...

Sheet Sheet3
A1: Endurance Technologies | B1: Previous Years �
A2: Consolidated Balance Sheet | B2: ------------------- in Rs. Cr. -------------------
B3: Mar 25 | C3: 45352 | D3: 44986 | E3: 44621 | F3: 44256
A4: #VALUE!
B5: 12 mths | C5: 12 mths | D5: 12 mths | E5: 12 mths | F5: 12 mths
A6: #VALUE!
A7: EQUITIES AND LIABILITIES
A8: SHAREHOLDER'S FUNDS
A9: Equity Share Capital | B9: 140.66 | C9: 140.66 | D9: 140.66 | E9: 140.66 | F9: 140.66
A10: Total Share Capital | B10: 140.66 | C10: 140.66 | D10: 140.66 | E10: 140.66 | F10: 140.66
A11: Reserves and Surplus | B11: 5576.75 | C11: 4836.78 | D11: 4271.47 | E11: 3779.33 | F11: 3421.45
A12: Total Reserves and Surplus | B12: 5576.75 | C12: 4836.78 | D12: 4271.47 | E12: 3779.33 | F12: 3421.45
A13: Total Shareholders Funds | B13: 5717.42 | C13: 4977.44 | D13: 4412.13 | E13: 3919.99 | F13: 3562.12
A14: Minority Interest | B14: 0 | C14: 0 | D14: 0 | E14: 0 | F14: 0.02
A15: NON-CURRENT LIABILITIES
A16: Long Term Borrowings | B16: 594.64 | C16: 480.25 | D16: 278.15 | E16: 193.92 | F16: 379.18
A17: Deferred Tax Liabilities [Net] | B17: 13.35 | C17: 14.43 | D17: 0.52 | E17: 0.63 | F17: 0.51
A18: Other Long Term Liabilities | B18: 48.6 | C18: 115.97 | D18: 116.4 | E18: 26.73 | F18: 8.98
A19: Long Term Provisions | B19: 73.46 | C19: 60.18 | D19: 64.53 | E19: 59.15 | F19: 73.36
A20: Total Non-Current Liabilities | B20: 730.05 | C20: 670.83 | D20: 459.59 | E20: 280.43 | F20: 462.03
A21: CURRENT LIABILITIES
A22: Short Term Borrowings | B22: 309.22 | C22: 259.53 | D22: 205.18 | E22: 205.53 | F22: 45
A23: Trade Payables | B23: 1974.26 | C23: 1604.47 | D23: 1425.74 | E23: 1241.35 | F23: 1278.33
A24: Other Current Liabilities | B24: 381.98 | C24: 348.98 | D24: 267.08 | E24: 182.07 | F24: 370.16
A25: Short Term Provisions | B25: 26.35 | C25: 24.45 | D25: 32.74 | E25: 28.25 | F25: 29.89
A26: Total Current Liabilities | B26: 2691.81 | C26: 2237.43 | D26: 1930.73 | E26: 1657.19 | F26: 1723.38
A27: Total Capital And Liabilities | B27: 9139.28 | C27: 7885.69 | D27: 6802.45 | E27: 5857.62 | F27: 5747.55
A28: ASSETS
A29: NON-CURRENT ASSETS
A30: Tangible Assets | B30: 3612.46 | C30: 3133.65 | D30: 2634.68 | E30: 2455.82 | F30: 2350.93
A31: Intangible Assets | B31: 105.18 | C31: 104.29 | D31: 118.16 | E31: 83.18 | F31: 77.66
A32: Capital Work-In-Progress | B32: 290.15 | C32: 156.72 | D32: 168.36 | E32: 119.05 | F32: 92.99
A33: Intangible Assets Under Development | B33: 2.82 | C33: 2.55 | D33: 2.53 | E33: 0.26 | F33: 3.17
A34: Fixed Assets | B34: 4010.6 | C34: 3397.21 | D34: 2923.74 | E34: 2658.32 | F34: 2524.74
A35: Non-Current Investments | B35: 15.68 | C35: 27.52 | D35: 25.47 | E35: 1.19 | F35: 1.2
A36: Deferred Tax Assets [Net] | B36: 69.51 | C36: 78.27 | D36: 71.98 | E36: 75.14 | F36: 60.24
A37: Long Term Loans And Advances | B37: 0 | C37: 0 | D37: 0 | E37: 0 | F37: 2.68
A38: Other Non-Current Assets | B38: 109.07 | C38: 200.47 | D38: 199.38 | E38: 97.92 | F38: 80.5
A39: Total Non-Current Assets | B39: 4545.38 | C39: 4095.76 | D39: 3610.58 | E39: 3008.26 | F39: 2843.34
A40: CURRENT ASSETS
...

Sheet Common Size Analysis - PL_Conso
A1: Endurance Technologies | I1: Endurance Technologies
A2: Income Statement | I2: Common-Size Income Statement
A3: (Rs Crore) | B3: 45717 | C3: 45352 | D3: 44986 | E3: 44621 | F3: 44256 | G3: 43891 | J3: 45717 | K3: 45352 | L3: 44986 | M3: 44621 | N3: 44256 | O3: 43891
A4: Revenue from Operations | I4: Revenue from Operations
A5: Gross Sales of Products | B5: =Financials_Consol!B73 -> 11371.37 | C5: =Financials_Consol!C73 -> 10082.5 | D5: =Financials_Consol!D73 -> 8676.06 | E5: =Financials_Consol!E73 -> 7424.4 | F5: =Financials_Consol!F73 -> 6405.48 | G5: =Financials_Consol!G73 -> 6775.39 | I5: Gross Sales of Products | J5: 1 | K5: 1 | L5: 1 | M5: 1 | N5: 1 | O5: 1
A6: Less - Excise Duty | B6: =Financials_Consol!B74 -> 0 | C6: =Financials_Consol!C74 -> 0 | D6: =Financials_Consol!D74 -> 0 | E6: =Financials_Consol!E74 -> 0 | F6: =Financials_Consol!F74 -> 0 | G6: =Financials_Consol!G74 -> 0 | I6: Less - Excise Duty | J6: =B6/B$5 -> 0 | K6: =C6/C$5 -> 0 | L6: =D6/D$5 -> 0 | M6: =E6/E$5 -> 0 | N6: =F6/F$5 -> 0 | O6: =G6/G$5 -> 0
A7: Other Operating Revenue | B7: =Financials_Consol!B76 -> 189.44 | C7: =Financials_Consol!C76 -> 158.37 | D7: =Financials_Consol!D76 -> 127.99 | E7: =Financials_Consol!E76 -> 124.75 | F7: =Financials_Consol!F76 -> 141.54 | G7: =Financials_Consol!G76 -> 142.31 | I7: Other Operating Revenue | J7: =B7/B$5 -> 0.016659382 | K7: =C7/C$5 -> 0.015707414 | L7: =D7/D$5 -> 0.014752088 | M7: =E7/E$5 -> 0.016802705 | N7: =F7/F$5 -> 0.022096705 | O7: =G7/G$5 -> 0.021003957
A8: Net Revenue from Operations (A) | B8: =B5-B6+B7 -> 11560.81 | C8: =C5-C6+C7 -> 10240.87 | D8: =D5-D6+D7 -> 8804.05 | E8: =E5-E6+E7 -> 7549.15 | F8: =F5-F6+F7 -> 6547.02 | G8: =G5-G6+G7 -> 6917.7 | I8: Net Revenue from Operations (A) | J8: =B8/B$8 -> 1 | K8: =C8/C$8 -> 1 | L8: =D8/D$8 -> 1 | M8: =E8/E$8 -> 1 | N8: =F8/F$8 -> 1 | O8: =G8/G$8 -> 1
A10: Other Income (B) | B10: =Financials_Consol!B78 -> 116.97 | C10: =Financials_Consol!C78 -> 85.62 | D10: =Financials_Consol!D78 -> 45.43 | E10: =Financials_Consol!E78 -> 41.04 | F10: =Financials_Consol!F78 -> 30.71 | G10: =Financials_Consol!G78 -> 47.6 | I10: Other Income (B) | J10: =B10/B$5 -> 0.01028636 | K10: =C10/C$5 -> 0.0084919415 | L10: =D10/D$5 -> 0.0052362478 | M10: =E10/E$5 -> 0.0055277194 | N10: =F10/F$5 -> 0.0047943324 | O10: =G10/G$5 -> 0.0070254258
A12: Less: Expenses | I12: Less: Expenses
A13: COGS | B13: =Financials_Consol!B81 -> 6504.87 | C13: =Financials_Consol!C81 -> 5922.96 | D13: =Financials_Consol!D81 -> 5320.19 | E13: =Financials_Consol!E81 -> 4428.43 | F13: =Financials_Consol!F81 -> 3497.65 | G13: =Financials_Consol!G81 -> 3704.52 | I13: Cost of Materials Consumed | J13: =B13/B$8 -> 0.56266559 | K13: =C13/C$8 -> 0.57836492 | L13: =D13/D$8 -> 0.60428894 | M13: =E13/E$8 -> 0.58661306 | N13: =F13/F$8 -> 0.53423542 | O13: =G13/G$8 -> 0.53551325
A14: Purchase Of Stock-In Trade | B14: =Financials_Consol!B82 -> 111.75 | C14: =Financials_Consol!C82 -> 140.91 | D14: =Financials_Consol!D82 -> 103.97 | E14: =Financials_Consol!E82 -> 86.38 | F14: =Financials_Consol!F82 -> 89.62 | G14: =Financials_Consol!G82 -> 27.84 | I14: Purchase Of Stock-In Trade | J14: =B14/B$8 -> 0.0096662777 | K14: =C14/C$8 -> 0.013759573 | L14: =D14/D$8 -> 0.011809338 | M14: =E14/E$8 -> 0.011442348 | N14: =F14/F$8 -> 0.013688671 | O14: =G14/G$8 -> 0.004024459
A15: Changes In Inventories Of FG,WIP And Stock-In Trade | B15: =Financials_Consol!B83 -> -13.51 | C15: =Financials_Consol!C83 -> -13.29 | D15: =Financials_Consol!D83 -> -94.64 | E15: =Financials_Consol!E83 -> -94.66 | F15: =Financials_Consol!F83 -> -16.71 | G15: =Financials_Consol!G83 -> 2.85 | I15: Changes in Inventories | J15: =B15/B$8 -> -0.0011686032 | K15: =C15/C$8 -> -0.0012977413 | L15: =D15/D$8 -> -0.010749598 | M15: =E15/E$8 -> -0.01253916 | N15: =F15/F$8 -> -0.0025523062 | O15: =G15/G$8 -> 0.00041198664
A16: Employee Benefit Expenses | B16: =Financials_Consol!B84 -> 1007.35 | C16: =Financials_Consol!C84 -> 879.9 | D16: =Financials_Consol!D84 -> 763.61 | E16: =Financials_Consol!E84 -> 694.36 | F16: =Financials_Consol!F84 -> 676.06 | G16: =Financials_Consol!G84 -> 677.33 | I16: Employee Benefits Expenses | J16: =B16/B$8 -> 0.087134898 | K16: =C16/C$8 -> 0.085920434 | L16: =D16/D$8 -> 0.086733946 | M16: =E16/E$8 -> 0.091978567 | N16: =F16/F$8 -> 0.10326225 | O16: =G16/G$8 -> 0.097912601
A17: Finance Costs | B17: =Financials_Consol!B85 -> 46.81 | C17: =Financials_Consol!C85 -> 42.66 | D17: =Financials_Consol!D85 -> 20.58 | E17: =Financials_Consol!E85 -> 6.35 | F17: =Financials_Consol!F85 -> 13.76 | G17: =Financials_Consol!G85 -> 17.54 | I17: Finance costs | J17: =B17/B$8 -> 0.0040490242 | K17: =C17/C$8 -> 0.0041656617 | L17: =D17/D$8 -> 0.0023375606 | M17: =E17/E$8 -> 0.0008411543 | N17: =F17/F$8 -> 0.0021017196 | O17: =G17/G$8 -> 0.0025355248
A18: Depreciation And Amortisation Expenses | B18: =Financials_Consol!B86 -> 538.71 | C18: =Financials_Consol!C86 -> 473.99 | D18: =Financials_Consol!D86 -> 421.58 | E18: =Financials_Consol!E86 -> 381.73 | F18: =Financials_Consol!F86 -> 399.14 | G18: =Financials_Consol!G86 -> 414.28 | I18: Depreciation and Amortisation Expenses | J18: =B18/B$8 -> 0.046597946 | K18: =C18/C$8 -> 0.046284154 | L18: =D18/D$8 -> 0.04788478 | M18: =E18/E$8 -> 0.050565958 | N18: =F18/F$8 -> 0.060965141 | O18: =G18/G$8 -> 0.059886957
A19: Other Expenses | B19: =Financials_Consol!B87 -> 2399.27 | C19: =Financials_Consol!C87 -> 1982.42 | D19: =Financials_Consol!D87 -> 1674.65 | E19: =Financials_Consol!E87 -> 1470 | F19: =Financials_Consol!F87 -> 1260.19 | G19: =Financials_Consol!G87 -> 1382.66 | I19: Other expenses | J19: =B19/B$8 -> 0.20753477 | K19: =C19/C$8 -> 0.19357926 | L19: =D19/D$8 -> 0.19021359 | M19: =E19/E$8 -> 0.19472391 | N19: =F19/F$8 -> 0.19248299 | O19: =G19/G$8 -> 0.19987279
A20: Less: Amounts Transfer To Capital Accounts | B20: =Financials_Consol!B88 -> 0 | C20: =Financials_Consol!C88 -> 0 | D20: =Financials_Consol!D88 -> 0 | E20: =Financials_Consol!E88 -> 0 | F20: =Financials_Consol!F88 -> 0 | G20: =Financials_Consol!G88 -> -8.26
A21: Total Expenses (C) | B21: =SUM(B13:B20) -> 10595.25 | C21: =SUM(C13:C20) -> 9429.55 | D21: =SUM(D13:D20) -> 8209.94 | E21: =SUM(E13:E20) -> 6972.59 | F21: =SUM(F13:F20) -> 5919.71 | G21: =SUM(G13:G20) -> 6218.76 | I21: Total Expenses (C) | J21: =B21/B$8 -> 0.9164799 | K21: =C21/C$8 -> 0.92077626 | L21: =D21/D$8 -> 0.93251856 | M21: =E21/E$8 -> 0.92362584 | N21: =F21/F$8 -> 0.90418389 | O21: =G21/G$8 -> 0.89896353
A23: Profit before Taxes (D = A+B-C) | B23: =B8+B10-B21 -> 1082.53 | C23: =C8+C10-C21 -> 896.94 | D23: =D8+D10-D21 -> 639.54 | E23: =E8+E10-E21 -> 617.6 | F23: =F8+F10-F21 -> 658.02 | G23: =G8+G10-G21 -> 746.54 | I23: Profit before Taxes (D = A+B-C) | J23: =B23/B$8 -> 0.093637903 | K23: =C23/C$8 -> 0.087584356 | L23: =D23/D$8 -> 0.072641568 | M23: =E23/E$8 -> 0.081810535 | N23: =F23/F$8 -> 0.1005068 | O23: =G23/G$8 -> 0.10791737
A25: Less: Taxes (E) | B25: =SUM(Financials_Consol!B94:B97) -> 258.36 | C25: =SUM(Financials_Consol!C94:C97) -> 216.46 | D25: =SUM(Financials_Consol!D94:D97) -> 149.67 | E25: =SUM(Financials_Consol!E94:E97) -> 125.44 | F25: =SUM(Financials_Consol!F94:F97) -> 127.23 | G25: =SUM(Financials_Consol!G94:G97) -> 181.01 | I25: Less: Taxes (E) | J25: =B25/B$8 -> 0.022347915 | K25: =C25/C$8 -> 0.021136876 | L25: =D25/D$8 -> 0.017000131 | M25: =E25/E$8 -> 0.01661644 | N25: =F25/F$8 -> 0.019433269 | O25: =G25/G$8 -> 0.026166211
A26: Extraordinary Items | B26: =Financials_Consol!B92 -> 12.18 | C26: =Financials_Consol!C92 -> 0 | D26: =Financials_Consol!D92 -> -10.29 | E26: =Financials_Consol!E92 -> -31.45 | F26: =Financials_Consol!F92 -> -11.23 | G26: =Financials_Consol!G92 -> 0 | I26: Extraordinary Items | J26: =B26/B$8 -> 0.0010535594 | K26: =C26/C$8 -> 0 | L26: =D26/D$8 -> -0.0011687803 | M26: =E26/E$8 -> -0.0041660319 | N26: =F26/F$8 -> -0.0017152842 | O26: =G26/G$8 -> 0
A28: Profit for the Year / Net Profit (D-E) | B28: =B23-B25+B26 -> 836.35 | C28: =C23-C25+C26 -> 680.48 | D28: =D23-D25+D26 -> 479.58 | E28: =E23-E25+E26 -> 460.71 | F28: =F23-F25+F26 -> 519.56 | G28: =G23-G25+G26 -> 565.53 | I28: Profit for the Year / Net Profit (D-E) | J28: =B28/B$8 -> 0.072343547 | K28: =C28/C$8 -> 0.06644748 | L28: =D28/D$8 -> 0.054472657 | M28: =E28/E$8 -> 0.061028063 | N28: =F28/F$8 -> 0.079358242 | O28: =G28/G$8 -> 0.08175116
B30: =Financials_Consol!B101 -> 836.35 | C30: =Financials_Consol!C101 -> 680.48 | D30: =Financials_Consol!D101 -> 479.58 | E30: =Financials_Consol!E101 -> 460.71 | F30: =Financials_Consol!F101 -> 519.56 | G30: =Financials_Consol!G101 -> 565.53
B31: =B28-B30 -> 0 | C31: =C28-C30 -> 0 | D31: =D28-D30 -> 0 | E31: =E28-E30 -> 0 | F31: =F28-F30 -> 0 | G31: =G28-G30 -> 0

Sheet Common Size Analysis - PL
A1: Endurance Technologies | I1: Endurance Technologies
A2: Income Statement | I2: Common-Size Income Statement
A3: (Rs lakhs) | B3: 45717 | C3: 45352 | D3: 44986 | E3: 44621 | F3: 44256 | G3: 43891 | J3: 45717 | K3: 45352 | L3: 44986 | M3: 44621 | N3: 44256 | O3: 43891
A4: Revenue from Operations | I4: Revenue from Operations
A5: Gross Sales of Products | B5: =Financials_Standalone!B73 -> 8730.32 | C5: =Financials_Standalone!C73 -> 7757.77 | D5: =Financials_Standalone!D73 -> 6674.81 | E5: =Financials_Standalone!E73 -> 5604.43 | F5: =Financials_Standalone!F73 -> 4658.97 | G5: =Financials_Standalone!G73 -> 4820.16 | I5: Gross Sales of Products | J5: 1 | K5: 1 | L5: 1 | M5: 1 | N5: 1 | O5: 1 | P5: =C5*12/9 -> 10343.693 | Q5: =P5/G5 -> 2.1459232
A6: Less - Excise Duty | B6: =Financials_Standalone!B74 -> 0 | C6: =Financials_Standalone!C74 -> 0 | D6: =Financials_Standalone!D74 -> 0 | E6: =Financials_Standalone!E74 -> 0 | F6: =Financials_Standalone!F74 -> 0 | G6: =Financials_Standalone!G74 -> 0 | I6: Less - Excise Duty | J6: =B6/B$5 -> 0 | K6: =C6/C$5 -> 0 | L6: =D6/D$5 -> 0 | M6: =E6/E$5 -> 0 | N6: =F6/F$5 -> 0 | O6: =G6/G$5 -> 0
A7: Other Operating Revenue | B7: =Financials_Standalone!B76 -> 115.83 | C7: =Financials_Standalone!C76 -> 113.23 | D7: =Financials_Standalone!D76 -> 92.7 | E7: =Financials_Standalone!E76 -> 92.66 | F7: =Financials_Standalone!F76 -> 114.07 | G7: =Financials_Standalone!G76 -> 118.41 | I7: Other Operating Revenue | J7: =B7/B$5 -> 0.013267555 | K7: =C7/C$5 -> 0.014595689 | L7: =D7/D$5 -> 0.013888036 | M7: =E7/E$5 -> 0.01653335 | N7: =F7/F$5 -> 0.024483952 | O7: =G7/G$5 -> 0.024565575
A8: Net Revenue from Operations (A) | B8: =B5-B6+B7 -> 8846.15 | C8: =C5-C6+C7 -> 7871 | D8: =D5-D6+D7 -> 6767.51 | E8: =E5-E6+E7 -> 5697.09 | F8: =F5-F6+F7 -> 4773.04 | G8: =G5-G6+G7 -> 4938.57 | I8: Net Revenue from Operations (A) | J8: =B8/B$8 -> 1 | K8: =C8/C$8 -> 1 | L8: =D8/D$8 -> 1 | M8: =E8/E$8 -> 1 | N8: =F8/F$8 -> 1 | O8: =G8/G$8 -> 1
A10: Other Income (B) | B10: =Financials_Standalone!B78 -> 66.58 | C10: =Financials_Standalone!C78 -> 49.47 | D10: =Financials_Standalone!D78 -> 28.2 | E10: =Financials_Standalone!E78 -> 24.39 | F10: =Financials_Standalone!F78 -> 13.55 | G10: =Financials_Standalone!G78 -> 36.19 | I10: Other Income (B) | J10: =B10/B$5 -> 0.0076262955 | K10: =C10/C$5 -> 0.0063768325 | L10: =D10/D$5 -> 0.0042248394 | M10: =E10/E$5 -> 0.0043519145 | N10: =F10/F$5 -> 0.0029083682 | O10: =G10/G$5 -> 0.0075080495
A12: Less: Expenses | I12: Less: Expenses
A13: COGS | B13: =Financials_Standalone!B81 -> 5686.35 | C13: =Financials_Standalone!C81 -> 5086.76 | D13: =Financials_Standalone!D81 -> 4511.09 | E13: =Financials_Standalone!E81 -> 3745.18 | F13: =Financials_Standalone!F81 -> 2969.19 | G13: =Financials_Standalone!G81 -> 3000.67 | I13: Cost of Materials Consumed | J13: =B13/B$8 -> 0.64280506 | K13: =C13/C$8 -> 0.64626604 | L13: =D13/D$8 -> 0.66658047 | M13: =E13/E$8 -> 0.65738474 | N13: =F13/F$8 -> 0.62207524 | O13: =G13/G$8 -> 0.60759896
A14: Purchase Of Stock-In Trade | B14: =Financials_Standalone!B82 -> 70.67 | C14: =Financials_Standalone!C82 -> 60.38 | D14: =Financials_Standalone!D82 -> 63.91 | E14: =Financials_Standalone!E82 -> 54.07 | F14: =Financials_Standalone!F82 -> 44.6 | G14: =Financials_Standalone!G82 -> 27.84 | I14: Purchase Of Stock-In Trade | J14: =B14/B$8 -> 0.0079887861 | K14: =C14/C$8 -> 0.0076711981 | L14: =D14/D$8 -> 0.0094436506 | M14: =E14/E$8 -> 0.0094908102 | N14: =F14/F$8 -> 0.0093441496 | O14: =G14/G$8 -> 0.0056372594
A15: Changes In Inventories Of FG,WIP And Stock-In Trade | B15: =Financials_Standalone!B83 -> -28.57 | C15: =Financials_Standalone!C83 -> -6.44 | D15: =Financials_Standalone!D83 -> -42.4 | E15: =Financials_Standalone!E83 -> -40.93 | F15: =Financials_Standalone!F83 -> -44.43 | G15: =Financials_Standalone!G83 -> 18.81 | I15: Changes in Inventories | J15: =B15/B$8 -> -0.0032296536 | K15: =C15/C$8 -> -0.00081819337 | L15: =D15/D$8 -> -0.006265229 | M15: =E15/E$8 -> -0.0071843696 | N15: =F15/F$8 -> -0.0093085329 | O15: =G15/G$8 -> 0.0038087949
A16: Employee Benefit Expenses | B16: =Financials_Standalone!B84 -> 435.78 | C16: =Financials_Standalone!C84 -> 380.12 | D16: =Financials_Standalone!D84 -> 324.18 | E16: =Financials_Standalone!E84 -> 290.31 | F16: =Financials_Standalone!F84 -> 286.56 | G16: =Financials_Standalone!G84 -> 296.13 | I16: Employee Benefits Expenses | J16: =B16/B$8 -> 0.049262108 | K16: =C16/C$8 -> 0.048293737 | L16: =D16/D$8 -> 0.047902404 | M16: =E16/E$8 -> 0.050957594 | N16: =F16/F$8 -> 0.060037209 | O16: =G16/G$8 -> 0.059962702
A17: Finance Costs | B17: =Financials_Standalone!B85 -> 2.56 | C17: =Financials_Standalone!C85 -> 2.99 | D17: =Financials_Standalone!D85 -> 4.27 | E17: =Financials_Standalone!E85 -> 1.82 | F17: =Financials_Standalone!F85 -> 4.8 | G17: =Financials_Standalone!G85 -> 10.82 | I17: Finance costs | J17: =B17/B$8 -> 0.00028939143 | K17: =C17/C$8 -> 0.00037987549 | L17: =D17/D$8 -> 0.00063095585 | M17: =E17/E$8 -> 0.00031946134 | N17: =F17/F$8 -> 0.0010056484 | O17: =G17/G$8 -> 0.0021909176
A18: Depreciation And Amortisation Expenses | B18: =Financials_Standalone!B86 -> 289.65 | C18: =Financials_Standalone!C86 -> 262.52 | D18: =Financials_Standalone!D86 -> 240.71 | E18: =Financials_Standalone!E86 -> 203.74 | F18: =Financials_Standalone!F86 -> 203.42 | G18: =Financials_Standalone!G86 -> 199.25 | I18: Depreciation and Amortisation Expenses | J18: =B18/B$8 -> 0.032743058 | K18: =C18/C$8 -> 0.033352814 | L18: =D18/D$8 -> 0.035568473 | M18: =E18/E$8 -> 0.035762117 | N18: =F18/F$8 -> 0.042618541 | O18: =G18/G$8 -> 0.040345687
A19: Other Expenses | B19: =Financials_Standalone!B87 -> 1530.87 | C19: =Financials_Standalone!C87 -> 1343.86 | D19: =Financials_Standalone!D87 -> 1131.49 | E19: =Financials_Standalone!E87 -> 919.79 | F19: =Financials_Standalone!F87 -> 785.53 | G19: =Financials_Standalone!G87 -> 861.06 | I19: Other expenses | J19: =B19/B$8 -> 0.17305494 | K19: =C19/C$8 -> 0.17073561 | L19: =D19/D$8 -> 0.16719443 | M19: =E19/E$8 -> 0.16144909 | N19: =F19/F$8 -> 0.16457645 | O19: =G19/G$8 -> 0.17435411
A20: Less: Amounts Transfer To Capital Accounts | B20: =Financials_Standalone!B88 -> 0 | C20: =Financials_Standalone!C88 -> 0 | D20: =Financials_Standalone!D88 -> 0 | E20: =Financials_Standalone!E88 -> 0 | F20: =Financials_Standalone!F88 -> 0 | G20: =Financials_Standalone!G88 -> -8.26 | J20: =B20/B$8 -> 0 | K20: =C20/C$8 -> 0 | L20: =D20/D$8 -> 0 | M20: =E20/E$8 -> 0 | N20: =F20/F$8 -> 0 | O20: =G20/G$8 -> -0.0016725489
A21: Total Expenses (C) | B21: =SUM(B13:B20) -> 7987.31 | C21: =SUM(C13:C20) -> 7130.19 | D21: =SUM(D13:D20) -> 6233.25 | E21: =SUM(E13:E20) -> 5173.98 | F21: =SUM(F13:F20) -> 4249.67 | G21: =SUM(G13:G20) -> 4406.32 | I21: Total Expenses (C) | J21: =B21/B$8 -> 0.9029137 | K21: =C21/C$8 -> 0.90588108 | L21: =D21/D$8 -> 0.92105516 | M21: =E21/E$8 -> 0.90817944 | N21: =F21/F$8 -> 0.89034871 | O21: =G21/G$8 -> 0.89222589
A23: Profit before Taxes (D = A+B-C) | B23: =B8+B10-B21 -> 925.42 | C23: =C8+C10-C21 -> 790.28 | D23: =D8+D10-D21 -> 562.46 | E23: =E8+E10-E21 -> 547.5 | F23: =F8+F10-F21 -> 536.92 | G23: =G8+G10-G21 -> 568.44 | I23: Profit before Taxes (D = A+B-C) | J23: =B23/B$8 -> 0.10461274 | K23: =C23/C$8 -> 0.10040401 | L23: =D23/D$8 -> 0.083111809 | M23: =E23/E$8 -> 0.096101694 | N23: =F23/F$8 -> 0.11249015 | O23: =G23/G$8 -> 0.11510214
A25: Less: Taxes (E) | B25: =Financials_Standalone!B98 -> 229.4 | C25: =Financials_Standalone!C98 -> 202.47 | D25: =Financials_Standalone!D98 -> 143.26 | E25: =Financials_Standalone!E98 -> 134.3 | F25: =Financials_Standalone!F98 -> 133.5 | G25: =Financials_Standalone!G98 -> 140.75 | I25: Less: Taxes (E) | J25: =B25/B$8 -> 0.025932185 | K25: =C25/C$8 -> 0.025723542 | L25: =D25/D$8 -> 0.02116879 | M25: =E25/E$8 -> 0.023573438 | N25: =F25/F$8 -> 0.027969596 | O25: =G25/G$8 -> 0.028500153
A26: Extraordinary Items | B26: =Financials_Standalone!B92 -> -17.36 | C26: =Financials_Standalone!C92 -> 0 | D26: =Financials_Standalone!D92 -> -10.29 | E26: =Financials_Standalone!E92 -> -31.45 | F26: =Financials_Standalone!F92 -> -11.23 | G26: =Financials_Standalone!G92 -> 0 | I26: Extraordinary Items | J26: =B26/B$8 -> -0.0019624356 | K26: =C26/C$8 -> 0 | L26: =D26/D$8 -> -0.0015205002 | M26: =E26/E$8 -> -0.0055203621 | N26: =F26/F$8 -> -0.0023527982 | O26: =G26/G$8 -> 0
A28: Profit for the Year / Net Profit (D-E) | B28: =B23-B25+B26 -> 678.66 | C28: =C23-C25+C26 -> 587.81 | D28: =D23-D25+D26 -> 408.91 | E28: =E23-E25+E26 -> 381.75 | F28: =F23-F25+F26 -> 392.19 | G28: =G23-G25+G26 -> 427.69 | I28: Profit for the Year / Net Profit (D-E) | J28: =B28/B$8 -> 0.07671812 | K28: =C28/C$8 -> 0.074680473 | L28: =D28/D$8 -> 0.060422519 | M28: =E28/E$8 -> 0.067007894 | N28: =F28/F$8 -> 0.082167759 | O28: =G28/G$8 -> 0.086601992
B30: =Financials_Standalone!B101 -> 678.66 | C30: =Financials_Standalone!C101 -> 587.81 | D30: =Financials_Standalone!D101 -> 408.91 | E30: =Financials_Standalone!E101 -> 381.75 | F30: =Financials_Standalone!F101 -> 392.19 | G30: =Financials_Standalone!G101 -> 427.69
B31: =B28-B30 -> 0 | C31: =C28-C30 -> 0 | D31: =D28-D30 -> 0 | E31: =E28-E30 -> 0 | F31: =F28-F30 -> 0 | G31: =G28-G30 -> 0
G34: =C28*1.25/G28 -> 1.7179791

Sheet Common Size Analysis - BS_conso
A1: Endurance Technologies | I1: Endurance Technologies
A2: Balance Sheet | I2: Common-Size Balance Sheet
B3: 45717 | C3: 45352 | D3: 44986 | E3: 44621 | F3: 44256 | G3: 43891 | J3: 45717 | K3: 45352 | L3: 44986 | M3: 44621 | N3: 44256 | O3: 43891
A4: Assets | I4: Assets
A5: Non-Current Assets | B5: =B6+B13+B15+B16+B14+B12 -> 4204.87 | C5: =C6+C13+C15+C16+C14+C12 -> 3703.47 | D5: =D6+D13+D15+D16+D14+D12 -> 3220.56 | E5: =E6+E13+E15+E16+E14+E12 -> 2832.56 | F5: =F6+F13+F15+F16+F14+F12 -> 2669.37 | G5: =G6+G13+G15+G16+G14+G12 -> 2759.91 | I5: Non-Current Assets | J5: =B5/B$24 -> 0.47789239 | K5: =C5/C$24 -> 0.49423026 | L5: =D5/D$24 -> 0.50223706 | M5: =E5/E$24 -> 0.49852163 | N5: =F5/F$24 -> 0.47893103 | O5: =G5/G$24 -> 0.56238958
A6: Fixed Assets | B6: =SUM(B7:B10) -> 4010.61 | C6: =SUM(C7:C10) -> 3397.21 | D6: =SUM(D7:D10) -> 2923.73 | E6: =SUM(E7:E10) -> 2658.31 | F6: =SUM(F7:F10) -> 2524.75 | G6: =SUM(G7:G10) -> 2569.81 | I6: Fixed Assets | J6: =B6/B$24 -> 0.45581433 | K6: =C6/C$24 -> 0.45335969 | L6: =D6/D$24 -> 0.45594728 | M6: =E6/E$24 -> 0.46785418 | N6: =F6/F$24 -> 0.45298371 | O6: =G6/G$24 -> 0.52365272
A7: Tangible Assets | B7: =Financials_Consol!B30 -> 3612.46 | C7: =Financials_Consol!C30 -> 3133.65 | D7: =Financials_Consol!D30 -> 2634.68 | E7: =Financials_Consol!E30 -> 2455.82 | F7: =Financials_Consol!F30 -> 2350.93 | G7: =Financials_Consol!G30 -> 2410.42 | I7: Tangible Assets | J7: =B7/B$24 -> 0.41056374 | K7: =C7/C$24 -> 0.41818745 | L7: =D7/D$24 -> 0.41087076 | M7: =E7/E$24 -> 0.43221657 | N7: =F7/F$24 -> 0.4217974 | O7: =G7/G$24 -> 0.49117366
A8: Intangible Assets | B8: =Financials_Consol!B31 -> 105.18 | C8: =Financials_Consol!C31 -> 104.29 | D8: =Financials_Consol!D31 -> 118.16 | E8: =Financials_Consol!E31 -> 83.18 | F8: =Financials_Consol!F31 -> 77.66 | G8: =Financials_Consol!G31 -> 33.44 | I8: Intangible Assets | J8: =B8/B$24 -> 0.01195393 | K8: =C8/C$24 -> 0.013917562 | L8: =D8/D$24 -> 0.018426712 | M8: =E8/E$24 -> 0.014639418 | N8: =F8/F$24 -> 0.013933544 | O8: =G8/G$24 -> 0.0068141018
A9: Capital Work-In-Progress | B9: =Financials_Consol!B32 -> 290.15 | C9: =Financials_Consol!C32 -> 156.72 | D9: =Financials_Consol!D32 -> 168.36 | E9: =Financials_Consol!E32 -> 119.05 | F9: =Financials_Consol!F32 -> 92.99 | G9: =Financials_Consol!G32 -> 106.45 | I9: Intangible Assets under development | J9: =B9/B$24 -> 0.032976163 | K9: =C9/C$24 -> 0.020914377 | L9: =D9/D$24 -> 0.026255257 | M9: =E9/E$24 -> 0.020952425 | N9: =F9/F$24 -> 0.01668401 | O9: =G9/G$24 -> 0.021691421
A10: Intangible Assets Under Development | B10: =Financials_Consol!B33 -> 2.82 | C10: =Financials_Consol!C33 -> 2.55 | D10: =Financials_Consol!D33 -> 2.53 | E10: =Financials_Consol!E33 -> 0.26 | F10: =Financials_Consol!F33 -> 3.17 | G10: =Financials_Consol!G33 -> 19.5 | I10: Capital Work-in-Progress | J10: =B10/B$24 -> 0.00032049898 | K10: =C10/C$24 -> 0.00034029901 | L10: =D10/D$24 -> 0.00039454622 | M10: =E10/E$24 -> 4.575918e-05 | N10: =F10/F$24 -> 0.00056875269 | O10: =G10/G$24 -> 0.0039735342
A11: Other assets | B11: =Financials_Consol!B33 -> 2.82 | C11: =Financials_Consol!C33 -> 2.55 | D11: =Financials_Consol!D33 -> 2.53 | E11: =Financials_Consol!E33 -> 0.26 | F11: =Financials_Consol!F33 -> 3.17 | G11: =Financials_Consol!G33 -> 19.5 | I11: Other assets | J11: =B11/B$24 -> 0.00032049898 | K11: =C11/C$24 -> 0.00034029901 | L11: =D11/D$24 -> 0.00039454622 | M11: =E11/E$24 -> 4.575918e-05 | N11: =F11/F$24 -> 0.00056875269 | O11: =G11/G$24 -> 0.0039735342
A12: Goodwill on consolidation | B12: =Financials_Consol!B35 -> 0 | C12: =Financials_Consol!C35 -> 0 | D12: =Financials_Consol!D35 -> 0 | E12: =Financials_Consol!E35 -> 0 | F12: =Financials_Consol!F35 -> 0 | G12: =Financials_Consol!G35 -> 0 | I12: Goodwill on consolidation | J12: =B12/B$24 -> 0 | K12: =C12/C$24 -> 0 | L12: =D12/D$24 -> 0 | M12: =E12/E$24 -> 0 | N12: =F12/F$24 -> 0 | O12: =G12/G$24 -> 0
A13: Long-Term Investments | B13: =Financials_Consol!B36 -> 15.68 | C13: =Financials_Consol!C36 -> 27.52 | D13: =Financials_Consol!D36 -> 25.47 | E13: =Financials_Consol!E36 -> 1.19 | F13: =Financials_Consol!F36 -> 1.2 | G13: =Financials_Consol!G36 -> 1.19 | I13: Long-Term Investments | J13: =B13/B$24 -> 0.0017820652 | K13: =C13/C$24 -> 0.0036725603 | L13: =D13/D$24 -> 0.0039719732 | M13: =E13/E$24 -> 0.00020943625 | N13: =F13/F$24 -> 0.0002153007 | O13: =G13/G$24 -> 0.00024248747
A14: Deferred Tax Assets [Net] | B14: =Financials_Consol!B37 -> 69.51 | C14: =Financials_Consol!C37 -> 78.27 | D14: =Financials_Consol!D37 -> 71.98 | E14: =Financials_Consol!E37 -> 75.14 | F14: =Financials_Consol!F37 -> 60.24 | G14: =Financials_Consol!G37 -> 32.08 | I14: Deferred Tax Assets [Net] | J14: =B14/B$24 -> 0.0078999589 | K14: =C14/C$24 -> 0.010445178 | L14: =D14/D$24 -> 0.011225074 | M14: =E14/E$24 -> 0.013224403 | N14: =F14/F$24 -> 0.010808095 | O14: =G14/G$24 -> 0.0065369732
A15: Long-Term Loans & Advances | B15: =Financials_Consol!B38 -> 0 | C15: =Financials_Consol!C38 -> 0 | D15: =Financials_Consol!D38 -> 0 | E15: =Financials_Consol!E38 -> 0 | F15: =Financials_Consol!F38 -> 2.68 | G15: =Financials_Consol!G38 -> 156.83 | I15: Long-Term Loans & Advances | J15: =B15/B$24 -> 0 | K15: =C15/C$24 -> 0 | L15: =D15/D$24 -> 0 | M15: =E15/E$24 -> 0 | N15: =F15/F$24 -> 0.00048083824 | O15: =G15/G$24 -> 0.031957404
A16: Other Non-Current Assets | B16: =Financials_Consol!B39 -> 109.07 | C16: =Financials_Consol!C39 -> 200.47 | D16: =Financials_Consol!D39 -> 199.38 | E16: =Financials_Consol!E39 -> 97.92 | F16: =Financials_Consol!F39 -> 80.5 | G16: =Financials_Consol!G39 -> 0 | I16: Other Non-Current Assets | J16: =B16/B$24 -> 0.012396037 | K16: =C16/C$24 -> 0.02675284 | L16: =D16/D$24 -> 0.031092737 | M16: =E16/E$24 -> 0.017233611 | N16: =F16/F$24 -> 0.014443089 | O16: =G16/G$24 -> 0
A17: Current Assets | B17: =SUM(B18:B23) -> 4593.91 | C17: =SUM(C18:C23) -> 3789.94 | D17: =SUM(D18:D23) -> 3191.87 | E17: =SUM(E18:E23) -> 2849.36 | F17: =SUM(F18:F23) -> 2904.23 | G17: =SUM(G18:G23) -> 2147.56 | I17: Current Assets | J17: =B17/B$24 -> 0.52210761 | K17: =C17/C$24 -> 0.50576974 | L17: =D17/D$24 -> 0.49776294 | M17: =E17/E$24 -> 0.50147837 | N17: =F17/F$24 -> 0.52106897 | O17: =G17/G$24 -> 0.43761042
A18: Current Investments | B18: =Financials_Consol!B42 -> 787.93 | C18: =Financials_Consol!C42 -> 765.07 | D18: =Financials_Consol!D42 -> 646.37 | E18: =Financials_Consol!E42 -> 485.59 | F18: =Financials_Consol!F42 -> 443.14 | G18: =Financials_Consol!G42 -> 164.83 | I18: Current Investments | J18: =B18/B$24 -> 0.089549915 | K18: =C18/C$24 -> 0.10209904 | L18: =D18/D$24 -> 0.10079954 | M18: =E18/E$24 -> 0.085462309 | N18: =F18/F$24 -> 0.079506961 | O18: =G18/G$24 -> 0.033587572
A19: Inventories | B19: =Financials_Consol!B43 -> 936.37 | C19: =Financials_Consol!C43 -> 872.21 | D19: =Financials_Consol!D43 -> 820.58 | E19: =Financials_Consol!E43 -> 701.14 | F19: =Financials_Consol!F43 -> 611.85 | G19: =Financials_Consol!G43 -> 550.1 | I19: Inventories | J19: =B19/B$24 -> 0.10642044 | K19: =C19/C$24 -> 0.11639694 | L19: =D19/D$24 -> 0.12796709 | M19: =E19/E$24 -> 0.12339843 | N19: =F19/F$24 -> 0.10977645 | O19: =G19/G$24 -> 0.11209442
A20: Trade Receivables | B20: =Financials_Consol!B44 -> 1418.58 | C20: =Financials_Consol!C44 -> 1262.38 | D20: =Financials_Consol!D44 -> 1162.03 | E20: =Financials_Consol!E44 -> 970.37 | F20: =Financials_Consol!F44 -> 1040.98 | G20: =Financials_Consol!G44 -> 672.74 | I20: Trade Receivables | J20: =B20/B$24 -> 0.16122462 | K20: =C20/C$24 -> 0.16846536 | L20: =D20/D$24 -> 0.18121523 | M20: =E20/E$24 -> 0.17078206 | N20: =F20/F$24 -> 0.18676977 | O20: =G20/G$24 -> 0.13708489
A21: Cash and Cash Equivalents | B21: =Financials_Consol!B45 -> 1018.9 | C21: =Financials_Consol!C45 -> 504.68 | D21: =Financials_Consol!D45 -> 287.71 | E21: =Financials_Consol!E45 -> 402.64 | F21: =Financials_Consol!F45 -> 513.33 | G21: =Financials_Consol!G45 -> 620.95 | I21: Cash and Cash Equivalents | J21: =B21/B$24 -> 0.11580015 | K21: =C21/C$24 -> 0.067349845 | L21: =D21/D$24 -> 0.044867546 | M21: =E21/E$24 -> 0.07086337 | N21: =F21/F$24 -> 0.092100258 | O21: =G21/G$24 -> 0.12653159
A22: Short-Term Loans & Advances | B22: =Financials_Consol!B46 -> 3.36 | C22: =Financials_Consol!C46 -> 2 | D22: =Financials_Consol!D46 -> 1.65 | E22: =Financials_Consol!E46 -> 3.72 | F22: =Financials_Consol!F46 -> 5.32 | G22: =Financials_Consol!G46 -> 2.01 | I22: Short-Term Loans & Advances | J22: =B22/B$24 -> 0.00038187112 | K22: =C22/C$24 -> 0.00026690118 | L22: =D22/D$24 -> 0.00025731275 | M22: =E22/E$24 -> 0.00065470827 | N22: =F22/F$24 -> 0.00095449978 | O22: =G22/G$24 -> 0.00040957968
A23: Other Current Assets | B23: =Financials_Consol!B47 -> 428.77 | C23: =Financials_Consol!C47 -> 383.6 | D23: =Financials_Consol!D47 -> 273.53 | E23: =Financials_Consol!E47 -> 285.9 | F23: =Financials_Consol!F47 -> 289.61 | G23: =Financials_Consol!G47 -> 136.93 | I23: Other Current Assets | J23: =B23/B$24 -> 0.048730619 | K23: =C23/C$24 -> 0.051191647 | L23: =D23/D$24 -> 0.042656216 | M23: =E23/E$24 -> 0.050317498 | N23: =F23/F$24 -> 0.051961031 | O23: =G23/G$24 -> 0.027902361
A24: Total Assets | B24: =B5+B17 -> 8798.78 | C24: =C5+C17 -> 7493.41 | D24: =D5+D17 -> 6412.43 | E24: =E5+E17 -> 5681.92 | F24: =F5+F17 -> 5573.6 | G24: =G5+G17 -> 4907.47 | I24: Total Assets | J24: =J5+J17 -> 1 | K24: =K5+K17 -> 1 | L24: =L5+L17 -> 1 | M24: =M5+M17 -> 1 | N24: =N5+N17 -> 1 | O24: =O5+O17 -> 1
A25: Equity and Liabilities | I25: Equity and Liabilities
