Workbook

Sheet Assumptions
B2: Marjan Gulf Trading LLC (sample)
B3: Year ended: 31 December 2025
B4: DRAFT - 0 proposed adjustment(s) and 6 open item(s) awaiting confirmation. Figures are preliminary.
B5: Assumptions and Confirmations from Management
B6: The following assumptions and confirmations from management form the basis for the Corporate Tax computation presented in the following pages:
B8: Qualifying Free Zone Person | C8: The company is not claiming Qualifying Free Zone Person status.
B9: Realisation Basis | C9: The management has not elected the realisation basis; unrealised gains and losses are taken into account as recorded (current basis, Option 3).
B10: Transitional Rules | C10: The management has not claimed Transitional Rules.
B11: Expense Documentation | C11: The management has been informed of the requirement to maintain proper supporting documents for all expenses incurred by the company and recorded in the statement of profit and loss.
B12: Business Purpose of Expenses | C12: Management confirmation that all expenses were incurred wholly and exclusively for business purposes is outstanding.
B13: Disallowed Expenses | C13: Management confirmation that no other expenses of a disallowable nature are recorded is outstanding.
B14: Exempt Income | C14: Management confirmation of the exempt-income position is outstanding.
B15: Related Party Transactions | C15: Management confirmation that related party transactions are at arm's length is outstanding; no transfer pricing adjustment has been made.
B16: Investments in Subsidiary | C16: The position on investments in subsidiaries (including the basis of preparation of their accounts under Ministerial Decision No. 134 of 2023 and IFRS) has not been confirmed by management.
B18: Disclaimer This Corporate Tax computation has been prepared based on the information, documents, and explanations made available to us as of the date of this report. In the absence of formal confirmations and supporting evidence from the management, certain assumptions have been made in good faith to facilitate the preparation of this computation. These assumptions are outlined above. This computation is intended solely for internal use by the company for preliminary assessment purposes and does not constitute a final or binding tax filing with the Federal Tax Authority. We have not independently verified the completeness or accuracy of the financial information or the factual representations provided by the management. We do not express an audit or assurance opinion on the financial information or tax positions. Any deviation from the stated assumptions or changes in the applicable laws, guidance, or interpretations by the authorities may impact the final tax liability of the company. The responsibility for ensuring the accuracy and completeness of the information submitted to the FTA, including compliance with Corporate Tax regulations, rests solely with the company’s management. We recommend that the company obtain formal tax advice where necessary and maintain adequate documentation to support its tax positions in line with the requirements of the UAE Corporate Tax Law and relevant Executive Regulations.
B21: Sheet applicability log
B22: Assumptions | C22: Included - Always produced
B23: Calculation of CT | C23: Included - Always produced
B24: Profit and Loss | C24: Included - Always produced - AED
B25: Balance Sheet | C25: Included - Always produced - AED
B26: FX Rates | C26: Not applicable, not produced - TB is already in AED - no conversion sheet needed
B27: TB (AED) | C27: Included - Source of the P&L and balance sheet
B28: Adjustments | C28: Included - Confirmed adjustments feed the computation
B29: UGUL | C29: Not applicable, not produced - No realisation-basis election confirmed
B30: Provision | C30: Included - Provision accounts or movements exist
B31: DTA & DTL Working | C31: Not applicable, not produced - Optional accounting working - not requested
B32: Tax Loss Carried Forward | C32: Not applicable, not produced - No tax losses involved
B33: Disallowed Expenses | C33: Included - Confirmed non-deductible expenses exist
... B35: Taxes Paid Abroad | C35: Not applicable, not produced - No foreign tax reported
B37: Template changes
B38: - | C38: Removed 27,709 stale defined names carried inside the template (leftovers from unrelated workbooks, mostly #REF!).
B39: - | C39: Sheet 'UGUL' omitted: No realisation-basis election confirmed.
B40: - | C40: Sheet 'DTA & DTL Working' omitted: Optional accounting working - not requested.
B41: - | C41: Sheet 'Tax Loss Carried Forward' omitted: No tax losses involved.
B42: - | C42: Sheet 'Freezone' omitted: QFZP not claimed.
B43: - | C43: Sheet 'Taxes Paid Abroad' omitted: No foreign tax reported.

Sheet Calculation of CT
C2: =+Assumptions!B2
C3: =+Assumptions!B3
C5: Basis of Accounting | D5: Accrual Basis
C6: Accounting Standards | D6: IFRS
C7: Related Party Transactions | D7: Not confirmed
C8: DRAFT - 0 proposed adjustment(s) await approval; 6 open item(s). Only confirmed adjustments are included below.
C9: COMPUTATION OF TAXABLE INCOME/(LOSS) (based on draft FS provided by the management) | E9: Current Basis Option 3 (AED) | I9: Comments
C11: Accounting Net Profit/(Loss) | D11: A | E11: ='Profit and Loss'!$D$30 | I11: Current basis - no election
I12: Transitional Rule - No
B13: Deduct: | C13: Exempt Income/Other adjustments | I13: Source: Marjan_Gulf_Trading_TB_31Dec2025.xlsx (AED)
C14: Unrealised gains on capital items (Options 1 & 2) | E14: 0
C15: Unrealised gains on revenue items (Option 1): | E15: 0
C16: Income from Qualifying Activity (Holding of shares for investment purposes) | E16: 0
C17: Dividends & profit distributions received from resident juridical person | E17: =SUMIF(Adjustments!$B$6:$B$10,"d_dividends_resident",Adjustments!$E$6:$E$10) | I17: Dividend from UAE resident juridical person - Dividend
C18: Income from Participating Interest (Dividend / Capital Gains) | E18: 0
C19: Income form foreign Permanent Establishment (subject to election) | E19: 0
C20: Income from operating aircraft/ships in international transportation (For Non-residents only) | E20: 0
C21: Gain from transfers within a qualifying group | E21: 0
C22: Gain from qualified business restructuring | E22: 0
C23: Other Adjustments to the Accounting Income for Determining the Taxable Income specified in MD No. 134 | E23: 0
E24: 0
C25: Total Deductions | D25: B | E25: =SUM(E14:E24)
B27: Add: | C27: Non-deductible Expenses/Other adjustments:
C28: Unrealised loss on capital items (Options 1 & 2) | E28: 0
C29: Unrealised loss on revenue items (Option 1) | E29: 0
C30: Loss from Qualifying Activity (Holding of shares for investment purposes) | E30: 0
C31: Expenses of capital nature | E31: 0
C32: Expenses incurred in deriving Exempt Income | E32: 0
C33: Expenses not incurred for the purposes of the Taxable Person’s Business | E33: =SUMIF(Adjustments!$B$6:$B$10,"a_non_business",Adjustments!$E$6:$E$10) | I33: Personal / owner expenses - Director personal expenses
C34: Losses not connected with or arising out of the Taxable Person’s Business | E34: 0
C35: Interest charged in excess of allowable limit | E35: 0
C36: Non-deductible interest | E36: 0
C37: 50% of any entertainment, amusement or recreation expenses incurred for Taxable Person’s customers, shareholders, suppliers or other business partners | E37: =SUMIF(Adjustments!$B$6:$B$10,"a_entertainment",Adjustments!$E$6:$E$10) | I37: Entertainment / hospitality - Client entertainment and
C38: Donations, grants or gifts made to a non-Qualifying Public Benefit Entity | E38: =SUMIF(Adjustments!$B$6:$B$10,"a_donations",Adjustments!$E$6:$E$10) | I38: Donations / charitable - Donations
C39: Fines and penalties, other than amounts awarded as compensation for damages or breach of contract | E39: =SUMIF(Adjustments!$B$6:$B$10,"a_fines",Adjustments!$E$6:$E$10) | I39: Fines and penalties - Fines and penalties
C40: Expenses without Supporting Documents | E40: 0
C41: Dividends, profit distributions or benefits of a similar nature paid to an owner of the Taxable Person | E41: 0
C42: Amounts withdrawn from the business by a natural person who is a Taxable Person or a partner in an Unincorporated Partnership | E42: 0
C43: Corporate Tax imposed on a Taxable Person as per the applicable Law | E43: 0
C44: Input Value Added Tax incurred by a Taxable Person that is recoverable as per the applicable Law | E44: 0
...

Sheet Profit and Loss
B1: ='Calculation of CT'!$C$2
B2: ='Calculation of CT'!$C$3
B3: Statement of profit or loss (AED) - prepared from the trial balance; income positive, expenses negative
B5: Line | C5: Source accounts (see TB (AED) sheet) | D5: AED
B6: Revenue | C6: Sales - goods; Service revenue | D6: =-SUMIFS('TB (AED)'!$L$6:$L$51,'TB (AED)'!$D$6:$D$51,"P_REV")
B7: Cost of sales | C7: Cost of goods sold | D7: =-SUMIFS('TB (AED)'!$L$6:$L$51,'TB (AED)'!$D$6:$D$51,"P_COS")
B8: Gross profit | D8: =D6+D7
B9: Other income
B10: Dividend income | C10: Dividend income - Marjan Logistics FZE | D10: =-SUMIFS('TB (AED)'!$L$6:$L$51,'TB (AED)'!$D$6:$D$51,"P_DIV")
B11: Interest income | C11: Interest income - bank deposits | D11: =-SUMIFS('TB (AED)'!$L$6:$L$51,'TB (AED)'!$D$6:$D$51,"P_INT_INC")
B12: Fair value gain/(loss) on investments | C12: Unrealised gain on fair value of investments | D12: =-SUMIFS('TB (AED)'!$L$6:$L$51,'TB (AED)'!$D$6:$D$51,"P_FV")
B13: Total other income | D13: =D10+D11+D12
B14: Operating expenses
B15: Staff costs | C15: Salaries and wages; Staff end of service benefit expense | D15: =-SUMIFS('TB (AED)'!$L$6:$L$51,'TB (AED)'!$D$6:$D$51,"P_STAFF")
B16: Audit, legal and professional fees | C16: Professional and legal fees | D16: =-SUMIFS('TB (AED)'!$L$6:$L$51,'TB (AED)'!$D$6:$D$51,"P_PROF")
B17: Bank fees and charges | C17: Bank charges | D17: =-SUMIFS('TB (AED)'!$L$6:$L$51,'TB (AED)'!$D$6:$D$51,"P_BANK")
B18: Rent and premises | C18: Office rent; Telephone and utilities | D18: =-SUMIFS('TB (AED)'!$L$6:$L$51,'TB (AED)'!$D$6:$D$51,"P_RENT")
B19: Marketing, promotion and commissions | C19: Marketing and advertising | D19: =-SUMIFS('TB (AED)'!$L$6:$L$51,'TB (AED)'!$D$6:$D$51,"P_MKT")
B20: Entertainment, events and gifts | C20: Client entertainment and hospitality | D20: =-SUMIFS('TB (AED)'!$L$6:$L$51,'TB (AED)'!$D$6:$D$51,"P_ENT")
B21: Donations | C21: Donations | D21: =-SUMIFS('TB (AED)'!$L$6:$L$51,'TB (AED)'!$D$6:$D$51,"P_DON")
B22: Fines and penalties | C22: Fines and penalties | D22: =-SUMIFS('TB (AED)'!$L$6:$L$51,'TB (AED)'!$D$6:$D$51,"P_FINES")
B23: Provisions, impairments and bad debts | C23: Impairment of trade receivables - provision for doubtful debts | D23: =-SUMIFS('TB (AED)'!$L$6:$L$51,'TB (AED)'!$D$6:$D$51,"P_PROV")
B24: General and administrative expenses (other) | C24: Repairs and maintenance; Management fee - Marjan Holdings LLC; Director personal expenses ... | D24: =-SUMIFS('TB (AED)'!$L$6:$L$51,'TB (AED)'!$D$6:$D$51,"P_GEN")
B25: Total operating expenses | D25: =D15+D16+D17+D18+D19+D20+D21+D22+D23+D24
B26: Depreciation and amortisation | C26: Depreciation expense | D26: =-SUMIFS('TB (AED)'!$L$6:$L$51,'TB (AED)'!$D$6:$D$51,"P_DEP")
B27: Finance costs | C27: Interest expense - shareholder loan; Interest expense - bank term loan | D27: =-SUMIFS('TB (AED)'!$L$6:$L$51,'TB (AED)'!$D$6:$D$51,"P_FIN")
B28: Foreign exchange (gain)/loss | C28: Foreign exchange gain; Foreign exchange loss | D28: =-SUMIFS('TB (AED)'!$L$6:$L$51,'TB (AED)'!$D$6:$D$51,"P_FX")
B29: Profit/(loss) before tax | D29: =D8+D13+D25+D26+D27+D28
B30: Profit/(loss) for the year | D30: =D29

Sheet Balance Sheet
B1: ='Calculation of CT'!$C$2
B2: Statement of financial position (AED) - at 31 December 2025
B3: Assets are not split into current / non-current: the TB does not support that classification.
B5: Line | C5: Source accounts (see TB (AED) sheet) | D5: AED
B6: ASSETS
B7: Cash, bank balances and deposits | C7: Cash on hand; Emirates NBD - current account | D7: =SUMIFS('TB (AED)'!$L$6:$L$51,'TB (AED)'!$D$6:$D$51,"A_CASH")
B8: Investments (funds, shares and other securities) | C8: Investments at fair value through profit or loss - quoted equities | D8: =SUMIFS('TB (AED)'!$L$6:$L$51,'TB (AED)'!$D$6:$D$51,"A_FIN_INV")
B9: Investments in entities (subsidiaries / associates - to be confirmed) | C9: Investment in subsidiary - Marjan Logistics FZE | D9: =SUMIFS('TB (AED)'!$L$6:$L$51,'TB (AED)'!$D$6:$D$51,"A_SUB_INV")
B10: Due from related parties | C10: Due from related party - Marjan Holdings LLC | D10: =SUMIFS('TB (AED)'!$L$6:$L$51,'TB (AED)'!$D$6:$D$51,"A_RP")
B11: Trade and other receivables | C11: Trade receivables; Allowance for doubtful debts; Prepayments and deposits | D11: =SUMIFS('TB (AED)'!$L$6:$L$51,'TB (AED)'!$D$6:$D$51,"A_TRADE_REC")
B12: Inventories | C12: Inventory | D12: =SUMIFS('TB (AED)'!$L$6:$L$51,'TB (AED)'!$D$6:$D$51,"A_INV")
B13: Property and equipment | C13: Furniture and equipment - cost; Accumulated depreciation | D13: =SUMIFS('TB (AED)'!$L$6:$L$51,'TB (AED)'!$D$6:$D$51,"A_PPE")
B14: Total assets | D14: =D7+D8+D9+D10+D11+D12+D13
B15: LIABILITIES
B16: Trade and other payables | C16: Trade payables; Accrued expenses; VAT payable | D16: =-SUMIFS('TB (AED)'!$L$6:$L$51,'TB (AED)'!$D$6:$D$51,"L_TRADE_PAY")
B17: Due to related parties | C17: Loan from shareholder - Marjan Holdings LLC | D17: =-SUMIFS('TB (AED)'!$L$6:$L$51,'TB (AED)'!$D$6:$D$51,"L_RP")
B18: Borrowings | C18: Bank term loan | D18: =-SUMIFS('TB (AED)'!$L$6:$L$51,'TB (AED)'!$D$6:$D$51,"L_BORR")
B19: Employees' end of service benefits | C19: Provision for employees' end of service benefits | D19: =-SUMIFS('TB (AED)'!$L$6:$L$51,'TB (AED)'!$D$6:$D$51,"L_EOSB")
B20: Total liabilities | D20: =D16+D17+D18+D19
B21: EQUITY
B22: Share capital | C22: Share capital | D22: =-SUMIFS('TB (AED)'!$L$6:$L$51,'TB (AED)'!$D$6:$D$51,"E_CAPITAL")
B23: Retained earnings (brought forward) | C23: Retained earnings - opening | D23: =-SUMIFS('TB (AED)'!$L$6:$L$51,'TB (AED)'!$D$6:$D$51,"E_RE")
B24: Profit/(loss) for the year (from the P&L) | D24: ='Profit and Loss'!$D$30
B25: Total equity | D25: =D22+D23+D24
B26: Total liabilities and equity | D26: =D20+D25
B28: Check: total assets less total liabilities and equity | C28: =IF(ABS(D28)<0.5,"Balances","DOES NOT BALANCE - review") | D28: =D14-D26

Sheet Adjustments
A1: ='Calculation of CT'!$C$2
A2: ='Calculation of CT'!$C$3
A4: Schedule of confirmed tax adjustments (AED) - feeds the Calculation of CT sheet
A5: Ref | B5: Row key | C5: Calc. row | D5: Description | E5: Amount (AED) | F5: Source account(s) | G5: Basis / reason | H5: Rule ref | I5: Supporting reference | J5: Management response | K5: Reviewer
A6: d_dividends_resident:4200 | B6: d_dividends_resident | C6: 17 | D6: Dividend from UAE resident juridical person - Dividend income - Marjan Logistics FZE | E6: 400000 | F6: Dividend income - Marjan Logistics FZE | G6: Payer: (UAE resident juridical person). | H6: PE-01 | I6: Dividend voucher
A7: a_non_business:6140 | B7: a_non_business | C7: 33 | D7: Personal / owner expenses - Director personal expenses | E7: 42000 | F7: Director personal expenses | G7: Proposed from the account name ('Personal / owner expenses') - not confirmed. | H7: NDE-01 | I7: Business purpose for each item; Supporting invoices | J7: disallowed | K7: [override: Disallowed]
A8: a_entertainment:6020 | B8: a_entertainment | C8: 37 | D8: Entertainment / hospitality - Client entertainment and hospitality | E8: 35000 | F8: Client entertainment and hospitality | G8: 50% of entertainment (net of any staff-only share) proposed - restriction applies to customers, shareholders, suppliers and business partners. | H8: NDE-01 | I8: Invoices and proof of payment; Attendee list and business purpose | J8: 50% Disallowed
A9: a_donations:6030 | B9: a_donations | C9: 38 | D9: Donations / charitable - Donations | E9: 75000 | F9: Donations | G9: Donations proposed as non-deductible unless the recipient is a Qualifying Public Benefit Entity. | H9: NDE-01 | I9: Recipient name and proof of Qualifying Public Benefit Entity status; Receipts
A10: a_fines:6040 | B10: a_fines | C10: 39 | D10: Fines and penalties - Fines and penalties | E10: 28000 | F10: Fines and penalties | G10: Fines and penalties proposed as non-deductible except amounts that are compensation for damages or breach of contract. | H10: NDE-01 | I10: Notice or order giving rise to each fine/penalty; Nature (regulatory vs contractual compensation)
D11: Total (Σ with sign by row type - see Calculation of CT)

Sheet Disallowed Expenses
A1: ='Calculation of CT'!$C$2
A2: ='Calculation of CT'!$C$3
A4: Details of Non-Deductible Expenses (confirmed adjustments)
A6: 50% of entertainment, amusement or recreation expenses
A7: Account ID | B7: G/L account | C7: Description | D7: Disallowed (AED) | E7: Treatment | F7: Reference
A8: 6020 | B8: Client entertainment and hospitality | C8: Entertainment / hospitality - Client entertainment and hospitality | D8: 35000 | E8: 50% disallowed | F8: NDE-01
A9: Sub total | D9: =SUM(D8:D8)
A11: Donations, grants or gifts made to a non-Qualifying Public Benefit Entity
A12: Account ID | B12: G/L account | C12: Description | D12: Disallowed (AED) | E12: Treatment | F12: Reference
A13: 6030 | B13: Donations | C13: Donations / charitable - Donations | D13: 75000 | E13: 100% disallowed | F13: NDE-01
A14: Sub total | D14: =SUM(D13:D13)
A16: Fines and penalties, other than amounts awarded as compensation
A17: Account ID | B17: G/L account | C17: Description | D17: Disallowed (AED) | E17: Treatment | F17: Reference
A18: 6040 | B18: Fines and penalties | C18: Fines and penalties - Fines and penalties | D18: 28000 | E18: 100% disallowed | F18: NDE-01
A19: Sub total | D19: =SUM(D18:D18)
A21: Expenses not incurred for the purposes of the Taxable Person's Business
A22: Account ID | B22: G/L account | C22: Description | D22: Disallowed (AED) | E22: Treatment | F22: Reference
A23: 6140 | B23: Director personal expenses | C23: Personal / owner expenses - Director personal expenses | D23: 42000 | E23: Disallowed | F23: NDE-01
A24: Sub total | D24: =SUM(D23:D23)
A26: Total disallowed expenses on this sheet | D26: =D9+D14+D19+D24
A27: Check: agrees to Calculation of CT | D27: =IF(ABS(D26-('Calculation of CT'!E33+'Calculation of CT'!E37+'Calculation of CT'!E38+'Calculation of CT'!E39))<0.5,"OK","CHECK")

Sheet Provision
B1: ='Calculation of CT'!$C$2
B2: ='Calculation of CT'!$C$3
B3: Movement in provisions
H4: (Amounts in AED)
A5: S/N | B5: Provision | C5: Ref. | D5: Balance at the beginning | E5: Provisions made | F5: Provisions utilised | G5: Adjustments / reversals | H5: Balance at the end
B6: Total | D6: 0 | E6: 0 | F6: 0 | G6: 0 | H6: 0
B7: No provision schedule was provided; provision accounts exist in the TB - complete the schedule.
B9: Calculation of disallowed provisions (provisions other than end-of-service / indemnity)
A11: S/N | B11: Provision | C11: Ref. | D11: Provisions made | E11: Adjustments | F11: Disallowed
B12: Total disallowed (Option 1 / scope A) | F12: 0
B13: Applied in the computation only where the realisation basis (scope A) is elected and the adjustment is confirmed.

Sheet TB (AED)
A1: ='Calculation of CT'!$C$2
A2: Trial balance - source currency (AED) and AED translation
A3: Blue = typed from the source TB; black = formula. Mapped line keys drive the P&L and balance sheet (SUMIFS on column D).
A5: Code | B5: Account | C5: Source class. | D5: Line key | E5: Mapped to | F5: Method | G5: Debit (AED) | H5: Credit (AED) | I5: Net (AED) | J5: Rate to AED | K5: Rate basis | L5: Net (AED) | M5: Debit (AED) | N5: Credit (AED) | O5: Review flags
A6: 1010 | B6: Cash on hand | D6: A_CASH | E6: Cash, bank balances and deposits | F6: rule | G6: 15000 | H6: 0 | I6: =G6-H6 | J6: 1 | K6: AED - no conversion | L6: =I6*J6 | M6: =MAX(L6,0) | N6: =MAX(-L6,0)
A7: 1020 | B7: Emirates NBD - current account | D7: A_CASH | E7: Cash, bank balances and deposits | F7: rule | G7: 2850000 | H7: 0 | I7: =G7-H7 | J7: 1 | K7: AED - no conversion | L7: =I7*J7 | M7: =MAX(L7,0) | N7: =MAX(-L7,0)
A8: 1100 | B8: Trade receivables | D8: A_TRADE_REC | E8: Trade and other receivables | F8: rule | G8: 3200000 | H8: 0 | I8: =G8-H8 | J8: 1 | K8: AED - no conversion | L8: =I8*J8 | M8: =MAX(L8,0) | N8: =MAX(-L8,0)
A9: 1110 | B9: Allowance for doubtful debts | D9: A_TRADE_REC | E9: Trade and other receivables | F9: rule | G9: 0 | H9: 180000 | I9: =G9-H9 | J9: 1 | K9: AED - no conversion | L9: =I9*J9 | M9: =MAX(L9,0) | N9: =MAX(-L9,0)
A10: 1200 | B10: Due from related party - Marjan Holdings LLC | D10: A_RP | E10: Due from related parties | F10: rule | G10: 750000 | H10: 0 | I10: =G10-H10 | J10: 1 | K10: AED - no conversion | L10: =I10*J10 | M10: =MAX(L10,0) | N10: =MAX(-L10,0)
A11: 1300 | B11: Prepayments and deposits | D11: A_TRADE_REC | E11: Trade and other receivables | F11: rule | G11: 240000 | H11: 0 | I11: =G11-H11 | J11: 1 | K11: AED - no conversion | L11: =I11*J11 | M11: =MAX(L11,0) | N11: =MAX(-L11,0)
A12: 1400 | B12: Investment in subsidiary - Marjan Logistics FZE | D12: A_SUB_INV | E12: Investments in entities (subsidiaries / associates - to be confirmed) | F12: rule | G12: 1500000 | H12: 0 | I12: =G12-H12 | J12: 1 | K12: AED - no conversion | L12: =I12*J12 | M12: =MAX(L12,0) | N12: =MAX(-L12,0)
A13: 1410 | B13: Investments at fair value through profit or loss - quoted equities | D13: A_FIN_INV | E13: Investments (funds, shares and other securities) | F13: rule | G13: 900000 | H13: 0 | I13: =G13-H13 | J13: 1 | K13: AED - no conversion | L13: =I13*J13 | M13: =MAX(L13,0) | N13: =MAX(-L13,0)
A14: 1500 | B14: Furniture and equipment - cost | D14: A_PPE | E14: Property and equipment | F14: rule | G14: 1400000 | H14: 0 | I14: =G14-H14 | J14: 1 | K14: AED - no conversion | L14: =I14*J14 | M14: =MAX(L14,0) | N14: =MAX(-L14,0)
A15: 1510 | B15: Accumulated depreciation | D15: A_PPE | E15: Property and equipment | F15: rule | G15: 0 | H15: 560000 | I15: =G15-H15 | J15: 1 | K15: AED - no conversion | L15: =I15*J15 | M15: =MAX(L15,0) | N15: =MAX(-L15,0)
A16: 1600 | B16: Inventory | D16: A_INV | E16: Inventories | F16: rule | G16: 2100000 | H16: 0 | I16: =G16-H16 | J16: 1 | K16: AED - no conversion | L16: =I16*J16 | M16: =MAX(L16,0) | N16: =MAX(-L16,0)
A17: 2000 | B17: Trade payables | D17: L_TRADE_PAY | E17: Trade and other payables | F17: rule | G17: 0 | H17: 1900000 | I17: =G17-H17 | J17: 1 | K17: AED - no conversion | L17: =I17*J17 | M17: =MAX(L17,0) | N17: =MAX(-L17,0)
... A51: 6180 | B51: Travel and accommodation | D51: P_GEN | E51: General and administrative expenses (other) | F51: rule | G51: 130000 | H51: 0 | I51: =G51-H51 | J51: 1 | K51: AED - no conversion | L51: =I51*J51 | M51: =MAX(L51,0) | N51: =MAX(-L51,0)
B52: Total | G52: =SUM(G6:G51) | H52: =SUM(H6:H51) | I52: =SUM(I6:I51) | L52: =SUM(L6:L51) | M52: =SUM(M6:M51) | N52: =SUM(N6:N51)
B53: Check: AED net must be nil | L53: =IF(ABS(L52)<0.5,"OK","CHECK")
