Workbook

Sheet Balance Sheet
A1: Rajasthan Precision Private Limited
A2: Balance Sheet as at 31/03/2026
A3: (Rs in lakhs, rounded off as required by Schedule III)
A5: Particulars | B5: Note | C5: As at 31/03/2026 | D5: As at 31/03/2025
A6: EQUITY AND LIABILITIES
A7: 1. Shareholders' funds
A8: (a) Share capital | B8: 1 | C8: =Notes!B6 -> 29.3 | D8: =Notes!C6 -> 29.3
A9: (b) Reserves and surplus | B9: 2 | C9: =Notes!B19 -> 51.06 | D9: =Notes!C19 -> 33.34
A10: 2. Non-current liabilities
A11: (a) Long-term borrowings [R17, R18] | B11: 3 | C11: =Notes!B27 -> 15.5 | D11: =Notes!C27 -> 15.5
A12: 3. Current liabilities
A13: (a) Trade payables [R4, R8, R13, R14, R15] | B13: 4 | C13: =Notes!B35 -> 138.56 | D13: =Notes!C35 -> 65.01
A14: (b) Other current liabilities [R11, R12] | B14: 5 | C14: =Notes!B45 -> 15.69 | D14: =Notes!C45 -> 7.71
A15: TOTAL EQUITY AND LIABILITIES | C15: =SUM(C7:C14) -> 250.11 | D15: =SUM(D7:D14) -> 150.86
A16: ASSETS
A17: 1. Non-current assets
A18: (a) Property, plant and equipment and intangible assets
A19: (i) Property, plant and equipment | B19: 6 | C19: =Notes!B56 -> 22.67 | D19: =Notes!C56 -> 24.47
A20: 2. Current assets
A21: (a) Inventories [R1] | B21: 7 | C21: =Notes!B74 -> 10.75 | D21: =Notes!C74 -> 10.75
A22: (b) Trade receivables [R2, R7, R9, R10, R16] | B22: 8 | C22: =Notes!B81 -> 179.23 | D22: =Notes!C81 -> 86.12
A23: (c) Cash and bank balances [R6] | B23: 9 | C23: =Notes!B91 -> 37.46 | D23: =Notes!C91 -> 29.52
A24: TOTAL ASSETS | C24: =SUM(C17:C23) -> 250.11 | D24: =SUM(D17:D23) -> 150.86
A26: Check: total assets less total equity and liabilities | C26: =C24-C15 -> 0 | D26: =D24-D15 -> 0
A28: DRAFT: generated from Tally data for review. Unaudited. Items marked [R#] need a reviewer's decision.
A30: For XYZ Chartered Accountants | C30: For and on behalf of the Board of Directors of
A31: Chartered Accountants | C31: Rajasthan Precision Private Limited
A32: Firm Registration No.: 1111111
C33: Director: QWE
A34: Partner: ABC | C34: DIN: 89766654
A35: Membership No.: 234543 | C35: Director: DFG
A36: Place: Indore | C36: DIN: 77654354
A37: Date of signing: 23/10/2026 | C37: Date of signing: 23/10/2026

Sheet P&L
A1: Rajasthan Precision Private Limited
A2: Statement of Profit and Loss for the year ended 31/03/2026
A3: (Rs in lakhs, rounded off as required by Schedule III)
A5: Particulars | B5: Note | C5: Year ended 31/03/2026 | D5: Year ended 31/03/2025
A6: I. Revenue from operations | B6: 10 | C6: =Notes!B98 -> 127.29 | D6: -
A7: II. Other income | B7: 11 | C7: =Notes!B106 -> 0.87 | D7: -
A8: III. Total income (I + II) | C8: =C6+C7 -> 128.16 | D8: -
A9: IV. Expenses:
A10: Cost of materials consumed | B10: 12 | C10: =Notes!B111 -> 89.43 | D10: -
A11: Employee benefit expense [R5] | B11: 13 | C11: =Notes!B118 -> 3.79 | D11: -
A12: Finance costs | B12: 14 | C12: =Notes!B123 -> 0.77 | D12: -
A13: Depreciation and amortisation expense | B13: 15 | C13: =Notes!B128 -> 1.8 | D13: -
A14: Other expenses [R3] | B14: 16 | C14: =Notes!B144 -> 14.65 | D14: -
A15: Total expenses | C15: =SUM(C10:C14) -> 110.44 | D15: -
A16: V. Profit / (loss) before tax (III - IV) | C16: =C8-C15 -> 17.72 | D16: -
A17: VI. Tax expense:
A18: (1) Current tax | C18: 0 | D18: -
A19: (2) Deferred tax | C19: 0 | D19: -
A20: VII. Profit / (loss) for the year (V - VI) | C20: =C16-C18-C19 -> 17.72 | D20: -
A21: VIII. Earnings per equity share (Rs): to be computed
A23: Previous-year figures were not loaded; see open item O1.
A25: For XYZ Chartered Accountants | C25: For and on behalf of the Board of Directors of
A26: Chartered Accountants | C26: Rajasthan Precision Private Limited
A27: Firm Registration No.: 1111111
C28: Director: QWE
A29: Partner: ABC | C29: DIN: 89766654
A30: Membership No.: 234543 | C30: Director: DFG
A31: Place: Indore | C31: DIN: 77654354
A32: Date of signing: 23/10/2026 | C32: Date of signing: 23/10/2026

Sheet Cash Flow
A1: Rajasthan Precision Private Limited
A2: Cash Flow Statement for the year ended 31/03/2026
A3: (Rs in lakhs, rounded off as required by Schedule III)
A5: Particulars | C5: Year ended 31/03/2026 | D5: Year ended 31/03/2025
A6: A. CASH FLOW FROM OPERATING ACTIVITIES
A7: Net profit / (loss) before tax | C7: ='P&L'!C16 -> 17.72 | D7: -
A8: Adjustments for:
A9: Depreciation and amortisation expense | C9: 1.8 | D9: -
A10: Finance costs | C10: 0.77 | D10: -
A11: Interest income | C11: -0.53 | D11: -
A12: Operating profit before working capital changes | C12: =SUM(C7:C11) -> 19.76 | D12: -
A13: Adjustments for changes in working capital:
A14: (Increase) / decrease in trade receivables | C14: -93.11 | D14: -
A15: Increase / (decrease) in trade payables | C15: 73.55 | D15: -
A16: Increase / (decrease) in other liabilities and provisions | C16: 7.98 | D16: -
A17: Cash generated from operations | C17: =C12+SUM(C13:C16) -> 8.18 | D17: -
A18: Direct taxes paid (net of refunds) | C18: 0 | D18: -
A19: Net cash from / (used in) operating activities (A) | C19: =C17+C18 -> 8.18 | D19: -
A20: B. CASH FLOW FROM INVESTING ACTIVITIES
A21: Interest received | C21: 0.53 | D21: -
A22: Net cash from / (used in) investing activities (B) | C22: =SUM(C21:C21) -> 0.53 | D22: -
A23: C. CASH FLOW FROM FINANCING ACTIVITIES
A24: Finance costs paid | C24: -0.77 | D24: -
A25: Net cash from / (used in) financing activities (C) | C25: =SUM(C24:C24) -> -0.77 | D25: -
A26: D. NET INCREASE / (DECREASE) IN CASH AND CASH EQUIVALENTS (A + B + C) | C26: =C19+C22+C25 -> 7.94 | D26: -
A27: Cash and cash equivalents at the beginning of the year | C27: =D33 -> 24.52 | D27: -
A28: Cash and cash equivalents at the end of the year | C28: =C27+C26 -> 32.46 | D28: -
A30: Cash and cash equivalents comprise: | C30: As at 31/03/2026 | D30: As at 31/03/2025
A31: Balances with banks (current accounts) | C31: 32.18 | D31: 24.17
A32: Cash on hand | C32: 0.28 | D32: 0.35
A33: Total | C33: =SUM(C31:C32) -> 32.46 | D33: =SUM(D31:D32) -> 24.52
A34: Check: closing cash less cash and cash equivalents above | C34: =C28-C33 -> 0
A36: Basis of the cash flow statement
A37: • Cash and cash equivalents are cash on hand and balances with banks in current accounts. Bank deposits are shown under investing activities until their maturity is confirmed.
A38: • Interest paid and received are taken as equal to the amounts in the statement of profit and loss, because Tally holds no accrued-interest ledgers.
A39: • Purchase of property, plant and equipment is derived from the change in net book value plus depreciation, because gross block is not available in Tally.
A40: • Previous-year cash flows need the balance sheet at the start of the previous year and its statement of profit and loss; only the current year was loaded.
A43: For XYZ Chartered Accountants | C43: For and on behalf of the Board of Directors of
A44: Chartered Accountants | C44: Rajasthan Precision Private Limited
A45: Firm Registration No.: 1111111
...

Sheet Notes
A1: Notes forming part of the financial statements
A3: Note 1: Share capital | F3: ↩ Balance Sheet
A4: Particulars | B4: As at 31/03/2026 | C4: As at 31/03/2025
A5: Equity share capital | B5: 29.3 | C5: 29.3
A6: Total | B6: =B5 -> 29.3 | C6: =C5 -> 29.3
A7: Information required (not available in Tally):
A8: • Authorised, issued, subscribed and paid-up shares (number and amount), par value and rights/preferences
A9: • Reconciliation of shares outstanding at the start and end of the year
A10: • Shareholders holding more than 5%, and promoter shareholding at the end and at the beginning of the year with the % change
A12: Note 2: Reserves and surplus | F12: ↩ Balance Sheet
A13: Particulars | B13: As at 31/03/2026 | C13: As at 31/03/2025
A14: General reserve | B14: 33.34 | C14: 33.34
A15: Surplus in the statement of profit and loss:
A16: Opening balance | B16: 0 | C16: -
A17: Add: profit for the year | B17: 17.72 | C17: -
A18: Closing balance | B18: 17.72 | C18: 0
A19: Total | B19: =SUM(B14,B18) -> 51.06 | C19: =SUM(C14,C18) -> 33.34
A20: Information required (not available in Tally):
A21: • Nature and purpose of each reserve; any appropriations (dividend, transfer to reserves) for the year
A23: Note 3: Long-term borrowings | F23: ↩ Balance Sheet
A24: Particulars | B24: As at 31/03/2026 | C24: As at 31/03/2025
A25: Term loans from banks (secured) | B25: 12.5 | C25: 12.5
A26: Loans from directors / related parties (unsecured) | B26: 3 | C26: 3
A27: Total | B27: =SUM(B25:B26) -> 15.5 | C27: =SUM(C25:C26) -> 15.5
A28: Information required (not available in Tally):
A29: • Terms of repayment, rate of interest and security for each loan; defaults; current maturities of long-term debt (to be shown under other current liabilities)
A30: • Loans from directors and other related parties: terms and amounts (related-party disclosure)
A32: Note 4: Trade payables | F32: ↩ Balance Sheet
A33: Particulars | B33: As at 31/03/2026 | C33: As at 31/03/2025
A34: Trade payables | B34: 138.56 | C34: 65.01
A35: Total | B35: =B34 -> 138.56 | C35: =C34 -> 65.01
A36: Information required (not available in Tally):
A37: • Ageing of trade payables from the due date of payment (less than 1 year, 1-2, 2-3, more than 3 years): MSME, others and disputed dues
A38: • Dues to micro and small enterprises (MSMED Act, 2006): principal, interest, payments beyond 45 days
A40: Note 5: Other current liabilities | F40: ↩ Balance Sheet
A41: Particulars | B41: As at 31/03/2026 | C41: As at 31/03/2025
A42: Statutory dues: GST payable (net of input tax credit) | B42: 12.31 | C42: 6.04
A43: Outstanding expenses | B43: 3.25 | C43: 1.6
A44: Statutory dues: TDS / TCS payable | B44: 0.13 | C44: 0.07
A45: Total | B45: =SUM(B42:B44) -> 15.69 | C45: =SUM(C42:C44) -> 7.71
...

Sheet Disclosures
A1: Additional regulatory information and other statutory disclosures
A2: Facts the books show are stated with their source; where only management can answer the cell says so. A blank or bracketed cell is not a statement that the item is nil.
A4: D1. Payment to auditors | B4: Schedule III, Division I (other expenses); Sec 143
A5: Particulars | B5: Current year | C5: Previous year
A6: Statutory audit fee | B6: 0.40 | C6: Not loaded
A7: Tax audit fee | B7: [Management to provide] | C7: [Management to provide]
A8: Other services (certification, limited review) | B8: [Management to provide] | C8: [Management to provide]
A9: Reimbursement of out-of-pocket expenses | B9: [Management to provide] | C9: [Management to provide]
A10: Total charged to the statement of profit and loss | B10: 0.40 | C10: Not loaded
A11: Source: expense ledgers with 'audit' in the name.
A13: D2. Managerial remuneration (Sec 197) | B13: Companies Act 2013, Sec 197 and Schedule V
A14: Particulars | B14: Current year | C14: Previous year
A15: Remuneration to directors booked in the year | B15: 0.44 | C15: Not loaded
A16: Net profit before tax (approximation of net profit under Sec 198) | B16: 17.72 | C16: Not loaded
A17: 11% of that profit (overall ceiling, Sec 197(1)) | B17: 1.95 | C17: Not loaded
A18: Booked remuneration within the ceiling? | B18: Yes | C18: Not loaded
A19: The ceiling applies to a public company; a private company is outside Sec 197. Sec 198 adjusts profit in ways Tally does not hold, so the ceiling shown is indicative. Company type is not in the books. Remuneration to each director and KMP is also a related-party disclosure (D3).
A21: D3. Related-party disclosures (AS 18) | B21: AS 18; Companies Act 2013, Sec 188
A22: Name | B22: Relationship | C22: Nature | D22: Current year | E22: Previous year
A23: Directors Remuneration | B23: Director / KMP / related party (from the ledger name) | C23: Remuneration | D23: 0.44 | E23: Not loaded
A24: Unsecured Loan - Director | B24: Director / KMP / related party (from the ledger name) | C24: Loan received | D24: 3.00 | E24: 3.00
A25: [Management to provide] | B25: Holding, subsidiary, associate, relatives, enterprises under common control | C25: [Management to provide] | D25: [Management to provide] | E25: [Management to provide]
A26: Rows above come from ledger names that suggest a related party and the balance shown in Tally; the relationship has to be confirmed. AS 18 also needs transactions in the year and balances outstanding for each party, which only the party-wise ledgers can supply. Transactions with related parties not named in a ledger are not visible.
A28: D4. Earnings per share (AS 20) | B28: AS 20
A29: Particulars | B29: Current year | C29: Previous year
A30: Profit after tax available to equity shareholders | B30: 17.72 | C30: Not loaded
A31: Weighted average number of equity shares | B31: [Management to provide] | C31: [Management to provide]
A32: Nominal value per share | B32: [Management to provide] | C32: [Management to provide]
A33: Basic and diluted earnings per share (Rs) | B33: [Profit after tax / weighted average shares] | C33: Not loaded
A34: Paid-up share capital is 29.30; the number of shares is not held in Tally.
A36: D5. Corporate social responsibility (Sec 135) | B36: Companies Act 2013, Sec 135; CSR Rules 2014
A37: Threshold | B37: Current year | C37: Met, current year | D37: Previous year | E37: Met, previous year
A38: Net worth of Rs 500 crore or more | B38: 80.36 | C38: No | D38: 62.64 | E38: No
A39: Turnover of Rs 1,000 crore or more | B39: 127.29 | C39: No | D39: Not loaded | E39: -
A40: Net profit (before tax, approximation) of Rs 5 crore or more | B40: 17.72 | C40: No | D40: Not loaded | E40: -
A41: CSR expenditure booked in the year | B41: No CSR ledger found | D41: Not loaded
A42: None of the three thresholds is met on current-year figures, so CSR does not appear to apply. The test is made on the immediately preceding financial year's figures, which is the previous-year column; only its net worth can be taken from the books (the opening balances), because its profit and loss was not loaded.
A44: D6. Contingent liabilities and commitments (AS 29) | B44: AS 29; Schedule III, Division I
A45: Particulars | B45: Current year | C45: Previous year
A46: Claims against the company not acknowledged as debt | B46: [Management to provide] | C46: [Management to provide]
...

Sheet AI analysis
A1: Ratio analysis and AI remarks
A2: AI review run. Reasons marked 'AI draft' and the observations below are drafts for the reviewer to confirm with management; the model saw figures and labels only and cited the facts it relied on.
A4: Schedule III ratios (ICAI Guidance Note, Annexure B)
A5: Ratio | B5: Current year | C5: Previous year | D5: % change | E5: Over 25% | F5: Reason for change / note | G5: Source of the reason
A6: Current ratio | B6: 1.47x | C6: 1.74x | D6: (15.2%)
A7: Debt-equity ratio | B7: 0.19x | C7: 0.25x | D7: (22.1%) | F7: Current maturities of long-term debt cannot be separated in Tally, so borrowings may be understated.
A8: Debt service coverage ratio | B8: 26.35x | C8: n/a | D8: n/a
A9: Return on equity | B9: 24.78% | C9: n/a | D9: n/a
A10: Inventory turnover ratio | B10: 8.32x | C10: n/a | D10: n/a | F10: Direct manufacturing expenses (job work, power, wages) are excluded from cost of goods sold.
A11: Trade receivables turnover ratio | B11: 0.96x | C11: n/a | D11: n/a | F11: All revenue is assumed to be on credit; cash sales are not separable in Tally.
A12: Trade payables turnover ratio | B12: 0.88x | C12: n/a | D12: n/a
A13: Net capital turnover ratio | B13: 2.01x | C13: n/a | D13: n/a
A14: Net profit ratio | B14: 13.92% | C14: n/a | D14: n/a
A15: Return on capital employed | B15: 19.29% | C15: n/a | D15: n/a
A16: Return on investment | B16: n/a | C16: n/a | D16: n/a | F16: Not applicable: the company holds no investments (a bank deposit is shown as a bank balance).
A18: Analytical observations
A19: Observation | B19: Severity | C19: Figures verified | F19: Why it matters and the procedure | G19: Facts relied on
A20: High Trade Receivables Days | B20: High | C20: Yes | F20: Trade receivables represent 514 days days of revenue, which is extremely high and indicates significant collection issues or potential revenue recognition concerns, impacting liquidity. Procedure: Obtain detailed ageing of trade receivables; discuss collection policies and any significant overdue balances with management. | G20: Trade receivables, current year: Rs 1,79,23,000; Revenue from operations: Rs 1,27,29,000; Trade receivables at year end, in days of revenue: 514 days; Trade receivables turnover ratio, current year: 0.96x
A21: High Trade Payables Days | B21: High | C21: Yes | F21: Trade payables represent 566 days days of purchases, indicating very long payment cycles to suppliers, which could strain supplier relationships or suggest liquidity management issues. Procedure: Obtain detailed ageing of trade payables; discuss payment policies and any significant overdue balances with management. | G21: Trade payables, current year: Rs 1,38,56,000; Purchases: Rs 89,43,000; Trade payables at year end, in days of purchases: 566 days; Trade payables turnover ratio, current year: 0.88x
A22: Divergence of Profit and Operating Cash Flow | B22: High | C22: Yes | F22: Profit after tax is Rs 17,72,000, but net cash from operating activities is only Rs 8,18,000, resulting in a significant difference of Rs 9,54,000. This divergence needs detailed reconciliation and explanation. Procedure: Review the detailed cash flow statement to understand the non-cash adjustments and working capital changes causing this difference. | G22: Profit after tax: Rs 17,72,000; Net cash from operating activities: Rs 8,18,000; Profit after tax less operating cash flow: Rs 9,54,000
A23: Low Implied Interest Rate on Borrowings | B23: Medium | C23: No: contains figures not in the books | F23: Total borrowings of Rs 15,50,000 yield finance costs of only Rs 77,000, implying an interest rate of approximately 4.97%. This seems unusually low for commercial borrowings in India. Procedure: Obtain loan agreements for all borrowings, especially the unsecured loan from directors, to confirm interest rates and terms. | G23: Total borrowings (long and short term), current year: Rs 15,50,000; Finance costs: Rs 77,000; Unsecured loan from directors: Rs 3,00,000
A24: Rapid Growth in Working Capital Components | B24: Medium | C24: No: contains figures not in the books | F24: Current assets increased by ~100% from Rs 1,26,39,000 to Rs 2,27,44,000 and current liabilities by ~112% from Rs 72,72,000 to Rs 1,54,25,000. This rapid expansion needs to be understood and justified by business operations. Procedure: Discuss with management the reasons for the substantial increase in both current assets and liabilities and their impact on working capital management. | G24: Current assets, current year: Rs 2,27,44,000; Current assets, previous year: Rs 1,26,39,000; Current liabilities, current year: Rs 1,54,25,000; Current liabilities, previous year: Rs 72,72,000

Sheet Open items
A1: Open items for the reviewer
A3: Ref | B3: Type | C3: Area | D3: Ledger | E3: Amount | F3: Matter | G3: Reviewer response
A4: R1 | B4: Classification | C4: Inventories | D4: Opening Stock | E4: 10.75 | F4: Tally's trial balance shows stock as one 'Opening Stock' line and does not include the closing stock. Confirm the closing stock value for the year; split it into raw materials, work-in-progress and finished goods.
A5: R2 | B5: Classification | C5: Trade receivables | D5: Apex Motors Pvt Ltd | E5: 29.72 | F5: The file gives no ledger group; 'Sundry Debtors' was guessed from the balance side. Confirm what this ledger is.
A6: R3 | B6: Classification | C6: Other expenses | D6: Audit Fees | E6: 0.4 | F6: Schedule III requires the split: audit fee, tax audit, other services, reimbursements.
A7: R4 | B7: Classification | C7: Trade payables | D7: Bright Bearings Co. | E7: 35.03 | F7: The file gives no ledger group; 'Sundry Creditors' was guessed from the balance side. Confirm what this ledger is.
A8: R5 | B8: Classification | C8: Employee benefit expense | D8: Directors Remuneration | E8: 0.44 | F8: Key managerial personnel: related-party disclosure (AS 18) and Sec 197 / Sch V limits.
A9: R6 | B9: Classification | C9: Cash and bank balances | D9: Fixed Deposit - HDFC Bank | E9: 5 | F9: A bank deposit is not an 'investment' under Schedule III. Confirm maturity: over 12 months is an other non-current asset; up to 3 months is a cash equivalent.
A10: R7 | B10: Classification | C10: Trade receivables | D10: Jaipur Machine Tools | E10: 42.31 | F10: The file gives no ledger group; 'Sundry Debtors' was guessed from the balance side. Confirm what this ledger is.
A11: R8 | B11: Classification | C11: Trade payables | D11: Jaipur Packaging Works | E11: 22.89 | F11: The file gives no ledger group; 'Sundry Creditors' was guessed from the balance side. Confirm what this ledger is.
A12: R9 | B12: Classification | C12: Trade receivables | D12: Metro Auto Components Ltd | E12: 37.01 | F12: The file gives no ledger group; 'Sundry Debtors' was guessed from the balance side. Confirm what this ledger is.
A13: R10 | B13: Classification | C13: Trade receivables | D13: National Fabricators | E13: 30.22 | F13: The file gives no ledger group; 'Sundry Debtors' was guessed from the balance side. Confirm what this ledger is.
A14: R11 | B14: Classification | C14: Other current liabilities | D14: Outstanding Audit Fees | E14: 0.8 | F14: Expenses already incurred and payable are not 'provisions' (AS 29); shown under other current liabilities.
A15: R12 | B15: Classification | C15: Other current liabilities | D15: Outstanding Salary | E15: 2.45 | F15: Expenses already incurred and payable are not 'provisions' (AS 29); shown under other current liabilities.
... A21: R18 | B21: Classification | C21: Long-term borrowings | D21: Unsecured Loan - Director | E21: 3 | F21: Related-party loan: needs related-party disclosure (AS 18), Sec 73/Rule 2(1)(c)(viii) declaration from director, and repayment terms. Confirm long-term.
A22: O1 | B22: Observation | C22: Comparatives | E22: - | F22: Only one year's trial balance was loaded, so the previous-year columns of the statement of profit and loss and the cash flow statement are blank. Load the previous year's data to complete them.
A23: O2 | B23: Observation | C23: Tax | E23: 17.72 | F23: The books show a profit of Rs 17,72,000 but no income-tax expense or provision (current or deferred). Confirm the tax computation and book the provision before finalising.
A24: O3 | B24: Observation | C24: Inventories | E24: 10.75 | F24: Closing stock equals opening stock for every inventory ledger although purchases were Rs 89,43,000. Confirm the year-end stock was recorded; otherwise cost of materials and profit are misstated.
A25: O4 | B25: Observation | C25: Cash flow statement | E25: - | F25: Paid-up capital of Rs 29,30,000 and turnover of Rs 1,27,29,000 are within the small-company limits (Rs 4 crore and Rs 40 crore, as currently notified), in which case a cash flow statement is not mandatory (Sec 2(40)). Confirm the company's status; it is included for completeness.
A27: Information required for the notes (not available in Tally)
A28: Note 1 | C28: Share capital | F28: Authorised, issued, subscribed and paid-up shares (number and amount), par value and rights/preferences
A29: Note 1 | C29: Share capital | F29: Reconciliation of shares outstanding at the start and end of the year
A30: Note 1 | C30: Share capital | F30: Shareholders holding more than 5%, and promoter shareholding at the end and at the beginning of the year with the % change
A31: Note 2 | C31: Reserves and surplus | F31: Nature and purpose of each reserve; any appropriations (dividend, transfer to reserves) for the year
A32: Note 3 | C32: Long-term borrowings | F32: Terms of repayment, rate of interest and security for each loan; defaults; current maturities of long-term debt (to be shown under other current liabilities)
A33: Note 3 | C33: Long-term borrowings | F33: Loans from directors and other related parties: terms and amounts (related-party disclosure)
A34: Note 4 | C34: Trade payables | F34: Ageing of trade payables from the due date of payment (less than 1 year, 1-2, 2-3, more than 3 years): MSME, others and disputed dues
A35: Note 4 | C35: Trade payables | F35: Dues to micro and small enterprises (MSMED Act, 2006): principal, interest, payments beyond 45 days
A36: Note 5 | C36: Other current liabilities | F36: Current maturities of long-term borrowings; statutory dues overdue, if any
A37: Note 6 | C37: Property, plant and equipment | F37: Gross block, accumulated depreciation and impairment for each class; additions, disposals and transfers (Tally shows only the net book value here)
A38: Note 6 | C38: Property, plant and equipment | F38: Useful lives or depreciation rates and method; title deeds of immovable property; revaluation, if any
A39: Note 7 | C39: Inventories | F39: Basis of valuation (lower of cost and net realisable value) and how closing stock was determined
... A47: Note 17 | C47: Analytical ratios | F47: Return on investment: the time-weighted method needs the market value and cash flows of the investment portfolio
A48: General | F48: Significant accounting policies (AS 1) and the basis of preparation
A49: General | F49: Earnings per share (AS 20): number of equity shares and weighted average
A50: General | F50: Related-party disclosures (AS 18): names, relationships, transactions and balances (including director remuneration)
A51: General | F51: Contingent liabilities and commitments (AS 29); employee benefits (AS 15); segment information (AS 17) if applicable
A52: General | F52: The 11 ratios required by Schedule III with explanations for changes above 25%

Sheet Mapping
A1: Ledger to Schedule III mapping (balances shown Dr / (Cr), as in Tally)
A3: Ledger | B3: Tally group | C3: Schedule III line | D3: Sub-head | E3: Opening | F3: Closing | G3: Source | H3: Rule | I3: Review note
A4: Opening Stock | B4: Stock-in-Hand | C4: Inventories | D4: Stock in hand (as shown in the trial balance) | E4: 1075000 | F4: 1075000 | G4: rule | H4: R-STK | I4: Tally's trial balance shows stock as one 'Opening Stock' line and does not include the closing stock. Confirm the closing stock value for the year; split it into raw materials, work-in-progress and finished goods.
A5: Advertisement Expenses | B5: Indirect Expenses | C5: Other expenses | D5: Selling and distribution expenses | E5: 0 | F5: 154546 | G5: rule | H5: R-IE
A6: Apex Motors Pvt Ltd | B6: Sundry Debtors | C6: Trade receivables | D6: Trade receivables | E6: 1452639 | F6: 2971589 | G6: rule | H6: R-SD | I6: The file gives no ledger group; 'Sundry Debtors' was guessed from the balance side. Confirm what this ledger is.
A7: Audit Fees | B7: Indirect Expenses | C7: Other expenses | D7: Payment to auditors | E7: 0 | F7: 39765 | G7: rule | H7: R-IE | I7: Schedule III requires the split: audit fee, tax audit, other services, reimbursements.
A8: Bank Charges | B8: Indirect Expenses | C8: Other expenses | D8: Bank charges | E8: 0 | F8: 23072 | G8: rule | H8: R-IE
A9: Bright Bearings Co. | B9: Sundry Creditors | C9: Trade payables | D9: Trade payables | E9: -1428161 | F9: -3503119 | G9: rule | H9: R-SCR | I9: The file gives no ledger group; 'Sundry Creditors' was guessed from the balance side. Confirm what this ledger is.
A10: Cash | B10: Cash-in-Hand | C10: Cash and bank balances | D10: Cash on hand | E10: 35325 | F10: 27781 | G10: rule | H10: R-CASH
A11: CGST Input | B11: Duties & Taxes | C11: Other current liabilities | D11: Statutory dues: GST payable (net of input tax credit) | E11: 613591 | F11: 1319685 | G11: rule | H11: R-DT
A12: CGST Output | B12: Duties & Taxes | C12: Other current liabilities | D12: Statutory dues: GST payable (net of input tax credit) | E12: -712285 | F12: -1520380 | G12: rule | H12: R-DT
A13: Computers | B13: Fixed Assets | C13: Property, plant and equipment | D13: Computers | E13: 85000 | F13: 85000 | G13: rule | H13: R-FA
A14: Consultancy Charges | B14: Indirect Expenses | C14: Other expenses | D14: Legal and professional fees | E14: 0 | F14: 89390 | G14: rule | H14: R-IE
A15: Depreciation | B15: Indirect Expenses | C15: Depreciation and amortisation expense | D15: Depreciation and amortisation | E15: 0 | F15: 180066 | G15: rule | H15: R-IE
A16: Directors Remuneration | B16: Indirect Expenses | C16: Employee benefit expense | D16: Directors' remuneration | E16: 0 | F16: 43639 | G16: rule | H16: R-IE | I16: Key managerial personnel: related-party disclosure (AS 18) and Sec 197 / Sch V limits.
A17: Discount Allowed | B17: Indirect Expenses | C17: Other expenses | D17: Selling and distribution expenses | E17: 0 | F17: 80214 | G17: rule | H17: R-IE
A18: Discount Received | B18: Indirect Incomes | C18: Other income | D18: Other non-operating income | E18: 0 | F18: -19919 | G18: rule | H18: R-II
A19: Factory Wages | B19: Direct Expenses | C19: Employee benefit expense | D19: Factory wages | E19: 0 | F19: 170222 | G19: rule | H19: R-DE
A20: Fixed Deposit - HDFC Bank | B20: Investments | C20: Cash and bank balances | D20: Other bank balances (bank deposits) | E20: 500000 | F20: 500000 | G20: rule | H20: R-INV | I20: A bank deposit is not an 'investment' under Schedule III. Confirm maturity: over 12 months is an other non-current asset; up to 3 months is a cash equivalent.
A21: Furniture & Fixtures | B21: Fixed Assets | C21: Property, plant and equipment | D21: Furniture and fixtures | E21: 65000 | F21: 65000 | G21: rule | H21: R-FA
A22: General Reserve | B22: Reserves & Surplus | C22: Reserves and surplus | D22: General reserve | E22: -3334416 | F22: -3334416 | G22: rule | H22: R-RS
A23: HDFC Bank - Current A/c | B23: Bank Accounts | C23: Cash and bank balances | D23: Balances with banks (current accounts) | E23: 1071233 | F23: 1217138 | G23: rule | H23: R-BANK
A24: ICICI Bank - Current A/c | B24: Bank Accounts | C24: Cash and bank balances | D24: Balances with banks (current accounts) | E24: 1345741 | F24: 2001329 | G24: rule | H24: R-BANK
A25: IGST Output | B25: Duties & Taxes | C25: Other current liabilities | D25: Statutory dues: GST payable (net of input tax credit) | E25: -406207 | F25: -829421 | G25: rule | H25: R-DT
A26: Insurance Expenses | B26: Indirect Expenses | C26: Other expenses | D26: Insurance | E26: 0 | F26: 34757 | G26: rule | H26: R-IE
A27: Interest on Term Loan | B27: Indirect Expenses | C27: Finance costs | D27: Interest expense | E27: 0 | F27: 76980 | G27: rule | H27: R-IE
A28: Interest Received - FD | B28: Indirect Incomes | C28: Other income | D28: Interest income | E28: 0 | F28: -52911 | G28: rule | H28: R-II
A29: Jaipur Machine Tools | B29: Sundry Debtors | C29: Trade receivables | D29: Trade receivables | E29: 1913796 | F29: 4231066 | G29: rule | H29: R-SD | I29: The file gives no ledger group; 'Sundry Debtors' was guessed from the balance side. Confirm what this ledger is.
A30: Jaipur Packaging Works | B30: Sundry Creditors | C30: Trade payables | D30: Trade payables | E30: -1148354 | F30: -2289430 | G30: rule | H30: R-SCR | I30: The file gives no ledger group; 'Sundry Creditors' was guessed from the balance side. Confirm what this ledger is.
A31: Job Work Charges | B31: Direct Expenses | C31: Other expenses | D31: Job work charges | E31: 0 | F31: 240810 | G31: rule | H31: R-DE
A32: Legal & Professional Charges | B32: Indirect Expenses | C32: Other expenses | D32: Legal and professional fees | E32: 0 | F32: 65080 | G32: rule | H32: R-IE
A33: Metro Auto Components Ltd | B33: Sundry Debtors | C33: Trade receivables | D33: Trade receivables | E33: 1897471 | F33: 3700532 | G33: rule | H33: R-SD | I33: The file gives no ledger group; 'Sundry Debtors' was guessed from the balance side. Confirm what this ledger is.
A34: Miscellaneous Income | B34: Indirect Incomes | C34: Other income | D34: Other non-operating income | E34: 0 | F34: -14081 | G34: rule | H34: R-II
A35: National Fabricators | B35: Sundry Debtors | C35: Trade receivables | D35: Trade receivables | E35: 1530807 | F35: 3022239 | G35: rule | H35: R-SD | I35: The file gives no ledger group; 'Sundry Debtors' was guessed from the balance side. Confirm what this ledger is.
A36: Office Equipment | B36: Fixed Assets | C36: Property, plant and equipment | D36: Office equipment | E36: 120000 | F36: 120000 | G36: rule | H36: R-FA
A37: Office Expenses | B37: Indirect Expenses | C37: Other expenses | D37: Miscellaneous expenses | E37: 0 | F37: 99678 | G37: rule | H37: R-IE
A38: Outstanding Audit Fees | B38: Provisions | C38: Other current liabilities | D38: Outstanding expenses | E38: -40000 | F38: -79765 | G38: rule | H38: R-PROV | I38: Expenses already incurred and payable are not 'provisions' (AS 29); shown under other current liabilities.
A39: Outstanding Salary | B39: Provisions | C39: Other current liabilities | D39: Outstanding expenses | E39: -120000 | F39: -244850 | G39: rule | H39: R-PROV | I39: Expenses already incurred and payable are not 'provisions' (AS 29); shown under other current liabilities.
A40: Plant & Machinery | B40: Fixed Assets | C40: Property, plant and equipment | D40: Plant and equipment | E40: 1726741 | F40: 1546675 | G40: rule | H40: R-FA
A41: Precision Tools Suppliers | B41: Sundry Creditors | C41: Trade payables | D41: Trade payables | E41: -1025741 | F41: -2325135 | G41: rule | H41: R-SCR | I41: The file gives no ledger group; 'Sundry Creditors' was guessed from the balance side. Confirm what this ledger is.
...
