Workbook
Name TOT_Cash: '91_Mapping'!$Z$1
Name TOT_Cash: 'Note_5_3_CashBank'!$B$14
Name TOT_Cash_PY: '91_Mapping'!$Z$1
Name TOT_Cash_PY: 'Note_5_3_CashBank'!$C$14
Name TOT_Contingencies: '91_Mapping'!$Z$1
Name TOT_Contingencies_PY: '91_Mapping'!$Z$1
Name TOT_CWIP: '91_Mapping'!$Z$1
Name TOT_CWIP: 'Note_4_2_CWIP'!$E$7
Name TOT_CWIP_PY: '91_Mapping'!$Z$1
Name TOT_CWIP_PY: 'Note_4_2_CWIP'!$F$7
Name TOT_Depreciation: '91_Mapping'!$Z$1
Name TOT_Depreciation: 'Note_7_4_Depreciation'!$B$9
Name TOT_Depreciation_PY: '91_Mapping'!$Z$1
Name TOT_Depreciation_PY: 'Note_7_4_Depreciation'!$C$9
Name TOT_Employee: '91_Mapping'!$Z$1
Name TOT_Employee: 'Note_7_2_Employee'!$B$11
Name TOT_Employee_PY: '91_Mapping'!$Z$1
Name TOT_Employee_PY: 'Note_7_2_Employee'!$C$11
Name TOT_Finance: '91_Mapping'!$Z$1
Name TOT_Finance: 'Note_7_3_Finance'!$B$10
Name TOT_Finance_PY: '91_Mapping'!$Z$1
Name TOT_Finance_PY: 'Note_7_3_Finance'!$C$10
Name TOT_Inventory: '91_Mapping'!$Z$1
Name TOT_Inventory: 'Note_5_1_Inventories'!$B$10
Name TOT_Inventory_PY: '91_Mapping'!$Z$1
Name TOT_Inventory_PY: 'Note_5_1_Inventories'!$C$10
Name TOT_Investments: '91_Mapping'!$Z$1
Name TOT_Investments: 'Note_4_3_Investments'!$C$9
Name TOT_Investments_PY: '91_Mapping'!$Z$1
Name TOT_Investments_PY: 'Note_4_3_Investments'!$D$9
Name TOT_LTBorrow: '91_Mapping'!$Z$1
Name TOT_LTBorrow: 'Note_2_1_LTBorrow'!$B$7
Name TOT_LTBorrow_PY: '91_Mapping'!$Z$1
Name TOT_LTBorrow_PY: 'Note_2_1_LTBorrow'!$C$7
Name TOT_LTLA: '91_Mapping'!$Z$1
Name TOT_LTLA: 'Note_4_4_LTLA'!$B$9
Name TOT_LTLA_PY: '91_Mapping'!$Z$1
Name TOT_LTLA_PY: 'Note_4_4_LTLA'!$C$9
Name TOT_LTProv: '91_Mapping'!$Z$1
Name TOT_LTProv: 'Note_2_2_LTProv'!$B$8
Name TOT_LTProv_PY: '91_Mapping'!$Z$1
Name TOT_LTProv_PY: 'Note_2_2_LTProv'!$C$8
Name TOT_Material: '91_Mapping'!$Z$1
Name TOT_Material: 'Note_7_1_Material'!$B$16
Name TOT_Material_PY: '91_Mapping'!$Z$1
Name TOT_Material_PY: 'Note_7_1_Material'!$C$16
Name TOT_OtherCA: '91_Mapping'!$Z$1
Name TOT_OtherCA: 'Note_5_5_OtherCA'!$B$8
Name TOT_OtherCA_PY: '91_Mapping'!$Z$1
Name TOT_OtherCA_PY: 'Note_5_5_OtherCA'!$C$8
Name TOT_OtherCL: '91_Mapping'!$Z$1
Name TOT_OtherCL: 'Note_3_3_OtherCL'!$B$11
Name TOT_OtherCL_PY: '91_Mapping'!$Z$1
Name TOT_OtherCL_PY: 'Note_3_3_OtherCL'!$C$11
Name TOT_OtherExp: '91_Mapping'!$Z$1
Name TOT_OtherExp: 'Note_7_5_OtherExp'!$B$17
Name TOT_OtherExp_PY: '91_Mapping'!$Z$1
Name TOT_OtherExp_PY: 'Note_7_5_OtherExp'!$C$17
Name TOT_OtherIncome: '91_Mapping'!$Z$1
Name TOT_OtherIncome: 'Note_6_2_OtherIncome'!$B$10

Sheet 90_Trial_Balance
A1: Ledger Code | B1: Ledger Name | C1: Original Group | D1: Debit | E1: Credit
A2: 1001 | B2: Equity Share Capital | C2: Capital Account | D2: 0 | E2: 0
A3: 1002 | B3: General Reserve | C3: Reserves & Surplus | D3: 0 | E3: 0
A4: 1003 | B4: Retained Earnings P&L | C4: Reserves & Surplus | D4: 0 | E4: 0
A5: 2001 | B5: HDFC Term Loan (Secured) | C5: Long Term Borrowings | D5: 0 | E5: 0
A6: 2002 | B6: ICICI Cash Credit Limit | C6: Short Term Borrowings | D6: 0 | E6: 0
A7: 2003 | B7: Trade Payables - MSME Vendors | C7: Current Liabilities | D7: 0 | E7: 0
A8: 2004 | B8: Trade Payables - Other Vendors | C8: Current Liabilities | D8: 0 | E8: 0
A9: 2005 | B9: Statutory Dues Payable (GST & TDS) | C9: Current Liabilities | D9: 0 | E9: 0
A10: 2006 | B10: Provision for Income Tax | C10: Provisions | D10: 0 | E10: 0
A11: 3001 | B11: Factory Land & Buildings | C11: Fixed Assets | D11: 0 | E11: 0
A12: 3002 | B12: Plant & Machinery | C12: Fixed Assets | D12: 0 | E12: 0
A13: 3003 | B13: Capital Work-in-Progress (Solar Plant) | C13: Fixed Assets | D13: 0 | E13: 0
... A25: 6005 | B25: Audit Fees & Legal Charges | C25: Administrative Expenses | D25: 0 | E25: 0

Sheet 91_Mapping
A1: Ledger Code | B1: Ledger Name | C1: Original Group | D1: Final Classification | E1: Statement | F1: Note # | G1: Current / Non-Current | H1: CY Amount (Lakhs) | I1: PY Amount (Lakhs)
A2: 1001 | B2: Equity Share Capital | C2: Capital Account | D2: Share Capital | E2: Balance Sheet | F2: 1.1 | G2: Shareholders' Funds | H2: =SUMIFS('90_Trial_Balance'!$D:$D, '90_Trial_Balance'!$A:$A, $A2) -> -100 | I2: =SUMIFS('90_Trial_Balance'!$E:$E, '90_Trial_Balance'!$A:$A, $A2) -> -100
A3: 1002 | B3: General Reserve | C3: Reserves & Surplus | D3: Reserves and Surplus | E3: Balance Sheet | F3: 1.2 | G3: Shareholders' Funds | H3: =SUMIFS('90_Trial_Balance'!$D:$D, '90_Trial_Balance'!$A:$A, $A3) -> -150 | I3: =SUMIFS('90_Trial_Balance'!$E:$E, '90_Trial_Balance'!$A:$A, $A3) -> -120
A4: 1003 | B4: Retained Earnings P&L | C4: Reserves & Surplus | D4: Reserves and Surplus | E4: Balance Sheet | F4: 1.2 | G4: Shareholders' Funds | H4: =SUMIFS('90_Trial_Balance'!$D:$D, '90_Trial_Balance'!$A:$A, $A4) -> -180 | I4: =SUMIFS('90_Trial_Balance'!$E:$E, '90_Trial_Balance'!$A:$A, $A4) -> -110
A5: 2001 | B5: HDFC Term Loan (Secured) | C5: Long Term Borrowings | D5: Long-term Borrowings | E5: Balance Sheet | F5: 2.1 | G5: Non-Current | H5: =SUMIFS('90_Trial_Balance'!$D:$D, '90_Trial_Balance'!$A:$A, $A5) -> -250 | I5: =SUMIFS('90_Trial_Balance'!$E:$E, '90_Trial_Balance'!$A:$A, $A5) -> -300
A6: 2002 | B6: ICICI Cash Credit Limit | C6: Short Term Borrowings | D6: Short-term Borrowings | E6: Balance Sheet | F6: 3.1 | G6: Current | H6: =SUMIFS('90_Trial_Balance'!$D:$D, '90_Trial_Balance'!$A:$A, $A6) -> -80 | I6: =SUMIFS('90_Trial_Balance'!$E:$E, '90_Trial_Balance'!$A:$A, $A6) -> -60
A7: 2003 | B7: Trade Payables - MSME Vendors | C7: Current Liabilities | D7: Trade Payables | E7: Balance Sheet | F7: 3.2 | G7: Current | H7: =SUMIFS('90_Trial_Balance'!$D:$D, '90_Trial_Balance'!$A:$A, $A7) -> -65 | I7: =SUMIFS('90_Trial_Balance'!$E:$E, '90_Trial_Balance'!$A:$A, $A7) -> -50
A8: 2004 | B8: Trade Payables - Other Vendors | C8: Current Liabilities | D8: Trade Payables | E8: Balance Sheet | F8: 3.2 | G8: Current | H8: =SUMIFS('90_Trial_Balance'!$D:$D, '90_Trial_Balance'!$A:$A, $A8) -> -120 | I8: =SUMIFS('90_Trial_Balance'!$E:$E, '90_Trial_Balance'!$A:$A, $A8) -> -95
A9: 2005 | B9: Statutory Dues Payable (GST & TDS) | C9: Current Liabilities | D9: Other Current Liabilities | E9: Balance Sheet | F9: 3.3 | G9: Current | H9: =SUMIFS('90_Trial_Balance'!$D:$D, '90_Trial_Balance'!$A:$A, $A9) -> -25 | I9: =SUMIFS('90_Trial_Balance'!$E:$E, '90_Trial_Balance'!$A:$A, $A9) -> -20
A10: 2006 | B10: Provision for Income Tax | C10: Provisions | D10: Tax Expense | E10: Profit & Loss | F10: 7.6 | G10: P&L Tax | H10: =SUMIFS('90_Trial_Balance'!$D:$D, '90_Trial_Balance'!$A:$A, $A10) -> -40 | I10: =SUMIFS('90_Trial_Balance'!$E:$E, '90_Trial_Balance'!$A:$A, $A10) -> -30
A11: 3001 | B11: Factory Land & Buildings | C11: Fixed Assets | D11: Property, Plant and Equipment | E11: Balance Sheet | F11: 4.1 | G11: Non-Current | H11: =SUMIFS('90_Trial_Balance'!$D:$D, '90_Trial_Balance'!$A:$A, $A11) -> 450 | I11: =SUMIFS('90_Trial_Balance'!$E:$E, '90_Trial_Balance'!$A:$A, $A11) -> 450
A12: 3002 | B12: Plant & Machinery | C12: Fixed Assets | D12: Property, Plant and Equipment | E12: Balance Sheet | F12: 4.1 | G12: Non-Current | H12: =SUMIFS('90_Trial_Balance'!$D:$D, '90_Trial_Balance'!$A:$A, $A12) -> 220 | I12: =SUMIFS('90_Trial_Balance'!$E:$E, '90_Trial_Balance'!$A:$A, $A12) -> 180
A13: 3003 | B13: Capital Work-in-Progress (Solar Plant) | C13: Fixed Assets | D13: Capital Work-in-Progress | E13: Balance Sheet | F13: 4.2 | G13: Non-Current | H13: =SUMIFS('90_Trial_Balance'!$D:$D, '90_Trial_Balance'!$A:$A, $A13) -> 45 | I13: =SUMIFS('90_Trial_Balance'!$E:$E, '90_Trial_Balance'!$A:$A, $A13) -> 15
... A25: 6005 | B25: Audit Fees & Legal Charges | C25: Administrative Expenses | D25: Other Expenses | E25: Profit & Loss | F25: 7.5 | G25: P&L Expense | H25: =SUMIFS('90_Trial_Balance'!$D:$D, '90_Trial_Balance'!$A:$A, $A25) -> 45 | I25: =SUMIFS('90_Trial_Balance'!$E:$E, '90_Trial_Balance'!$A:$A, $A25) -> 32

Sheet 29_Cash_Flow_Adjustments
A1: Adjustment Line Item | B1: Description | C1: CY Amount | D1: PY Amount | E1: Source Category
A2: Income Taxes Paid | B2: Direct Corporate Income Taxes Paid | C2: =-TOT_Tax -> -40 | D2: =-TOT_Tax_PY -> -30 | E2: Operating
A3: Dividend Paid | B3: Equity Dividend Paid During Year | C3: 0 | D3: 0 | E3: Financing
A4: Finance Cost Paid | B4: Actual Interest & Finance Cost Paid | C4: =-TOT_Finance -> -32 | D4: =-TOT_Finance_PY -> -38 | E4: Financing
A5: Interest / Dividend Received | B5: Interest and Dividend Income Received | C5: =TOT_InterestIncome -> 15 | D5: =TOT_InterestIncome_PY -> 10 | E5: Investing
A6: Actual Capex Paid | B6: Purchase of Property, Plant & Equipment | C6: =-((TOT_PPE+TOT_CWIP)-(TOT_PPE_PY+TOT_CWIP_PY)+TOT_Depreciation) -> -804.64 | D6: 0 | E6: Investing

Sheet Note_1_1_ShareCapital
A1: APEX_ENGINEERING_INDUSTRIES_LIMITED
A2: NOTE 1.1: SHARE CAPITAL | B2: =HYPERLINK("#\'02_Balance_Sheet\'!A1", "[<- Back to Balance Sheet]") -> 0
A3: (All amounts in INR Lakhs unless otherwise stated)
A5: Particulars | B5: As at FY 2024-25 | C5: As at FY 2023-24
A6: Authorised Share Capital:
A7: 10,00,000 Equity Shares of Rs. 10/- each | B7: 100 | C7: 100
A8: Issued, Subscribed & Paid-up Capital:
A9: Equity Shares of Rs. 10/- each fully paid | B9: 100 | C9: 100
A10: TOTAL SHARE CAPITAL | B10: =-1*SUM(B6:B9) -> 100 | C10: =-1*SUM(C6:C9) -> 100
A12: Per Trial Balance (Control Total) | B12: =-SUMIFS('91_Mapping'!H:H, '91_Mapping'!F:F, "1.1") -> 100 | C12: =-SUMIFS('91_Mapping'!I:I, '91_Mapping'!F:F, "1.1") -> 100
A13: Difference | B13: =TOT_ShareCapital-B12 -> 0 | C13: =TOT_ShareCapital_PY-C12 -> 0

Sheet Note_1_2_Reserves
A1: APEX_ENGINEERING_INDUSTRIES_LIMITED
A2: NOTE 1.2: RESERVES AND SURPLUS | B2: =HYPERLINK("#\'02_Balance_Sheet\'!A1", "[<- Back to Balance Sheet]") -> 0
A3: (All amounts in INR Lakhs unless otherwise stated)
A5: Particulars | B5: As at FY 2024-25 | C5: As at FY 2023-24
A6: (a) General Reserve:
A7: Opening Balance | B7: =SUMIFS('91_Mapping'!H:H, '91_Mapping'!D:D, "Opening Balance") -> 230 | C7: =SUMIFS('91_Mapping'!I:I, '91_Mapping'!D:D, "Opening Balance") -> 230
A8: Add: Transfer during the year | B8: =SUMIFS('91_Mapping'!H:H, '91_Mapping'!D:D, "Add: Transfer during the year") -> 0 | C8: =SUMIFS('91_Mapping'!I:I, '91_Mapping'!D:D, "Add: Transfer during the year") -> 0
A9: Closing General Reserve (A) | B9: =SUMIFS('91_Mapping'!H:H, '91_Mapping'!D:D, "Closing General Reserve (A)") -> 230 | C9: =SUMIFS('91_Mapping'!I:I, '91_Mapping'!D:D, "Closing General Reserve (A)") -> 230
A10: (b) Surplus in Statement of Profit & Loss:
A11: Opening Balance | B11: =SUMIFS('91_Mapping'!H:H, '91_Mapping'!D:D, "Opening Balance") -> 175 | C11: =SUMIFS('91_Mapping'!I:I, '91_Mapping'!D:D, "Opening Balance") -> 0
A12: Add: Profit After Tax for the year | B12: =SUMIFS('91_Mapping'!H:H, '91_Mapping'!D:D, "Add: Profit After Tax for the year") -> 240 | C12: =SUMIFS('91_Mapping'!I:I, '91_Mapping'!D:D, "Add: Profit After Tax for the year") -> 175
A13: Closing Surplus in P&L (B) | B13: =SUMIFS('91_Mapping'!H:H, '91_Mapping'!D:D, "Closing Surplus in P&L (B)") -> 240 | C13: =SUMIFS('91_Mapping'!I:I, '91_Mapping'!D:D, "Closing Surplus in P&L (B)") -> 175
A14: TOTAL RESERVES AND SURPLUS (A + B) | B14: =-1*SUM(B6:B13) -> 570 | C14: =-1*SUM(C6:C13) -> 405
A16: Per Trial Balance (Control Total) | B16: =-SUMIFS('91_Mapping'!H:H, '91_Mapping'!F:F, "1.2") -> 570 | C16: =-SUMIFS('91_Mapping'!I:I, '91_Mapping'!F:F, "1.2") -> 405
A17: Difference | B17: =TOT_Reserves-B16 -> 0 | C17: =TOT_Reserves_PY-C16 -> 0

Sheet Note_2_1_LTBorrow
A1: APEX_ENGINEERING_INDUSTRIES_LIMITED
A2: NOTE 2.1: LONG-TERM BORROWINGS | B2: =HYPERLINK("#\'02_Balance_Sheet\'!A1", "[<- Back to Balance Sheet]") -> 0
A3: (All amounts in INR Lakhs unless otherwise stated)
A5: Particulars | B5: As at FY 2024-25 | C5: As at FY 2023-24
A6: HDFC Bank Limited - Rupee Term Loan (Secured) | B6: 250 | C6: 300
A7: TOTAL LONG-TERM BORROWINGS | B7: =-1*SUM(B6:B6) -> 250 | C7: =-1*SUM(C6:C6) -> 300
A9: Per Trial Balance (Control Total) | B9: =-SUMIFS('91_Mapping'!H:H, '91_Mapping'!F:F, "2.1") -> 250 | C9: =-SUMIFS('91_Mapping'!I:I, '91_Mapping'!F:F, "2.1") -> 300
A10: Difference | B10: =TOT_LTBorrow-B9 -> 0 | C10: =TOT_LTBorrow_PY-C9 -> 0

Sheet Note_2_2_LTProv
A1: APEX_ENGINEERING_INDUSTRIES_LIMITED
A2: NOTE 2.2: LONG-TERM PROVISIONS | B2: =HYPERLINK("#\'02_Balance_Sheet\'!A1", "[<- Back to Balance Sheet]") -> 0
A3: (All amounts in INR Lakhs unless otherwise stated)
A5: Particulars | B5: As at FY 2024-25 | C5: As at FY 2023-24
A6: Provision for Gratuity (AS 15 - Defined Benefit) | B6: 0 | C6: 0
A7: Provision for Leave Encashment (Long-term portion) | B7: 0 | C7: 0
A8: TOTAL LONG-TERM PROVISIONS | B8: =-1*SUM(B6:B7) -> 0 | C8: =-1*SUM(C6:C7) -> 0
A10: Per Trial Balance (Control Total) | B10: =-SUMIFS('91_Mapping'!H:H, '91_Mapping'!F:F, "2.2") -> 0 | C10: =-SUMIFS('91_Mapping'!I:I, '91_Mapping'!F:F, "2.2") -> 0
A11: Difference | B11: =TOT_LTProv-B10 -> 0 | C11: =TOT_LTProv_PY-C10 -> 0

Sheet Note_3_1_STBorrow
A1: APEX_ENGINEERING_INDUSTRIES_LIMITED
A2: NOTE 3.1: SHORT-TERM BORROWINGS | B2: =HYPERLINK("#\'02_Balance_Sheet\'!A1", "[<- Back to Balance Sheet]") -> 0
A3: (All amounts in INR Lakhs unless otherwise stated)
A5: Particulars | B5: As at FY 2024-25 | C5: As at FY 2023-24
A6: ICICI Bank Limited - Working Capital Cash Credit Limit | B6: 80 | C6: 60
A7: TOTAL SHORT-TERM BORROWINGS | B7: =-1*SUM(B6:B6) -> 80 | C7: =-1*SUM(C6:C6) -> 60
A9: Per Trial Balance (Control Total) | B9: =-SUMIFS('91_Mapping'!H:H, '91_Mapping'!F:F, "3.1") -> 80 | C9: =-SUMIFS('91_Mapping'!I:I, '91_Mapping'!F:F, "3.1") -> 60
A10: Difference | B10: =TOT_STBorrow-B9 -> 0 | C10: =TOT_STBorrow_PY-C9 -> 0

Sheet Note_3_2_TradePayables
A1: APEX_ENGINEERING_INDUSTRIES_LIMITED
A2: NOTE 3.2: TRADE PAYABLES | B2: =HYPERLINK("#\'02_Balance_Sheet\'!A1", "[<- Back to Balance Sheet]") -> 0
A3: (All amounts in INR Lakhs unless otherwise stated)
A5: Vendor Name | B5: MSME | C5: < 1 Year | D5: 1-2 Years | E5: 2-3 Years | F5: > 3 Years | G5: Total Outstanding
A6: Shree Metals & Alloys Pvt Ltd (MSME) | B6: Yes | C6: 60 | D6: 5 | E6: 0 | F6: 0 | G6: 65
A7: Global Industrial Suppliers Inc | B7: No | C7: 110 | D7: 10 | E7: 0 | F7: 0 | G7: 120
A8: TOTAL TRADE PAYABLES | B8: 0 | C8: 185 | D8: 0 | E8: 0 | F8: 0 | G8: 185
A10: Per Trial Balance (Control Total) | F10: =-SUMIFS('91_Mapping'!H:H, '91_Mapping'!F:F, "3.2") -> 0 | G10: =-SUMIFS('91_Mapping'!I:I, '91_Mapping'!F:F, "3.2") -> 185
A11: Difference | F11: =TOT_Payables-F10 -> 0 | G11: =TOT_Payables_PY-G10 -> 0

Sheet Note_3_3_OtherCL
A1: APEX_ENGINEERING_INDUSTRIES_LIMITED
A2: NOTE 3.3: OTHER CURRENT LIABILITIES | B2: =HYPERLINK("#\'02_Balance_Sheet\'!A1", "[<- Back to Balance Sheet]") -> 0
A3: (All amounts in INR Lakhs unless otherwise stated)
A5: Particulars | B5: As at FY 2024-25 | C5: As at FY 2023-24
A6: Current Maturities of Long-term Borrowings | B6: 11.25 | C6: 9
A7: Interest Accrued but not Due on Borrowings | B7: 3.75 | C7: 3
A8: Advance Received from Customers | B8: 5 | C8: 4
A9: Statutory Liabilities (GST, TDS, PF Payable) | B9: 3.75 | C9: 3
A10: Other Payables - Security Deposits / Accruals | B10: 1.25 | C10: 1
A11: TOTAL OTHER CURRENT LIABILITIES | B11: =-1*SUM(B6:B10) -> 25 | C11: =-1*SUM(C6:C10) -> 20
A13: Per Trial Balance (Control Total) | B13: =-SUMIFS('91_Mapping'!H:H, '91_Mapping'!F:F, "3.3") -> 25 | C13: =-SUMIFS('91_Mapping'!I:I, '91_Mapping'!F:F, "3.3") -> 20
A14: Difference | B14: =TOT_OtherCL-B13 -> 0 | C14: =TOT_OtherCL_PY-C13 -> 0

Sheet Note_3_4_STProv
A1: APEX_ENGINEERING_INDUSTRIES_LIMITED
A2: NOTE 3.4: SHORT-TERM PROVISIONS | B2: =HYPERLINK("#\'02_Balance_Sheet\'!A1", "[<- Back to Balance Sheet]") -> 0
A3: (All amounts in INR Lakhs unless otherwise stated)
A5: Particulars | B5: As at FY 2024-25 | C5: As at FY 2023-24
A6: Provision for Income Tax (Net of Advance Tax) | B6: 0 | C6: 0
A7: Provision for Employee Benefits (Leave & Gratuity - Current) | B7: 0 | C7: 0
A8: Provision for Bonus / Ex-gratia | B8: 0 | C8: 0
A9: TOTAL SHORT-TERM PROVISIONS | B9: =-1*SUM(B6:B8) -> 0 | C9: =-1*SUM(C6:C8) -> 0
A11: Per Trial Balance (Control Total) | B11: =-SUMIFS('91_Mapping'!H:H, '91_Mapping'!F:F, "3.4") -> 0 | C11: =-SUMIFS('91_Mapping'!I:I, '91_Mapping'!F:F, "3.4") -> 0
A12: Difference | B12: =TOT_STProv-B11 -> 0 | C12: =TOT_STProv_PY-C11 -> 0

Sheet Note_4_1_PPE
A1: APEX_ENGINEERING_INDUSTRIES_LIMITED
A2: NOTE 4.1: PROPERTY, PLANT AND EQUIPMENT | B2: =HYPERLINK("#\'02_Balance_Sheet\'!A1", "[<- Back to Balance Sheet]") -> 0
A3: (All amounts in INR Lakhs unless otherwise stated)
A5: Asset Category | B5: Opening Gross Block | C5: Additions | D5: Disposals | E5: Closing Gross Block | F5: Accum. Dep (Open) | G5: Dep for Year | H5: Dep on Disposal | I5: Accum. Dep (Close) | J5: Net Block FY 2024-25 | K5: Net Block FY 2023-24
A6: Freehold Land | B6: 160.26 | C6: 13.94 | D6: 0 | E6: 174.2 | F6: 0 | G6: 0 | H6: 0 | I6: 0 | J6: 174.2 | K6: 160.26
A7: Buildings | B7: 200.33 | C7: 17.42 | D7: 0 | E7: 217.75 | F7: 10.02 | G7: 10.89 | H7: 0 | I7: 20.91 | J7: 196.84 | K7: 190.31
A8: Plant & Machinery | B8: 280.46 | C8: 24.39 | D8: 0 | E8: 304.85 | F8: 28.05 | G8: 30.49 | H8: 0 | I8: 58.54 | J8: 246.31 | K8: 252.41
A9: Furniture & Fixtures | B9: 80.13 | C9: 6.97 | D9: 0 | E9: 87.1 | F9: 8.01 | G9: 8.71 | H9: 0 | I9: 16.72 | J9: 70.38 | K9: 72.12
A10: Office Equipment | B10: 40.07 | C10: 3.48 | D10: 0 | E10: 43.55 | F10: 6.01 | G10: 6.53 | H10: 0 | I10: 12.54 | J10: 31.01 | K10: 34.06
A11: Vehicles | B11: 40.07 | C11: 3.48 | D11: 0 | E11: 43.55 | F11: 6.01 | G11: 6.53 | H11: 0 | I11: 12.54 | J11: 31.01 | K11: 34.06
A12: TOTAL PROPERTY, PLANT & EQUIPMENT | B12: 801.32 | C12: 69.68 | D12: 0 | E12: 871 | F12: 58.1 | G12: 63.15 | H12: 0 | I12: 121.25 | J12: 749.75 | K12: 743.22
A14: Per Trial Balance (Control Total) | J14: =SUMIFS('91_Mapping'!H:H, '91_Mapping'!F:F, "4.1") -> 801.32 | K14: =SUMIFS('91_Mapping'!I:I, '91_Mapping'!F:F, "4.1") -> 69.68
A15: Difference | J15: =TOT_PPE-J14 -> 0 | K15: =TOT_PPE_PY-K14 -> 0

Sheet Note_4_2_CWIP
A1: APEX_ENGINEERING_INDUSTRIES_LIMITED
A2: NOTE 4.2: CAPITAL WORK-IN-PROGRESS | B2: =HYPERLINK("#\'02_Balance_Sheet\'!A1", "[<- Back to Balance Sheet]") -> 0
A3: (All amounts in INR Lakhs unless otherwise stated)
A5: Project Name | B5: < 1 Year | C5: 1-2 Years | D5: 2-3 Years | E5: > 3 Years | F5: Total CWIP
A6: Rooftop Captive Solar Power Plant (500 KW) | B6: 30 | C6: 15 | D6: 0 | E6: 0 | F6: 45
A7: TOTAL CAPITAL WORK-IN-PROGRESS | B7: 45 | C7: 0 | D7: 0 | E7: 0 | F7: 45
A9: Per Trial Balance (Control Total) | E9: =SUMIFS('91_Mapping'!H:H, '91_Mapping'!F:F, "4.2") -> 45 | F9: =SUMIFS('91_Mapping'!I:I, '91_Mapping'!F:F, "4.2") -> 0
A10: Difference | E10: =TOT_CWIP-E9 -> 0 | F10: =TOT_CWIP_PY-F9 -> 0

Sheet Note_4_3_Investments
A1: APEX_ENGINEERING_INDUSTRIES_LIMITED
A2: NOTE 4.3: NON-CURRENT INVESTMENTS | B2: =HYPERLINK("#\'02_Balance_Sheet\'!A1", "[<- Back to Balance Sheet]") -> 0
A3: (All amounts in INR Lakhs unless otherwise stated)
A5: Particulars | B5: No. of Units | C5: As at FY 2024-25 | D5: As at FY 2023-24
A6: Unquoted Equity Instruments - at cost:
A7: Investment in Associate Companies | B7: - | C7: 0 | D7: 0
A8: Investment in Other Companies | B8: - | C8: 0 | D8: 0
A9: TOTAL NON-CURRENT INVESTMENTS | B9: 0 | C9: 0 | D9: 0
A11: Per Trial Balance (Control Total) | C11: =SUMIFS('91_Mapping'!H:H, '91_Mapping'!F:F, "4.3") -> 0 | D11: =SUMIFS('91_Mapping'!I:I, '91_Mapping'!F:F, "4.3") -> 0
A12: Difference | C12: =TOT_Investments-C11 -> 0 | D12: =TOT_Investments_PY-D11 -> 0

Sheet Note_4_4_LTLA
A1: APEX_ENGINEERING_INDUSTRIES_LIMITED
A2: NOTE 4.4: LONG-TERM LOANS AND ADVANCES | B2: =HYPERLINK("#\'02_Balance_Sheet\'!A1", "[<- Back to Balance Sheet]") -> 0
A3: (All amounts in INR Lakhs unless otherwise stated)
A5: Particulars | B5: As at FY 2024-25 | C5: As at FY 2023-24
A6: Security Deposits - Considered Good (Unsecured) | B6: 0 | C6: 0
A7: Capital Advances - Considered Good | B7: 0 | C7: 0
A8: Advance Income Tax & TDS Recoverable (Net) | B8: 0 | C8: 0
A9: TOTAL LONG-TERM LOANS AND ADVANCES | B9: =SUM(B6:B8) -> 0 | C9: =SUM(C6:C8) -> 0
A11: Per Trial Balance (Control Total) | B11: =SUMIFS('91_Mapping'!H:H, '91_Mapping'!F:F, "4.4") -> 0 | C11: =SUMIFS('91_Mapping'!I:I, '91_Mapping'!F:F, "4.4") -> 0
A12: Difference | B12: =TOT_LTLA-B11 -> 0 | C12: =TOT_LTLA_PY-C11 -> 0

Sheet Note_5_1_Inventories
A1: APEX_ENGINEERING_INDUSTRIES_LIMITED
A2: NOTE 5.1: INVENTORIES | B2: =HYPERLINK("#\'02_Balance_Sheet\'!A1", "[<- Back to Balance Sheet]") -> 0
A3: (All amounts in INR Lakhs unless otherwise stated)
A5: Particulars | B5: As at FY 2024-25 | C5: As at FY 2023-24
A6: Raw Materials (at cost - FIFO basis) | B6: 58 | C6: 48
A7: Work-in-Progress (at estimated cost) | B7: 29 | C7: 24
A8: Finished Goods (at lower of cost and NRV) | B8: 43.5 | C8: 36
A9: Stores, Spares & Consumables | B9: 14.5 | C9: 12
A10: TOTAL INVENTORIES | B10: =SUM(B6:B9) -> 145 | C10: =SUM(C6:C9) -> 120
A12: Per Trial Balance (Control Total) | B12: =SUMIFS('91_Mapping'!H:H, '91_Mapping'!F:F, "5.1") -> 145 | C12: =SUMIFS('91_Mapping'!I:I, '91_Mapping'!F:F, "5.1") -> 120
A13: Difference | B13: =TOT_Inventory-B12 -> 0 | C13: =TOT_Inventory_PY-C12 -> 0

Sheet Note_5_2_Receivables
A1: APEX_ENGINEERING_INDUSTRIES_LIMITED
A2: NOTE 5.2: TRADE RECEIVABLES | B2: =HYPERLINK("#\'02_Balance_Sheet\'!A1", "[<- Back to Balance Sheet]") -> 0
A3: (All amounts in INR Lakhs unless otherwise stated)
A5: Customer Name | B5: Category | C5: < 6 Months | D5: 6M-1 Year | E5: 1-2 Years | F5: 2-3 Years | G5: > 3 Years | H5: Total
A6: Precision Engineering Solutions Ltd | B6: Undisputed Considered Good | C6: 85 | D6: 15 | E6: 0 | F6: 0 | G6: 0 | H6: 100
A7: Bharat Auto Components Pvt Ltd | B7: Undisputed Considered Good | C7: 45 | D7: 10 | E7: 5 | F7: 0 | G7: 0 | H7: 60
A8: Apex Heavy Infra Projects | B8: Undisputed Considered Doubtful | C8: 0 | D8: 5 | E8: 10 | F8: 0 | G8: 0 | H8: 15
A9: TOTAL TRADE RECEIVABLES | B9: 0 | C9: 175 | D9: 0 | E9: 0 | F9: 0 | G9: 0 | H9: 175
A11: Per Trial Balance (Control Total) | G11: =SUMIFS('91_Mapping'!H:H, '91_Mapping'!F:F, "5.2") -> 0 | H11: =SUMIFS('91_Mapping'!I:I, '91_Mapping'!F:F, "5.2") -> 175
A12: Difference | G12: =TOT_Receivables-G11 -> 0 | H12: =TOT_Receivables_PY-H11 -> 0

Sheet Note_5_3_CashBank
A1: APEX_ENGINEERING_INDUSTRIES_LIMITED
A2: NOTE 5.3: CASH AND BANK BALANCES | B2: =HYPERLINK("#\'02_Balance_Sheet\'!A1", "[<- Back to Balance Sheet]") -> 0
A3: (All amounts in INR Lakhs unless otherwise stated)
A5: Particulars | B5: As at FY 2024-25 | C5: As at FY 2023-24
A6: A. Cash and Cash Equivalents:
A7: Cash in Hand | B7: 8.75 | C7: 7.75
A8: Balances with Banks - Current Accounts | B8: 96.25 | C8: 85.25
A9: Bank Fixed Deposits (Original Maturity up to 3 months) | B9: 35 | C9: 31
A10: Total Cash & Cash Equivalents (A) | B10: 140 | C10: 124
A11: B. Other Bank Balances:
A12: Bank Fixed Deposits (Maturity > 3 months, pledged as margin) | B12: 35 | C12: 31
A13: Total Other Bank Balances (B) | B13: 35 | C13: 31
A14: TOTAL CASH AND BANK BALANCES (A + B) | B14: =SUM(B6:B13) -> 175 | C14: =SUM(C6:C13) -> 155
A16: Per Trial Balance (Control Total) | B16: =SUMIFS('91_Mapping'!H:H, '91_Mapping'!F:F, "5.3") -> 175 | C16: =SUMIFS('91_Mapping'!I:I, '91_Mapping'!F:F, "5.3") -> 155
A17: Difference | B17: =TOT_Cash-B16 -> 0 | C17: =TOT_Cash_PY-C16 -> 0

Sheet Note_5_4_STLA
A1: APEX_ENGINEERING_INDUSTRIES_LIMITED
A2: NOTE 5.4: SHORT-TERM LOANS AND ADVANCES | B2: =HYPERLINK("#\'02_Balance_Sheet\'!A1", "[<- Back to Balance Sheet]") -> 0
A3: (All amounts in INR Lakhs unless otherwise stated)
A5: Particulars | B5: As at FY 2024-25 | C5: As at FY 2023-24
A6: Advance to Suppliers - Considered Good | B6: 0 | C6: 0
A7: Prepaid Expenses | B7: 0 | C7: 0
A8: GST Input Tax Credit Receivable | B8: 0 | C8: 0
A9: Advance to Employees | B9: 0 | C9: 0
A10: Other Short-term Advances - Considered Good | B10: 0 | C10: 0
A11: TOTAL SHORT-TERM LOANS AND ADVANCES | B11: =SUM(B6:B10) -> 0 | C11: =SUM(C6:C10) -> 0
A13: Per Trial Balance (Control Total) | B13: =SUMIFS('91_Mapping'!H:H, '91_Mapping'!F:F, "5.4") -> 0 | C13: =SUMIFS('91_Mapping'!I:I, '91_Mapping'!F:F, "5.4") -> 0
A14: Difference | B14: =TOT_STLA-B13 -> 0 | C14: =TOT_STLA_PY-C13 -> 0

Sheet Note_5_5_OtherCA
A1: APEX_ENGINEERING_INDUSTRIES_LIMITED
A2: NOTE 5.5: OTHER CURRENT ASSETS | B2: =HYPERLINK("#\'02_Balance_Sheet\'!A1", "[<- Back to Balance Sheet]") -> 0
A3: (All amounts in INR Lakhs unless otherwise stated)
A5: Particulars | B5: As at FY 2024-25 | C5: As at FY 2023-24
A6: Interest Accrued on Fixed Deposits | B6: 0 | C6: 0
A7: Other Receivables & Accruals | B7: 0 | C7: 0
A8: TOTAL OTHER CURRENT ASSETS | B8: =SUM(B6:B7) -> 0 | C8: =SUM(C6:C7) -> 0
A10: Per Trial Balance (Control Total) | B10: =SUMIFS('91_Mapping'!H:H, '91_Mapping'!F:F, "5.5") -> 0 | C10: =SUMIFS('91_Mapping'!I:I, '91_Mapping'!F:F, "5.5") -> 0
A11: Difference | B11: =TOT_OtherCA-B10 -> 0 | C11: =TOT_OtherCA_PY-C10 -> 0

Sheet Note_6_1_Revenue
A1: APEX_ENGINEERING_INDUSTRIES_LIMITED
A2: NOTE 6.1: REVENUE FROM OPERATIONS | B2: =HYPERLINK("#\'02_Balance_Sheet\'!A1", "[<- Back to Balance Sheet]") -> 0
A3: (All amounts in INR Lakhs unless otherwise stated)
A5: Particulars | B5: Year ended FY 2024-25 | C5: Year ended FY 2023-24
A6: (a) Sale of Manufactured Products:
A7: Domestic Sales | B7: =SUMIFS('91_Mapping'!H:H, '91_Mapping'!D:D, "Domestic Sales") -> 765 | C7: =SUMIFS('91_Mapping'!I:I, '91_Mapping'!D:D, "Domestic Sales") -> 630
A8: Export Sales | B8: =SUMIFS('91_Mapping'!H:H, '91_Mapping'!D:D, "Export Sales") -> 85 | C8: =SUMIFS('91_Mapping'!I:I, '91_Mapping'!D:D, "Export Sales") -> 70
A9: (b) Sale of Services / Job Work Income | B9: 0 | C9: 0
A10: (c) Other Operating Revenue | B10: 0 | C10: 0
A11: TOTAL REVENUE FROM OPERATIONS | B11: =-1*SUM(B6:B10) -> 850 | C11: =-1*SUM(C6:C10) -> 700
A13: Per Trial Balance (Control Total) | B13: =-SUMIFS('91_Mapping'!H:H, '91_Mapping'!F:F, "6.1") -> 850 | C13: =-SUMIFS('91_Mapping'!I:I, '91_Mapping'!F:F, "6.1") -> 700
A14: Difference | B14: =TOT_Revenue-B13 -> 0 | C14: =TOT_Revenue_PY-C13 -> 0

Sheet Note_6_2_OtherIncome
A1: APEX_ENGINEERING_INDUSTRIES_LIMITED
A2: NOTE 6.2: OTHER INCOME | B2: =HYPERLINK("#\'02_Balance_Sheet\'!A1", "[<- Back to Balance Sheet]") -> 0
A3: (All amounts in INR Lakhs unless otherwise stated)
A5: Particulars | B5: Year ended FY 2024-25 | C5: Year ended FY 2023-24
A6: Interest Income on Bank Fixed Deposits | B6: 10.5 | C6: 7
A7: Profit on Sale of Fixed Assets | B7: 0 | C7: 0
A8: Liabilities / Provisions no longer required written back | B8: 3 | C8: 2
A9: Miscellaneous Income | B9: 1.5 | C9: 1
A10: TOTAL OTHER INCOME | B10: =-1*SUM(B6:B9) -> 15 | C10: =-1*SUM(C6:C9) -> 10
A12: Per Trial Balance (Control Total) | B12: =-SUMIFS('91_Mapping'!H:H, '91_Mapping'!F:F, "6.2") -> 15 | C12: =-SUMIFS('91_Mapping'!I:I, '91_Mapping'!F:F, "6.2") -> 10
A13: Difference | B13: =TOT_OtherIncome-B12 -> 0 | C13: =TOT_OtherIncome_PY-C12 -> 0

Sheet Note_7_1_Material
A1: APEX_ENGINEERING_INDUSTRIES_LIMITED
A2: NOTE 7.1: COST OF MATERIALS CONSUMED | B2: =HYPERLINK("#\'02_Balance_Sheet\'!A1", "[<- Back to Balance Sheet]") -> 0
A3: (All amounts in INR Lakhs unless otherwise stated)
A5: Particulars | B5: Year ended FY 2024-25 | C5: Year ended FY 2023-24
A6: (a) Cost of Raw Materials Consumed:
A7: Opening Stock of Raw Materials | B7: =SUMIFS('91_Mapping'!H:H, '91_Mapping'!D:D, "Opening Stock of Raw Materials") -> 75.6 | C7: =SUMIFS('91_Mapping'!I:I, '91_Mapping'!D:D, "Opening Stock of Raw Materials") -> 63
A8: Add: Purchases of Raw Materials | B8: =SUMIFS('91_Mapping'!H:H, '91_Mapping'!D:D, "Add: Purchases of Raw Materials") -> 357 | C8: =SUMIFS('91_Mapping'!I:I, '91_Mapping'!D:D, "Add: Purchases of Raw Materials") -> 297.5
A9: Less: Closing Stock of Raw Materials | B9: =SUMIFS('91_Mapping'!H:H, '91_Mapping'!D:D, "Less: Closing Stock of Raw Materials") -> 12.6 | C9: =SUMIFS('91_Mapping'!I:I, '91_Mapping'!D:D, "Less: Closing Stock of Raw Materials") -> 10.5
A10: Total Cost of Materials Consumed (A) | B10: =SUMIFS('91_Mapping'!H:H, '91_Mapping'!D:D, "Total Cost of Materials Consumed (A)") -> 420 | C10: =SUMIFS('91_Mapping'!I:I, '91_Mapping'!D:D, "Total Cost of Materials Consumed (A)") -> 350
A11: (b) Purchases of Stock-in-Trade (B) | B11: 0 | C11: 0
A12: (c) Changes in Inventories:
A13: Opening Stock (WIP + Finished Goods) | B13: =SUMIFS('91_Mapping'!H:H, '91_Mapping'!D:D, "Opening Stock (WIP + Finished Goods)") -> 0 | C13: =SUMIFS('91_Mapping'!I:I, '91_Mapping'!D:D, "Opening Stock (WIP + Finished Goods)") -> 0
A14: Less: Closing Stock (WIP + Finished Goods) | B14: =SUMIFS('91_Mapping'!H:H, '91_Mapping'!D:D, "Less: Closing Stock (WIP + Finished Goods)") -> 0 | C14: =SUMIFS('91_Mapping'!I:I, '91_Mapping'!D:D, "Less: Closing Stock (WIP + Finished Goods)") -> 0
A15: Net Change in Inventories (C) | B15: =SUMIFS('91_Mapping'!H:H, '91_Mapping'!D:D, "Net Change in Inventories (C)") -> 0 | C15: =SUMIFS('91_Mapping'!I:I, '91_Mapping'!D:D, "Net Change in Inventories (C)") -> 0
A16: TOTAL MATERIAL COSTS (A + B + C) | B16: =SUM(B6:B15) -> 420 | C16: =SUM(C6:C15) -> 350
A18: Per Trial Balance (Control Total) | B18: =SUMIFS('91_Mapping'!H:H, '91_Mapping'!F:F, "7.1") -> 420 | C18: =SUMIFS('91_Mapping'!I:I, '91_Mapping'!F:F, "7.1") -> 350
A19: Difference | B19: =TOT_Material-B18 -> 0 | C19: =TOT_Material_PY-C18 -> 0

Sheet Note_7_2_Employee
A1: APEX_ENGINEERING_INDUSTRIES_LIMITED
A2: NOTE 7.2: EMPLOYEE BENEFIT EXPENSES | B2: =HYPERLINK("#\'02_Balance_Sheet\'!A1", "[<- Back to Balance Sheet]") -> 0
A3: (All amounts in INR Lakhs unless otherwise stated)
A5: Particulars | B5: Year ended FY 2024-25 | C5: Year ended FY 2023-24
A6: Salaries, Wages, Bonus & Allowances | B6: 114.8 | C6: 98.4
A7: Contribution to Provident Fund (PF) | B7: 9.8 | C7: 8.4
A8: Contribution to ESIC / Gratuity / Other Funds | B8: 8.4 | C8: 7.2
A9: Leave Encashment (Short-term) | B9: 4.2 | C9: 3.6
A10: Staff Welfare & Training Expenses | B10: 2.8 | C10: 2.4
A11: TOTAL EMPLOYEE BENEFIT EXPENSES | B11: =SUM(B6:B10) -> 140 | C11: =SUM(C6:C10) -> 120
A13: Per Trial Balance (Control Total) | B13: =SUMIFS('91_Mapping'!H:H, '91_Mapping'!F:F, "7.2") -> 140 | C13: =SUMIFS('91_Mapping'!I:I, '91_Mapping'!F:F, "7.2") -> 120
A14: Difference | B14: =TOT_Employee-B13 -> 0 | C14: =TOT_Employee_PY-C13 -> 0

Sheet Note_7_3_Finance
A1: APEX_ENGINEERING_INDUSTRIES_LIMITED
A2: NOTE 7.3: FINANCE COSTS | B2: =HYPERLINK("#\'02_Balance_Sheet\'!A1", "[<- Back to Balance Sheet]") -> 0
A3: (All amounts in INR Lakhs unless otherwise stated)
A5: Particulars | B5: Year ended FY 2024-25 | C5: Year ended FY 2023-24
A6: Interest on Term Loans | B6: 20.8 | C6: 24.7
A7: Interest on Working Capital Facilities | B7: 8 | C7: 9.5
A8: Bank Charges, Processing Fees & Commission | B8: 2.56 | C8: 3.04
A9: Other Borrowing Costs | B9: 0.64 | C9: 0.76
A10: TOTAL FINANCE COSTS | B10: =SUM(B6:B9) -> 32 | C10: =SUM(C6:C9) -> 38
A12: Per Trial Balance (Control Total) | B12: =SUMIFS('91_Mapping'!H:H, '91_Mapping'!F:F, "7.3") -> 32 | C12: =SUMIFS('91_Mapping'!I:I, '91_Mapping'!F:F, "7.3") -> 38
A13: Difference | B13: =TOT_Finance-B12 -> 0 | C13: =TOT_Finance_PY-C12 -> 0

Sheet Note_7_4_Depreciation
A1: APEX_ENGINEERING_INDUSTRIES_LIMITED
A2: NOTE 7.4: DEPRECIATION AND AMORTISATION EXPENSE | B2: =HYPERLINK("#\'02_Balance_Sheet\'!A1", "[<- Back to Balance Sheet]") -> 0
A3: (All amounts in INR Lakhs unless otherwise stated)
A5: Particulars | B5: Year ended FY 2024-25 | C5: Year ended FY 2023-24
A6: Depreciation on Property, Plant & Equipment (SLM) | B6: 27.16 | C6: 24.25
A7: Amortisation of Intangible Assets | B7: 0.56 | C7: 0.5
A8: Amortisation of Preliminary / Pre-operative Expenses | B8: 0.28 | C8: 0.25
A9: TOTAL DEPRECIATION AND AMORTISATION | B9: =SUM(B6:B8) -> 28 | C9: =SUM(C6:C8) -> 25
A11: Per Trial Balance (Control Total) | B11: =SUMIFS('91_Mapping'!H:H, '91_Mapping'!F:F, "7.4") -> 28 | C11: =SUMIFS('91_Mapping'!I:I, '91_Mapping'!F:F, "7.4") -> 25
A12: Difference | B12: =TOT_Depreciation-B11 -> 0 | C12: =TOT_Depreciation_PY-C11 -> 0

Sheet Note_7_5_OtherExp
A1: APEX_ENGINEERING_INDUSTRIES_LIMITED
A2: NOTE 7.5: OTHER EXPENSES | B2: =HYPERLINK("#\'02_Balance_Sheet\'!A1", "[<- Back to Balance Sheet]") -> 0
A3: (All amounts in INR Lakhs unless otherwise stated)
A5: Particulars | B5: Year ended FY 2024-25 | C5: Year ended FY 2023-24
A6: Power & Fuel Expenses | B6: 12.6 | C6: 8.96
A7: Rent, Rates & Taxes | B7: 8.1 | C7: 5.76
A8: Repairs & Maintenance - Plant & Machinery | B8: 4.5 | C8: 3.2
A9: Repairs & Maintenance - Buildings & Civil | B9: 2.25 | C9: 1.6
A10: Freight & Transportation Outward | B10: 5.4 | C10: 3.84
A11: Legal & Professional Fees | B11: 3.6 | C11: 2.56
A12: Insurance Premiums | B12: 1.8 | C12: 1.28
A13: Printing, Stationery & Communication | B13: 1.35 | C13: 0.96
A14: Travelling & Conveyance Expenses | B14: 2.25 | C14: 1.6
A15: Statutory Auditor Remuneration (as auditor) | B15: 0.9 | C15: 0.64
A16: Miscellaneous Administrative Expenses | B16: 2.25 | C16: 1.6
A17: TOTAL OTHER EXPENSES | B17: =SUM(B6:B16) -> 45 | C17: =SUM(C6:C16) -> 32
A19: Per Trial Balance (Control Total) | B19: =SUMIFS('91_Mapping'!H:H, '91_Mapping'!F:F, "7.5") -> 45 | C19: =SUMIFS('91_Mapping'!I:I, '91_Mapping'!F:F, "7.5") -> 32
A20: Difference | B20: =TOT_OtherExp-B19 -> 0 | C20: =TOT_OtherExp_PY-C19 -> 0

Sheet Note_7_6_Tax
A1: APEX_ENGINEERING_INDUSTRIES_LIMITED
A2: NOTE 7.6: TAX EXPENSE | B2: =HYPERLINK("#\'02_Balance_Sheet\'!A1", "[<- Back to Balance Sheet]") -> 0
A3: (All amounts in INR Lakhs unless otherwise stated)
A5: Particulars | B5: Year ended FY 2024-25 | C5: Year ended FY 2023-24
A6: Current Tax - Income Tax for the year | B6: 36 | C6: 27
A7: Deferred Tax Charge / (Credit) | B7: 4 | C7: 3
A8: Earlier Years' Tax Adjustments | B8: 0 | C8: 0
A9: TOTAL TAX EXPENSE | B9: =-1*SUM(B6:B8) -> 40 | C9: =-1*SUM(C6:C8) -> 30
A11: Per Trial Balance (Control Total) | B11: =-SUMIFS('91_Mapping'!H:H, '91_Mapping'!F:F, "7.6") -> 40 | C11: =-SUMIFS('91_Mapping'!I:I, '91_Mapping'!F:F, "7.6") -> 30
A12: Difference | B12: =TOT_Tax-B11 -> 0 | C12: =TOT_Tax_PY-C11 -> 0

Sheet Note_8_1_RPT
A1: APEX_ENGINEERING_INDUSTRIES_LIMITED
A2: NOTE 8.1: RELATED PARTY DISCLOSURES (AS 18) | B2: =HYPERLINK("#\'02_Balance_Sheet\'!A1", "[<- Back to Balance Sheet]") -> 0
A3: (All amounts in INR Lakhs unless otherwise stated)
A5: Related Party Name | B5: Relationship | C5: Nature of Transaction | D5: Opening Balance | E5: Debit Tx | F5: Credit Tx | G5: Closing Balance
A6: Rajesh Kumar (Managing Director) | B6: Key Managerial Personnel (KMP) | C6: Managerial Remuneration & Director Sitting Fees | D6: 0 | E6: 0 | F6: 36 | G6: 3
A8: Per Trial Balance (Control Total) | F8: =SUMIFS('91_Mapping'!H:H, '91_Mapping'!F:F, "8.1") -> 0 | G8: =SUMIFS('91_Mapping'!I:I, '91_Mapping'!F:F, "8.1") -> 0
A9: Difference | F9: =TOT_RPT-F8 -> 0 | G9: =TOT_RPT_PY-G8 -> 0

Sheet Note_8_2_Contingencies
A1: APEX_ENGINEERING_INDUSTRIES_LIMITED
A2: NOTE 8.2: CONTINGENT LIABILITIES & COMMITMENTS (AS 29) | B2: =HYPERLINK("#\'02_Balance_Sheet\'!A1", "[<- Back to Balance Sheet]") -> 0
A3: (All amounts in INR Lakhs unless otherwise stated)
A5: Nature of Contingency | B5: Forum / Authority | C5: CY Amount (FY 2024-25) | D5: PY Amount (FY 2023-24) | E5: Management Assessment | F5: Provision Required
A6: Disputed GST Penalty Assessment | B6: GST Appellate Authority | C6: 35 | D6: 35 | E6: High probability of favorable decision based on legal counsel opinion | F6: No
A8: Per Trial Balance (Control Total) | E8: =SUMIFS('91_Mapping'!H:H, '91_Mapping'!F:F, "8.2") -> 0 | F8: =SUMIFS('91_Mapping'!I:I, '91_Mapping'!F:F, "8.2") -> 0
A9: Difference | E9: =TOT_Contingencies-E8 -> 0 | F9: =TOT_Contingencies_PY-F8 -> 0

Sheet 02_Balance_Sheet
A1: SW INDIA | CHARTERED ACCOUNTANTS
A2: BALANCE SHEET AS AT MARCH 31, 2025
A4: Particulars | B4: Note # | C4: As at 31-Mar-2025 (CY) | D4: As at 31-Mar-2024 (PY)
A5: EQUITY AND LIABILITIES | C5: 0 | D5: 0
A6: 1. Shareholders' Funds | C6: 670 | D6: 505
A7: (a) Share Capital | B7: =HYPERLINK("#\'Note_1_1_ShareCapital\'!A1", "1.1") -> 0 | C7: =-TOT_ShareCapital -> 100 | D7: =-TOT_ShareCapital_PY -> 100
A8: (b) Reserves and Surplus | B8: =HYPERLINK("#\'Note_1_2_Reserves\'!A1", "1.2") -> 0 | C8: =-TOT_Reserves -> 570 | D8: =-TOT_Reserves_PY -> 405
A9: 2. Non-Current Liabilities | C9: 250 | D9: 300
A10: (a) Long-term Borrowings | B10: =HYPERLINK("#\'Note_2_1_LTBorrow\'!A1", "2.1") -> 0 | C10: =-TOT_LTBorrow -> 250 | D10: =-TOT_LTBorrow_PY -> 300
A11: (b) Long-term Provisions | B11: =HYPERLINK("#\'Note_2_2_LTProv\'!A1", "2.2") -> 0 | C11: =-TOT_LTProv -> 0 | D11: =-TOT_LTProv_PY -> 0
A12: 3. Current Liabilities | C12: 290 | D12: 225
A13: (a) Short-term Borrowings | B13: =HYPERLINK("#\'Note_3_1_STBorrow\'!A1", "3.1") -> 0 | C13: =-TOT_STBorrow -> 80 | D13: =-TOT_STBorrow_PY -> 60
A14: (b) Trade Payables | B14: =HYPERLINK("#\'Note_3_2_TradePayables\'!A1", "3.2") -> 0 | C14: =-TOT_Payables -> 185 | D14: =-TOT_Payables_PY -> 145
A15: (c) Other Current Liabilities | B15: =HYPERLINK("#\'Note_3_3_OtherCL\'!A1", "3.3") -> 0 | C15: =-TOT_OtherCL -> 25 | D15: =-TOT_OtherCL_PY -> 20
A16: (d) Short-term Provisions | B16: =HYPERLINK("#\'Note_3_4_STProv\'!A1", "3.4") -> 0 | C16: =-TOT_STProv -> 0 | D16: =-TOT_STProv_PY -> 0
A17: TOTAL EQUITY AND LIABILITIES | C17: =C0+C0+C0 -> 1210 | D17: =D0+D0+D0 -> 1030
A18: ASSETS | C18: 0 | D18: 0
A19: 1. Non-Current Assets | C19: 715 | D19: 645
A20: (a) Property, Plant and Equipment | B20: =HYPERLINK("#\'Note_4_1_PPE\'!A1", "4.1") -> 0 | C20: =TOT_PPE -> 670 | D20: =TOT_PPE_PY -> 630
A21: (b) Capital Work-in-Progress | B21: =HYPERLINK("#\'Note_4_2_CWIP\'!A1", "4.2") -> 0 | C21: =TOT_CWIP -> 45 | D21: =TOT_CWIP_PY -> 15
A22: (c) Non-current Investments | B22: =HYPERLINK("#\'Note_4_3_Investments\'!A1", "4.3") -> 0 | C22: =TOT_Investments -> 0 | D22: =TOT_Investments_PY -> 0
A23: (d) Long-term Loans and Advances | B23: =HYPERLINK("#\'Note_4_4_LTLA\'!A1", "4.4") -> 0 | C23: =TOT_LTLA -> 0 | D23: =TOT_LTLA_PY -> 0
A24: (e) Other Non-current Assets | B24: 4.5 | C24: 0 | D24: 0
A25: 2. Current Assets | C25: 495 | D25: 415
A26: (a) Inventories | B26: =HYPERLINK("#\'Note_5_1_Inventories\'!A1", "5.1") -> 0 | C26: =TOT_Inventory -> 145 | D26: =TOT_Inventory_PY -> 120
A27: (b) Trade Receivables | B27: =HYPERLINK("#\'Note_5_2_Receivables\'!A1", "5.2") -> 0 | C27: =TOT_Receivables -> 175 | D27: =TOT_Receivables_PY -> 140
A28: (c) Cash and Bank Balances | B28: =HYPERLINK("#\'Note_5_3_CashBank\'!A1", "5.3") -> 0 | C28: =TOT_Cash -> 175 | D28: =TOT_Cash_PY -> 155
A29: (d) Short-term Loans and Advances | B29: =HYPERLINK("#\'Note_5_4_STLA\'!A1", "5.4") -> 0 | C29: =TOT_STLA -> 0 | D29: =TOT_STLA_PY -> 0
A30: (e) Other Current Assets | B30: =HYPERLINK("#\'Note_5_5_OtherCA\'!A1", "5.5") -> 0 | C30: =TOT_OtherCA -> 0 | D30: =TOT_OtherCA_PY -> 0
A31: TOTAL ASSETS | C31: =C0+C0 -> 1210 | D31: =D0+D0 -> 1060
A33: Balance Check (Total Assets - Total Equity & Liabilities) | C33: =C31-C17 -> 0 | D33: =D31-D17 -> 0

Sheet 03_Profit_and_Loss
A1: SW INDIA | CHARTERED ACCOUNTANTS
A2: STATEMENT OF PROFIT AND LOSS FOR THE YEAR ENDED MARCH 31, 2025
A4: Particulars | B4: Note # | C4: Year Ended 31-Mar-2025 (CY) | D4: Year Ended 31-Mar-2024 (PY)
A5: I. Revenue from Operations | B5: =HYPERLINK("#\'Note_6_1_Revenue\'!A1", "6.1") -> 0 | C5: =-TOT_Revenue -> 850 | D5: =-TOT_Revenue_PY -> 700
A6: II. Other Income | B6: =HYPERLINK("#\'Note_6_2_OtherIncome\'!A1", "6.2") -> 0 | C6: =-TOT_OtherIncome -> 15 | D6: =-TOT_OtherIncome_PY -> 10
A7: III. Total Income (I + II) | C7: =C5+C6 -> 865 | D7: =D5+D6 -> 710
A8: IV. Expenses: | C8: 0 | D8: 0
A9: Cost of Materials Consumed | B9: =HYPERLINK("#\'Note_7_1_Material\'!A1", "7.1") -> 0 | C9: =TOT_Material -> 420 | D9: =TOT_Material_PY -> 350
A10: Purchases of Stock-in-Trade | B10: =HYPERLINK("#\'Note_7_1_Material\'!A1", "7.1") -> 0 | C10: =TOT_Material -> 0 | D10: =TOT_Material_PY -> 0
A11: Changes in Inventories | B11: =HYPERLINK("#\'Note_7_1_Material\'!A1", "7.1") -> 0 | C11: =TOT_Material -> 0 | D11: =TOT_Material_PY -> 0
A12: Employee Benefit Expenses | B12: =HYPERLINK("#\'Note_7_2_Employee\'!A1", "7.2") -> 0 | C12: =TOT_Employee -> 140 | D12: =TOT_Employee_PY -> 120
A13: Finance Costs | B13: =HYPERLINK("#\'Note_7_3_Finance\'!A1", "7.3") -> 0 | C13: =TOT_Finance -> 32 | D13: =TOT_Finance_PY -> 38
A14: Depreciation and Amortisation Expense | B14: =HYPERLINK("#\'Note_7_4_Depreciation\'!A1", "7.4") -> 0 | C14: =TOT_Depreciation -> 28 | D14: =TOT_Depreciation_PY -> 25
A15: Other Expenses | B15: =HYPERLINK("#\'Note_7_5_OtherExp\'!A1", "7.5") -> 0 | C15: =TOT_OtherExp -> 45 | D15: =TOT_OtherExp_PY -> 32
A16: Total Expenses (IV) | C16: =SUM(C9:C15) -> 665 | D16: =SUM(D9:D15) -> 565
A17: V. Profit Before Tax (III - IV) | C17: =C7-C16 -> 200 | D17: =D7-D16 -> 145
A18: VI. Tax Expense | B18: =HYPERLINK("#\'Note_7_6_Tax\'!A1", "7.6") -> 0 | C18: =-TOT_Tax -> -40 | D18: =-TOT_Tax_PY -> -30
A19: VII. Profit After Tax (V - VI) | C19: =C17-C18 -> 240 | D19: =D17-D18 -> 175

Sheet 04_Cash_Flow_Statement
A1: SW INDIA | CHARTERED ACCOUNTANTS
A2: CASH FLOW STATEMENT FOR THE YEAR ENDED MARCH 31, 2025
A4: Particulars | B4: CY | C4: PY
A5: A. CASH FLOW FROM OPERATING ACTIVITIES | B5: 0 | C5: 0
A6: Net Profit Before Tax | B6: 200 | C6: 145
A7: Non-Cash Adjustments: | B7: 0 | C7: 0
A8: Add: Depreciation and Amortisation | B8: 28 | C8: 25
A9: Add: Finance Costs (reclassified to Financing) | B9: 32 | C9: 38
A10: Non-Operating Adjustments: | B10: 0 | C10: 0
A11: Less: Interest and Dividend Income (reclassified to Investing) | B11: -15 | C11: 0
A12: Less: Profit on Sale of PPE (reclassified to Investing) | B12: 0 | C12: 0
A13: Add: Loss on Sale of PPE | B13: 0 | C13: 0
A14: Operating Profit before Working Capital Changes | B14: 245 | C14: 208
A15: Working Capital Changes: | B15: 0 | C15: 0
A16: (Increase) / Decrease in Inventories | B16: -25 | C16: 0
... A40: Reconciliation Difference (Nil if reconciled) | B40: 7 | C40: 0

Sheet 07_Financial_Ratios
A1: SW INDIA | CHARTERED ACCOUNTANTS
A2: FINANCIAL RATIOS
A4: Ratio Name | B4: Formula | C4: CY Value | D4: PY Value | E4: Variance
A5: Current Ratio | B5: Current Assets / Current Liabilities | C5: ='02_Balance_Sheet'!C0/'02_Balance_Sheet'!C0 -> 1.71 | D5: ='02_Balance_Sheet'!D0/'02_Balance_Sheet'!D0 -> 1.84
A6: Debt Equity Ratio | B6: Total Debt / Shareholders' Equity | C6: =(TOT_LTBorrow+TOT_STBorrow)/'02_Balance_Sheet'!C0 -> 0.49 | D6: =(TOT_LTBorrow_PY+TOT_STBorrow_PY)/'02_Balance_Sheet'!D0 -> 0.71
A7: Net Profit Ratio | B7: (Net Profit After Tax / Revenue) * 100 | C7: ='03_Profit_and_Loss'!C19/TOT_Revenue -> 28.24 | D7: ='03_Profit_and_Loss'!D19/TOT_Revenue_PY -> 25
A8: EBITDA Margin | B8: (EBITDA / Revenue) * 100 | C8: =('03_Profit_and_Loss'!C17+TOT_Finance+TOT_Depreciation)/TOT_Revenue -> 30.59 | D8: =('03_Profit_and_Loss'!D17+TOT_Finance_PY+TOT_Depreciation_PY)/TOT_Revenue_PY -> 29.71
A9: Return on Equity | B9: (Net Profit After Tax / Equity) * 100 | C9: ='03_Profit_and_Loss'!C19/'02_Balance_Sheet'!C0 -> 35.82 | D9: ='03_Profit_and_Loss'!D19/'02_Balance_Sheet'!D0 -> 34.65
A10: Trade Receivable Days | B10: (Trade Receivables / Revenue) * 365 | C10: =(TOT_Receivables/TOT_Revenue)*365 -> 75.15 | D10: =(TOT_Receivables_PY/TOT_Revenue_PY)*365 -> 73
A11: Trade Payable Days | B11: (Trade Payables / COGS) * 365 | C11: =(TOT_Payables/'03_Profit_and_Loss'!C9)*365 -> 160.77 | D11: =(TOT_Payables_PY/'03_Profit_and_Loss'!D9)*365 -> 151.21
A12: Inventory Days | B12: (Inventories / COGS) * 365 | C12: =(TOT_Inventory/'03_Profit_and_Loss'!C9)*365 -> 126.01 | D12: =(TOT_Inventory_PY/'03_Profit_and_Loss'!D9)*365 -> 125.14

Sheet 98_Tie_Out
A1: SW INDIA | CHARTERED ACCOUNTANTS
A2: TIE-OUT AND BALANCING
A4: Control ID | B4: Description | C4: Expected Value | D4: Computed Formula | E4: Variance | F4: Tie-Out Status
A5: CHK-01 | B5: Balance Sheet Balance Check (CY) | C5: 0 | D5: ='02_Balance_Sheet'!C31-'02_Balance_Sheet'!C17 -> 0 | E5: =D4-C4 -> 0 | F5: TALLIED
A6: CHK-02 | B6: Cash Flow Reconciliation Difference (CY) | C6: 0 | D6: 7 | E6: =D5-C5 -> 7 | F6: REVIEW REQUIRED

Sheet 99_Formula_Audit
A1: SW INDIA | CHARTERED ACCOUNTANTS
A2: FORMULA AUDIT LOG
A4: Sheet | B4: Cell Address | C4: Applied Excel Formula | D4: Resolved Value
A5: 91_Mapping | B5: H2 | C5: =SUMIFS('90_Trial_Balance'!$D:$D, '90_Trial_Balance'!$A:$A, $A2) -> 0 | D5: -100
A6: 91_Mapping | B6: I2 | C6: =SUMIFS('90_Trial_Balance'!$E:$E, '90_Trial_Balance'!$A:$A, $A2) -> 0 | D6: -100
A7: 91_Mapping | B7: H3 | C7: =SUMIFS('90_Trial_Balance'!$D:$D, '90_Trial_Balance'!$A:$A, $A3) -> 0 | D7: -150
A8: 91_Mapping | B8: I3 | C8: =SUMIFS('90_Trial_Balance'!$E:$E, '90_Trial_Balance'!$A:$A, $A3) -> 0 | D8: -120
A9: 91_Mapping | B9: H4 | C9: =SUMIFS('90_Trial_Balance'!$D:$D, '90_Trial_Balance'!$A:$A, $A4) -> 0 | D9: -180
A10: 91_Mapping | B10: I4 | C10: =SUMIFS('90_Trial_Balance'!$E:$E, '90_Trial_Balance'!$A:$A, $A4) -> 0 | D10: -110
A11: 91_Mapping | B11: H5 | C11: =SUMIFS('90_Trial_Balance'!$D:$D, '90_Trial_Balance'!$A:$A, $A5) -> 0 | D11: -250
A12: 91_Mapping | B12: I5 | C12: =SUMIFS('90_Trial_Balance'!$E:$E, '90_Trial_Balance'!$A:$A, $A5) -> 0 | D12: -300
A13: 91_Mapping | B13: H6 | C13: =SUMIFS('90_Trial_Balance'!$D:$D, '90_Trial_Balance'!$A:$A, $A6) -> 0 | D13: -80
A14: 91_Mapping | B14: I6 | C14: =SUMIFS('90_Trial_Balance'!$E:$E, '90_Trial_Balance'!$A:$A, $A6) -> 0 | D14: -60
A15: 91_Mapping | B15: H7 | C15: =SUMIFS('90_Trial_Balance'!$D:$D, '90_Trial_Balance'!$A:$A, $A7) -> 0 | D15: -65
A16: 91_Mapping | B16: I7 | C16: =SUMIFS('90_Trial_Balance'!$E:$E, '90_Trial_Balance'!$A:$A, $A7) -> 0 | D16: -50
A17: 91_Mapping | B17: H8 | C17: =SUMIFS('90_Trial_Balance'!$D:$D, '90_Trial_Balance'!$A:$A, $A8) -> 0 | D17: -120
A18: 91_Mapping | B18: I8 | C18: =SUMIFS('90_Trial_Balance'!$E:$E, '90_Trial_Balance'!$A:$A, $A8) -> 0 | D18: -95
A19: 91_Mapping | B19: H9 | C19: =SUMIFS('90_Trial_Balance'!$D:$D, '90_Trial_Balance'!$A:$A, $A9) -> 0 | D19: -25
A20: 91_Mapping | B20: I9 | C20: =SUMIFS('90_Trial_Balance'!$E:$E, '90_Trial_Balance'!$A:$A, $A9) -> 0 | D20: -20
A21: 91_Mapping | B21: H10 | C21: =SUMIFS('90_Trial_Balance'!$D:$D, '90_Trial_Balance'!$A:$A, $A10) -> 0 | D21: -40
A22: 91_Mapping | B22: I10 | C22: =SUMIFS('90_Trial_Balance'!$E:$E, '90_Trial_Balance'!$A:$A, $A10) -> 0 | D22: -30
A23: 91_Mapping | B23: H11 | C23: =SUMIFS('90_Trial_Balance'!$D:$D, '90_Trial_Balance'!$A:$A, $A11) -> 0 | D23: 450
A24: 91_Mapping | B24: I11 | C24: =SUMIFS('90_Trial_Balance'!$E:$E, '90_Trial_Balance'!$A:$A, $A11) -> 0 | D24: 450
A25: 91_Mapping | B25: H12 | C25: =SUMIFS('90_Trial_Balance'!$D:$D, '90_Trial_Balance'!$A:$A, $A12) -> 0 | D25: 220
A26: 91_Mapping | B26: I12 | C26: =SUMIFS('90_Trial_Balance'!$E:$E, '90_Trial_Balance'!$A:$A, $A12) -> 0 | D26: 180
A27: 91_Mapping | B27: H13 | C27: =SUMIFS('90_Trial_Balance'!$D:$D, '90_Trial_Balance'!$A:$A, $A13) -> 0 | D27: 45
A28: 91_Mapping | B28: I13 | C28: =SUMIFS('90_Trial_Balance'!$E:$E, '90_Trial_Balance'!$A:$A, $A13) -> 0 | D28: 15
A29: 91_Mapping | B29: H14 | C29: =SUMIFS('90_Trial_Balance'!$D:$D, '90_Trial_Balance'!$A:$A, $A14) -> 0 | D29: 85
A30: 91_Mapping | B30: I14 | C30: =SUMIFS('90_Trial_Balance'!$E:$E, '90_Trial_Balance'!$A:$A, $A14) -> 0 | D30: 70
A31: 91_Mapping | B31: H15 | C31: =SUMIFS('90_Trial_Balance'!$D:$D, '90_Trial_Balance'!$A:$A, $A15) -> 0 | D31: 60
A32: 91_Mapping | B32: I15 | C32: =SUMIFS('90_Trial_Balance'!$E:$E, '90_Trial_Balance'!$A:$A, $A15) -> 0 | D32: 50
A33: 91_Mapping | B33: H16 | C33: =SUMIFS('90_Trial_Balance'!$D:$D, '90_Trial_Balance'!$A:$A, $A16) -> 0 | D33: 175
A34: 91_Mapping | B34: I16 | C34: =SUMIFS('90_Trial_Balance'!$E:$E, '90_Trial_Balance'!$A:$A, $A16) -> 0 | D34: 140
A35: 91_Mapping | B35: H17 | C35: =SUMIFS('90_Trial_Balance'!$D:$D, '90_Trial_Balance'!$A:$A, $A17) -> 0 | D35: 165
A36: 91_Mapping | B36: I17 | C36: =SUMIFS('90_Trial_Balance'!$E:$E, '90_Trial_Balance'!$A:$A, $A17) -> 0 | D36: 150
A37: 91_Mapping | B37: H18 | C37: =SUMIFS('90_Trial_Balance'!$D:$D, '90_Trial_Balance'!$A:$A, $A18) -> 0 | D37: 10
A38: 91_Mapping | B38: I18 | C38: =SUMIFS('90_Trial_Balance'!$E:$E, '90_Trial_Balance'!$A:$A, $A18) -> 0 | D38: 5
A39: 91_Mapping | B39: H19 | C39: =SUMIFS('90_Trial_Balance'!$D:$D, '90_Trial_Balance'!$A:$A, $A19) -> 0 | D39: -850
A40: 91_Mapping | B40: I19 | C40: =SUMIFS('90_Trial_Balance'!$E:$E, '90_Trial_Balance'!$A:$A, $A19) -> 0 | D40: -700
A41: 91_Mapping | B41: H20 | C41: =SUMIFS('90_Trial_Balance'!$D:$D, '90_Trial_Balance'!$A:$A, $A20) -> 0 | D41: -15
...

Sheet Sign_Off
A1: SW INDIA | CHARTERED ACCOUNTANTS
A2: APPROVAL AND SIGN-OFF
A4: For SW INDIA Chartered Accountants | B4: For Apex Engineering Industries Limited Board of Directors
A8: ________________________ | B8: ________________________
A9: Partner | B9: Director
A10: Membership No: 123456 | B10: DIN: 09876543
